File: data/hpybf4-AA-cons-P.csv
Elapsed Time,Sample Temp,Heater Temp,Pressure,Rotor Speed,Shear Rate,Shear Stress,Viscosity,Temperature Setpoint,T Output,Bob Deflection,Torque,Motor Temp,Raw Encoder Value,Aux1
(hh:mm:ss),(°F),(°F),(PSIg),(RPM),(1/s),(dyne/cm²),(cP),(°F),(%),(deg.),(dyne-cm),(°C),(cts),
1.15741E-05,73.7,73,106,0,0,0.0001,0,32,0,0,0.017,30,0,0
0.000104167,73.7,73,106,58.8,50,181.6053,363.2105,77,3.2,12.672,22222.72,30,352,0
0.000196759,73.7,74,106,58.8,50,181.6053,363.2105,77,0,12.672,22222.72,30,352,0
0.000300926,73.7,74,106,58.8,50,181.6053,363.2105,77,0,12.672,22222.72,30,352,0
0.000393519,73.7,74,106,58.8,50,181.0959,362.1917,77,0,12.636,22160.39,30,351,0
0.000532407,73.7,74,112,58.8,50,180.5865,361.1729,77,0,12.6,22098.05,30,350,0
0.000625,73.7,74,112,58.8,50,180.077,360.1541,77,0,12.564,22035.71,30,349,0
0.000740741,73.7,74,112,58.8,50,180.077,360.1541,77,0,12.564,22035.71,30,349,0
0.000833333,73.7,74,112,58.8,50,179.5676,359.1353,77,0,12.528,21973.38,30,348,0
0.000925926,73.7,74,112,58.8,50,179.5676,359.1353,77,0,12.528,21973.38,30,348,0
0.001018519,73.7,74,112,58.8,50,179.5676,359.1353,77,0,12.528,21973.38,30,348,0
0.001111111,73.7,74,115,58.8,50,179.0582,358.1165,77,0,12.492,21911.05,30,347,0
0.001203704,73.7,74,115,58.8,50,179.0582,358.1165,77,0,12.492,21911.05,30,347,0
0.001296296,73.9,74,115,58.8,50,178.5488,357.0977,77,0.2,12.456,21848.71,30,346,0
0.001400463,73.9,74,115,58.8,50,178.5488,357.0977,77,0.1,12.456,21848.71,30,346,0
0.001493056,73.9,74,115,58.8,50,179.0582,358.1165,77,0.5,12.492,21911.05,30,347,0
0.001585648,73.9,74,115,58.8,50,178.5488,357.0977,77,0.7,12.456,21848.71,30,346,0
0.001678241,73.9,74,118,58.8,50,178.5488,357.0977,77,0.3,12.456,21848.71,30,346,0
0.001770833,73.9,74,118,58.8,50,178.5488,357.0977,77,0.6,12.456,21848.71,30,346,0
0.001863426,74.1,75,118,58.8,50,178.0394,356.0788,77,0.5,12.42,21786.38,30,345,0
0.001956019,74.1,75,118,58.8,50,178.0394,356.0788,77,0.4,12.42,21786.38,30,345,0
0.002048611,74.1,75,118,58.8,50,178.0394,356.0788,77,0.9,12.42,21786.38,30,345,0
0.002141204,74.1,75,118,117.61,100,351.879,351.879,77,0.5,24.408,43058.83,30,678,0
0.002233796,74.1,75,118,88.2,75,264.0696,352.0929,77,0.6,18.396,32313.74,30,511,0
0.002337963,74.1,75,121,58.8,50,192.3028,384.6056,77,0,13.428,23531.76,30,373,0
0.002430556,74.1,76,121,29.4,25,89.3597,357.4387,77,0,6.228,10934.79,30,173,0
0.002523148,74.1,76,121,29.4,25,88.8435,355.374,77,0,6.192,10871.62,30,172,0
0.002615741,74.1,76,121,58.8,50,172.436,344.8719,77,0.7,12.024,21100.69,30,334,0
0.002708333,74.1,76,121,88.2,75,256.7383,342.3177,77,0.9,17.892,31416.62,30,497,0
0.002800926,74.1,76,121,117.61,100,341.2253,341.2253,100,38.2,23.688,41755.15,30,658,0
0.002893519,74.3,82,121,58.8,50,171.4171,342.8343,150,70,11.952,20976.02,30,332,0
0.002997685,74.3,97,127,58.8,50,165.3043,330.6086,150,37.6,11.52,20228,30,320,0
0.003090278,74.3,112,127,58.8,50,151.5482,303.0965,149,11.4,10.548,18544.7,30,293,0
0.00318287,74.3,122,127,58.8,50,135.7533,271.5066,149,23.9,9.432,16611.89,30,262,0
0.003275463,74.6,126,127,58.8,50,118.63,237.2601,149,29.7,8.244,14516.55,30,229,0
0.003368056,74.6,130,130,58.8,50,107.6057,215.2114,149,22.8,7.488,13167.52,30,208,0
0.003460648,75.2,136,130,58.8,50,96.0702,192.1405,148,14.5,6.696,11755.95,30,186,0
0.003553241,75.9,139,130,58.8,50,86.7787,173.5574,148,15.5,6.048,10618.96,30,168,0
0.003645833,76.4,141,130,58.8,50,80.5844,161.1687,148,16,5.616,9860.968,30,156,0
0.00375,77.1,144,130,58.8,50,74.9062,149.8124,147,11.5,5.22,9166.142,30,145,0
0.003842593,78.2,145,130,58.8,50,69.7442,139.4885,147,10.4,4.86,8534.481,30,135,0
0.003935185,79.1,146,130,58.8,50,65.6147,131.2293,147,10.7,4.572,8029.153,30,127,0
0.004027778,80.4,147,134,58.8,50,62.4964,124.9927,147,10.2,4.356,7647.569,30,121,0
0.00412037,81.5,148,134,58.8,50,60.4105,120.8209,146,7.2,4.212,7392.325,30,117,0
0.004212963,82.7,149,134,58.8,50,58.3246,116.6492,146,7.9,4.068,7137.08,30,113,0
0.004305556,84.2,149,130,58.8,50,55.1958,110.3916,146,7.7,3.852,6754.213,30,107,0
0.004398148,85.2,149,134,58.8,50,54.1529,108.3057,146,7.5,3.78,6626.59,30,105,0
0.004502315,86.3,149,134,58.8,50,53.1099,106.2198,145,5.1,3.708,6498.968,30,103,0
0.004594907,87.8,149,134,58.8,50,52.067,104.134,145,5.9,3.636,6371.346,30,101,0
0.0046875,89,149,134,58.8,50,51.5455,103.091,145,6.1,3.6,6307.535,30,100,0
0.004780093,90.3,149,134,58.8,50,51.024,102.0481,144,3.8,3.564,6243.724,30,99,0
0.004872685,91.5,149,134,58.8,50,49.9811,99.9622,144,4.1,3.492,6116.102,30,97,0
0.004965278,92.8,148,134,58.8,50,49.4596,98.9193,144,4.8,3.456,6052.291,30,96,0
0.00505787,93.9,148,134,58.8,50,48.9382,97.8763,144,4.8,3.42,5988.479,30,95,0
0.005162037,94.9,148,134,58.8,50,48.4167,96.8334,143,2.8,3.384,5924.668,30,94,0
0.00525463,96.2,147,134,58.8,50,47.8952,95.7905,143,3.1,3.348,5860.857,30,93,0
0.005347222,97.3,147,134,58.8,50,47.3738,94.7475,143,4.6,3.312,5797.046,30,92,0
0.005439815,98.5,146,134,58.8,50,46.8523,93.7046,143,4.1,3.276,5733.234,30,91,0
0.005532407,99.4,146,134,58.8,50,46.3308,92.6617,142,2.2,3.24,5669.423,30,90,0
0.005625,100.3,145,134,58.8,50,46.3308,92.6617,142,3.2,3.24,5669.423,30,90,0
0.005717593,101.6,145,134,58.8,50,45.8094,91.6187,142,4.3,3.204,5605.612,30,89,0
0.005821759,102.5,145,134,58.8,50,45.2879,90.5758,141,2.1,3.168,5541.801,30,88,0
0.005914352,103.4,144,134,58.8,50,45.2879,90.5758,141,2.7,3.168,5541.801,30,88,0
0.006006944,104.5,144,134,58.8,50,44.7664,89.5329,141,3.6,3.132,5477.99,30,87,0
0.006099537,105.4,143,134,58.8,50,44.7664,89.5329,141,3.7,3.132,5477.99,30,87,0
0.00619213,105.9,143,134,58.8,50,44.245,88.4899,140,1.3,3.096,5414.179,30,86,0
0.006284722,107,143,134,58.8,50,44.245,88.4899,140,2.5,3.096,5414.179,30,86,0
0.006388889,107.7,142,134,58.8,50,43.7235,87.447,140,3.3,3.06,5350.368,30,85,0
0.006481481,108.4,142,134,58.8,50,43.7235,87.447,140,3.2,3.06,5350.368,30,85,0
0.006574074,109.3,142,134,58.8,50,43.202,86.4041,139,1.5,3.024,5286.557,30,84,0
0.006666667,109.9,141,134,58.8,50,43.202,86.4041,139,2.3,3.024,5286.557,30,84,0
0.006770833,110.8,141,134,58.8,50,42.6806,85.3611,139,2.9,2.988,5222.745,30,83,0
0.006863426,111.5,140,134,58.8,50,41.6376,83.2752,139,2.9,2.916,5095.123,30,81,0
0.006956019,112,140,134,58.8,50,41.6376,83.2752,138,1.4,2.916,5095.123,30,81,0
0.007060185,112.6,140,134,58.8,50,41.6376,83.2752,138,2.3,2.916,5095.123,30,81,0
0.007395833,114.9,139,134,58.8,50,41.1162,82.2323,138,2.5,2.88,5031.312,30,80,0
0.007488426,115.4,139,134,58.8,50,41.1162,82.2323,126,0,2.88,5031.312,30,80,0
0.007592593,116,138,134,58.8,50,41.1162,82.2323,125,0,2.88,5031.312,30,80,0
0.007685185,116.3,137,134,58.8,50,40.5947,81.1894,125,0,2.844,4967.501,30,79,0
0.007777778,116.9,136,134,58.8,50,40.5947,81.1894,125,0,2.844,4967.501,30,79,0
0.00787037,117.4,136,134,58.8,50,40.5947,81.1894,125,0,2.844,4967.501,30,79,0
0.007962963,117.8,135,134,58.8,50,40.5947,81.1894,125,0,2.844,4967.501,30,79,0
0.00806713,118.3,134,134,58.8,50,40.5947,81.1894,125,0,2.844,4967.501,30,79,0
0.008159722,118.7,134,134,58.8,50,40.5947,81.1894,125,0,2.844,4967.501,30,79,0
0.008252315,119,133,134,58.8,50,40.5947,81.1894,125,0,2.844,4967.501,30,79,0
0.008344907,119.4,133,134,58.8,50,40.5947,81.1894,125,0,2.844,4967.501,30,79,0
0.0084375,119.9,132,134,58.8,50,40.5947,81.1894,125,0,2.844,4967.501,30,79,0
0.008530093,120.1,132,134,58.8,50,40.5947,81.1894,125,0,2.844,4967.501,30,79,0
0.008634259,120.5,131,134,58.8,50,40.5947,81.1894,124,0,2.844,4967.501,30,79,0
0.008726852,120.8,131,134,58.8,50,40.5947,81.1894,124,0,2.844,4967.501,30,79,0
0.008819444,121,130,134,58.8,50,40.5947,81.1894,124,0,2.844,4967.501,30,79,0
0.008912037,121.4,130,134,58.8,50,40.5947,81.1894,124,0,2.844,4967.501,30,79,0
0.00900463,121.6,129,134,58.8,50,40.5947,81.1894,124,0,2.844,4967.501,30,79,0
0.009097222,121.7,129,134,58.8,50,40.5947,81.1894,124,0,2.844,4967.501,30,79,0
0.009201389,121.7,128,134,58.8,50,40.5947,81.1894,124,0,2.844,4967.501,30,79,0
0.009293981,122.1,128,134,58.8,50,40.5947,81.1894,124,0,2.844,4967.501,30,79,0
0.009386574,122.3,128,130,58.8,50,40.5947,81.1894,124,0,2.844,4967.501,30,79,0
0.009490741,122.5,127,130,58.8,50,40.5947,81.1894,124,0,2.844,4967.501,30,79,0
0.009583333,122.5,127,134,58.8,50,40.5947,81.1894,124,0,2.844,4967.501,30,79,0
0.009675926,122.6,127,134,58.8,50,40.5947,81.1894,123,0,2.844,4967.501,30,79,0
0.009768519,122.8,126,130,58.8,50,40.5947,81.1894,123,0,2.844,4967.501,30,79,0
0.009861111,122.8,126,130,58.8,50,40.5947,81.1894,123,0,2.844,4967.501,30,79,0
0.009953704,123,126,130,58.8,50,40.5947,81.1894,123,0,2.844,4967.501,30,79,0
0.01005787,123.2,125,127,58.8,50,40.5947,81.1894,123,0,2.844,4967.501,30,79,0
0.010150463,123.2,125,127,58.8,50,40.5947,81.1894,123,0,2.844,4967.501,30,79,0
0.010243056,123.2,125,121,58.8,50,40.5947,81.1894,123,0,2.844,4967.501,30,79,0
0.010335648,123.4,125,121,58.8,50,40.5947,81.1894,123,0,2.844,4967.501,30,79,0
0.010428241,123.4,124,118,58.8,50,41.1162,82.2323,123,0,2.88,5031.312,30,80,0
0.010532407,123.5,124,118,58.8,50,41.1162,82.2323,123,0,2.88,5031.312,30,80,0
0.010625,123.5,124,118,58.8,50,41.1162,82.2323,123,0,2.88,5031.312,30,80,0
0.010717593,123.5,124,115,58.8,50,41.1162,82.2323,122,0,2.88,5031.312,30,80,0
0.010810185,123.5,123,115,58.8,50,41.1162,82.2323,122,0,2.88,5031.312,30,80,0
0.010914352,123.5,123,115,58.8,50,41.1162,82.2323,122,0,2.88,5031.312,30,80,0
0.011006944,123.5,123,115,58.8,50,41.1162,82.2323,122,0,2.88,5031.312,30,80,0
0.011099537,123.5,123,115,58.8,50,41.1162,82.2323,122,0,2.88,5031.312,30,80,0
0.01119213,123.5,123,112,58.8,50,41.1162,82.2323,122,0,2.88,5031.312,30,80,0
0.011284722,123.5,122,112,58.8,50,41.1162,82.2323,122,0,2.88,5031.312,30,80,0
0.011377315,123.5,122,112,58.8,50,41.1162,82.2323,122,0,2.88,5031.312,30,80,0
0.011469907,123.5,122,112,58.8,50,41.1162,82.2323,122,0,2.88,5031.312,30,80,0
0.0115625,123.5,122,106,58.8,50,41.1162,82.2323,122,0,2.88,5031.312,30,80,0
0.011666667,123.5,122,112,58.8,50,41.1162,82.2323,122,0,2.88,5031.312,30,80,0
0.011759259,123.5,122,112,58.8,50,41.1162,82.2323,121,0,2.88,5031.312,30,80,0
0.011851852,123.5,122,112,58.8,50,41.1162,82.2323,121,0,2.88,5031.312,30,80,0
0.011944444,123.5,122,106,58.8,50,41.1162,82.2323,121,0,2.88,5031.312,30,80,0
0.012037037,123.5,121,106,58.8,50,41.1162,82.2323,121,0,2.88,5031.312,30,80,0
0.01212963,123.4,121,106,58.8,50,41.1162,82.2323,121,0,2.88,5031.312,30,80,0
0.012222222,123.2,121,106,58.8,50,41.1162,82.2323,121,0.3,2.88,5031.312,30,80,0
0.012326389,123.4,121,106,58.8,50,41.6376,83.2752,121,0.5,2.916,5095.123,30,81,0
0.012418981,123.2,121,102,58.8,50,41.6376,83.2752,121,0.4,2.916,5095.123,30,81,0
0.012511574,123.2,121,102,58.8,50,41.6376,83.2752,121,0,2.916,5095.123,30,81,0
0.012615741,123,121,106,58.8,50,41.6376,83.2752,121,0,2.916,5095.123,30,81,0
0.012708333,123,121,102,58.8,50,41.6376,83.2752,121,0,2.916,5095.123,30,81,0
0.012800926,123,121,102,58.8,50,41.6376,83.2752,120,0,2.916,5095.123,30,81,0
0.012893519,123,121,102,58.8,50,41.6376,83.2752,120,0,2.916,5095.123,30,81,0
0.012986111,122.8,121,102,58.8,50,41.6376,83.2752,120,0,2.916,5095.123,30,81,0
0.013090278,122.8,121,102,58.8,50,41.6376,83.2752,120,0,2.916,5095.123,30,81,0
0.01318287,122.8,120,102,58.8,50,41.6376,83.2752,120,0.1,2.916,5095.123,30,81,0
0.013275463,122.8,120,102,117.61,100,81.6167,81.6167,120,0.1,5.688,9987.3,30,158,0
0.013368056,122.6,120,102,88.2,75,77.4872,77.4872,120,0.7,5.4,9481.972,30,150,0
0.013460648,122.6,120,102,58.8,50,41.1162,82.2323,120,0.3,2.88,5031.312,30,80,0
0.013553241,122.6,120,102,29.4,25,22.5253,90.1011,120,0.4,1.584,2756.378,30,44,0
0.013645833,122.6,120,102,58.8,50,39.5518,79.1035,120,0.5,2.772,4839.878,30,77,0
0.013738426,122.5,120,102,88.2,75,58.3246,77.7661,120,0.5,4.068,7137.08,30,113,0
0.013842593,122.6,120,99,117.61,100,76.4548,76.4548,120,0.2,5.328,9355.64,30,148,0
0.013935185,122.3,123,102,58.8,50,44.245,88.4899,243,70,3.096,5414.179,30,86,0
0.014027778,122.3,136,102,58.8,50,40.0732,80.1464,250,70,2.808,4903.69,30,78,0
0.01412037,122.3,153,102,58.8,50,39.0303,78.0606,250,70,2.736,4776.067,30,76,0
0.014212963,122.3,174,102,58.8,50,36.9444,73.8888,249,65,2.592,4520.823,30,72,0
0.014305556,122.3,190,102,58.8,50,33.2941,66.5883,249,48.5,2.34,4074.145,30,65,0
0.014398148,122.6,203,99,58.8,50,30.2043,60.4086,249,43.9,2.124,3696.047,30,59,0
0.014502315,123,213,102,58.8,50,27.6446,55.2892,248,42.8,1.944,3382.824,30,54,0
0.014594907,124.1,220,102,58.8,50,25.0849,50.1699,248,40.1,1.764,3069.601,30,49,0
0.0146875,125,227,102,58.8,50,23.5491,47.0983,248,35.6,1.656,2881.667,30,46,0
0.014780093,126.4,233,102,58.8,50,22.0133,44.0267,248,31.1,1.548,2693.734,30,43,0
0.014872685,128,238,102,58.8,50,20.9895,41.9789,247,27.1,1.476,2568.445,30,41,0
0.014965278,129.8,241,102,58.8,50,19.9656,39.9312,247,25.6,1.404,2443.156,30,39,0
0.01505787,131.4,244,102,58.8,50,18.9417,37.8835,247,23.4,1.332,2317.866,30,37,0
0.015150463,133.2,247,102,58.8,50,18.4298,36.8596,246,20,1.296,2255.222,30,36,0
0.01525463,135.6,249,102,58.8,50,17.9179,35.8357,246,18.8,1.26,2192.577,30,35,0
0.015347222,137.6,250,102,58.8,50,17.4059,34.8118,246,18.4,1.224,2129.933,30,34,0
0.015439815,139.9,251,102,58.8,50,16.894,33.788,246,16.7,1.188,2067.288,30,33,0
0.015532407,141.9,252,102,58.8,50,16.894,33.788,245,14.1,1.188,2067.288,30,33,0
0.015625,143.8,252,102,58.8,50,16.3821,32.7641,245,13.7,1.152,2004.643,30,32,0
0.015717593,146.2,252,102,58.8,50,16.3821,32.7641,245,13.6,1.152,2004.643,30,32,0
0.015810185,148,252,102,58.8,50,16.3821,32.7641,245,12.8,1.152,2004.643,30,32,0
0.015902778,150,252,102,58.8,50,15.8701,31.7402,244,10.6,1.116,1941.999,30,31,0
0.01599537,152.1,252,102,58.8,50,15.8701,31.7402,244,10.9,1.116,1941.999,30,31,0
0.016099537,153.9,252,102,58.8,50,15.8701,31.7402,244,11,1.116,1941.999,30,31,0
0.01619213,155.7,251,102,58.8,50,15.8701,31.7402,244,10.5,1.116,1941.999,30,31,0
0.016284722,157.9,251,102,58.8,50,15.3582,30.7164,243,8.7,1.08,1879.354,30,30,0
0.016377315,159.5,251,102,58.8,50,15.3582,30.7164,243,8.8,1.08,1879.354,30,30,0
0.016469907,161.1,250,102,58.8,50,15.3582,30.7164,243,9.7,1.08,1879.354,30,30,0
0.0165625,163.1,249,106,58.8,50,15.3582,30.7164,242,7.7,1.08,1879.354,30,30,0
0.016655093,164.7,249,102,58.8,50,15.3582,30.7164,242,7.6,1.08,1879.354,30,30,0
0.016747685,166.3,248,102,58.8,50,15.3582,30.7164,242,7.9,1.08,1879.354,30,30,0
0.016851852,168.1,248,102,58.8,50,14.8463,29.6925,242,8.6,1.044,1816.71,30,29,0
0.016944444,169.6,247,102,58.8,50,14.8463,29.6925,241,6.9,1.044,1816.71,30,29,0
0.017037037,171.2,247,102,58.8,50,14.8463,29.6925,241,7.2,1.044,1816.71,30,29,0
0.01712963,173,246,102,58.8,50,14.8463,29.6925,241,7.8,1.044,1816.71,30,29,0
0.017222222,174.4,245,102,58.8,50,14.8463,29.6925,241,7.9,1.044,1816.71,30,29,0
0.017314815,175.8,245,102,58.8,50,14.8463,29.6925,240,6.1,1.044,1816.71,30,29,0
0.017407407,177.5,244,102,58.8,50,14.8463,29.6925,240,7.2,1.044,1816.71,30,29,0
0.0175,178.7,244,102,58.8,50,14.8463,29.6925,240,7.2,1.044,1816.71,30,29,0
0.017604167,180,243,102,58.8,50,14.8463,29.6925,239,5.4,1.044,1816.71,30,29,0
0.017696759,181.2,243,102,58.8,50,14.3343,28.6686,239,5.8,1.008,1754.065,30,28,0
0.017789352,182.7,242,102,58.8,50,14.3343,28.6686,239,6.7,1.008,1754.065,30,28,0
0.017881944,183.9,242,102,58.8,50,14.3343,28.6686,239,6.8,1.008,1754.065,30,28,0
0.017974537,185.4,242,102,58.8,50,14.3343,28.6686,238,4.8,1.008,1754.065,30,28,0
0.01806713,186.6,241,102,58.8,50,13.8224,27.6448,238,5.3,0.972,1691.421,30,27,0
0.018159722,187.7,241,102,58.8,50,13.8224,27.6448,238,6.4,0.972,1691.421,30,27,0
0.018263889,189,240,102,58.8,50,13.8224,27.6448,238,6,0.972,1691.421,30,27,0
0.018356481,190.1,240,102,58.8,50,13.8224,27.6448,237,4.6,0.972,1691.421,30,27,0
0.018449074,191.3,240,102,58.8,50,13.8224,27.6448,237,5.6,0.972,1691.421,30,27,0
0.018541667,192.2,239,102,58.8,50,13.8224,27.6448,237,6.4,0.972,1691.421,30,27,0
0.018634259,193.3,239,102,58.8,50,13.8224,27.6448,236,4.1,0.972,1691.421,30,27,0
0.018726852,194.2,239,102,58.8,50,13.8224,27.6448,236,4.5,0.972,1691.421,30,27,0
0.018819444,195.4,238,102,58.8,50,13.8224,27.6448,236,5.2,0.972,1691.421,30,27,0
0.018912037,196.3,238,102,58.8,50,13.8224,27.6448,236,5.9,0.972,1691.421,30,27,0
0.019016204,197.2,237,102,58.8,50,13.8224,27.6448,235,4,0.972,1691.421,30,27,0
0.019108796,198.3,237,102,58.8,50,13.8224,27.6448,235,4.3,0.972,1691.421,30,27,0
0.019201389,199,237,102,58.8,50,13.8224,27.6448,235,5.1,0.972,1691.421,30,27,0
0.019293981,199.9,236,102,58.8,50,13.8224,27.6448,235,5.4,0.972,1691.421,30,27,0
0.019386574,200.8,236,102,58.8,50,13.8224,27.6448,234,3.7,0.972,1691.421,30,27,0
0.019479167,201.4,236,106,58.8,50,13.8224,27.6448,234,4.5,0.972,1691.421,30,27,0
0.019571759,202.5,235,106,58.8,50,13.8224,27.6448,234,5.1,0.972,1691.421,30,27,0
0.019664352,203.2,235,102,58.8,50,13.8224,27.6448,233,5.1,0.972,1691.421,30,27,0
0.019768519,203.7,235,106,58.8,50,13.8224,27.6448,233,3.3,0.972,1691.421,30,27,0
0.019861111,204.6,234,106,58.8,50,13.8224,27.6448,233,4.7,0.972,1691.421,30,27,0
0.019953704,205.2,234,106,58.8,50,13.8224,27.6448,233,5,0.972,1691.421,30,27,0
0.020046296,206.1,234,106,58.8,50,13.3104,26.6209,232,3.4,0.936,1628.776,30,26,0
0.020150463,206.6,234,106,58.8,50,13.3104,26.6209,232,3.4,0.936,1628.776,30,26,0
0.020243056,207.1,233,106,58.8,50,13.3104,26.6209,232,4.7,0.936,1628.776,30,26,0
0.020335648,207.9,233,106,58.8,50,13.3104,26.6209,232,4.3,0.936,1628.776,30,26,0
0.020428241,208.2,233,106,58.8,50,13.3104,26.6209,231,2.8,0.936,1628.776,30,26,0
0.020520833,208.9,232,112,58.8,50,13.3104,26.6209,231,3.7,0.936,1628.776,30,26,0
0.020613426,209.5,232,106,58.8,50,13.3104,26.6209,231,4.8,0.936,1628.776,30,26,0
0.020717593,210,232,106,58.8,50,13.3104,26.6209,231,4,0.936,1628.776,30,26,0
0.020810185,210.4,232,112,58.8,50,13.3104,26.6209,230,2.5,0.936,1628.776,30,26,0
0.020902778,211.1,231,106,58.8,50,13.3104,26.6209,230,3.7,0.936,1628.776,30,26,0
0.02099537,211.4,231,106,58.8,50,13.3104,26.6209,230,3.9,0.936,1628.776,30,26,0
0.021087963,212,231,106,58.8,50,13.3104,26.6209,229,2.3,0.936,1628.776,30,26,0
0.021180556,212.3,231,112,58.8,50,13.3104,26.6209,229,2.5,0.936,1628.776,30,26,0
0.021273148,212.7,230,112,58.8,50,13.3104,26.6209,229,3.6,0.936,1628.776,30,26,0
0.021365741,213.2,230,112,58.8,50,13.3104,26.6209,229,4,0.936,1628.776,30,26,0
0.021469907,213.6,230,106,58.8,50,13.3104,26.6209,228,1.9,0.936,1628.776,30,26,0
0.0215625,214,229,112,58.8,50,13.3104,26.6209,228,2.5,0.936,1628.776,30,26,0
0.021655093,214.3,229,112,58.8,50,13.3104,26.6209,228,4,0.936,1628.776,30,26,0
0.021747685,214.7,229,112,58.8,50,13.3104,26.6209,227,2.2,0.936,1628.776,30,26,0
0.021840278,214.9,228,112,58.8,50,13.3104,26.6209,227,2.2,0.936,1628.776,30,26,0
0.02193287,215.2,228,112,58.8,50,13.3104,26.6209,227,3.6,0.936,1628.776,30,26,0
0.022025463,215.6,228,112,58.8,50,13.3104,26.6209,227,3.1,0.936,1628.776,30,26,0
0.022118056,215.8,228,115,58.8,50,13.3104,26.6209,226,1.6,0.936,1628.776,30,26,0
0.022222222,216.1,227,112,58.8,50,13.3104,26.6209,226,2.1,0.936,1628.776,30,26,0
0.022314815,216.3,227,112,58.8,50,13.3104,26.6209,226,2.6,0.936,1628.776,30,26,0
0.022407407,216.7,227,115,58.8,50,13.3104,26.6209,226,3.3,0.936,1628.776,30,26,0
0.022511574,216.8,226,115,58.8,50,13.3104,26.6209,225,1.6,0.936,1628.776,30,26,0
0.022604167,217,226,115,58.8,50,13.3104,26.6209,225,2.1,0.936,1628.776,30,26,0
0.022696759,217.2,226,115,58.8,50,13.3104,26.6209,225,3.3,0.936,1628.776,30,26,0
0.022789352,217.6,226,115,58.8,50,13.3104,26.6209,224,1.3,0.936,1628.776,30,26,0
0.022881944,217.6,225,115,58.8,50,13.3104,26.6209,224,1.6,0.936,1628.776,30,26,0
0.022974537,217.9,225,115,58.8,50,13.3104,26.6209,224,2.5,0.936,1628.776,30,26,0
0.02306713,217.9,225,115,58.8,50,13.3104,26.6209,224,3.1,0.936,1628.776,30,26,0
0.023159722,218.1,224,115,58.8,50,13.3104,26.6209,223,1.1,0.936,1628.776,30,26,0
0.023263889,218.5,224,115,58.8,50,13.3104,26.6209,223,1.7,0.936,1628.776,30,26,0
0.023356481,218.5,224,115,58.8,50,13.3104,26.6209,223,2.6,0.936,1628.776,30,26,0
0.023449074,218.5,224,118,58.8,50,13.3104,26.6209,223,2.8,0.936,1628.776,30,26,0
0.023541667,218.6,223,115,58.8,50,13.3104,26.6209,222,0.8,0.936,1628.776,30,26,0
0.023634259,218.8,223,115,58.8,50,13.3104,26.6209,222,2.1,0.936,1628.776,30,26,0
0.023726852,218.8,223,115,58.8,50,13.3104,26.6209,222,2.7,0.936,1628.776,30,26,0
0.023819444,219,222,118,58.8,50,13.3104,26.6209,222,2.8,0.936,1628.776,30,26,0
0.023912037,219,222,118,58.8,50,13.3104,26.6209,221,0.6,0.936,1628.776,30,26,0
0.024016204,219,222,118,58.8,50,13.3104,26.6209,221,1.4,0.936,1628.776,30,26,0
0.024108796,219.2,222,115,58.8,50,13.3104,26.6209,221,2.7,0.936,1628.776,30,26,0
0.024305556,219.4,221,118,58.8,50,13.3104,26.6209,220,1.1,0.936,1628.776,30,26,0
0.024398148,219.4,221,118,117.61,100,16.3821,16.3821,220,1.9,1.152,2004.643,30,32,0
0.024490741,219.4,220,118,88.2,75,15.3582,20.4776,220,2.5,1.08,1879.354,30,30,0
0.024583333,219.4,220,118,58.8,50,13.3104,26.6209,220,2.1,0.936,1628.776,30,26,0
0.024675926,219.4,220,118,29.4,25,10.2388,40.9553,220,2,0.72,1252.909,30,20,0
0.024780093,219.4,220,118,29.4,25,10.2388,40.9553,220,2.2,0.72,1252.909,30,20,0
0.024872685,219.4,220,118,58.8,50,11.7746,23.5493,220,2.7,0.828,1440.842,30,23,0
0.025,219.4,220,118,88.2,75,13.3104,17.7473,220,2.8,0.936,1628.776,30,26,0
0.025115741,219.4,220,118,58.8,50,15.3582,15.3582,305,70,1.08,1879.354,30,30,0
0.025208333,219.4,226,118,58.8,50,12.2866,24.5732,340,70,0.864,1503.487,30,24,0
0.0253125,219.4,242,118,58.8,50,12.2866,24.5732,339,70,0.864,1503.487,30,24,0
0.025405093,219.4,257,118,58.8,50,12.2866,24.5732,339,70,0.864,1503.487,30,24,0
0.025532407,219.5,278,118,58.8,50,12.2866,24.5732,339,58.8,0.864,1503.487,30,24,0
0.025625,219.7,291,118,58.8,50,11.7746,23.5493,339,47.2,0.828,1440.842,30,23,0
0.025717593,220.3,302,118,58.8,50,11.7746,23.5493,338,40.7,0.828,1440.842,30,23,0
0.025821759,221,310,118,58.8,50,11.7746,23.5493,338,41.8,0.828,1440.842,30,23,0
0.025960648,222.2,319,118,58.8,50,11.2627,22.5254,338,39.2,0.792,1378.198,30,22,0
0.026087963,224.4,327,118,58.8,50,11.2627,22.5254,337,30.4,0.792,1378.198,30,22,0
0.02619213,226,330,118,58.8,50,11.2627,22.5254,337,28.5,0.792,1378.198,30,22,0
0.02630787,227.8,334,115,58.8,50,10.7508,21.5015,337,26.5,0.756,1315.553,30,21,0
0.026412037,229.8,337,115,58.8,50,10.7508,21.5015,336,21.9,0.756,1315.553,30,21,0
0.026527778,231.6,339,115,58.8,50,10.7508,21.5015,336,21.2,0.756,1315.553,30,21,0
0.02662037,233.2,340,115,58.8,50,10.7508,21.5015,336,20.4,0.756,1315.553,30,21,0
0.026712963,234.8,341,115,58.8,50,10.7508,21.5015,335,18.8,0.756,1315.553,30,21,0
0.026840278,237.2,342,115,58.8,50,10.7508,21.5015,335,16.3,0.756,1315.553,30,21,0
0.026967593,239.3,342,112,58.8,50,10.7508,21.5015,335,15.6,0.756,1315.553,30,21,0
0.027083333,241.5,342,112,58.8,50,10.7508,21.5015,334,13.6,0.756,1315.553,30,21,0
0.027222222,243.6,342,106,58.8,50,10.7508,21.5015,334,13.2,0.756,1315.553,30,21,0
0.027349537,246,342,112,58.8,50,10.7508,21.5015,334,13.1,0.756,1315.553,30,21,0
0.027453704,247.6,341,106,58.8,50,10.2388,20.4777,333,11,0.72,1252.909,30,20,0
0.027546296,249.2,341,106,58.8,50,10.2388,20.4777,333,11.5,0.72,1252.909,30,20,0
0.027638889,250.8,340,106,58.8,50,10.2388,20.4777,333,11.6,0.72,1252.909,30,20,0
0.027743056,252.3,340,106,58.8,50,10.2388,20.4777,333,11.3,0.72,1252.909,30,20,0
0.027835648,253.9,339,102,58.8,50,10.2388,20.4777,332,9.2,0.72,1252.909,30,20,0
0.027928241,255.7,339,102,58.8,50,10.2388,20.4777,332,10.3,0.72,1252.909,30,20,0
0.028020833,257.1,338,102,58.8,50,10.2388,20.4777,332,10.7,0.72,1252.909,30,20,0
0.028113426,258.5,338,102,58.8,50,10.2388,20.4777,331,8.5,0.72,1252.909,30,20,0
0.028206019,260.3,337,102,58.8,50,10.2388,20.4777,331,8.8,0.72,1252.909,30,20,0
0.028298611,262,337,102,58.8,50,10.2388,20.4777,331,9.7,0.72,1252.909,30,20,0
0.028402778,263,336,102,58.8,50,10.2388,20.4777,331,9.9,0.72,1252.909,30,20,0
0.02849537,265,335,99,58.8,50,10.2388,20.4777,330,7.9,0.72,1252.909,30,20,0
0.028587963,266.5,335,102,58.8,50,10.2388,20.4777,330,8.3,0.72,1252.909,30,20,0
0.028680556,267.7,334,99,58.8,50,10.2388,20.4777,330,9.1,0.72,1252.909,30,20,0
0.028773148,269.3,334,99,58.8,50,10.2388,20.4777,330,9.1,0.72,1252.909,30,20,0
0.028865741,270.6,333,99,58.8,50,10.2388,20.4777,329,7.4,0.72,1252.909,30,20,0
0.028958333,272,333,99,58.8,50,10.2388,20.4777,329,8,0.72,1252.909,30,20,0
0.029050926,273.5,332,96,58.8,50,10.2388,20.4777,329,8.7,0.72,1252.909,30,20,0
0.029143519,274.7,332,96,58.8,50,10.2388,20.4777,328,7,0.72,1252.909,30,20,0
0.029236111,275.8,331,96,58.8,50,10.2388,20.4777,328,7.3,0.72,1252.909,30,20,0
0.029340278,277.2,331,96,58.8,50,10.2388,20.4777,328,7.8,0.72,1252.909,30,20,0
0.02943287,278.3,331,96,58.8,50,10.2388,20.4777,328,8.1,0.72,1252.909,30,20,0
0.029525463,279.6,330,96,58.8,50,10.2388,20.4777,327,6.4,0.72,1252.909,30,20,0
0.029618056,280.8,330,93,58.8,50,10.2388,20.4777,327,6.6,0.72,1252.909,30,20,0
0.029710648,281.9,329,93,58.8,50,10.2388,20.4777,327,7.7,0.72,1252.909,30,20,0
0.029803241,282.8,329,93,58.8,50,10.2388,20.4777,327,8,0.72,1252.909,30,20,0
0.029895833,284.1,329,93,58.8,50,10.2388,20.4777,326,6.2,0.72,1252.909,30,20,0
0.03,285.2,328,93,58.8,50,10.2388,20.4777,326,6.8,0.72,1252.909,30,20,0
0.030092593,285.9,328,87,58.8,50,10.2388,20.4777,326,7.4,0.72,1252.909,30,20,0
0.030185185,287.1,328,87,58.8,50,10.2388,20.4777,326,7.3,0.72,1252.909,30,20,0
0.030277778,288,327,87,58.8,50,10.2388,20.4777,325,5.7,0.72,1252.909,30,20,0
0.03037037,288.9,327,93,58.8,50,10.2388,20.4777,325,6.5,0.72,1252.909,30,20,0
0.030462963,289.8,327,87,58.8,50,10.2388,20.4777,325,7,0.72,1252.909,30,20,0
0.030555556,290.7,326,87,58.8,50,10.2388,20.4777,324,5.4,0.72,1252.909,30,20,0
0.030648148,291.6,326,87,58.8,50,10.2388,20.4777,324,5.9,0.72,1252.909,30,20,0
0.030740741,292.5,326,87,58.8,50,10.2388,20.4777,324,6.8,0.72,1252.909,30,20,0
0.030833333,293.2,325,84,58.8,50,10.2388,20.4777,324,7.1,0.72,1252.909,30,20,0
0.0309375,294,325,84,58.8,50,10.2388,20.4777,323,5.1,0.72,1252.909,30,20,0
0.031030093,294.7,325,84,58.8,50,10.2388,20.4777,323,6,0.72,1252.909,30,20,0
0.031122685,295.4,324,84,58.8,50,10.2388,20.4777,323,6.5,0.72,1252.909,30,20,0
0.031215278,296.1,324,84,58.8,50,10.2388,20.4777,322,5.7,0.72,1252.909,30,20,0
0.03130787,296.7,324,81,58.8,50,10.2388,20.4777,322,5,0.72,1252.909,30,20,0
0.031400463,297.4,324,81,58.8,50,10.2388,20.4777,322,5.7,0.72,1252.909,30,20,0
0.031493056,297.9,323,81,58.8,50,10.2388,20.4777,322,6.4,0.72,1252.909,30,20,0
0.031597222,298.6,323,81,58.8,50,10.2388,20.4777,321,4.6,0.72,1252.909,30,20,0
0.031689815,299,323,81,58.8,50,10.2388,20.4777,321,4.6,0.72,1252.909,30,20,0
0.031782407,299.7,322,81,58.8,50,10.2388,20.4777,321,5.9,0.72,1252.909,30,20,0
0.031875,300.3,322,81,58.8,50,10.2388,20.4777,321,6.1,0.72,1252.909,30,20,0
0.031967593,300.6,322,71,58.8,50,10.2388,20.4777,320,4,0.72,1252.909,30,20,0
0.032060185,301.2,321,81,58.8,50,10.2388,20.4777,320,5.3,0.72,1252.909,30,20,0
0.032152778,301.7,321,71,58.8,50,10.2388,20.4777,320,5.8,0.72,1252.909,30,20,0
0.03224537,302.1,321,71,58.8,50,9.7269,19.4538,320,5.6,0.684,1190.264,30,19,0
0.032337963,302.4,321,71,58.8,50,9.7269,19.4538,319,4.2,0.684,1190.264,30,19,0
0.032430556,303,320,71,58.8,50,9.7269,19.4538,319,5.1,0.684,1190.264,30,19,0
0.032523148,303.3,320,71,58.8,50,9.7269,19.4538,319,5.4,0.684,1190.264,30,19,0
0.032627315,303.7,320,71,58.8,50,9.7269,19.4538,318,3.6,0.684,1190.264,30,19,0
0.032719907,304,319,71,58.8,50,9.7269,19.4538,318,4.1,0.684,1190.264,30,19,0
0.0328125,306.2,319,307,58.8,50,9.7269,19.4538,318,4.8,0.684,1190.264,30,19,0
0.032905093,304.8,319,255,58.8,50,9.7269,19.4538,318,5.7,0.684,1190.264,30,19,0
0.032997685,304.4,319,171,58.8,50,9.7269,19.4538,317,3.3,0.684,1190.264,30,19,0
0.033090278,304.9,318,112,58.8,50,9.7269,19.4538,317,3.6,0.684,1190.264,30,19,0
0.03318287,305.3,318,84,58.8,50,9.7269,19.4538,317,5.1,0.684,1190.264,30,19,0
0.033275463,305.8,318,102,58.8,50,9.7269,19.4538,317,5.3,0.684,1190.264,30,19,0
0.03337963,306,317,96,58.8,50,9.7269,19.4538,316,3.6,0.684,1190.264,30,19,0
0.033472222,306.2,317,96,58.8,50,9.7269,19.4538,316,4.2,0.684,1190.264,30,19,0
0.033564815,306.6,317,93,58.8,50,9.7269,19.4538,316,5.3,0.684,1190.264,30,19,0
0.033680556,306.9,317,87,58.8,50,9.7269,19.4538,315,3.3,0.684,1190.264,30,19,0
0.033784722,306.9,316,84,58.8,50,9.7269,19.4538,315,4,0.684,1190.264,30,19,0
0.033923611,307.3,316,81,58.8,50,9.7269,19.4538,315,5.2,0.684,1190.264,30,19,0
0.034039352,307.5,315,81,58.8,50,9.7269,19.4538,314,3.2,0.684,1190.264,30,19,0
0.034131944,307.6,315,84,58.8,50,9.7269,19.4538,314,3.8,0.684,1190.264,30,19,0
0.034236111,308,315,96,58.8,50,9.7269,19.4538,314,4.3,0.684,1190.264,30,19,0
0.034351852,308,315,99,58.8,50,9.7269,19.4538,314,4.6,0.684,1190.264,30,19,0
0.034467593,308,314,102,58.8,50,9.7269,19.4538,313,3.4,0.684,1190.264,30,19,0
0.034560185,308.2,314,102,58.8,50,9.7269,19.4538,313,3.9,0.684,1190.264,30,19,0
0.034652778,308.4,314,102,58.8,50,9.7269,19.4538,313,4.3,0.684,1190.264,30,19,0
0.03474537,308.4,313,102,58.8,50,9.7269,19.4538,312,2.9,0.684,1190.264,30,19,0
0.034849537,308.5,313,102,58.8,50,9.7269,19.4538,312,3.6,0.684,1190.264,30,19,0
0.03494213,308.4,313,102,58.8,50,9.7269,19.4538,312,4.3,0.684,1190.264,30,19,0
0.035034722,308.5,312,99,58.8,50,9.7269,19.4538,311,4.3,0.684,1190.264,30,19,0
0.035138889,308.7,312,102,58.8,50,9.7269,19.4538,311,2.5,0.684,1190.264,30,19,0
0.035231481,308.7,312,102,58.8,50,9.7269,19.4538,311,4.1,0.684,1190.264,30,19,0
0.035324074,308.7,312,102,58.8,50,9.7269,19.4538,311,4.3,0.684,1190.264,30,19,0
0.035416667,308.7,311,102,58.8,50,9.7269,19.4538,310,2.5,0.684,1190.264,30,19,0
0.035509259,308.7,311,102,58.8,50,9.7269,19.4538,310,2.8,0.684,1190.264,30,19,0
0.035601852,308.7,311,102,117.61,100,10.2388,10.2388,310,3.7,0.72,1252.909,30,20,0
0.035694444,308.7,310,102,88.2,75,10.2388,13.6518,310,4.5,0.72,1252.909,30,20,0
0.035798611,308.7,310,102,58.8,50,9.7269,19.4538,310,3.7,0.684,1190.264,30,19,0
0.035891204,308.7,310,99,29.4,25,9.7269,38.9076,310,3.8,0.684,1190.264,30,19,0
0.035983796,308.7,310,102,58.8,50,9.215,36.8599,310,4,0.648,1127.619,30,18,0
0.036076389,308.7,310,99,58.8,50,9.7269,19.4538,310,4.2,0.684,1190.264,30,19,0
0.036180556,308.7,310,102,88.2,75,9.7269,12.9692,310,4.3,0.684,1190.264,30,19,0
0.036273148,308.5,310,99,117.61,100,10.2388,10.2388,389,70,0.72,1252.909,30,20,0
0.036365741,308.7,316,102,58.8,50,9.7269,19.4538,445,70,0.684,1190.264,30,19,0
0.036469907,308.4,329,102,58.8,50,9.7269,19.4538,445,70,0.684,1190.264,30,19,0
0.0365625,308.4,342,102,58.8,50,9.7269,19.4538,444,70,0.684,1190.264,30,19,0
0.036655093,308.4,358,102,58.8,50,9.7269,19.4538,444,70,0.684,1190.264,30,19,0
0.036747685,308.7,371,102,58.8,50,9.7269,19.4538,444,70,0.684,1190.264,30,19,0
0.036840278,308.9,382,102,58.8,50,9.7269,19.4538,443,70,0.684,1190.264,30,19,0
0.03693287,309.6,396,102,58.8,50,9.7269,19.4538,443,59,0.684,1190.264,30,19,0
0.037025463,310.3,407,102,58.8,50,9.7269,19.4538,443,51.6,0.684,1190.264,30,19,0
0.037118056,311,415,102,58.8,50,9.7269,19.4538,442,46.7,0.684,1190.264,30,19,0
0.037210648,312.1,422,102,58.8,50,9.7269,19.4538,442,44.7,0.684,1190.264,30,19,0
0.037314815,313.6,427,102,58.8,50,9.7269,19.4538,442,42.6,0.684,1190.264,30,19,0
0.037407407,314.6,432,102,58.8,50,9.7269,19.4538,441,37.7,0.684,1190.264,30,19,0
0.0375,316.1,436,102,58.8,50,9.215,18.4299,441,34.6,0.648,1127.619,30,18,0
0.037592593,317.5,439,102,58.8,50,9.215,18.4299,441,32.4,0.648,1127.619,30,18,0
0.037685185,319,442,102,58.8,50,9.215,18.4299,440,29.5,0.648,1127.619,30,18,0
0.037789352,320.6,443,102,58.8,50,9.215,18.4299,440,28,0.648,1127.619,30,18,0
0.037881944,322.4,445,102,58.8,50,9.215,18.4299,440,27.1,0.648,1127.619,30,18,0
0.037974537,324.2,446,102,58.8,50,9.215,18.4299,439,24,0.648,1127.619,30,18,0
0.03806713,326.7,446,102,58.8,50,9.215,18.4299,439,23,0.648,1127.619,30,18,0
0.038159722,328.8,447,102,58.8,50,9.215,18.4299,439,22.6,0.648,1127.619,30,18,0
0.038252315,331,447,102,58.8,50,9.215,18.4299,439,21.5,0.648,1127.619,30,18,0
0.038356481,333.9,447,102,58.8,50,9.215,18.4299,438,19.4,0.648,1127.619,30,18,0
0.038449074,336,447,102,58.8,50,9.215,18.4299,438,19.4,0.648,1127.619,30,18,0
0.038541667,338.7,447,102,58.8,50,9.215,18.4299,438,18.7,0.648,1127.619,30,18,0
0.038634259,340.9,447,102,58.8,50,9.215,18.4299,437,16.3,0.648,1127.619,30,18,0
0.038726852,343,446,102,58.8,50,9.215,18.4299,437,16.4,0.648,1127.619,30,18,0
0.038819444,345.6,446,102,58.8,50,9.215,18.4299,437,16.4,0.648,1127.619,30,18,0
0.038923611,347.4,445,99,58.8,50,9.215,18.4299,436,14.2,0.648,1127.619,30,18,0
0.039016204,349.5,445,102,58.8,50,9.215,18.4299,436,14.3,0.648,1127.619,30,18,0
0.039108796,351.3,444,102,58.8,50,9.215,18.4299,436,15,0.648,1127.619,30,18,0
0.039201389,353.7,444,102,58.8,50,9.215,18.4299,435,13,0.648,1127.619,30,18,0
0.039293981,355.5,443,99,58.8,50,9.215,18.4299,435,12.7,0.648,1127.619,30,18,0
0.039386574,357.6,442,102,58.8,50,9.215,18.4299,435,13.6,0.648,1127.619,30,18,0
0.039479167,359.4,442,99,58.8,50,9.215,18.4299,434,13.5,0.648,1127.619,30,18,0
0.039583333,361.2,441,102,58.8,50,9.215,18.4299,434,11.6,0.648,1127.619,30,18,0
0.039675926,363.2,441,102,58.8,50,9.215,18.4299,434,11.7,0.648,1127.619,30,18,0
0.039768519,364.8,440,102,58.8,50,9.215,18.4299,433,10.5,0.648,1127.619,30,18,0
0.039861111,367.3,439,99,58.8,50,9.215,18.4299,433,10.3,0.648,1127.619,30,18,0
0.039965278,369.3,439,102,58.8,50,9.215,18.4299,433,11.2,0.648,1127.619,30,18,0
0.04005787,370.7,438,102,58.8,50,9.215,18.4299,432,9.7,0.648,1127.619,30,18,0
0.040150463,372.4,438,102,58.8,50,9.215,18.4299,432,9.9,0.648,1127.619,30,18,0
0.040243056,373.6,437,99,58.8,50,9.215,18.4299,432,10.9,0.648,1127.619,30,18,0
0.040335648,374.9,436,102,58.8,50,9.215,18.4299,432,10.9,0.648,1127.619,30,18,0
0.040428241,376.7,436,102,58.8,50,9.215,18.4299,431,9.3,0.648,1127.619,30,18,0
0.040520833,377.9,435,102,58.8,50,9.215,18.4299,431,9.9,0.648,1127.619,30,18,0
0.040625,379,435,99,58.8,50,9.215,18.4299,431,10.4,0.648,1127.619,30,18,0
0.040717593,380.4,434,99,58.8,50,9.215,18.4299,430,9,0.648,1127.619,30,18,0
0.040810185,381.5,434,99,58.8,50,9.215,18.4299,430,9.2,0.648,1127.619,30,18,0
0.040902778,382.8,433,99,58.8,50,9.215,18.4299,430,10.5,0.648,1127.619,30,18,0
0.04099537,383.9,433,99,58.8,50,9.215,18.4299,429,8.6,0.648,1127.619,30,18,0
0.041087963,384.8,432,99,58.8,50,9.215,18.4299,429,8.9,0.648,1127.619,30,18,0
0.04119213,386,432,99,58.8,50,9.215,18.4299,429,9.9,0.648,1127.619,30,18,0
0.041284722,387.1,431,99,58.8,50,9.215,18.4299,428,8.2,0.648,1127.619,30,18,0
0.041377315,388,431,99,58.8,50,9.215,18.4299,428,9.1,0.648,1127.619,30,18,0
0.041469907,389.1,430,99,58.8,50,9.215,18.4299,428,9.2,0.648,1127.619,30,18,0
0.041574074,389.8,430,99,58.8,50,9.215,18.4299,427,7.8,0.648,1127.619,30,18,0
0.041666667,391.1,430,99,58.8,50,9.215,18.4299,427,8.2,0.648,1127.619,30,18,0
0.041759259,391.8,429,99,58.8,50,9.215,18.4299,427,9.5,0.648,1127.619,30,18,0
0.041851852,392.5,429,102,58.8,50,9.215,18.4299,426,7.7,0.648,1127.619,30,18,0
0.041944444,393.4,428,99,58.8,50,9.215,18.4299,426,7.8,0.648,1127.619,30,18,0
0.042037037,394.3,428,102,58.8,50,9.215,18.4299,426,9,0.648,1127.619,30,18,0
0.04212963,395,427,99,58.8,50,9.215,18.4299,426,9.1,0.648,1127.619,30,18,0
0.042222222,395.9,427,99,58.8,50,9.215,18.4299,425,7.3,0.648,1127.619,30,18,0
0.042314815,396.4,427,99,58.8,50,9.215,18.4299,425,8.2,0.648,1127.619,30,18,0
0.042407407,397.2,426,99,58.8,50,9.215,18.4299,425,8.6,0.648,1127.619,30,18,0
0.042511574,397.9,426,99,58.8,50,9.215,18.4299,424,7.3,0.648,1127.619,30,18,0
0.042604167,398.4,426,99,58.8,50,9.215,18.4299,424,8,0.648,1127.619,30,18,0
0.042696759,399.1,425,99,58.8,50,9.215,18.4299,424,8.4,0.648,1127.619,30,18,0
0.042789352,399.7,425,99,58.8,50,9.215,18.4299,423,7,0.648,1127.619,30,18,0
0.042881944,400.2,425,99,58.8,50,9.215,18.4299,423,7,0.648,1127.619,30,18,0
0.042974537,400.6,424,99,58.8,50,9.215,18.4299,423,8,0.648,1127.619,30,18,0
0.043078704,401.3,424,99,58.8,50,9.215,18.4299,422,6.8,0.648,1127.619,30,18,0
0.043171296,401.7,424,99,58.8,50,9.215,18.4299,422,7.4,0.648,1127.619,30,18,0
0.043263889,402.2,423,99,58.8,50,9.215,18.4299,422,7.8,0.648,1127.619,30,18,0
0.043368056,402.6,423,99,58.8,50,9.215,18.4299,421,6.3,0.648,1127.619,30,18,0
0.043460648,403.1,423,99,58.8,50,9.215,18.4299,421,6.9,0.648,1127.619,30,18,0
0.043553241,403.5,422,99,58.8,50,9.215,18.4299,421,7.7,0.648,1127.619,30,18,0
0.043645833,403.8,422,99,58.8,50,9.215,18.4299,420,6.2,0.648,1127.619,30,18,0
0.043738426,404.2,422,99,58.8,50,9.215,18.4299,420,6.7,0.648,1127.619,30,18,0
0.043831019,404.5,421,99,58.8,50,9.215,18.4299,420,7.3,0.648,1127.619,30,18,0
0.043935185,404.9,421,99,58.8,50,9.215,18.4299,419,6.1,0.648,1127.619,30,18,0
0.044027778,405.1,421,99,58.8,50,9.215,18.4299,419,6.4,0.648,1127.619,30,18,0
0.04412037,405.4,420,99,58.8,50,9.215,18.4299,419,7,0.648,1127.619,30,18,0
0.044212963,405.6,420,99,58.8,50,9.215,18.4299,419,7.3,0.648,1127.619,30,18,0
0.044305556,405.8,420,99,58.8,50,9.215,18.4299,418,5.8,0.648,1127.619,30,18,0
0.044398148,406.2,419,99,58.8,50,8.703,17.4061,418,6.7,0.612,1064.975,30,17,0
0.044502315,406.3,419,99,58.8,50,9.215,18.4299,418,7.3,0.648,1127.619,30,18,0
0.044594907,406.5,419,99,58.8,50,9.215,18.4299,417,5.4,0.648,1127.619,30,18,0
0.0446875,406.7,418,99,58.8,50,9.215,18.4299,417,6.6,0.648,1127.619,30,18,0
0.044780093,406.9,418,99,58.8,50,9.215,18.4299,417,7.1,0.648,1127.619,30,18,0
0.044872685,407.1,418,99,58.8,50,9.215,18.4299,416,5.1,0.648,1127.619,30,18,0
0.044965278,407.2,417,99,58.8,50,9.215,18.4299,416,6.1,0.648,1127.619,30,18,0
0.04505787,407.2,417,99,58.8,50,9.215,18.4299,416,7,0.648,1127.619,30,18,0
0.045150463,407.4,417,99,58.8,50,9.215,18.4299,415,5.5,0.648,1127.619,30,18,0
0.04525463,407.6,416,99,58.8,50,9.215,18.4299,415,5.6,0.648,1127.619,30,18,0
0.045347222,407.6,416,99,58.8,50,9.215,18.4299,415,6.7,0.648,1127.619,30,18,0
0.045439815,407.8,416,99,58.8,50,9.215,18.4299,414,4.9,0.648,1127.619,30,18,0
0.045532407,407.8,415,99,58.8,50,9.215,18.4299,414,5.7,0.648,1127.619,30,18,0
0.045625,407.8,415,99,58.8,50,9.215,18.4299,414,6.5,0.648,1127.619,30,18,0
0.045717593,407.8,415,99,58.8,50,9.215,18.4299,413,4.9,0.648,1127.619,30,18,0
0.045810185,408,414,99,58.8,50,9.215,18.4299,413,5.2,0.648,1127.619,30,18,0
0.045914352,408,414,99,58.8,50,9.215,18.4299,413,6.1,0.648,1127.619,30,18,0
0.046006944,407.8,414,99,58.8,50,9.215,18.4299,412,5.1,0.648,1127.619,30,18,0
0.046099537,408,413,99,58.8,50,9.215,18.4299,412,5.1,0.648,1127.619,30,18,0
0.04619213,408.1,413,99,58.8,50,9.215,18.4299,412,6,0.648,1127.619,30,18,0
0.046296296,407.8,413,99,58.8,50,9.215,18.4299,412,6.4,0.648,1127.619,30,18,0
0.046388889,408,412,99,58.8,50,9.215,18.4299,411,4.5,0.648,1127.619,30,18,0
0.046481481,408,412,99,58.8,50,9.215,18.4299,411,5.4,0.648,1127.619,30,18,0
0.046574074,408,412,102,58.8,50,9.215,18.4299,411,6.5,0.648,1127.619,30,18,0
0.046666667,407.8,411,99,58.8,50,9.215,18.4299,410,4.6,0.648,1127.619,30,18,0
0.046770833,407.8,411,99,117.61,100,9.215,9.215,410,5.5,0.648,1127.619,30,18,0
0.046863426,407.8,411,99,88.2,75,9.215,12.2866,410,6.4,0.648,1127.619,30,18,0
0.046956019,407.6,410,99,58.8,50,9.215,18.4299,410,6.1,0.648,1127.619,30,18,0
0.047060185,407.6,410,99,29.4,25,9.215,18.4299,410,5.9,0.648,1127.619,30,18,0
0.047152778,407.4,410,99,29.4,25,9.215,36.8599,410,6.1,0.648,1127.619,30,18,0
0.04724537,407.2,410,99,58.8,50,9.215,18.4299,410,6,0.648,1127.619,30,18,0
0.047337963,407.4,410,99,88.2,75,9.215,12.2866,410,6.4,0.648,1127.619,30,18,0
0.047430556,407.2,410,99,117.61,100,9.215,9.215,425,32,0.648,1127.619,30,18,0
0.047534722,407.1,413,99,58.8,50,9.215,18.4299,500,70,0.648,1127.619,30,18,0
0.047627315,406.9,422,99,58.8,50,9.215,18.4299,500,70,0.648,1127.619,30,18,0
0.047719907,406.9,434,99,58.8,50,9.215,18.4299,500,70,0.648,1127.619,30,18,0
0.0478125,406.9,449,99,58.8,50,9.215,18.4299,499,51.6,0.648,1127.619,30,18,0
0.047905093,406.9,459,99,58.8,50,9.215,18.4299,499,43.9,0.648,1127.619,30,18,0
0.048009259,407.1,467,99,58.8,50,9.215,18.4299,499,44.1,0.648,1127.619,30,18,0
0.048101852,407.4,474,99,58.8,50,9.215,18.4299,499,43.2,0.648,1127.619,30,18,0
0.048194444,408.1,479,99,58.8,50,9.215,18.4299,499,39.9,0.648,1127.619,30,18,0
0.048287037,408.7,484,99,58.8,50,9.215,18.4299,498,35.5,0.648,1127.619,30,18,0
0.04837963,409.6,488,102,58.8,50,9.215,18.4299,498,31.5,0.648,1127.619,30,18,0
0.048472222,410.3,491,99,58.8,50,9.215,18.4299,498,30.6,0.648,1127.619,30,18,0
0.048564815,411,494,99,58.8,50,9.215,18.4299,498,29.1,0.648,1127.619,30,18,0
0.048657407,412.1,496,102,58.8,50,8.703,17.4061,498,27.3,0.612,1064.975,30,17,0
0.048761574,413,498,102,58.8,50,8.703,17.4061,498,25.1,0.612,1064.975,30,17,0
0.048865741,414.4,499,99,58.8,50,9.215,18.4299,497,22.2,0.648,1127.619,30,18,0
0.048969907,415.5,501,102,58.8,50,8.703,17.4061,497,21.6,0.612,1064.975,30,17,0
0.0490625,416.6,501,102,58.8,50,8.703,17.4061,497,21.4,0.612,1064.975,30,17,0
0.049166667,417.8,502,102,58.8,50,8.703,17.4061,497,20.6,0.612,1064.975,30,17,0
0.049270833,419.3,502,99,58.8,50,8.703,17.4061,497,19.5,0.612,1064.975,30,17,0
0.049363426,420.4,502,102,58.8,50,8.703,17.4061,496,16.7,0.612,1064.975,30,17,0
0.049467593,421.8,502,99,58.8,50,9.215,18.4299,496,16.8,0.648,1127.619,30,18,0
0.049560185,423.1,502,99,58.8,50,8.703,17.4061,496,17.3,0.612,1064.975,30,17,0
0.049664352,424.7,502,99,58.8,50,8.703,17.4061,496,16.4,0.612,1064.975,30,17,0
0.049756944,425.7,502,102,58.8,50,8.703,17.4061,496,15.8,0.612,1064.975,30,17,0
0.049861111,427.4,502,102,58.8,50,8.703,17.4061,496,15.5,0.612,1064.975,30,17,0
0.049953704,428.4,502,102,58.8,50,9.215,18.4299,495,13.9,0.648,1127.619,30,18,0
0.05005787,430.1,501,99,58.8,50,8.703,17.4061,495,14.6,0.612,1064.975,30,17,0
0.050150463,431.1,501,99,58.8,50,9.215,18.4299,495,14.5,0.648,1127.619,30,18,0
0.050243056,432.6,500,99,58.8,50,8.703,17.4061,495,14,0.612,1064.975,30,17,0
0.050335648,433.8,500,102,58.8,50,8.703,17.4061,495,13.8,0.612,1064.975,30,17,0
0.050428241,435.1,500,102,58.8,50,8.703,17.4061,494,11.8,0.612,1064.975,30,17,0
0.050520833,436.5,499,99,58.8,50,8.703,17.4061,494,12.5,0.612,1064.975,30,17,0
0.050613426,437.6,499,102,58.8,50,8.703,17.4061,494,13.3,0.612,1064.975,30,17,0
0.050706019,438.7,498,99,58.8,50,9.215,18.4299,494,13.1,0.648,1127.619,30,18,0
0.050810185,440.1,498,99,58.8,50,9.215,18.4299,494,13.2,0.648,1127.619,30,18,0
0.050902778,441.4,498,99,58.8,50,8.703,17.4061,493,11,0.612,1064.975,30,17,0
0.05099537,442.3,497,99,58.8,50,8.703,17.4061,493,11.4,0.612,1064.975,30,17,0
0.051087963,443.5,497,99,58.8,50,9.215,18.4299,493,11.7,0.648,1127.619,30,18,0
0.051180556,444.6,496,99,58.8,50,8.703,17.4061,493,12.7,0.612,1064.975,30,17,0
0.051273148,445.5,496,99,58.8,50,8.703,17.4061,493,12.1,0.612,1064.975,30,17,0
0.051365741,446.6,496,99,58.8,50,9.215,18.4299,493,12,0.648,1127.619,30,18,0
0.051458333,447.7,496,99,58.8,50,8.703,17.4061,492,10.3,0.612,1064.975,30,17,0
0.0515625,448.6,495,99,58.8,50,8.703,17.4061,492,11.2,0.612,1064.975,30,17,0
0.051655093,449.8,495,99,58.8,50,8.703,17.4061,492,11.6,0.612,1064.975,30,17,0
0.051747685,450.7,494,99,58.8,50,8.703,17.4061,492,11.8,0.612,1064.975,30,17,0
0.051840278,451.6,494,99,58.8,50,8.703,17.4061,492,11.4,0.612,1064.975,30,17,0
0.05193287,452.5,494,99,58.8,50,8.703,17.4061,492,11.7,0.612,1064.975,30,17,0
0.052025463,453.4,494,99,58.8,50,8.703,17.4061,491,9.9,0.612,1064.975,30,17,0
0.052118056,454,493,99,58.8,50,8.703,17.4061,491,10.9,0.612,1064.975,30,17,0
0.052210648,455.1,493,99,58.8,50,8.703,17.4061,491,11.1,0.612,1064.975,30,17,0
0.052303241,455.8,493,99,58.8,50,8.703,17.4061,491,10.8,0.612,1064.975,30,17,0
0.052395833,456.5,492,99,58.8,50,8.703,17.4061,491,11.2,0.612,1064.975,30,17,0
0.0525,457.2,492,99,58.8,50,8.703,17.4061,490,9.3,0.612,1064.975,30,17,0
0.052592593,457.9,492,99,58.8,50,8.703,17.4061,490,9.7,0.612,1064.975,30,17,0
0.052685185,458.5,492,99,58.8,50,8.703,17.4061,490,10.8,0.612,1064.975,30,17,0
0.052777778,459.4,491,99,58.8,50,8.703,17.4061,490,11,0.612,1064.975,30,17,0
0.05287037,459.9,491,99,58.8,50,8.703,17.4061,490,10.8,0.612,1064.975,30,17,0
0.052962963,460.6,491,99,58.8,50,8.703,17.4061,490,10.5,0.612,1064.975,30,17,0
0.053055556,461.2,491,102,58.8,50,8.703,17.4061,489,9.5,0.612,1064.975,30,17,0
0.053148148,461.7,491,99,58.8,50,8.703,17.4061,489,9.8,0.612,1064.975,30,17,0
0.053240741,462.2,490,99,58.8,50,8.703,17.4061,489,10.6,0.612,1064.975,30,17,0
0.053344907,462.8,490,99,58.8,50,8.703,17.4061,489,10.2,0.612,1064.975,30,17,0
0.0534375,463.3,490,99,58.8,50,8.703,17.4061,489,10.2,0.612,1064.975,30,17,0
0.053530093,463.9,490,99,58.8,50,8.703,17.4061,488,8.1,0.612,1064.975,30,17,0
0.053622685,464.2,490,99,58.8,50,8.703,17.4061,488,9.2,0.612,1064.975,30,17,0
0.053715278,464.8,489,99,58.8,50,8.703,17.4061,488,10.4,0.612,1064.975,30,17,0
0.05380787,465.1,489,99,58.8,50,8.703,17.4061,488,10.3,0.612,1064.975,30,17,0
0.053900463,465.7,489,99,58.8,50,8.703,17.4061,488,9.8,0.612,1064.975,30,17,0
0.053993056,466,489,99,58.8,50,8.703,17.4061,488,9.8,0.612,1064.975,30,17,0
0.054085648,466.2,489,99,58.8,50,8.703,17.4061,487,8.3,0.612,1064.975,30,17,0
0.054178241,466.7,488,99,58.8,50,8.703,17.4061,487,9.6,0.612,1064.975,30,17,0
0.054270833,467.1,488,99,58.8,50,8.703,17.4061,487,9.7,0.612,1064.975,30,17,0
0.054375,467.3,488,99,58.8,50,8.703,17.4061,487,9.9,0.612,1064.975,30,17,0
0.054467593,467.6,488,102,58.8,50,8.703,17.4061,487,9.4,0.612,1064.975,30,17,0
0.054560185,468,488,99,58.8,50,8.703,17.4061,486,9.5,0.612,1064.975,30,17,0
0.054652778,468.2,487,99,58.8,50,8.703,17.4061,486,8.6,0.612,1064.975,30,17,0
0.05474537,468.7,487,99,58.8,50,8.703,17.4061,486,9.7,0.612,1064.975,30,17,0
0.054837963,468.7,487,99,58.8,50,8.703,17.4061,486,9.3,0.612,1064.975,30,17,0
0.054930556,469.1,487,99,58.8,50,8.703,17.4061,486,9.2,0.612,1064.975,30,17,0
0.055034722,469.3,487,96,58.8,50,8.703,17.4061,486,9.3,0.612,1064.975,30,17,0
0.055127315,469.6,486,99,58.8,50,8.703,17.4061,485,7.7,0.612,1064.975,30,17,0
0.055219907,469.8,486,99,58.8,50,8.703,17.4061,485,8.9,0.612,1064.975,30,17,0
0.0553125,470,486,99,58.8,50,8.703,17.4061,485,9.1,0.612,1064.975,30,17,0
0.055405093,470.2,486,99,58.8,50,8.703,17.4061,485,9.1,0.612,1064.975,30,17,0
0.055497685,470.3,486,99,58.8,50,8.703,17.4061,485,9.1,0.612,1064.975,30,17,0
0.055590278,470.5,485,99,58.8,50,8.703,17.4061,485,9.4,0.612,1064.975,30,17,0
0.055694444,470.7,485,99,58.8,50,8.703,17.4061,484,7.9,0.612,1064.975,30,17,0
0.055787037,470.7,485,99,58.8,50,8.703,17.4061,484,8.3,0.612,1064.975,30,17,0
0.05587963,471.1,485,99,58.8,50,8.703,17.4061,484,9.3,0.612,1064.975,30,17,0
0.055972222,471.1,485,99,58.8,50,8.703,17.4061,484,9,0.612,1064.975,30,17,0
0.056064815,471.2,484,99,58.8,50,8.703,17.4061,484,8.9,0.612,1064.975,30,17,0
0.056157407,471.4,484,99,58.8,50,8.703,17.4061,483,7.4,0.612,1064.975,30,17,0
0.05625,471.4,484,99,58.8,50,8.703,17.4061,483,8.1,0.612,1064.975,30,17,0
0.056342593,471.4,484,99,58.8,50,8.703,17.4061,483,8.7,0.612,1064.975,30,17,0
0.056435185,471.6,484,99,58.8,50,8.703,17.4061,483,9,0.612,1064.975,30,17,0
0.056539352,471.8,483,99,58.8,50,8.703,17.4061,483,8.7,0.612,1064.975,30,17,0
0.056631944,471.8,483,99,58.8,50,8.703,17.4061,482,7.2,0.612,1064.975,30,17,0
0.056724537,472,483,99,58.8,50,8.703,17.4061,482,7.6,0.612,1064.975,30,17,0
0.05681713,472,483,99,58.8,50,8.703,17.4061,482,8.4,0.612,1064.975,30,17,0
0.056909722,472,483,99,58.8,50,8.703,17.4061,482,8.5,0.612,1064.975,30,17,0
0.057002315,472,482,99,58.8,50,8.703,17.4061,482,8.8,0.612,1064.975,30,17,0
0.057094907,472.1,482,99,58.8,50,8.703,17.4061,482,8.7,0.612,1064.975,30,17,0
0.0571875,472,482,99,58.8,50,8.703,17.4061,481,7,0.612,1064.975,30,17,0
0.057280093,472.3,482,96,58.8,50,8.703,17.4061,481,7.8,0.612,1064.975,30,17,0
0.057372685,472.1,482,96,58.8,50,8.703,17.4061,481,8.4,0.612,1064.975,30,17,0
0.057465278,472.1,481,99,58.8,50,8.703,17.4061,481,8.6,0.612,1064.975,30,17,0
0.057569444,472.1,481,99,58.8,50,8.703,17.4061,481,8.8,0.612,1064.975,30,17,0
0.057662037,472.3,481,99,58.8,50,8.703,17.4061,481,9.1,0.612,1064.975,30,17,0
0.05775463,472.1,481,99,58.8,50,8.703,17.4061,480,6.8,0.612,1064.975,30,17,0
0.057847222,472.1,481,99,58.8,50,8.703,17.4061,480,8,0.612,1064.975,30,17,0
0.057939815,472.1,481,99,117.61,100,8.703,8.703,480,8.8,0.612,1064.975,30,17,0
0.058032407,472.1,480,99,88.2,75,9.215,9.215,480,8.4,0.648,1127.619,30,18,0
0.058125,472.1,480,99,88.2,75,9.215,12.2866,480,8,0.648,1127.619,30,18,0
0.058217593,472,480,99,58.8,50,9.215,18.4299,480,8.6,0.648,1127.619,30,18,0
0.058310185,472,480,99,29.4,25,8.703,34.8121,480,8.2,0.612,1064.975,30,17,0
0.058414352,472,480,99,58.8,50,8.703,17.4061,480,8.3,0.612,1064.975,30,17,0
0.058506944,472,480,99,88.2,75,8.703,11.604,480,9.1,0.612,1064.975,30,17,0
0.058599537,472,480,99,117.61,100,9.215,9.215,480,8.5,0.648,1127.619,30,18,0
0.058668981,472,480,99,117.61,100,9.215,9.215,480,8.8,0.648,1127.619,30,18,0