File: data/hpybf4-AA-cons-P-2.csv
Elapsed Time,Sample Temp,Heater Temp,Pressure,Rotor Speed,Shear Rate,Shear Stress,Viscosity,Temperature Setpoint,T Output,Bob Deflection,Torque,Motor Temp,Raw Encoder Value,Aux1
(hh:mm:ss),(°F),(°F),(PSIg),(RPM),(1/s),(dyne/cm²),(cP),(°F),(%),(deg.),(dyne-cm),(°C),(cts),
1.16E-05,71.4,72,65,0,0,0.0001,0,32,0,0,0.017,30,0,0
0.000104167,71.6,72,62,58.8,50,163.7761,327.5521,77,24.3,11.412,20040.99,30,317,0
0.000243056,71.6,79,62,58.8,50,162.7572,325.5145,77,0,11.34,19916.32,30,315,0
0.000347222,71.8,81,62,58.8,50,159.1909,318.3819,77,0,11.088,19479.92,30,308,0
0.000451389,71.8,81,81,58.8,50,155.6243,311.2487,77,1.9,10.836,19043.48,30,301,0
0.000543981,71.9,81,112,58.8,50,153.5863,307.1726,77,1.6,10.692,18794.09,30,297,0
0.000636574,71.9,81,106,58.8,50,151.0387,302.0774,77,0.4,10.512,18482.35,30,292,0
0.000740741,71.9,81,106,58.8,50,149.0007,298.0013,77,0,10.368,18232.95,30,288,0
0.000833333,72.1,81,106,58.8,50,146.9626,293.9252,77,0,10.224,17983.56,30,284,0
0.0009375,72.3,81,106,58.8,50,145.4341,290.8681,77,0,10.116,17796.51,30,281,0
0.001041667,72.3,80,106,58.8,50,144.415,288.8301,77,0,10.044,17671.82,30,279,0
0.001134259,72.5,80,106,58.8,50,143.396,286.792,77,0,9.972,17547.12,30,277,0
0.001238426,72.8,80,106,58.8,50,142.8865,285.7729,77,0,9.936,17484.77,30,276,0
0.001331019,72.8,80,106,58.8,50,142.8865,285.7729,77,0,9.936,17484.77,30,276,0
0.001423611,73.2,79,106,58.8,50,142.377,284.7539,77,0,9.9,17422.42,30,275,0
0.001516204,73.2,79,112,58.8,50,142.377,284.7539,77,0,9.9,17422.42,30,275,0
0.001608796,73.4,79,106,58.8,50,141.3579,282.7159,77,0,9.828,17297.73,30,273,0
0.001712963,73.4,79,106,58.8,50,141.3579,282.7159,77,0,9.828,17297.73,30,273,0
0.001805556,73.7,79,106,58.8,50,141.3579,282.7159,77,0,9.828,17297.73,30,273,0
0.001898148,73.7,79,106,58.8,50,141.3579,282.7159,77,0,9.828,17297.73,30,273,0
0.001990741,73.9,79,106,58.8,50,141.3579,282.7159,77,0,9.828,17297.73,30,273,0
0.002083333,74.1,79,106,58.8,50,141.3579,282.7159,77,0,9.828,17297.73,30,273,0
0.0021875,74.3,78,106,117.61,100,283.9991,283.9991,77,0,19.764,34752.48,30,549,0
0.002291667,74.3,78,106,88.2,75,214.5847,286.1129,77,0,14.976,26258.36,30,416,0
0.002384259,74.5,78,106,58.8,50,143.396,286.792,77,0,9.972,17547.12,30,277,0
0.002476852,74.6,78,106,29.4,25,72.3252,289.3009,77,0,5.04,8850.313,30,140,0
0.002569444,74.6,78,106,58.8,50,140.8484,281.6968,77,0,9.792,17235.38,30,272,0
0.002662037,74.6,78,106,88.2,75,208.3591,277.8122,77,0,14.544,25496.54,30,404,0
0.002766204,74.8,78,112,117.61,100,277.7056,277.7056,77,0,19.332,33982.36,30,537,0
0.002858796,75,78,106,58.8,50,92.9731,92.9731,123,70,6.48,11376.95,30,180,0
0.002951389,75,88,106,58.8,50,141.3579,282.7159,130,38.5,9.828,17297.73,30,273,0
0.003043981,75,102,106,58.8,50,134.7343,269.4685,130,5.1,9.36,16487.2,30,260,0
0.003136574,75.2,109,106,58.8,50,124.9297,249.8593,130,10.8,8.676,15287.43,30,241,0
0.003229167,75.2,113,112,58.8,50,115.4802,230.9604,130,23.6,8.028,14131.12,30,223,0
0.003333333,75.3,116,106,58.8,50,104.9809,209.9617,130,18.4,7.308,12846.33,30,203,0
0.003425926,75.5,120,106,58.8,50,97.1063,194.2127,129,9.3,6.768,11882.73,30,188,0
0.003518519,76.1,123,112,58.8,50,89.3597,178.7194,129,9.7,6.228,10934.79,30,173,0
0.003622685,76.4,124,112,58.8,50,84.1977,168.3954,129,11.8,5.868,10303.13,30,163,0
0.003715278,77,126,112,58.8,50,79.552,159.1039,129,10,5.544,9734.636,30,154,0
0.00380787,77.7,127,112,58.8,50,74.9062,149.8124,129,7.8,5.22,9166.142,30,145,0
0.003900463,78.4,128,112,58.8,50,72.3252,144.6505,129,8,5.04,8850.313,30,140,0
0.003993056,79.1,129,112,58.8,50,69.7442,139.4885,129,7.7,4.86,8534.481,30,135,0
0.004097222,80.2,130,112,58.8,50,66.6471,133.2941,129,6.1,4.644,8155.486,30,129,0
0.004189815,80.9,130,112,58.8,50,64.5822,129.1644,129,6,4.5,7902.813,30,125,0
0.004282407,81.8,131,112,58.8,50,63.0178,126.0356,129,6.2,4.392,7711.38,30,122,0
0.004375,82.7,131,112,58.8,50,61.4534,122.9068,129,5.3,4.284,7519.947,30,119,0
0.004467593,83.6,131,106,58.8,50,59.889,119.778,128,3.2,4.176,7328.513,30,116,0
0.004571759,84.7,131,106,58.8,50,58.3246,116.6492,128,3.9,4.068,7137.08,30,113,0
0.004664352,85.8,131,112,58.8,50,56.7602,113.5204,128,4.8,3.96,6945.646,30,110,0
0.004756944,86.7,131,112,58.8,50,55.7173,111.4345,128,4.1,3.888,6818.024,30,108,0
0.004849537,87.4,131,112,58.8,50,55.1958,110.3916,128,3.9,3.852,6754.213,30,107,0
0.00494213,88.5,131,112,58.8,50,54.1529,108.3057,128,3.9,3.78,6626.59,30,105,0
0.005034722,89.2,130,112,58.8,50,53.6314,107.2628,128,3.9,3.744,6562.78,30,104,0
0.005138889,90.3,130,112,58.8,50,52.5885,105.1769,128,3.6,3.672,6435.157,30,102,0
0.005231481,91.2,130,112,58.8,50,52.067,104.134,128,3.4,3.636,6371.346,30,101,0
0.005324074,91.9,130,112,58.8,50,52.067,104.134,128,4.1,3.636,6371.346,30,101,0
0.005416667,92.8,130,112,58.8,50,51.5455,103.091,128,3.4,3.6,6307.535,30,100,0
0.005509259,93.5,130,112,58.8,50,51.024,102.0481,127,1.4,3.564,6243.724,30,99,0
0.005613426,94.2,129,112,58.8,50,50.5026,101.0051,127,2.7,3.528,6179.913,30,98,0
0.005706019,95.1,129,112,58.8,50,50.5026,101.0051,127,3.4,3.528,6179.913,30,98,0
0.005798611,95.7,129,112,58.8,50,49.9811,99.9622,127,3.3,3.492,6116.102,30,97,0
0.005891204,96.6,129,112,58.8,50,49.4596,98.9193,127,2.8,3.456,6052.291,30,96,0
0.005983796,97.3,129,112,58.8,50,49.4596,98.9193,127,3,3.456,6052.291,30,96,0
0.006087963,97.8,128,112,58.8,50,48.9382,97.8763,127,3.2,3.42,5988.479,30,95,0
0.006180556,98.7,128,112,58.8,50,48.9382,97.8763,127,3.3,3.42,5988.479,30,95,0
0.006273148,99.4,128,112,58.8,50,48.4167,96.8334,127,3,3.384,5924.668,30,94,0
0.006377315,99.8,128,112,58.8,50,48.4167,96.8334,127,3.1,3.384,5924.668,30,94,0
0.006469907,100.5,128,112,58.8,50,47.8952,95.7905,127,2.9,3.348,5860.857,30,93,0
0.0065625,101.2,128,112,58.8,50,47.8952,95.7905,126,1.2,3.348,5860.857,30,93,0
0.006655093,101.6,128,112,58.8,50,47.3738,94.7475,126,2.1,3.312,5797.046,30,92,0
0.006759259,102.1,127,112,58.8,50,47.3738,94.7475,126,2.2,3.312,5797.046,30,92,0
0.006851852,102.9,127,112,58.8,50,46.8523,93.7046,126,2.6,3.276,5733.234,30,91,0
0.006944444,103.2,127,112,58.8,50,46.8523,93.7046,126,2.6,3.276,5733.234,30,91,0
0.007037037,103.9,127,112,58.8,50,46.3308,92.6617,126,1.9,3.24,5669.423,30,90,0
0.00712963,104.3,127,112,58.8,50,46.3308,92.6617,126,2.4,3.24,5669.423,30,90,0
0.007222222,104.8,127,112,58.8,50,46.3308,92.6617,126,2.6,3.24,5669.423,30,90,0
0.007326389,105.4,127,112,58.8,50,45.8094,91.6187,126,2.3,3.204,5605.612,30,89,0
0.007418981,105.7,127,112,58.8,50,45.8094,91.6187,126,2.2,3.204,5605.612,30,89,0
0.007511574,106.3,127,112,58.8,50,45.8094,91.6187,126,2.2,3.204,5605.612,30,89,0
0.007604167,106.6,126,112,58.8,50,45.2879,90.5758,125,0.6,3.168,5541.801,30,88,0
0.007696759,107.2,126,112,58.8,50,45.2879,90.5758,125,1.9,3.168,5541.801,30,88,0
0.007800926,107.5,126,112,58.8,50,45.2879,90.5758,125,1.8,3.168,5541.801,30,88,0
0.007893519,107.9,126,112,58.8,50,45.2879,90.5758,125,2.1,3.168,5541.801,30,88,0
0.007986111,108.4,126,112,58.8,50,44.7664,89.5329,125,1.6,3.132,5477.99,30,87,0
0.008078704,108.8,126,112,58.8,50,44.7664,89.5329,125,1.7,3.132,5477.99,30,87,0
0.008171296,109.1,126,112,58.8,50,44.7664,89.5329,125,2,3.132,5477.99,30,87,0
0.008275463,109.5,125,112,58.8,50,44.7664,89.5329,125,2.1,3.132,5477.99,30,87,0
0.008368056,109.9,125,112,58.8,50,44.245,88.4899,125,1.7,3.096,5414.179,30,86,0
0.008460648,110,125,112,58.8,50,44.245,88.4899,125,2,3.096,5414.179,30,86,0
0.008553241,110.6,125,106,58.8,50,44.245,88.4899,125,1.6,3.096,5414.179,30,86,0
0.008645833,110.9,125,112,58.8,50,44.245,88.4899,124,0.2,3.096,5414.179,30,86,0
0.008738426,111.1,125,112,58.8,50,43.7235,87.447,124,1.4,3.06,5350.368,30,85,0
0.008842593,111.5,125,112,58.8,50,43.7235,87.447,124,1.8,3.06,5350.368,30,85,0
0.008935185,111.7,125,112,58.8,50,43.7235,87.447,124,1.3,3.06,5350.368,30,85,0
0.009027778,112,125,112,58.8,50,43.7235,87.447,124,1,3.06,5350.368,30,85,0
0.00912037,112.4,124,112,58.8,50,43.202,86.4041,124,2.3,3.024,5286.557,30,84,0
0.009212963,112.6,124,112,58.8,50,43.202,86.4041,124,2.3,3.024,5286.557,30,84,0
0.00931713,112.7,124,112,58.8,50,43.202,86.4041,124,1.2,3.024,5286.557,30,84,0
0.009409722,113.1,124,112,58.8,50,43.202,86.4041,124,1.3,3.024,5286.557,30,84,0
0.009502315,113.3,124,112,58.8,50,43.202,86.4041,124,1.8,3.024,5286.557,30,84,0
0.009594907,113.6,124,112,58.8,50,43.202,86.4041,124,1.9,3.024,5286.557,30,84,0
0.0096875,113.8,124,112,58.8,50,42.6806,85.3611,123,0,2.988,5222.745,30,83,0
0.009780093,114.2,124,112,58.8,50,42.6806,85.3611,123,0.6,2.988,5222.745,30,83,0
0.009884259,114.2,124,112,58.8,50,42.6806,85.3611,123,0.5,2.988,5222.745,30,83,0
0.009976852,114.5,124,112,58.8,50,42.6806,85.3611,123,0.7,2.988,5222.745,30,83,0
0.010069444,114.7,124,112,58.8,50,42.6806,85.3611,123,1.2,2.988,5222.745,30,83,0
0.010162037,114.7,123,112,58.8,50,42.6806,85.3611,123,1.3,2.988,5222.745,30,83,0
0.01025463,115.1,123,112,58.8,50,42.1591,84.3182,123,1.2,2.952,5158.934,30,82,0
0.010358796,115.3,123,112,58.8,50,42.1591,84.3182,123,1,2.952,5158.934,30,82,0
0.010451389,115.4,123,106,58.8,50,42.1591,84.3182,123,1.4,2.952,5158.934,30,82,0
0.010543981,115.6,123,112,58.8,50,42.1591,84.3182,123,1.3,2.952,5158.934,30,82,0
0.010636574,115.6,123,112,58.8,50,42.1591,84.3182,123,1.6,2.952,5158.934,30,82,0
0.010729167,116,123,112,58.8,50,42.1591,84.3182,122,0,2.952,5158.934,30,82,0
0.010833333,116.2,123,112,58.8,50,42.1591,84.3182,122,0.8,2.952,5158.934,30,82,0
0.010925926,116.3,123,112,58.8,50,42.1591,84.3182,122,0.8,2.952,5158.934,30,82,0
0.011018519,116.3,122,112,58.8,50,42.1591,84.3182,122,1.2,2.952,5158.934,30,82,0
0.011111111,116.5,122,112,58.8,50,42.1591,84.3182,122,0.8,2.952,5158.934,30,82,0
0.011203704,116.7,122,112,58.8,50,42.1591,84.3182,122,1,2.952,5158.934,30,82,0
0.011296296,116.9,122,112,58.8,50,42.1591,84.3182,122,0.9,2.952,5158.934,30,82,0
0.011388889,116.9,122,112,58.8,50,41.6376,83.2752,122,1.2,2.916,5095.123,30,81,0
0.011493056,117.1,122,112,58.8,50,41.6376,83.2752,122,0.9,2.916,5095.123,30,81,0
0.011585648,117.2,122,112,58.8,50,41.6376,83.2752,122,1.2,2.916,5095.123,30,81,0
0.011678241,117.2,122,112,58.8,50,41.6376,83.2752,122,1,2.916,5095.123,30,81,0
0.011770833,117.4,122,112,58.8,50,41.6376,83.2752,121,0,2.916,5095.123,30,81,0
0.011875,117.4,122,112,58.8,50,41.6376,83.2752,121,0.1,2.916,5095.123,30,81,0
0.011967593,117.6,122,112,58.8,50,41.6376,83.2752,121,0.7,2.916,5095.123,30,81,0
0.012060185,117.8,122,112,58.8,50,41.6376,83.2752,121,0.6,2.916,5095.123,30,81,0
0.012152778,117.8,121,106,58.8,50,41.6376,83.2752,121,0.9,2.916,5095.123,30,81,0
0.01224537,117.8,121,112,58.8,50,41.6376,83.2752,121,0.4,2.916,5095.123,30,81,0
0.012337963,118,121,112,58.8,50,41.6376,83.2752,121,0.8,2.916,5095.123,30,81,0
0.01244213,118,121,112,58.8,50,41.6376,83.2752,121,0.8,2.916,5095.123,30,81,0
0.012534722,118.1,121,112,58.8,50,41.6376,83.2752,121,0.9,2.916,5095.123,30,81,0
0.012627315,118.1,121,112,58.8,50,41.6376,83.2752,121,0.8,2.916,5095.123,30,81,0
0.012719907,118.1,121,112,58.8,50,41.6376,83.2752,121,0.6,2.916,5095.123,30,81,0
0.012824074,118.3,121,112,58.8,50,41.6376,83.2752,120,0,2.916,5095.123,30,81,0
0.012916667,118.3,121,112,58.8,50,41.6376,83.2752,120,0,2.916,5095.123,30,81,0
0.013009259,118.3,121,112,58.8,50,41.6376,83.2752,120,0.4,2.916,5095.123,30,81,0
0.013113426,118.3,120,106,58.8,50,41.6376,83.2752,120,0.8,2.916,5095.123,30,81,0
0.013206019,118.5,120,112,58.8,50,41.6376,83.2752,120,0.5,2.916,5095.123,30,81,0
0.013298611,118.7,120,112,117.61,100,73.8738,73.8738,120,0.5,5.148,9039.811,30,143,0
0.013391204,118.7,120,112,58.8,50,56.2387,112.4774,120,0.6,3.924,6881.835,30,109,0
0.013483796,118.7,120,112,58.8,50,37.9873,75.9747,120,0.6,2.664,4648.445,30,74,0
0.013587963,118.7,120,112,29.4,25,17.9179,71.6714,120,0.8,1.26,2192.577,30,35,0
0.013680556,118.7,120,112,58.8,50,35.9015,71.8029,120,0.6,2.52,4393.201,30,70,0
0.013773148,118.7,120,106,88.2,75,52.5885,70.1179,120,0.5,3.672,6435.157,30,102,0
0.013865741,118.9,120,112,117.61,100,71.2928,71.2928,163,70,4.968,8723.98,30,138,0
0.013958333,118.9,123,106,58.8,50,35.9015,71.8029,247,70,2.52,4393.201,30,70,0
0.0140625,118.9,137,112,58.8,50,35.9015,71.8029,250,70,2.52,4393.201,30,70,0
0.014155093,119,158,106,58.8,50,33.8156,67.6312,249,70,2.376,4137.956,30,66,0
0.014259259,119,179,112,58.8,50,31.2282,62.4563,249,59.1,2.196,3821.336,30,61,0
0.014351852,119.2,194,112,58.8,50,28.1566,56.3131,249,46,1.98,3445.469,30,55,0
0.014444444,119.6,205,112,58.8,50,25.5969,51.1938,249,44.4,1.8,3132.246,30,50,0
0.014537037,120.1,215,112,58.8,50,22.5253,45.0505,248,43.4,1.584,2756.378,30,44,0
0.01462963,121,222,112,58.8,50,19.4537,38.9073,248,39.1,1.368,2380.511,30,38,0
0.014733796,122.1,229,112,58.8,50,17.4059,34.8118,248,33.8,1.224,2129.933,30,34,0
0.014826389,123.4,235,115,58.8,50,15.8701,31.7402,247,28.6,1.116,1941.999,30,31,0
0.014918981,125.1,239,115,58.8,50,14.3343,28.6686,247,27.3,1.008,1754.065,30,28,0
0.015011574,126.9,243,112,58.8,50,13.3104,26.6209,247,24.8,0.936,1628.776,30,26,0
0.015115741,129.1,245,115,58.8,50,12.2866,24.5732,247,22.5,0.864,1503.487,30,24,0
0.015208333,130.9,247,115,58.8,50,11.7746,23.5493,246,19.1,0.828,1440.842,30,23,0
0.015300926,132.9,249,115,58.8,50,11.7746,23.5493,246,18.7,0.828,1440.842,30,23,0
0.015393519,135.4,250,115,58.8,50,11.2627,22.5254,246,17.9,0.792,1378.198,30,22,0
0.015486111,137.4,251,115,58.8,50,10.7508,21.5015,246,16.7,0.756,1315.553,30,21,0
0.015578704,139.4,252,115,58.8,50,10.7508,21.5015,245,13.8,0.756,1315.553,30,21,0
0.01568287,141.7,252,115,58.8,50,10.2388,20.4777,245,13.8,0.72,1252.909,30,20,0
0.015775463,143.7,252,115,58.8,50,10.2388,20.4777,245,13.7,0.72,1252.909,30,20,0
0.015868056,145.6,252,115,58.8,50,10.2388,20.4777,244,10.9,0.72,1252.909,30,20,0
0.015960648,148,252,115,58.8,50,9.7269,19.4538,244,10.5,0.684,1190.264,30,19,0
0.016053241,149.8,252,115,58.8,50,9.7269,19.4538,244,11.5,0.684,1190.264,30,19,0
0.016157407,151.8,252,115,58.8,50,9.7269,19.4538,244,10.9,0.684,1190.264,30,19,0
0.01625,153.9,251,118,58.8,50,9.7269,19.4538,243,9.1,0.684,1190.264,30,19,0
0.016342593,155.9,251,115,58.8,50,9.7269,19.4538,243,9.1,0.684,1190.264,30,19,0
0.016446759,157.9,250,115,58.8,50,9.215,18.4299,243,9.9,0.648,1127.619,30,18,0
0.016539352,159.7,250,115,58.8,50,9.215,18.4299,243,9.4,0.648,1127.619,30,18,0
0.016631944,161.6,249,115,58.8,50,9.215,18.4299,242,7.2,0.648,1127.619,30,18,0
0.016724537,163.3,249,115,58.8,50,9.215,18.4299,242,8.3,0.648,1127.619,30,18,0
0.01681713,164.9,248,115,58.8,50,9.215,18.4299,242,8.9,0.648,1127.619,30,18,0
0.016921296,166.9,247,115,58.8,50,9.215,18.4299,241,8.8,0.648,1127.619,30,18,0
0.017013889,168.3,247,115,58.8,50,9.215,18.4299,241,6.5,0.648,1127.619,30,18,0
0.017106481,169.9,246,115,58.8,50,9.215,18.4299,241,7.5,0.648,1127.619,30,18,0
0.017199074,171.7,246,115,58.8,50,9.215,18.4299,241,8.1,0.648,1127.619,30,18,0
0.017303241,173.2,245,115,58.8,50,9.215,18.4299,240,6.2,0.648,1127.619,30,18,0
0.017395833,174.6,245,115,58.8,50,8.703,17.4061,240,6.4,0.612,1064.975,30,17,0
0.017488426,176.2,244,115,58.8,50,8.703,17.4061,240,7.4,0.612,1064.975,30,17,0
0.017581019,177.5,244,115,58.8,50,8.703,17.4061,240,7.6,0.612,1064.975,30,17,0
0.017685185,178.9,243,115,58.8,50,8.703,17.4061,239,5.5,0.612,1064.975,30,17,0
0.017777778,180.5,243,115,58.8,50,8.703,17.4061,239,6.3,0.612,1064.975,30,17,0
0.01787037,181.8,242,115,58.8,50,8.703,17.4061,239,7.1,0.612,1064.975,30,17,0
0.017962963,183.4,242,112,58.8,50,8.703,17.4061,238,4.7,0.612,1064.975,30,17,0
0.018055556,184.7,241,115,58.8,50,8.703,17.4061,238,5,0.612,1064.975,30,17,0
0.018148148,185.7,241,115,58.8,50,8.703,17.4061,238,6.3,0.612,1064.975,30,17,0
0.018240741,187.2,240,112,58.8,50,8.703,17.4061,238,6.7,0.612,1064.975,30,17,0
0.018344907,188.3,240,115,58.8,50,8.703,17.4061,237,4.7,0.612,1064.975,30,17,0
0.0184375,189.3,240,112,58.8,50,8.703,17.4061,237,5.5,0.612,1064.975,30,17,0
0.018530093,190.6,239,112,58.8,50,8.703,17.4061,237,6.1,0.612,1064.975,30,17,0
0.018622685,191.7,239,112,58.8,50,8.703,17.4061,237,5.6,0.612,1064.975,30,17,0
0.018715278,192.7,239,115,58.8,50,8.703,17.4061,236,4.5,0.612,1064.975,30,17,0
0.01880787,193.8,238,112,58.8,50,8.703,17.4061,236,4.9,0.612,1064.975,30,17,0
0.018912037,194.7,238,115,58.8,50,8.703,17.4061,236,5.7,0.612,1064.975,30,17,0
0.01900463,195.8,237,112,58.8,50,8.703,17.4061,235,4,0.612,1064.975,30,17,0
0.019097222,196.9,237,112,58.8,50,8.703,17.4061,235,3.4,0.612,1064.975,30,17,0
0.019189815,197.8,237,112,58.8,50,8.703,17.4061,235,4.9,0.612,1064.975,30,17,0
0.019282407,198.7,237,112,58.8,50,8.1911,16.3822,235,5.7,0.576,1002.33,30,16,0
0.019375,199.6,236,112,58.8,50,8.1911,16.3822,234,3.5,0.576,1002.33,30,16,0
0.019467593,200.5,236,112,58.8,50,8.1911,16.3822,234,4.1,0.576,1002.33,30,16,0
0.019571759,201.2,235,112,58.8,50,8.1911,16.3822,234,5.1,0.576,1002.33,30,16,0
0.019664352,202.1,235,112,58.8,50,8.1911,16.3822,234,5.1,0.576,1002.33,30,16,0
0.019756944,202.8,235,112,58.8,50,8.1911,16.3822,233,3.1,0.576,1002.33,30,16,0
0.019849537,203.5,235,112,58.8,50,8.1911,16.3822,233,4.2,0.576,1002.33,30,16,0
0.01994213,204.4,234,112,58.8,50,8.1911,16.3822,233,4.8,0.576,1002.33,30,16,0
0.020034722,205.2,234,112,58.8,50,8.1911,16.3822,232,3.5,0.576,1002.33,30,16,0
0.020127315,205.9,234,112,58.8,50,8.1911,16.3822,232,2.7,0.576,1002.33,30,16,0
0.020231481,206.4,233,112,58.8,50,8.1911,16.3822,232,3.9,0.576,1002.33,30,16,0
0.020324074,207.1,233,112,58.8,50,8.1911,16.3822,232,4.8,0.576,1002.33,30,16,0
0.020416667,207.7,233,112,58.8,50,8.1911,16.3822,231,2.5,0.576,1002.33,30,16,0
0.020509259,208.4,233,112,58.8,50,8.1911,16.3822,231,3.2,0.576,1002.33,30,16,0
0.020601852,208.9,232,106,58.8,50,8.1911,16.3822,231,3.8,0.576,1002.33,30,16,0
0.020694444,209.5,232,112,58.8,50,8.1911,16.3822,231,4.3,0.576,1002.33,30,16,0
0.020787037,210,232,112,58.8,50,8.1911,16.3822,230,2.2,0.576,1002.33,30,16,0
0.02087963,210.7,231,112,58.8,50,8.1911,16.3822,230,2.9,0.576,1002.33,30,16,0
0.020983796,211.1,231,112,58.8,50,8.1911,16.3822,230,4.2,0.576,1002.33,30,16,0
0.021076389,211.6,231,112,58.8,50,8.1911,16.3822,230,4,0.576,1002.33,30,16,0
0.021168981,212.2,231,112,58.8,50,8.1911,16.3822,229,2.2,0.576,1002.33,30,16,0
0.021273148,212.5,230,112,58.8,50,8.1911,16.3822,229,3.1,0.576,1002.33,30,16,0
0.021365741,213.1,230,106,58.8,50,8.1911,16.3822,229,4,0.576,1002.33,30,16,0
0.021458333,213.4,230,112,58.8,50,8.1911,16.3822,228,1.9,0.576,1002.33,30,16,0
0.0215625,213.6,229,106,58.8,50,8.1911,16.3822,228,2.5,0.576,1002.33,30,16,0
0.021655093,214,229,112,58.8,50,8.1911,16.3822,228,3.7,0.576,1002.33,30,16,0
0.021759259,214.5,229,112,58.8,50,8.1911,16.3822,227,2.1,0.576,1002.33,30,16,0
0.021851852,214.9,229,112,58.8,50,8.1911,16.3822,227,1.7,0.576,1002.33,30,16,0
0.021944444,215.2,228,106,58.8,50,8.1911,16.3822,227,2.6,0.576,1002.33,30,16,0
0.022037037,215.4,228,112,58.8,50,8.1911,16.3822,227,3.6,0.576,1002.33,30,16,0
0.02212963,215.8,228,112,58.8,50,8.1911,16.3822,226,1.6,0.576,1002.33,30,16,0
0.022233796,216.1,227,106,58.8,50,8.1911,16.3822,226,1.7,0.576,1002.33,30,16,0
0.022326389,216.1,227,106,58.8,50,8.1911,16.3822,226,3.1,0.576,1002.33,30,16,0
0.022418981,216.5,227,106,58.8,50,8.1911,16.3822,226,3.5,0.576,1002.33,30,16,0
0.022511574,216.7,227,106,58.8,50,8.1911,16.3822,225,1.2,0.576,1002.33,30,16,0
0.022604167,217,226,112,58.8,50,8.1911,16.3822,225,2,0.576,1002.33,30,16,0
0.022708333,217.2,226,106,58.8,50,8.1911,16.3822,225,3,0.576,1002.33,30,16,0
0.022800926,217.4,226,112,58.8,50,8.1911,16.3822,225,3,0.576,1002.33,30,16,0
0.022893519,217.6,225,106,58.8,50,8.1911,16.3822,224,1.3,0.576,1002.33,30,16,0
0.022986111,217.7,225,106,58.8,50,8.1911,16.3822,224,1.9,0.576,1002.33,30,16,0
0.023090278,217.9,225,106,58.8,50,8.1911,16.3822,224,3.1,0.576,1002.33,30,16,0
0.02318287,218.1,224,106,58.8,50,8.1911,16.3822,223,1.2,0.576,1002.33,30,16,0
0.023275463,218.3,224,106,58.8,50,8.1911,16.3822,223,1.3,0.576,1002.33,30,16,0
0.023368056,218.5,224,106,58.8,50,8.1911,16.3822,223,2.1,0.576,1002.33,30,16,0
0.023460648,218.6,224,106,58.8,50,8.1911,16.3822,223,2.6,0.576,1002.33,30,16,0
0.023564815,218.6,223,106,58.8,50,8.1911,16.3822,222,0.8,0.576,1002.33,30,16,0
0.023657407,218.8,223,106,58.8,50,8.1911,16.3822,222,1.4,0.576,1002.33,30,16,0
0.02375,219,223,106,58.8,50,8.1911,16.3822,222,2.4,0.576,1002.33,30,16,0
0.023842593,219,223,112,58.8,50,8.1911,16.3822,221,1,0.576,1002.33,30,16,0
0.023935185,219.2,222,106,58.8,50,8.1911,16.3822,221,1.3,0.576,1002.33,30,16,0
0.024027778,219.4,222,106,58.8,50,8.1911,16.3822,221,2.3,0.576,1002.33,30,16,0
0.02412037,219.4,222,106,58.8,50,8.1911,16.3822,221,2.2,0.576,1002.33,30,16,0
0.024224537,219.4,221,106,58.8,50,8.1911,16.3822,220,0.7,0.576,1002.33,30,16,0
0.02431713,219.4,221,106,58.8,50,8.1911,16.3822,220,1.4,0.576,1002.33,30,16,0
0.024409722,219.5,221,106,117.61,100,10.2388,10.2388,220,2.3,0.72,1252.909,30,20,0
0.024502315,219.7,220,106,88.2,75,9.7269,12.9692,220,2.3,0.684,1190.264,30,19,0
0.024594907,219.5,220,106,58.8,50,8.1911,16.3822,220,2.1,0.576,1002.33,30,16,0
0.0246875,219.7,220,102,29.4,25,5.6314,22.5257,220,2.1,0.396,689.1074,30,11,0
0.024780093,219.5,220,102,29.4,25,5.6314,22.5257,220,2.2,0.396,689.1074,30,11,0
0.024884259,219.7,220,102,58.8,50,6.6553,13.3106,220,2.6,0.468,814.3965,30,13,0
0.024976852,219.7,220,102,88.2,75,8.1911,10.9215,220,2,0.576,1002.33,30,16,0
0.025069444,219.5,220,106,117.61,100,10.2388,10.2388,248,49.2,0.72,1252.909,30,20,0
0.025162037,219.7,225,102,58.8,50,7.1672,14.3345,340,70,0.504,877.0411,30,14,0
0.02525463,219.5,237,102,58.8,50,7.1672,14.3345,340,70,0.504,877.0411,30,14,0
0.025358796,219.5,255,102,58.8,50,7.1672,14.3345,339,70,0.504,877.0411,30,14,0
0.025451389,219.7,271,106,58.8,50,7.1672,14.3345,339,67.6,0.504,877.0411,30,14,0
0.025543981,219.7,284,102,58.8,50,7.1672,14.3345,339,53.5,0.504,877.0411,30,14,0
0.025636574,220.1,298,106,58.8,50,7.1672,14.3345,338,41.7,0.504,877.0411,30,14,0
0.025729167,220.6,307,106,58.8,50,6.6553,13.3106,338,40.9,0.468,814.3965,30,13,0
0.025821759,221.5,313,106,58.8,50,6.6553,13.3106,338,42.4,0.468,814.3965,30,13,0
0.025914352,222.4,318,106,58.8,50,6.6553,13.3106,338,39.4,0.468,814.3965,30,13,0
0.026018519,223.9,325,106,58.8,50,6.1434,12.2867,337,31.5,0.432,751.752,30,12,0
0.026111111,225.3,329,112,58.8,50,6.1434,12.2867,337,29,0.432,751.752,30,12,0
0.026203704,226.5,332,106,58.8,50,6.1434,12.2867,337,27.8,0.432,751.752,30,12,0
0.026296296,228.3,335,106,58.8,50,6.1434,12.2867,337,24.9,0.432,751.752,30,12,0
0.026388889,229.8,337,106,58.8,50,6.1434,12.2867,336,22,0.432,751.752,30,12,0
0.026481481,231.4,339,112,58.8,50,6.1434,12.2867,336,20.9,0.432,751.752,30,12,0
0.026585648,233.2,340,112,58.8,50,6.1434,12.2867,336,20.1,0.432,751.752,30,12,0
0.026678241,234.6,341,112,58.8,50,5.6314,11.2628,336,19.2,0.396,689.1074,30,11,0
0.026770833,236.4,342,112,58.8,50,5.6314,11.2628,335,15.8,0.396,689.1074,30,11,0
0.026863426,238.1,342,112,58.8,50,5.6314,11.2628,335,16,0.396,689.1074,30,11,0
0.026956019,239.7,342,112,58.8,50,5.6314,11.2628,335,15.6,0.396,689.1074,30,11,0
0.027048611,240.9,342,112,58.8,50,5.6314,11.2628,334,13.1,0.396,689.1074,30,11,0
0.027141204,243.1,342,112,58.8,50,5.6314,11.2628,334,12.4,0.396,689.1074,30,11,0
0.02724537,244.5,342,112,58.8,50,5.6314,11.2628,334,13.4,0.396,689.1074,30,11,0
0.027337963,246,342,112,58.8,50,5.6314,11.2628,334,12.9,0.396,689.1074,30,11,0
0.027430556,247.8,341,112,58.8,50,5.6314,11.2628,333,10.5,0.396,689.1074,30,11,0
0.027523148,249.4,341,112,58.8,50,5.6314,11.2628,333,11.1,0.396,689.1074,30,11,0
0.027615741,250.8,340,112,58.8,50,5.6314,11.2628,333,11.5,0.396,689.1074,30,11,0
0.027719907,252.8,340,112,58.8,50,5.6314,11.2628,333,10.9,0.396,689.1074,30,11,0
0.0278125,254.1,339,112,58.8,50,5.6314,11.2628,332,9.2,0.396,689.1074,30,11,0
0.027905093,255.7,339,106,58.8,50,5.6314,11.2628,332,10,0.396,689.1074,30,11,0
0.027997685,257.5,338,112,58.8,50,5.6314,11.2628,332,10.4,0.396,689.1074,30,11,0
0.028090278,259.1,338,112,58.8,50,5.6314,11.2628,331,9.7,0.396,689.1074,30,11,0
0.02818287,260.5,337,112,58.8,50,5.6314,11.2628,331,8.6,0.396,689.1074,30,11,0
0.028287037,262.3,336,112,58.8,50,5.6314,11.2628,331,9.5,0.396,689.1074,30,11,0
0.02837963,263.8,336,106,58.8,50,5.6314,11.2628,331,9.2,0.396,689.1074,30,11,0
0.028472222,265.2,335,112,58.8,50,5.6314,11.2628,330,7.9,0.396,689.1074,30,11,0
0.028564815,266.8,335,112,58.8,50,5.6314,11.2628,330,8,0.396,689.1074,30,11,0
0.028657407,268.3,334,106,58.8,50,5.6314,11.2628,330,9,0.396,689.1074,30,11,0
0.02875,270.1,334,112,58.8,50,5.6314,11.2628,330,9.1,0.396,689.1074,30,11,0
0.028842593,271.3,333,112,58.8,50,5.6314,11.2628,329,7,0.396,689.1074,30,11,0
0.028946759,272.6,333,112,58.8,50,5.6314,11.2628,329,8,0.396,689.1074,30,11,0
0.029039352,274.2,332,112,58.8,50,5.6314,11.2628,329,8.6,0.396,689.1074,30,11,0
0.029131944,275.3,332,112,58.8,50,5.6314,11.2628,329,8.9,0.396,689.1074,30,11,0
0.029224537,276.5,332,112,58.8,50,5.6314,11.2628,328,6.3,0.396,689.1074,30,11,0
0.029328704,278,331,106,58.8,50,5.6314,11.2628,328,7.5,0.396,689.1074,30,11,0
0.029421296,279.2,331,112,58.8,50,5.6314,11.2628,328,8.3,0.396,689.1074,30,11,0
0.029513889,280.5,330,112,58.8,50,5.6314,11.2628,327,6.2,0.396,689.1074,30,11,0
0.029606481,281.6,330,112,58.8,50,5.6314,11.2628,327,6.4,0.396,689.1074,30,11,0
0.029699074,282.6,329,106,58.8,50,5.6314,11.2628,327,7.5,0.396,689.1074,30,11,0
0.029803241,283.7,329,106,58.8,50,5.6314,11.2628,327,7.7,0.396,689.1074,30,11,0
0.029895833,284.8,329,106,58.8,50,5.6314,11.2628,326,5.7,0.396,689.1074,30,11,0
0.029988426,285.9,328,106,58.8,50,5.6314,11.2628,326,6.7,0.396,689.1074,30,11,0
0.030081019,287,328,106,58.8,50,5.6314,11.2628,326,7.2,0.396,689.1074,30,11,0
0.030173611,287.9,328,106,58.8,50,5.6314,11.2628,325,5.6,0.396,689.1074,30,11,0
0.030277778,288.9,327,106,58.8,50,5.6314,11.2628,325,6,0.396,689.1074,30,11,0
0.03037037,289.7,327,106,58.8,50,5.6314,11.2628,325,6.2,0.396,689.1074,30,11,0
0.030462963,290.6,327,106,58.8,50,5.6314,11.2628,325,7.1,0.396,689.1074,30,11,0
0.030555556,291.6,326,106,58.8,50,5.6314,11.2628,324,5.3,0.396,689.1074,30,11,0
0.030659722,292.3,326,106,58.8,50,5.6314,11.2628,324,6.2,0.396,689.1074,30,11,0
0.030752315,293.1,326,112,58.8,50,5.6314,11.2628,324,6.2,0.396,689.1074,30,11,0
0.030844907,293.8,325,112,58.8,50,5.1195,10.239,324,6.3,0.36,626.4627,30,10,0
0.0309375,294.7,325,106,58.8,50,5.6314,11.2628,323,5.2,0.396,689.1074,30,11,0
0.031030093,295.4,325,106,58.8,50,5.1195,10.239,323,6.3,0.36,626.4627,30,10,0
0.031122685,296.1,324,106,58.8,50,5.1195,10.239,323,6.5,0.36,626.4627,30,10,0
0.031226852,296.7,324,106,58.8,50,5.1195,10.239,322,4.5,0.36,626.4627,30,10,0
0.031319444,297.4,324,102,58.8,50,5.1195,10.239,322,4.6,0.36,626.4627,30,10,0
0.031412037,298.1,323,106,58.8,50,5.1195,10.239,322,6.3,0.36,626.4627,30,10,0
0.03150463,298.6,323,106,58.8,50,5.1195,10.239,322,6.3,0.36,626.4627,30,10,0
0.031597222,299.2,323,102,58.8,50,5.1195,10.239,321,3.9,0.36,626.4627,30,10,0
0.031689815,299.7,323,106,58.8,50,5.1195,10.239,321,4.8,0.36,626.4627,30,10,0
0.031793981,300.3,322,106,58.8,50,5.1195,10.239,321,5.8,0.36,626.4627,30,10,0
0.031886574,300.8,322,106,58.8,50,5.1195,10.239,320,4.3,0.36,626.4627,30,10,0
0.031979167,301.5,322,106,58.8,50,5.1195,10.239,320,4.3,0.36,626.4627,30,10,0
0.032071759,301.9,321,106,58.8,50,5.1195,10.239,320,5,0.36,626.4627,30,10,0
0.032164352,302.4,321,106,58.8,50,5.1195,10.239,320,5.9,0.36,626.4627,30,10,0
0.032268519,302.6,321,106,58.8,50,5.1195,10.239,319,4,0.36,626.4627,30,10,0
0.032361111,303.1,321,106,58.8,50,5.1195,10.239,319,4.2,0.36,626.4627,30,10,0
0.032453704,303.5,320,106,58.8,50,5.1195,10.239,319,5.4,0.36,626.4627,30,10,0
0.032546296,303.9,320,106,58.8,50,5.1195,10.239,319,5.7,0.36,626.4627,30,10,0
0.032638889,304.2,320,106,58.8,50,5.1195,10.239,318,3.8,0.36,626.4627,30,10,0
0.032731481,304.6,319,102,58.8,50,5.1195,10.239,318,4.2,0.36,626.4627,30,10,0
0.032824074,304.9,319,106,58.8,50,5.1195,10.239,318,5.3,0.36,626.4627,30,10,0
0.032928241,305.3,319,106,58.8,50,5.1195,10.239,318,5.3,0.36,626.4627,30,10,0
0.033020833,305.7,319,106,58.8,50,5.1195,10.239,317,3.4,0.36,626.4627,30,10,0
0.033113426,305.8,318,106,58.8,50,5.1195,10.239,317,4.3,0.36,626.4627,30,10,0
0.033206019,306.2,318,106,58.8,50,5.1195,10.239,317,4.9,0.36,626.4627,30,10,0
0.033298611,306.4,318,102,58.8,50,5.1195,10.239,316,3.3,0.36,626.4627,30,10,0
0.033391204,306.6,317,106,58.8,50,5.1195,10.239,316,3.3,0.36,626.4627,30,10,0
0.033483796,306.9,317,106,58.8,50,5.1195,10.239,316,4.4,0.36,626.4627,30,10,0
0.033587963,307.1,317,106,58.8,50,5.1195,10.239,316,5,0.36,626.4627,30,10,0
0.033680556,307.3,317,102,58.8,50,5.1195,10.239,315,3.1,0.36,626.4627,30,10,0
0.033773148,307.5,316,102,58.8,50,5.1195,10.239,315,3.2,0.36,626.4627,30,10,0
0.033865741,307.6,316,102,58.8,50,5.1195,10.239,315,4.2,0.36,626.4627,30,10,0
0.033958333,307.8,316,102,58.8,50,5.1195,10.239,315,5.1,0.36,626.4627,30,10,0
0.034050926,307.8,315,102,58.8,50,5.1195,10.239,314,2.9,0.36,626.4627,30,10,0
0.034143519,308,315,102,58.8,50,5.1195,10.239,314,3.4,0.36,626.4627,30,10,0
0.034247685,308,315,102,58.8,50,5.1195,10.239,314,4.2,0.36,626.4627,30,10,0
0.034340278,308.4,314,102,58.8,50,5.1195,10.239,313,3.2,0.36,626.4627,30,10,0
0.03443287,308.4,314,102,58.8,50,5.1195,10.239,313,3.1,0.36,626.4627,30,10,0
0.034525463,308.4,314,102,58.8,50,5.1195,10.239,313,4,0.36,626.4627,30,10,0
0.034618056,308.5,314,102,58.8,50,5.1195,10.239,313,4.6,0.36,626.4627,30,10,0
0.034710648,308.7,313,102,58.8,50,5.1195,10.239,312,2.6,0.36,626.4627,30,10,0
0.034803241,308.7,313,102,58.8,50,5.1195,10.239,312,3,0.36,626.4627,30,10,0
0.034895833,308.7,313,102,58.8,50,5.1195,10.239,312,4.3,0.36,626.4627,30,10,0
0.034988426,308.7,312,102,58.8,50,5.1195,10.239,312,4,0.36,626.4627,30,10,0
0.035092593,308.9,312,102,58.8,50,5.1195,10.239,311,2.5,0.36,626.4627,30,10,0
0.035185185,308.9,312,106,58.8,50,5.1195,10.239,311,3.8,0.36,626.4627,30,10,0
0.035277778,308.9,312,102,58.8,50,5.1195,10.239,311,4.6,0.36,626.4627,30,10,0
0.03537037,308.9,311,102,58.8,50,5.1195,10.239,311,3.9,0.36,626.4627,30,10,0
0.035462963,308.9,311,102,58.8,50,5.1195,10.239,310,2.4,0.36,626.4627,30,10,0
0.035555556,308.9,311,102,117.61,100,5.6314,5.6314,310,3.4,0.396,689.1074,30,11,0
0.035648148,308.9,311,102,88.2,75,5.6314,7.5086,310,4,0.396,689.1074,30,11,0
0.035752315,308.9,310,102,58.8,50,5.6314,7.5086,310,4,0.396,689.1074,30,11,0
0.035844907,308.9,310,102,58.8,50,5.6314,11.2628,310,3.6,0.396,689.1074,30,11,0
0.0359375,308.9,310,102,29.4,25,5.1195,20.478,310,3.7,0.36,626.4627,30,10,0
0.036030093,308.7,310,102,58.8,50,5.1195,10.239,310,4.1,0.36,626.4627,30,10,0
0.036122685,308.9,310,102,88.2,75,5.1195,6.826,310,4.2,0.36,626.4627,30,10,0
0.036215278,308.9,310,102,117.61,100,5.6314,5.6314,310,4,0.396,689.1074,30,11,0
0.03630787,308.7,312,102,58.8,50,5.6314,5.6314,441,70,0.396,689.1074,30,11,0
0.036412037,308.7,321,102,58.8,50,5.1195,10.239,445,70,0.36,626.4627,30,10,0
0.03650463,308.7,334,102,58.8,50,5.1195,10.239,444,70,0.36,626.4627,30,10,0
0.036597222,308.7,348,102,58.8,50,5.1195,10.239,444,70,0.36,626.4627,30,10,0
0.036689815,308.7,364,102,58.8,50,5.1195,10.239,444,70,0.36,626.4627,30,10,0
0.036782407,308.9,377,102,58.8,50,5.1195,10.239,443,70,0.36,626.4627,30,10,0
0.036875,309.2,391,106,58.8,50,5.1195,10.239,443,63.5,0.36,626.4627,30,10,0
0.036967593,309.8,401,106,58.8,50,5.1195,10.239,443,54.5,0.36,626.4627,30,10,0
0.037071759,310.7,411,102,58.8,50,5.1195,10.239,443,49.7,0.36,626.4627,30,10,0
0.037164352,311.6,419,106,58.8,50,5.1195,10.239,442,45.7,0.36,626.4627,30,10,0
0.037256944,312.8,425,102,58.8,50,5.1195,10.239,442,43.6,0.36,626.4627,30,10,0
0.037349537,313.7,429,106,58.8,50,5.1195,10.239,442,40.9,0.36,626.4627,30,10,0
0.03744213,315,434,106,58.8,50,5.1195,10.239,441,35.1,0.36,626.4627,30,10,0
0.037534722,316.4,437,106,58.8,50,5.1195,10.239,441,33.5,0.36,626.4627,30,10,0
0.037627315,317.9,440,106,58.8,50,5.1195,10.239,441,32.2,0.36,626.4627,30,10,0
0.037719907,319.1,442,106,58.8,50,5.1195,10.239,440,28.3,0.36,626.4627,30,10,0
0.0378125,320.9,444,106,58.8,50,5.1195,10.239,440,27.4,0.36,626.4627,30,10,0
0.037916667,322.6,445,106,58.8,50,5.1195,10.239,440,26,0.36,626.4627,30,10,0
0.038009259,324.5,446,106,58.8,50,5.1195,10.239,439,23,0.36,626.4627,30,10,0
0.038101852,326.9,447,106,58.8,50,5.1195,10.239,439,22.2,0.36,626.4627,30,10,0
0.038194444,329,447,106,58.8,50,5.1195,10.239,439,22.3,0.36,626.4627,30,10,0
0.038287037,331.4,447,106,58.8,50,5.1195,10.239,438,19.3,0.36,626.4627,30,10,0
0.03837963,334.1,447,106,58.8,50,5.1195,10.239,438,19.2,0.36,626.4627,30,10,0
0.038483796,336.4,447,106,58.8,50,5.1195,10.239,438,19,0.36,626.4627,30,10,0
0.038576389,338.4,447,106,58.8,50,5.1195,10.239,437,16,0.36,626.4627,30,10,0
0.038668981,341.1,447,106,58.8,50,5.1195,10.239,437,15.8,0.36,626.4627,30,10,0
0.038761574,343,446,106,58.8,50,5.1195,10.239,437,16.6,0.36,626.4627,30,10,0
0.038854167,345.2,446,106,58.8,50,5.1195,10.239,437,16.3,0.36,626.4627,30,10,0
0.038946759,347.7,445,106,58.8,50,5.1195,10.239,436,13.6,0.36,626.4627,30,10,0
0.039039352,349.5,445,106,58.8,50,5.1195,10.239,436,14.1,0.36,626.4627,30,10,0
0.039143519,351.5,444,112,58.8,50,5.1195,10.239,436,14.6,0.36,626.4627,30,10,0
0.039236111,353.7,443,106,58.8,50,5.1195,10.239,435,12.2,0.36,626.4627,30,10,0
0.039328704,355.6,443,106,58.8,50,5.1195,10.239,435,13.1,0.36,626.4627,30,10,0
0.039421296,357.4,442,106,58.8,50,5.1195,10.239,435,13.5,0.36,626.4627,30,10,0
0.039513889,359.6,441,106,58.8,50,4.6076,9.2151,434,11.7,0.324,563.8182,30,9,0
0.039606481,361.4,441,106,58.8,50,5.1195,10.239,434,11.4,0.36,626.4627,30,10,0
0.039699074,363,440,106,58.8,50,4.6076,9.2151,434,12.8,0.324,563.8182,30,9,0
0.039803241,365,440,106,58.8,50,4.6076,9.2151,433,10.4,0.324,563.8182,30,9,0
0.039895833,367.5,439,106,58.8,50,4.6076,9.2151,433,10.6,0.324,563.8182,30,9,0
0.039988426,369.1,438,106,58.8,50,4.6076,9.2151,433,11.8,0.324,563.8182,30,9,0
0.040081019,370.9,438,112,58.8,50,4.6076,9.2151,432,9.7,0.324,563.8182,30,9,0
0.040173611,372.2,437,106,58.8,50,4.6076,9.2151,432,10.1,0.324,563.8182,30,9,0
0.040266204,373.6,437,106,58.8,50,4.6076,9.2151,432,10.8,0.324,563.8182,30,9,0
0.04037037,375.2,436,106,58.8,50,4.6076,9.2151,431,9.3,0.324,563.8182,30,9,0
0.040462963,376.3,436,112,58.8,50,4.6076,9.2151,431,9.4,0.324,563.8182,30,9,0
0.040555556,377.7,435,106,58.8,50,4.6076,9.2151,431,10.4,0.324,563.8182,30,9,0
0.040648148,379,434,106,58.8,50,4.6076,9.2151,430,9,0.324,563.8182,30,9,0
0.040740741,380.3,434,106,58.8,50,4.6076,9.2151,430,9.1,0.324,563.8182,30,9,0
0.040833333,381.5,433,106,58.8,50,4.6076,9.2151,430,9.6,0.324,563.8182,30,9,0
0.0409375,382.8,433,106,58.8,50,4.6076,9.2151,429,9,0.324,563.8182,30,9,0
0.041030093,383.9,432,106,58.8,50,4.6076,9.2151,429,9,0.324,563.8182,30,9,0
0.041122685,385.1,432,106,58.8,50,4.6076,9.2151,429,9.7,0.324,563.8182,30,9,0
0.041215278,386,431,106,58.8,50,4.6076,9.2151,429,9.8,0.324,563.8182,30,9,0
0.04130787,387.1,431,106,58.8,50,4.6076,9.2151,428,8.2,0.324,563.8182,30,9,0
0.041400463,388,431,106,58.8,50,4.6076,9.2151,428,9,0.324,563.8182,30,9,0
0.04150463,389.1,430,106,58.8,50,4.6076,9.2151,428,9.8,0.324,563.8182,30,9,0
0.041597222,390.2,430,106,58.8,50,4.6076,9.2151,427,7.7,0.324,563.8182,30,9,0
0.041689815,391.1,429,106,58.8,50,4.6076,9.2151,427,9.2,0.324,563.8182,30,9,0
0.041782407,391.9,429,112,58.8,50,4.6076,9.2151,427,9,0.324,563.8182,30,9,0
0.041875,392.7,429,102,58.8,50,4.6076,9.2151,426,7.4,0.324,563.8182,30,9,0
0.041979167,393.4,428,106,58.8,50,4.6076,9.2151,426,8.6,0.324,563.8182,30,9,0
0.042071759,394.5,428,106,58.8,50,4.6076,9.2151,426,9.1,0.324,563.8182,30,9,0
0.042164352,395.2,427,106,58.8,50,4.6076,9.2151,425,7.3,0.324,563.8182,30,9,0
0.042256944,395.9,427,106,58.8,50,4.6076,9.2151,425,8.5,0.324,563.8182,30,9,0
0.042349537,396.6,427,106,58.8,50,4.6076,9.2151,425,8.3,0.324,563.8182,30,9,0
0.04244213,397.3,426,106,58.8,50,4.6076,9.2151,424,8.6,0.324,563.8182,30,9,0
0.042534722,397.9,426,106,58.8,50,4.6076,9.2151,424,7.5,0.324,563.8182,30,9,0
0.042638889,398.6,426,106,58.8,50,4.6076,9.2151,424,8.3,0.324,563.8182,30,9,0
0.042731481,399.1,425,102,58.8,50,4.6076,9.2151,423,6.6,0.324,563.8182,30,9,0
0.042824074,399.7,425,102,58.8,50,4.6076,9.2151,423,7.1,0.324,563.8182,30,9,0
0.042916667,400.4,424,102,58.8,50,4.6076,9.2151,423,8.1,0.324,563.8182,30,9,0
0.043009259,400.6,424,106,58.8,50,4.6076,9.2151,423,8.2,0.324,563.8182,30,9,0
0.043101852,401.3,424,106,58.8,50,4.6076,9.2151,422,6.5,0.324,563.8182,30,9,0
0.043194444,401.8,423,106,58.8,50,4.6076,9.2151,422,7.8,0.324,563.8182,30,9,0
0.043298611,402.2,423,106,58.8,50,4.6076,9.2151,422,8.1,0.324,563.8182,30,9,0
0.043391204,402.7,423,106,58.8,50,4.6076,9.2151,421,6.5,0.324,563.8182,30,9,0
0.043483796,403.1,423,106,58.8,50,4.6076,9.2151,421,6.6,0.324,563.8182,30,9,0
0.043576389,403.5,422,102,58.8,50,4.6076,9.2151,421,7.8,0.324,563.8182,30,9,0
0.043668981,404,422,106,58.8,50,4.6076,9.2151,420,6.3,0.324,563.8182,30,9,0
0.043773148,404.2,421,106,58.8,50,4.6076,9.2151,420,6.4,0.324,563.8182,30,9,0
0.043865741,404.5,421,106,58.8,50,4.6076,9.2151,420,7.6,0.324,563.8182,30,9,0
0.043958333,404.9,421,106,58.8,50,4.6076,9.2151,419,6.1,0.324,563.8182,30,9,0
0.044050926,405.1,420,102,58.8,50,4.6076,9.2151,419,6.3,0.324,563.8182,30,9,0
0.044143519,405.4,420,102,58.8,50,4.6076,9.2151,419,7.5,0.324,563.8182,30,9,0
0.044236111,405.8,420,106,58.8,50,4.6076,9.2151,418,5.8,0.324,563.8182,30,9,0
0.044328704,406,420,102,58.8,50,4.6076,9.2151,418,5.7,0.324,563.8182,30,9,0
0.04443287,406.2,419,102,58.8,50,4.6076,9.2151,418,6.9,0.324,563.8182,30,9,0
0.044525463,406.3,419,102,58.8,50,4.6076,9.2151,417,5.6,0.324,563.8182,30,9,0
0.044618056,406.7,418,102,58.8,50,4.6076,9.2151,417,6,0.324,563.8182,30,9,0
0.044710648,406.7,418,102,58.8,50,4.6076,9.2151,417,6.6,0.324,563.8182,30,9,0
0.044803241,406.9,418,102,58.8,50,4.6076,9.2151,416,5.6,0.324,563.8182,30,9,0
0.044895833,407.1,417,102,58.8,50,4.6076,9.2151,416,5.5,0.324,563.8182,30,9,0
0.045,407.2,417,102,58.8,50,4.6076,9.2151,416,6.4,0.324,563.8182,30,9,0
0.045092593,407.4,417,102,58.8,50,4.6076,9.2151,416,7.3,0.324,563.8182,30,9,0
0.045185185,407.4,416,102,58.8,50,4.6076,9.2151,415,5.3,0.324,563.8182,30,9,0
0.045277778,407.6,416,102,58.8,50,4.6076,9.2151,415,6.1,0.324,563.8182,30,9,0
0.045381944,407.6,416,102,58.8,50,4.6076,9.2151,415,6.7,0.324,563.8182,30,9,0
0.045474537,407.8,415,102,58.8,50,4.6076,9.2151,414,5.4,0.324,563.8182,30,9,0
0.04556713,407.8,415,102,58.8,50,4.6076,9.2151,414,6.3,0.324,563.8182,30,9,0
0.045659722,407.8,415,102,58.8,50,4.6076,9.2151,414,6.7,0.324,563.8182,30,9,0
0.045752315,407.8,415,102,58.8,50,4.6076,9.2151,413,4.5,0.324,563.8182,30,9,0
0.045844907,408,414,102,58.8,50,4.6076,9.2151,413,5.6,0.324,563.8182,30,9,0
0.0459375,408,414,102,58.8,50,4.6076,9.2151,413,6.4,0.324,563.8182,30,9,0
0.046030093,408.1,413,102,58.8,50,4.6076,9.2151,412,5.2,0.324,563.8182,30,9,0
0.046122685,408.1,413,102,58.8,50,4.6076,9.2151,412,5.3,0.324,563.8182,30,9,0
0.046226852,408.1,413,102,58.8,50,4.6076,9.2151,412,6.1,0.324,563.8182,30,9,0
0.046319444,408,413,102,58.8,50,4.6076,9.2151,411,4.6,0.324,563.8182,30,9,0
0.046412037,408,412,102,58.8,50,4.6076,9.2151,411,4.9,0.324,563.8182,30,9,0
0.04650463,408,412,102,58.8,50,4.6076,9.2151,411,6.2,0.324,563.8182,30,9,0
0.046597222,408,412,102,58.8,50,4.6076,9.2151,410,4.6,0.324,563.8182,30,9,0
0.046689815,407.8,411,102,58.8,50,4.6076,9.2151,410,4.6,0.324,563.8182,30,9,0
0.046793981,407.8,411,102,117.61,100,4.6076,4.6076,410,5.7,0.324,563.8182,30,9,0
0.046886574,407.8,411,102,88.2,75,5.1195,6.826,410,6.3,0.36,626.4627,30,10,0
0.046979167,407.6,410,102,58.8,50,4.6076,9.2151,410,5.8,0.324,563.8182,30,9,0
0.047083333,407.4,410,102,29.4,25,4.6076,18.4302,410,6.3,0.324,563.8182,30,9,0
0.047175926,407.4,410,102,58.8,50,4.6076,9.2151,410,6.5,0.324,563.8182,30,9,0
0.047268519,407.2,410,102,88.2,75,4.6076,6.1434,410,6.6,0.324,563.8182,30,9,0
0.047361111,407.2,410,102,88.2,75,4.6076,6.1434,410,6.2,0.324,563.8182,30,9,0
0.047453704,407.2,410,102,117.61,100,5.1195,5.1195,447,68.1,0.36,626.4627,30,10,0
0.047546296,407.2,413,102,58.8,50,4.6076,9.2151,500,70,0.324,563.8182,30,9,0
0.047650463,406.9,425,102,58.8,50,4.6076,9.2151,500,70,0.324,563.8182,30,9,0
0.047743056,406.9,438,102,58.8,50,4.6076,9.2151,500,69.5,0.324,563.8182,30,9,0
0.047835648,406.9,452,102,58.8,50,4.6076,9.2151,499,48.9,0.324,563.8182,30,9,0
0.047928241,406.9,461,102,58.8,50,4.6076,9.2151,499,43.8,0.324,563.8182,30,9,0
0.048020833,407.2,468,102,58.8,50,4.6076,9.2151,499,45,0.324,563.8182,30,9,0
0.048113426,407.6,474,102,58.8,50,4.6076,9.2151,499,43.5,0.324,563.8182,30,9,0
0.048217593,408.1,480,102,58.8,50,4.6076,9.2151,499,39.1,0.324,563.8182,30,9,0
0.048310185,408.7,484,102,58.8,50,4.6076,9.2151,499,35.7,0.324,563.8182,30,9,0
0.048402778,409.4,489,102,58.8,50,4.6076,9.2151,498,31.7,0.324,563.8182,30,9,0
0.04849537,410.3,491,102,58.8,50,4.6076,9.2151,498,30.9,0.324,563.8182,30,9,0
0.048587963,411.2,494,102,58.8,50,4.6076,9.2151,498,29.2,0.324,563.8182,30,9,0
0.048680556,412.1,496,102,58.8,50,4.6076,9.2151,498,27.2,0.324,563.8182,30,9,0
0.048773148,413,498,102,58.8,50,4.6076,9.2151,498,25.3,0.324,563.8182,30,9,0
0.048865741,414.1,499,102,58.8,50,4.6076,9.2151,497,22.5,0.324,563.8182,30,9,0
0.048958333,415,501,102,58.8,50,4.6076,9.2151,497,21.1,0.324,563.8182,30,9,0
0.049050926,416.4,501,102,58.8,50,4.6076,9.2151,497,21.6,0.324,563.8182,30,9,0
0.049155093,417.5,502,106,58.8,50,4.6076,9.2151,497,20.8,0.324,563.8182,30,9,0
0.049247685,418.6,502,106,58.8,50,4.6076,9.2151,497,19.1,0.324,563.8182,30,9,0
0.049351852,420.2,502,102,58.8,50,4.6076,9.2151,496,18.7,0.324,563.8182,30,9,0
0.049444444,421.3,503,106,58.8,50,4.6076,9.2151,496,16.8,0.324,563.8182,30,9,0
0.049548611,422.7,502,106,58.8,50,4.6076,9.2151,496,17,0.324,563.8182,30,9,0
0.049641204,424.1,502,102,58.8,50,4.6076,9.2151,496,16.5,0.324,563.8182,30,9,0
0.04974537,425.4,502,102,58.8,50,4.6076,9.2151,496,16.3,0.324,563.8182,30,9,0
0.049837963,426.8,502,106,58.8,50,4.6076,9.2151,496,15.5,0.324,563.8182,30,9,0
0.04994213,428.1,502,106,58.8,50,4.6076,9.2151,495,14,0.324,563.8182,30,9,0
0.050034722,429.7,501,102,58.8,50,4.6076,9.2151,495,14.7,0.324,563.8182,30,9,0
0.050138889,431,501,102,58.8,50,4.6076,9.2151,495,14.2,0.324,563.8182,30,9,0
0.050231481,432.4,500,102,58.8,50,4.6076,9.2151,495,14.2,0.324,563.8182,30,9,0
0.050324074,433.7,500,106,58.8,50,4.6076,9.2151,495,14.1,0.324,563.8182,30,9,0
0.050416667,435.1,500,102,58.8,50,4.6076,9.2151,494,12.1,0.324,563.8182,30,9,0
0.050509259,436.2,499,102,58.8,50,4.6076,9.2151,494,11.9,0.324,563.8182,30,9,0
0.050613426,437.4,499,106,58.8,50,4.6076,9.2151,494,13.1,0.324,563.8182,30,9,0
0.050706019,438.5,498,106,58.8,50,4.6076,9.2151,494,13.1,0.324,563.8182,30,9,0
0.050798611,440,498,106,58.8,50,4.6076,9.2151,494,12.8,0.324,563.8182,30,9,0
0.050891204,441,498,106,58.8,50,4.6076,9.2151,494,12.7,0.324,563.8182,30,9,0
0.050983796,441.9,497,102,58.8,50,4.6076,9.2151,493,11.7,0.324,563.8182,30,9,0
0.051076389,443.2,497,106,58.8,50,4.6076,9.2151,493,12,0.324,563.8182,30,9,0
0.051168981,444.4,496,106,58.8,50,4.6076,9.2151,493,11.9,0.324,563.8182,30,9,0
0.051261574,445.5,496,102,58.8,50,4.6076,9.2151,493,12.2,0.324,563.8182,30,9,0
0.051354167,446.4,496,102,58.8,50,4.6076,9.2151,493,11.9,0.324,563.8182,30,9,0
0.051446759,447.5,496,106,58.8,50,4.6076,9.2151,492,10.3,0.324,563.8182,30,9,0
0.051539352,448.6,495,106,58.8,50,4.6076,9.2151,492,10.9,0.324,563.8182,30,9,0
0.051631944,449.5,495,106,58.8,50,4.6076,9.2151,492,11.7,0.324,563.8182,30,9,0
0.051724537,450.4,494,106,58.8,50,4.6076,9.2151,492,11.5,0.324,563.8182,30,9,0
0.051828704,451.6,494,102,58.8,50,4.6076,9.2151,492,11.6,0.324,563.8182,30,9,0
0.051921296,452.4,494,106,58.8,50,4.6076,9.2151,492,11.4,0.324,563.8182,30,9,0
0.052013889,453.1,494,106,58.8,50,4.6076,9.2151,491,9.9,0.324,563.8182,30,9,0
0.052106481,454,493,106,58.8,50,4.6076,9.2151,491,11.2,0.324,563.8182,30,9,0
0.052199074,454.9,493,106,58.8,50,4.6076,9.2151,491,11.6,0.324,563.8182,30,9,0
0.052291667,455.6,493,102,58.8,50,4.6076,9.2151,491,11.3,0.324,563.8182,30,9,0
0.052384259,456.3,492,106,58.8,50,4.6076,9.2151,491,11,0.324,563.8182,30,9,0
0.052488426,457.2,492,106,58.8,50,4.6076,9.2151,490,9.6,0.324,563.8182,30,9,0
0.052581019,457.9,492,106,58.8,50,4.6076,9.2151,490,9.7,0.324,563.8182,30,9,0
0.052673611,458.5,492,106,58.8,50,4.6076,9.2151,490,10.7,0.324,563.8182,30,9,0
0.052766204,459.2,491,106,58.8,50,4.6076,9.2151,490,11,0.324,563.8182,30,9,0
0.052858796,459.7,491,106,58.8,50,4.6076,9.2151,490,11,0.324,563.8182,30,9,0
0.052951389,460.6,491,102,58.8,50,4.6076,9.2151,490,10.5,0.324,563.8182,30,9,0
0.053043981,461.2,491,106,58.8,50,4.6076,9.2151,489,8.8,0.324,563.8182,30,9,0
0.053136574,461.7,491,106,58.8,50,4.6076,9.2151,489,9.7,0.324,563.8182,30,9,0
0.053240741,462.2,490,106,58.8,50,4.6076,9.2151,489,10.8,0.324,563.8182,30,9,0
0.053333333,462.6,490,106,58.8,50,4.6076,9.2151,489,10.4,0.324,563.8182,30,9,0
0.053425926,463.3,490,102,58.8,50,4.6076,9.2151,489,10.1,0.324,563.8182,30,9,0
0.053518519,463.5,490,106,58.8,50,4.6076,9.2151,488,9,0.324,563.8182,30,9,0
0.053611111,464.2,490,106,58.8,50,4.6076,9.2151,488,9.2,0.324,563.8182,30,9,0
0.053703704,464.8,489,106,58.8,50,4.6076,9.2151,488,10.1,0.324,563.8182,30,9,0
0.053796296,465.1,489,102,58.8,50,4.6076,9.2151,488,10.2,0.324,563.8182,30,9,0
0.053888889,465.7,489,102,58.8,50,4.6076,9.2151,488,9.9,0.324,563.8182,30,9,0
0.053981481,466,489,102,58.8,50,4.6076,9.2151,488,9.7,0.324,563.8182,30,9,0
0.054074074,466.2,489,106,58.8,50,4.6076,9.2151,487,8.7,0.324,563.8182,30,9,0
0.054178241,466.7,488,106,58.8,50,4.6076,9.2151,487,9.2,0.324,563.8182,30,9,0
0.054270833,467.1,488,102,58.8,50,4.6076,9.2151,487,9.9,0.324,563.8182,30,9,0
0.054363426,467.5,488,102,58.8,50,4.6076,9.2151,487,10,0.324,563.8182,30,9,0
0.054456019,467.6,488,102,58.8,50,4.6076,9.2151,487,9.9,0.324,563.8182,30,9,0
0.054548611,468,488,102,58.8,50,4.6076,9.2151,486,7.6,0.324,563.8182,30,9,0
0.054641204,468.4,487,102,58.8,50,4.6076,9.2151,486,8.5,0.324,563.8182,30,9,0
0.054733796,468.5,487,106,58.8,50,4.6076,9.2151,486,9.4,0.324,563.8182,30,9,0
0.054826389,468.7,487,106,58.8,50,4.6076,9.2151,486,9.5,0.324,563.8182,30,9,0
0.054930556,469.1,487,102,58.8,50,4.6076,9.2151,486,9.8,0.324,563.8182,30,9,0
0.055023148,469.3,486,106,58.8,50,4.6076,9.2151,486,9.6,0.324,563.8182,30,9,0
0.055115741,469.6,486,102,58.8,50,4.6076,9.2151,485,7.6,0.324,563.8182,30,9,0
0.055208333,469.8,486,102,58.8,50,4.6076,9.2151,485,8.6,0.324,563.8182,30,9,0
0.055300926,470,486,106,58.8,50,4.6076,9.2151,485,9,0.324,563.8182,30,9,0
0.055393519,470.2,486,102,58.8,50,4.6076,9.2151,485,9.3,0.324,563.8182,30,9,0
0.055486111,470.5,485,106,58.8,50,4.6076,9.2151,485,9.4,0.324,563.8182,30,9,0
0.055578704,470.5,485,102,58.8,50,4.6076,9.2151,484,7.3,0.324,563.8182,30,9,0
0.05568287,470.7,485,102,58.8,50,4.6076,9.2151,484,8.1,0.324,563.8182,30,9,0
0.055775463,470.9,485,106,58.8,50,4.6076,9.2151,484,9.2,0.324,563.8182,30,9,0
0.055868056,471.1,485,102,58.8,50,4.6076,9.2151,484,9.2,0.324,563.8182,30,9,0
0.055960648,471.1,484,106,58.8,50,4.6076,9.2151,484,9.2,0.324,563.8182,30,9,0
0.056053241,471.2,484,102,58.8,50,4.6076,9.2151,484,9.2,0.324,563.8182,30,9,0
0.056145833,471.4,484,106,58.8,50,4.6076,9.2151,483,7.3,0.324,563.8182,30,9,0
0.056238426,471.4,484,102,58.8,50,4.6076,9.2151,483,8.4,0.324,563.8182,30,9,0
0.056331019,471.6,484,106,58.8,50,4.6076,9.2151,483,9.1,0.324,563.8182,30,9,0
0.056435185,471.6,484,102,58.8,50,4.6076,9.2151,483,9.1,0.324,563.8182,30,9,0
0.056527778,471.6,483,106,58.8,50,4.6076,9.2151,483,8.5,0.324,563.8182,30,9,0
0.05662037,471.6,483,102,58.8,50,4.6076,9.2151,483,8.5,0.324,563.8182,30,9,0
0.056712963,472,483,102,58.8,50,4.6076,9.2151,482,7.6,0.324,563.8182,30,9,0
0.056805556,472,483,102,58.8,50,4.6076,9.2151,482,8.6,0.324,563.8182,30,9,0
0.056898148,472,483,106,58.8,50,4.6076,9.2151,482,8.7,0.324,563.8182,30,9,0
0.056990741,472,482,106,58.8,50,4.6076,9.2151,482,8.6,0.324,563.8182,30,9,0
0.057083333,472,482,106,58.8,50,4.6076,9.2151,482,8.6,0.324,563.8182,30,9,0
0.057175926,472.1,482,106,58.8,50,4.6076,9.2151,481,6.8,0.324,563.8182,30,9,0
0.057280093,472.1,482,106,58.8,50,4.6076,9.2151,481,7.6,0.324,563.8182,30,9,0
0.057372685,472.1,482,102,58.8,50,4.6076,9.2151,481,8.2,0.324,563.8182,30,9,0
0.057465278,472.3,482,102,58.8,50,4.6076,9.2151,481,8.4,0.324,563.8182,30,9,0
0.05755787,472.1,481,102,58.8,50,4.6076,9.2151,481,8.7,0.324,563.8182,30,9,0
0.057650463,472.1,481,106,58.8,50,4.6076,9.2151,481,8.4,0.324,563.8182,30,9,0
0.057743056,472.1,481,106,58.8,50,4.6076,9.2151,480,7,0.324,563.8182,30,9,0
0.057835648,472.1,481,106,58.8,50,4.6076,9.2151,480,8.1,0.324,563.8182,30,9,0
0.057939815,472.1,481,106,117.61,100,4.6076,9.2151,480,8.3,0.324,563.8182,30,9,0
0.058032407,472.3,480,106,88.2,75,4.6076,4.6076,480,8.5,0.324,563.8182,30,9,0
0.058125,472,480,102,88.2,75,4.6076,6.1434,480,8.4,0.324,563.8182,30,9,0
0.058217593,472,480,102,58.8,50,4.6076,9.2151,480,8.6,0.324,563.8182,30,9,0
0.058310185,472,480,106,29.4,25,4.6076,18.4302,480,8.6,0.324,563.8182,30,9,0
0.058402778,472,480,106,58.8,50,4.6076,9.2151,480,8.7,0.324,563.8182,30,9,0
0.05849537,472,480,106,88.2,75,4.6076,6.1434,480,8.8,0.324,563.8182,30,9,0
0.058587963,472,480,102,117.61,100,4.6076,4.6076,480,8.9,0.324,563.8182,30,9,0
0.058668981,472,480,102,117.61,100,5.1195,5.1195,480,8.9,0.36,626.4627,30,10,0