File: data/hpybr-cons-P.csv
Elapsed Time,Sample Temp,Heater Temp,Pressure,Rotor Speed,Shear Rate,Shear Stress,Viscosity,Temperature Setpoint,T Output,Bob Deflection,Torque,Motor Temp,Raw Encoder Value,Aux1
(hh:mm:ss),(°F),(°F),(PSIg),(RPM),(1/s),(dyne/cm²),(cP),(°F),(%),(deg.),(dyne-cm),(°C),(cts),
0:00:01,92.7,96,101,0,0,1.9104,0,32,0,0.108,233.7767,301096,5004,0
0:00:12,92.9,96,101,0,0,2.5472,0,32,0,0.144,311.6989,301096,5005,0
0:00:07,93.1,96,111,117.61,100,685.2439,685.2439,77,0,37.368,83852.11,301096,6039,0
0:00:18,93.1,96,111,117.61,100,683.1661,683.1661,77,0,37.26,83597.85,301096,6036,0
0:00:29,93.1,96,111,117.61,100,681.7808,681.7808,77,0,37.188,83428.33,301096,6034,0
0:00:40,93.1,96,111,117.61,100,684.5513,684.5513,77,0,37.332,83767.35,301096,6038,0
0:00:51,93.1,95,111,117.61,100,682.4734,682.4734,77,0,37.224,83513.09,301096,6035,0
0:01:02,93.1,95,111,88.2,75,685.2439,685.2439,77,0,37.368,83852.11,301096,6039,0
0:01:13,93.1,95,111,88.2,75,517.9901,690.6534,77,0,28.404,63385.54,301096,5790,0
0:01:24,93.1,95,111,88.2,75,517.9901,690.6534,77,0,28.404,63385.54,301096,5790,0
0:01:35,93.1,95,111,88.2,75,518.6543,691.5391,77,0,28.44,63466.83,301096,5791,0
0:01:46,93.1,95,111,88.2,75,518.6543,691.5391,77,0,28.44,63466.83,301096,5791,0
0:01:57,93.2,95,111,88.2,75,518.6543,691.5391,77,0,28.44,63466.83,301096,5791,0
0:02:08,93.2,95,111,58.8,50,349.7277,699.4553,77,0,19.224,42795.57,301096,5535,0
0:02:19,93.2,95,111,58.8,50,350.3728,700.7457,77,0,19.26,42874.52,301096,5536,0
0:02:30,93.2,95,111,58.8,50,349.7277,699.4553,77,0,19.224,42795.57,301096,5535,0
0:02:41,93.4,94,111,58.8,50,350.3728,700.7457,77,0,19.26,42874.52,301096,5536,0
0:02:52,93.2,94,111,58.8,50,350.3728,700.7457,77,0,19.26,42874.52,301096,5536,0
0:03:03,93.4,94,111,29.4,25,171.4854,685.9417,77,0,9.468,20984.38,301096,5264,0
0:03:14,93.4,94,111,29.4,25,178.7479,714.9916,77,0,9.864,21873.07,301096,5275,0
0:03:25,93.4,94,111,29.4,25,178.7479,714.9916,77,0,9.864,21873.07,301096,5275,0
0:03:36,93.4,94,111,29.4,25,178.7479,714.9916,77,0,9.864,21873.07,301096,5275,0
0:03:47,93.4,94,111,29.4,25,178.7479,714.9916,77,0,9.864,21873.07,301096,5275,0
0:03:58,93.4,94,104,29.4,25,178.7479,714.9916,77,0,9.864,21873.07,301096,5275,0
0:04:10,93.4,94,104,58.8,50,352.9346,705.8691,77,0,19.404,43187.99,301096,5540,0
0:04:21,93.4,94,111,58.8,50,352.9346,705.8691,77,0,19.404,43187.99,301096,5540,0
0:04:32,93.4,94,111,58.8,50,352.9346,705.8691,77,0,19.404,43187.99,301096,5540,0
0:04:43,93.4,94,104,58.8,50,352.9346,705.8691,77,0,19.404,43187.99,301096,5540,0
0:04:54,93.4,93,104,58.8,50,353.575,707.15,77,0,19.44,43266.36,301096,5541,0
0:05:05,93.4,93,104,88.2,75,526.6473,702.1965,77,0,28.872,64444.92,301096,5803,0
0:05:16,93.4,93,104,88.2,75,527.322,703.096,77,0,28.908,64527.48,301096,5804,0
0:05:27,93.2,93,104,88.2,75,527.322,703.096,77,0,28.908,64527.48,301096,5804,0
0:05:38,93.4,93,111,88.2,75,527.9966,703.9955,77,0,28.944,64610.04,301096,5805,0
0:05:49,93.2,93,111,88.2,75,527.322,703.096,77,0,28.908,64527.48,301096,5804,0
0:06:00,93.4,93,111,88.2,75,527.9966,703.9955,77,0,28.944,64610.04,301096,5805,0
0:06:11,93.2,93,111,117.61,100,709.4858,709.4858,81,0,38.628,86818.55,301096,6074,0
0:06:22,93.4,93,111,117.61,100,709.4858,709.4858,92,0,38.628,86818.55,301096,6074,0
0:06:33,93.2,93,104,117.61,100,710.871,710.871,103,13.1,38.7,86988.05,301096,6076,0
0:06:44,93.2,95,111,117.61,100,709.4858,709.4858,111,15.5,38.628,86818.55,301096,6074,0
0:06:55,93.2,101,111,117.61,100,702.5595,702.5595,121,14.4,38.268,85970.99,301096,6064,0
0:07:06,93.1,107,111,58.8,50,330.1089,660.2178,130,19.9,18.144,40394.85,301096,5505,0
0:07:17,93.2,114,104,58.8,50,317.6837,635.3673,130,10,17.46,38874.4,301096,5486,0
0:07:28,93.2,118,104,58.8,50,300.2254,600.4507,130,9.2,16.524,36738.06,301096,5460,0
0:07:39,93.2,121,104,58.8,50,278.0832,556.1664,130,10.3,15.336,34028.56,301096,5427,0
0:07:50,93.4,124,104,58.8,50,259.4821,518.9643,129,5.8,14.292,31752.38,301096,5398,0
0:08:01,93.4,125,104,58.8,50,242.7377,485.4755,129,6.6,13.356,29703.4,301096,5372,0
0:08:12,93.6,126,104,58.8,50,231.4983,462.9965,129,6.3,12.744,28328.04,301096,5355,0
0:08:23,94.1,127,104,58.8,50,218.9365,437.873,129,5,12.06,26790.88,301096,5336,0
0:08:34,94.5,128,111,58.8,50,209.6821,419.3642,129,5.1,11.556,25658.44,301096,5322,0
0:08:45,95.1,129,111,58.8,50,201.784,403.5681,129,4.6,11.124,24691.96,301096,5310,0
0:08:56,95.6,129,111,58.8,50,191.9114,383.8228,129,4.2,10.584,23483.87,301096,5295,0
0:09:07,96.3,129,111,58.8,50,187.9624,375.9247,128,3.1,10.368,23000.63,301096,5289,0
0:09:18,96.7,129,111,58.8,50,184.6715,369.343,128,3.5,10.188,22597.93,301096,5284,0
0:09:29,97.4,129,111,58.8,50,181.3806,362.7612,128,3.2,10.008,22195.23,301096,5279,0
0:09:40,98.1,129,111,58.8,50,178.0898,356.1795,128,3.4,9.828,21792.54,301096,5274,0
0:09:51,98.8,129,111,58.8,50,175.4571,350.9141,128,2.9,9.684,21470.38,301096,5270,0
0:10:02,99.6,129,111,58.8,50,172.1477,344.2954,128,2.8,9.504,21065.42,301096,5265,0
0:10:13,100.3,129,111,58.8,50,170.1609,340.3217,127,0.9,9.396,20822.29,301096,5262,0
0:10:24,100.8,129,111,58.8,50,168.1741,336.3481,127,1.9,9.288,20579.17,301096,5259,0
0:10:35,101.5,128,111,58.8,50,166.8495,333.699,127,2.9,9.216,20417.08,301096,5257,0
0:10:46,102.3,128,111,58.8,50,165.5249,331.0499,127,2.3,9.144,20255,301096,5255,0
0:10:57,102.8,128,111,58.8,50,164.2004,328.4008,127,1.9,9.072,20092.92,301096,5253,0
0:11:08,103.5,128,111,58.8,50,163.5381,327.0762,127,2.6,9.036,20011.87,301096,5252,0
0:11:19,104.3,128,111,58.8,50,162.2135,324.4271,127,2,8.964,19849.79,301096,5250,0
0:11:30,104.8,128,111,58.8,50,161.5513,323.1025,126,0.4,8.928,19768.75,301096,5249,0
0:11:41,105.3,127,104,58.8,50,160.889,321.778,126,1.6,8.892,19687.71,301096,5248,0
0:11:52,105.9,127,104,58.8,50,160.2267,320.4534,126,1.9,8.856,19606.67,301096,5247,0
0:12:03,106.4,127,104,58.8,50,159.5644,319.1289,126,1.7,8.82,19525.62,301096,5246,0
0:12:14,107,127,111,58.8,50,158.9022,317.8043,126,1.3,8.784,19444.58,301096,5245,0
0:12:25,107.5,127,111,58.8,50,158.2399,316.4798,126,2,8.748,19363.54,301096,5244,0
0:12:36,107.9,126,104,58.8,50,157.5776,315.1552,126,1.9,8.712,19282.5,301096,5243,0
0:12:47,108.4,126,111,58.8,50,156.9153,313.8307,125,0,8.676,19201.46,301096,5242,0
0:12:58,108.9,126,111,58.8,50,156.2531,312.5061,125,0.5,8.64,19120.42,301096,5241,0
0:13:09,109.3,126,101,58.8,50,156.2531,312.5061,125,1.7,8.64,19120.42,301096,5241,0
0:13:20,109.8,126,111,58.8,50,155.5908,311.1816,125,1.3,8.604,19039.38,301096,5240,0
0:13:31,110.2,126,104,58.8,50,154.9285,309.857,125,1.1,8.568,18958.33,301096,5239,0
0:13:42,110.6,125,104,58.8,50,154.9285,309.857,125,1.8,8.568,18958.33,301096,5239,0
0:13:53,111.1,125,111,58.8,50,154.2662,308.5324,125,1.3,8.532,18877.29,301096,5238,0
0:14:04,111.3,125,101,58.8,50,153.6039,307.2079,124,0,8.496,18796.25,301096,5237,0
0:14:15,111.6,125,104,58.8,50,153.6039,307.2079,124,1.4,8.496,18796.25,301096,5237,0
0:14:26,112,125,111,58.8,50,152.9417,305.8833,124,1.3,8.46,18715.21,301096,5236,0
0:14:37,112.4,124,104,58.8,50,152.9417,305.8833,124,1.7,8.46,18715.21,301096,5236,0
0:14:48,112.7,124,111,58.8,50,152.2794,304.5588,124,1.2,8.424,18634.16,301096,5235,0
0:14:59,112.9,124,111,58.8,50,152.2794,304.5588,124,0.8,8.424,18634.16,301096,5235,0
0:15:10,113.3,124,101,58.8,50,152.2794,304.5588,124,1.3,8.424,18634.16,301096,5235,0
0:15:21,113.5,124,111,58.8,50,152.2794,304.5588,123,0,8.424,18634.16,301096,5235,0
0:15:32,113.8,124,111,58.8,50,151.6171,303.2342,123,1.4,8.388,18553.12,301096,5234,0
0:15:43,114.2,123,101,58.8,50,151.6171,303.2342,123,0.7,8.388,18553.12,301096,5234,0
0:15:54,114.4,123,104,58.8,50,151.6171,303.2342,123,0.7,8.388,18553.12,301096,5234,0
0:16:05,114.7,123,111,58.8,50,150.9548,301.9097,123,0.9,8.352,18472.08,301096,5233,0
0:16:16,114.9,123,101,58.8,50,150.9548,301.9097,123,0.3,8.352,18472.08,301096,5233,0
0:16:27,115.1,123,111,58.8,50,150.9548,301.9097,122,0,8.352,18472.08,301096,5233,0
0:16:38,115.3,123,111,58.8,50,150.9548,301.9097,122,0.2,8.352,18472.08,301096,5233,0
0:16:49,115.4,123,104,58.8,50,150.2926,300.5851,122,0.4,8.316,18391.04,301096,5232,0
0:17:00,115.6,122,101,58.8,50,150.2926,300.5851,122,0.8,8.316,18391.04,301096,5232,0
0:17:11,115.8,122,104,117.61,100,270.3862,270.3862,122,0,14.904,33086.7,301096,5415,0
0:17:22,116,122,104,117.61,100,270.3862,270.3862,122,0.1,14.904,33086.7,301096,5415,0
0:17:33,116.2,122,104,117.61,100,269.7448,269.7448,122,1.2,14.868,33008.21,301096,5414,0
0:17:44,116.5,122,104,117.61,100,269.7448,269.7448,122,0.4,14.868,33008.21,301096,5414,0
0:17:56,116.7,122,111,117.61,100,269.7448,269.7448,122,0.4,14.868,33008.21,301096,5414,0
0:18:20,117.1,122,111,117.61,100,269.7448,269.7448,122,0.3,14.868,33008.21,301096,5414,0
0:18:31,117.2,122,104,117.61,100,269.1034,269.1034,122,0.7,14.832,32929.71,301096,5413,0
0:18:42,117.4,122,111,117.61,100,269.1034,269.1034,122,0.5,14.832,32929.71,301096,5413,0
0:18:53,117.4,122,104,117.61,100,269.1034,269.1034,122,0.7,14.832,32929.71,301096,5413,0
0:19:04,117.8,122,104,117.61,100,268.462,268.462,122,0.7,14.796,32851.23,301096,5412,0
0:19:15,117.8,122,104,117.61,100,269.1034,269.1034,122,1,14.832,32929.71,301096,5413,0
0:19:27,118,122,104,117.61,100,268.462,268.462,122,0.9,14.796,32851.23,301096,5412,0
0:19:44,118,122,104,117.61,100,267.8206,267.8206,122,0.9,14.76,32772.74,301096,5411,0
0:19:55,118,122,104,117.61,100,267.1791,267.1791,122,0.8,14.724,32694.25,301096,5410,0
0:20:07,118.3,122,104,117.61,100,267.1791,267.1791,122,0.7,14.724,32694.25,301096,5410,0
0:20:28,118.3,122,104,117.61,100,265.8963,265.8963,125,5.6,14.652,32537.27,301096,5408,0
0:20:39,118.7,123,104,117.61,100,265.8963,265.8963,125,3.2,14.652,32537.27,301096,5408,0
0:20:50,118.7,124,104,117.61,100,265.2549,265.2549,125,0.6,14.616,32458.78,301096,5407,0
0:21:01,118.7,124,104,117.61,100,263.3306,263.3306,125,1.9,14.508,32223.31,301096,5404,0
0:21:12,118.7,124,104,117.61,100,262.0478,262.0478,125,1.9,14.436,32066.34,301096,5402,0
0:21:23,118.9,124,104,117.61,100,260.1236,260.1236,125,1.5,14.328,31830.87,301096,5399,0
0:21:34,118.9,125,104,117.61,100,259.4821,259.4821,125,1.4,14.292,31752.38,301096,5398,0
0:21:46,119,125,101,117.61,100,258.1993,258.1993,125,1.4,14.22,31595.4,301096,5396,0
0:21:57,119.2,125,104,117.61,100,256.9165,256.9165,125,1.1,14.148,31438.42,301096,5394,0
0:22:10,119.4,125,111,88.2,75,187.9624,250.6165,125,0.8,10.368,23000.63,301096,5289,0
0:22:23,119.6,125,104,88.2,75,187.3042,249.7389,125,1.2,10.332,22920.09,301096,5288,0
0:22:34,119.6,125,104,88.2,75,187.3042,249.7389,125,1.2,10.332,22920.09,301096,5288,0
0:22:45,119.8,125,104,88.2,75,187.3042,249.7389,125,0.7,10.332,22920.09,301096,5288,0
0:22:57,119.8,125,104,88.2,75,187.3042,249.7389,125,1.2,10.332,22920.09,301096,5288,0
0:23:08,119.8,125,104,58.8,50,130.6448,261.2897,125,1.1,7.236,15986.78,301096,5202,0
0:23:19,120.1,125,111,58.8,50,130.6448,261.2897,124,0,7.236,15986.78,301096,5202,0
0:23:30,120.3,125,104,58.8,50,130.6448,261.2897,124,0.4,7.236,15986.78,301096,5202,0
0:23:41,120.3,125,104,58.8,50,130.6448,261.2897,123,0,7.236,15986.78,301096,5202,0
0:23:52,120.3,124,104,58.8,50,129.9978,259.9955,123,0,7.2,15907.6,301096,5201,0
0:24:03,120.5,124,104,58.8,50,130.6448,261.2897,122,0,7.236,15986.78,301096,5202,0
0:24:14,120.5,124,104,29.4,25,71.3236,285.2944,122,0,3.96,8727.746,301096,5111,0
0:24:25,120.7,123,101,29.4,25,71.3236,285.2944,122,0,3.96,8727.746,301096,5111,0
0:24:36,120.7,123,104,29.4,25,71.3236,285.2944,122,0,3.96,8727.746,301096,5111,0
0:24:47,120.7,123,111,29.4,25,71.3236,285.2944,122,0,3.96,8727.746,301096,5111,0
0:24:58,120.9,123,111,29.4,25,71.3236,285.2944,122,0,3.96,8727.746,301096,5111,0
0:25:09,121,123,104,58.8,50,121.5859,243.1719,122,0,6.732,14878.26,301096,5188,0
0:25:20,120.9,123,104,58.8,50,122.233,244.466,122,0,6.768,14957.44,301096,5189,0
0:25:31,121,122,104,58.8,50,122.233,244.466,122,0,6.768,14957.44,301096,5189,0
0:25:42,121,122,104,58.8,50,122.233,244.466,122,0.3,6.768,14957.44,301096,5189,0
0:25:53,121,122,101,58.8,50,122.233,244.466,122,0,6.768,14957.44,301096,5189,0
0:26:04,121,122,104,58.8,50,180.7225,361.4449,122,0.5,9.972,22114.69,301096,5278,0
0:26:15,121,122,104,88.2,75,179.4061,239.2081,122,0.4,9.9,21953.61,301096,5276,0
0:26:26,121,122,104,88.2,75,179.4061,239.2081,122,0.4,9.9,21953.61,301096,5276,0
0:26:37,121.2,122,104,88.2,75,179.4061,239.2081,122,0.6,9.9,21953.61,301096,5276,0
0:26:48,121.2,122,104,88.2,75,179.4061,239.2081,122,0.7,9.9,21953.61,301096,5276,0
0:26:59,121.2,122,104,88.2,75,179.4061,239.2081,122,0.3,9.9,21953.61,301096,5276,0
0:27:10,121.2,122,104,117.61,100,238.7709,238.7709,129,11.5,13.14,29217.98,301096,5366,0
0:27:21,121.2,123,104,117.61,100,238.7709,238.7709,144,30.9,13.14,29217.98,301096,5366,0
0:27:32,121,132,104,117.61,100,238.7709,238.7709,163,30.1,13.14,29217.98,301096,5366,0
0:27:43,121,143,104,117.61,100,232.8206,232.8206,182,39,12.816,28489.85,301096,5357,0
0:27:54,121.4,155,104,117.61,100,223.5645,223.5645,196,42.4,12.312,27357.2,301096,5343,0
0:28:05,121.6,170,104,58.8,50,193.2278,193.2278,216,48.7,10.656,23644.95,301096,5297,0
0:28:16,121.6,184,104,58.8,50,87.713,175.426,218,30.8,4.86,10733.29,301096,5136,0
0:28:27,121.9,195,104,58.8,50,79.1905,158.381,218,26.5,4.392,9690.407,301096,5123,0
0:28:38,122.5,202,104,58.8,50,70.668,141.3361,218,26.1,3.924,8647.524,301096,5110,0
0:28:49,123.2,207,104,58.8,50,63.4099,126.8199,218,21.7,3.528,7759.363,301096,5099,0
0:29:00,124.1,212,104,58.8,50,60.109,120.218,218,19.5,3.348,7355.436,301096,5094,0
0:29:11,125.2,215,104,58.8,50,56.8081,113.6162,217,15.7,3.168,6951.509,301096,5089,0
0:29:22,127.2,217,104,58.8,50,54.1674,108.3347,217,15.3,3.024,6628.367,301096,5085,0
0:29:33,128.6,218,111,58.8,50,52.1868,104.3736,217,13.6,2.916,6386.011,301096,5082,0
0:29:44,130.4,220,104,58.8,50,48.8859,97.7718,217,12.3,2.736,5982.084,301096,5077,0
0:29:55,132.6,220,104,58.8,50,46.2452,92.4904,217,11.4,2.592,5658.942,301096,5073,0
0:30:06,134.6,221,104,58.8,50,44.9248,89.8496,217,10.8,2.52,5497.372,301096,5071,0
0:30:17,136.5,221,104,58.8,50,44.2646,88.5293,217,10.2,2.484,5416.586,301096,5070,0
0:30:28,138.9,221,104,58.8,50,43.6045,87.2089,217,9.7,2.448,5335.8,301096,5069,0
0:30:39,140.9,221,104,58.8,50,42.9443,85.8885,217,8.8,2.412,5255.015,301096,5068,0
0:30:50,143,221,101,58.8,50,42.2841,84.5682,217,8.4,2.376,5174.229,301096,5067,0
0:31:01,145,221,104,58.8,50,41.6239,83.2478,217,8.5,2.34,5093.444,301096,5066,0
0:31:12,147.4,221,104,58.8,50,41.6239,83.2478,216,6.6,2.34,5093.444,301096,5066,0
0:31:24,149.4,220,104,58.8,50,40.9637,81.9274,216,7.4,2.304,5012.659,301096,5065,0
0:31:35,151.2,220,104,58.8,50,39.6434,79.2867,216,7.4,2.232,4851.088,301096,5063,0
0:31:46,153.1,220,104,58.8,50,39.6434,79.2867,216,7.2,2.232,4851.088,301096,5063,0
0:31:57,154.9,219,111,58.8,50,38.9832,77.9663,216,6.7,2.196,4770.303,301096,5062,0
0:32:08,156.8,219,104,58.8,50,38.9832,77.9663,216,6.9,2.196,4770.303,301096,5062,0
0:32:19,158.6,219,111,58.8,50,38.9832,77.9663,216,6.5,2.196,4770.303,301096,5062,0
0:32:30,160.2,218,104,58.8,50,38.9832,77.9663,216,6.3,2.196,4770.303,301096,5062,0
0:32:41,161.8,218,104,58.8,50,38.9832,77.9663,216,6.4,2.196,4770.303,301096,5062,0
0:32:52,163.4,218,104,58.8,50,38.9832,77.9663,216,6.4,2.196,4770.303,301096,5062,0
0:33:03,164.9,218,104,58.8,50,38.9832,77.9663,216,6.1,2.196,4770.303,301096,5062,0
0:33:14,166.3,218,104,58.8,50,38.323,76.646,215,4.5,2.16,4689.518,301096,5061,0
0:33:25,167.9,217,111,58.8,50,38.323,76.646,215,5.8,2.16,4689.518,301096,5061,0
0:33:36,169.2,217,104,58.8,50,38.323,76.646,215,5.8,2.16,4689.518,301096,5061,0
0:33:47,170.5,217,104,58.8,50,37.6628,75.3256,215,5.4,2.124,4608.732,301096,5060,0
0:33:58,171.9,216,104,58.8,50,37.6628,75.3256,215,5.3,2.124,4608.732,301096,5060,0
0:34:09,173,216,111,58.8,50,37.6628,75.3256,215,5.8,2.124,4608.732,301096,5060,0
0:34:20,174.4,216,104,58.8,50,37.6628,75.3256,215,5.3,2.124,4608.732,301096,5060,0
0:34:31,175.5,216,111,58.8,50,37.6628,75.3256,215,5,2.124,4608.732,301096,5060,0
0:34:42,176.4,216,104,58.8,50,37.0026,74.0052,215,5.4,2.088,4527.947,301096,5059,0
0:34:54,177.9,216,104,58.8,50,37.0026,74.0052,215,5.3,2.088,4527.947,301096,5059,0
0:35:05,178.8,216,111,58.8,50,37.0026,74.0052,215,5.1,2.088,4527.947,301096,5059,0
0:35:16,180,216,101,58.8,50,37.0026,74.0052,214,3.6,2.088,4527.947,301096,5059,0
0:35:27,180.9,215,104,58.8,50,37.0026,74.0052,214,5,2.088,4527.947,301096,5059,0
0:35:38,182,215,104,58.8,50,37.0026,74.0052,214,4.4,2.088,4527.947,301096,5059,0
0:35:49,182.9,215,101,58.8,50,37.0026,74.0052,214,4.5,2.088,4527.947,301096,5059,0
0:36:00,183.6,215,111,58.8,50,36.3424,72.6849,214,4.6,2.052,4447.161,301096,5058,0
0:36:11,184.5,215,101,58.8,50,36.3424,72.6849,214,4.6,2.052,4447.161,301096,5058,0
0:36:22,185.4,215,104,58.8,50,36.3424,72.6849,214,4.3,2.052,4447.161,301096,5058,0
0:36:33,186.2,215,104,58.8,50,36.3424,72.6849,214,4.2,2.052,4447.161,301096,5058,0
0:36:45,187.1,215,104,58.8,50,36.3424,72.6849,214,4.3,2.052,4447.161,301096,5058,0
0:36:57,188,214,104,58.8,50,35.6823,71.3645,214,4.2,2.016,4366.375,301096,5057,0
0:37:13,189,214,104,58.8,50,35.6823,71.3645,213,2.3,2.016,4366.375,301096,5057,0
0:37:24,189.8,215,111,58.8,50,34.3865,68.773,219,10.9,1.944,4207.814,301096,5055,0
0:37:48,191.2,216,104,58.8,50,34.3865,68.773,219,4.5,1.944,4207.814,301096,5055,0
0:37:59,191.8,218,104,58.8,50,34.3865,68.773,222,9,1.944,4207.814,301096,5055,0
0:38:10,192.5,220,104,58.8,50,33.7497,67.4994,222,5.1,1.908,4129.891,301096,5054,0
0:38:21,193.2,221,101,58.8,50,33.7497,67.4994,222,6.4,1.908,4129.891,301096,5054,0
0:38:32,193.7,221,101,58.8,50,33.7497,67.4994,222,6.4,1.908,4129.891,301096,5054,0
0:38:43,194.5,222,104,58.8,50,33.7497,67.4994,222,5.1,1.908,4129.891,301096,5054,0
0:38:54,195.2,222,101,58.8,50,33.7497,67.4994,221,3.9,1.908,4129.891,301096,5054,0
0:39:05,195.7,222,104,58.8,50,33.7497,67.4994,221,5.4,1.908,4129.891,301096,5054,0
0:39:16,196.4,222,104,58.8,50,33.7497,67.4994,221,4.3,1.908,4129.891,301096,5054,0
0:39:27,197.2,222,104,58.8,50,33.1129,66.2258,221,4,1.872,4051.969,301096,5053,0
0:39:38,197.7,222,104,58.8,50,33.1129,66.2258,221,4.9,1.872,4051.969,301096,5053,0
0:39:49,198.4,222,104,58.8,50,33.1129,66.2258,221,4.5,1.872,4051.969,301096,5053,0
0:40:00,199.1,222,104,58.8,50,33.1129,66.2258,221,4,1.872,4051.969,301096,5053,0
0:40:11,199.7,221,104,58.8,50,33.1129,66.2258,220,3.5,1.872,4051.969,301096,5053,0
0:40:22,200.2,221,104,58.8,50,33.1129,66.2258,220,4,1.872,4051.969,301096,5053,0
0:40:33,200.8,221,104,58.8,50,33.1129,66.2258,220,4,1.872,4051.969,301096,5053,0
0:40:44,201.3,221,101,58.8,50,33.1129,66.2258,220,3.6,1.872,4051.969,301096,5053,0
0:40:55,201.9,221,104,58.8,50,33.1129,66.2258,220,3.4,1.872,4051.969,301096,5053,0
0:41:06,202.6,221,104,58.8,50,33.1129,66.2258,220,3.6,1.872,4051.969,301096,5053,0
0:41:17,202.8,221,104,58.8,50,33.1129,66.2258,219,2.1,1.872,4051.969,301096,5053,0
0:41:28,203.5,220,104,58.8,50,33.1129,66.2258,219,2.7,1.872,4051.969,301096,5053,0
0:41:39,203.8,220,104,58.8,50,33.1129,66.2258,219,3.5,1.872,4051.969,301096,5053,0
0:41:50,204.4,220,104,58.8,50,33.1129,66.2258,219,3.6,1.872,4051.969,301096,5053,0
0:42:01,204.7,220,104,58.8,50,33.1129,66.2258,219,3.1,1.872,4051.969,301096,5053,0
0:42:12,205.3,220,101,58.8,50,32.4761,64.9522,219,3.2,1.836,3974.047,301096,5052,0
0:42:23,205.5,219,101,58.8,50,32.4761,64.9522,219,3.5,1.836,3974.047,301096,5052,0
0:42:34,205.8,219,101,58.8,50,32.4761,64.9522,218,1.6,1.836,3974.047,301096,5052,0
0:42:45,206.4,219,104,58.8,50,32.4761,64.9522,218,2.8,1.836,3974.047,301096,5052,0
0:42:56,206.7,219,104,58.8,50,32.4761,64.9522,218,3.1,1.836,3974.047,301096,5052,0
0:43:07,207.1,219,104,117.61,100,34.3865,34.3865,218,2.6,1.944,4207.814,301096,5055,0
0:43:18,207.3,218,101,117.61,100,35.0233,35.0233,218,2.8,1.98,4285.736,301096,5056,0
0:43:29,207.6,218,104,117.61,100,35.0233,35.0233,218,3,1.98,4285.736,301096,5056,0
0:43:40,208.2,218,101,117.61,100,35.0233,35.0233,218,3.4,1.98,4285.736,301096,5056,0
0:43:52,208.4,218,104,117.61,100,35.0233,35.0233,218,3.1,1.98,4285.736,301096,5056,0
0:44:03,208.7,218,101,117.61,100,35.0233,35.0233,218,3.5,1.98,4285.736,301096,5056,0
0:44:14,208.9,218,101,88.2,75,33.7497,44.9996,218,2.8,1.908,4129.891,301096,5054,0
0:44:25,209.1,218,104,88.2,75,33.7497,44.9996,218,3.1,1.908,4129.891,301096,5054,0
0:44:36,209.4,218,101,88.2,75,33.7497,44.9996,218,2.8,1.908,4129.891,301096,5054,0
0:44:48,209.6,218,104,88.2,75,33.7497,44.9996,218,2.7,1.908,4129.891,301096,5054,0
0:45:00,209.8,218,104,88.2,75,33.7497,44.9996,218,3,1.908,4129.891,301096,5054,0
0:45:11,210.2,218,104,58.8,50,32.4761,64.9522,218,3,1.836,3974.047,301096,5052,0
0:45:22,210.3,218,104,58.8,50,31.8393,63.6787,218,3.1,1.8,3896.124,301096,5051,0
0:45:33,210.5,218,104,58.8,50,31.8393,63.6787,218,2.9,1.8,3896.124,301096,5051,0
0:45:44,210.7,218,104,58.8,50,31.8393,63.6787,218,3.1,1.8,3896.124,301096,5051,0
0:45:55,210.9,218,104,58.8,50,31.8393,63.6787,218,3.1,1.8,3896.124,301096,5051,0
0:46:06,210.9,218,104,29.4,25,31.8393,63.6787,218,3,1.8,3896.124,301096,5051,0
0:46:17,211.2,218,101,29.4,25,28.6554,114.6216,218,2.9,1.62,3506.513,301096,5046,0
0:46:28,211.2,218,104,29.4,25,28.0186,112.0745,218,2.8,1.584,3428.591,301096,5045,0
0:46:39,211.4,218,104,29.4,25,28.0186,112.0745,218,2.7,1.584,3428.591,301096,5045,0
0:46:50,211.6,218,104,29.4,25,28.0186,112.0745,218,2.8,1.584,3428.591,301096,5045,0
0:47:01,211.8,218,104,29.4,25,27.3818,109.5274,218,2.9,1.548,3350.668,301096,5044,0
0:47:12,212,218,104,58.8,50,28.0186,56.0373,218,2.7,1.584,3428.591,301096,5045,0
0:47:23,212.1,218,104,58.8,50,28.0186,56.0373,217,1.7,1.584,3428.591,301096,5045,0
0:47:34,212.1,218,104,58.8,50,28.0186,56.0373,216,0.8,1.584,3428.591,301096,5045,0
0:47:45,212.3,217,104,58.8,50,28.0186,56.0373,215,0,1.584,3428.591,301096,5045,0
0:47:56,212.5,217,101,58.8,50,28.0186,56.0373,214,0,1.584,3428.591,301096,5045,0
0:48:07,212.7,216,104,58.8,50,28.0186,56.0373,213,0,1.584,3428.591,301096,5045,0
0:48:18,212.7,215,104,88.2,75,29.2922,39.0563,213,1.1,1.656,3584.435,301096,5047,0
0:48:29,212.7,214,104,88.2,75,29.2922,39.0563,213,1.2,1.656,3584.435,301096,5047,0
0:48:40,212.9,214,101,88.2,75,29.2922,39.0563,212,0,1.656,3584.435,301096,5047,0
0:48:51,213,213,104,88.2,75,29.2922,39.0563,212,0.7,1.656,3584.435,301096,5047,0
0:49:02,213,213,104,88.2,75,29.2922,39.0563,212,1.5,1.656,3584.435,301096,5047,0
0:49:14,213,213,104,117.61,100,31.8393,31.8393,218,4.8,1.8,3896.124,301096,5051,0
0:49:25,213,214,104,117.61,100,32.4761,32.4761,233,28.4,1.836,3974.047,301096,5052,0
0:49:36,213,222,104,117.61,100,32.4761,32.4761,252,32.6,1.836,3974.047,301096,5052,0
0:49:47,212.9,232,104,117.61,100,32.4761,32.4761,271,42.8,1.836,3974.047,301096,5052,0
0:49:58,212.9,243,104,117.61,100,32.4761,32.4761,286,48.1,1.836,3974.047,301096,5052,0
0:50:09,213,258,104,117.61,100,31.8393,31.8393,305,53.1,1.8,3896.124,301096,5051,0
0:50:20,213.4,272,104,58.8,50,28.0186,56.0373,308,37.2,1.584,3428.591,301096,5045,0
0:50:32,213.8,283,101,58.8,50,26.7451,53.4901,308,30.9,1.512,3272.746,301096,5043,0
0:50:58,216.1,299,104,58.8,50,25.4715,50.943,308,24.4,1.44,3116.901,301096,5041,0
0:51:09,217.6,303,101,58.8,50,25.4715,50.943,320,36.9,1.44,3116.901,301096,5041,0
0:51:20,219,310,104,58.8,50,25.4715,50.943,320,23,1.44,3116.901,301096,5041,0
0:51:31,220.8,315,104,58.8,50,25.4715,50.943,320,22.7,1.44,3116.901,301096,5041,0
0:51:42,222.8,318,104,58.8,50,24.8347,49.6694,320,22.2,1.404,3038.979,301096,5040,0
0:51:53,224.8,320,104,58.8,50,24.8347,49.6694,320,19.4,1.404,3038.979,301096,5040,0
0:52:04,226.8,322,104,58.8,50,24.8347,49.6694,320,17.9,1.404,3038.979,301096,5040,0
0:52:15,228.9,323,104,58.8,50,24.8347,49.6694,320,16.9,1.404,3038.979,301096,5040,0
0:52:26,230.9,324,104,58.8,50,24.8347,49.6694,320,15.7,1.404,3038.979,301096,5040,0
0:52:37,232.9,324,104,58.8,50,24.1979,48.3958,320,14.7,1.368,2961.057,301096,5039,0
0:52:48,235.2,325,104,58.8,50,24.1979,48.3958,320,13.8,1.368,2961.057,301096,5039,0
0:52:59,237,325,104,58.8,50,24.1979,48.3958,320,13.8,1.368,2961.057,301096,5039,0
0:53:10,239.2,325,104,58.8,50,24.1979,48.3958,320,12.4,1.368,2961.057,301096,5039,0
0:53:21,241.5,325,104,58.8,50,24.1979,48.3958,320,12.4,1.368,2961.057,301096,5039,0
0:53:32,243.4,325,104,58.8,50,24.1979,48.3958,320,11.4,1.368,2961.057,301096,5039,0
0:53:44,245.5,324,104,58.8,50,24.1979,48.3958,320,11.6,1.368,2961.057,301096,5039,0
0:53:55,247.5,324,111,58.8,50,24.1979,48.3958,320,11.3,1.368,2961.057,301096,5039,0
0:54:06,249.7,324,104,58.8,50,23.5611,47.1223,320,10.6,1.332,2883.135,301096,5038,0
0:54:17,251.5,324,101,58.8,50,23.5611,47.1223,320,10.7,1.332,2883.135,301096,5038,0
0:54:28,253.1,323,104,58.8,50,23.5611,47.1223,320,10.7,1.332,2883.135,301096,5038,0
0:54:39,255.3,323,104,58.8,50,23.5611,47.1223,320,9.7,1.332,2883.135,301096,5038,0
0:54:50,256.9,323,104,58.8,50,23.5611,47.1223,320,9.8,1.332,2883.135,301096,5038,0
0:55:01,258.5,323,104,58.8,50,23.5611,47.1223,320,9.9,1.332,2883.135,301096,5038,0
0:55:12,260.3,323,104,58.8,50,23.5611,47.1223,320,9.5,1.332,2883.135,301096,5038,0
0:55:23,261.9,322,104,58.8,50,23.5611,47.1223,320,9.2,1.332,2883.135,301096,5038,0
0:55:34,263.6,322,111,58.8,50,23.5611,47.1223,320,9.1,1.332,2883.135,301096,5038,0
0:55:45,265.2,322,111,58.8,50,23.5611,47.1223,320,9.1,1.332,2883.135,301096,5038,0
0:55:56,266.6,322,111,58.8,50,23.5611,47.1223,320,8.6,1.332,2883.135,301096,5038,0
0:56:07,268.2,322,104,58.8,50,23.5611,47.1223,320,8.9,1.332,2883.135,301096,5038,0
0:56:18,269.7,322,104,58.8,50,23.5611,47.1223,320,8.5,1.332,2883.135,301096,5038,0
0:56:29,271.1,322,104,58.8,50,22.9244,45.8487,320,8.4,1.296,2805.212,301096,5037,0
0:56:40,272.6,321,104,58.8,50,22.9244,45.8487,320,8.4,1.296,2805.212,301096,5037,0
0:56:51,274,321,101,58.8,50,22.9244,45.8487,320,8.3,1.296,2805.212,301096,5037,0
0:57:02,275.3,321,101,58.8,50,22.9244,45.8487,320,8,1.296,2805.212,301096,5037,0
0:57:13,276.4,321,101,58.8,50,22.9244,45.8487,320,7.8,1.296,2805.212,301096,5037,0
0:57:24,277.8,321,101,58.8,50,22.9244,45.8487,320,7.8,1.296,2805.212,301096,5037,0
0:57:35,278.9,321,101,58.8,50,22.9244,45.8487,320,7.6,1.296,2805.212,301096,5037,0
0:57:46,280.2,321,101,58.8,50,22.9244,45.8487,320,7.4,1.296,2805.212,301096,5037,0
0:57:57,281.2,321,104,58.8,50,22.9244,45.8487,320,7.8,1.296,2805.212,301096,5037,0
0:58:08,282.5,321,104,58.8,50,22.9244,45.8487,320,7.8,1.296,2805.212,301096,5037,0
0:58:19,283.4,321,101,58.8,50,22.9244,45.8487,320,7.2,1.296,2805.212,301096,5037,0
0:58:30,284.7,321,101,58.8,50,22.9244,45.8487,320,7.4,1.296,2805.212,301096,5037,0
0:58:41,285.6,321,104,58.8,50,22.9244,45.8487,320,7.3,1.296,2805.212,301096,5037,0
0:58:52,286.5,321,104,58.8,50,22.9244,45.8487,320,7.5,1.296,2805.212,301096,5037,0
0:59:03,287.6,321,104,58.8,50,22.9244,45.8487,320,7.4,1.296,2805.212,301096,5037,0
0:59:14,288.5,321,104,58.8,50,22.9244,45.8487,320,7.1,1.296,2805.212,301096,5037,0
0:59:25,289.4,321,101,58.8,50,22.9244,45.8487,320,7.2,1.296,2805.212,301096,5037,0
0:59:38,290.3,321,101,58.8,50,22.2876,44.5751,320,7.1,1.26,2727.29,301096,5036,0
1:00:00,292.1,321,104,58.8,50,22.2876,44.5751,320,6.6,1.26,2727.29,301096,5036,0
1:00:11,293,320,101,58.8,50,22.2876,44.5751,320,6.9,1.26,2727.29,301096,5036,0
1:00:23,293.7,320,104,58.8,50,21.014,42.028,320,6.8,1.188,2571.445,301096,5034,0
1:00:35,294.6,320,101,58.8,50,21.014,42.028,320,6.5,1.188,2571.445,301096,5034,0
1:01:04,296.4,320,101,58.8,50,21.014,42.028,316,0,1.188,2571.445,301096,5034,0
1:01:15,296.9,319,104,58.8,50,21.014,42.028,316,4.6,1.188,2571.445,301096,5034,0
1:01:27,297.7,318,104,58.8,50,21.014,42.028,316,5.2,1.188,2571.445,301096,5034,0
1:01:51,298.4,318,104,58.8,50,21.014,42.028,316,4,1.188,2571.445,301096,5034,0
1:02:03,299.5,317,101,58.8,50,21.014,42.028,315,3.8,1.188,2571.445,301096,5034,0
1:02:15,300.2,316,101,58.8,50,20.3772,40.7544,315,4.9,1.152,2493.523,301096,5033,0
1:02:27,300.5,316,101,58.8,50,20.3772,40.7544,315,4.9,1.152,2493.523,301096,5033,0
1:02:41,301.1,316,104,58.8,50,20.3772,40.7544,315,4.6,1.152,2493.523,301096,5033,0
1:02:53,301.6,315,104,58.8,50,20.3772,40.7544,315,5.3,1.152,2493.523,301096,5033,0
1:03:05,302.2,315,101,58.8,50,19.7404,39.4808,315,4.8,1.116,2415.601,301096,5032,0
1:03:18,302.5,315,104,117.61,100,21.014,21.014,315,5.4,1.188,2571.445,301096,5034,0
1:03:30,302.9,315,111,117.61,100,20.3772,20.3772,314,4.1,1.152,2493.523,301096,5033,0
1:03:46,303.4,315,111,117.61,100,20.3772,20.3772,313,3.5,1.152,2493.523,301096,5033,0
1:03:58,303.8,314,111,117.61,100,20.3772,20.3772,311,1.6,1.152,2493.523,301096,5033,0
1:04:11,304.1,313,111,117.61,100,20.3772,20.3772,310,1.8,1.152,2493.523,301096,5033,0
1:04:32,304.7,311,111,88.2,75,20.3772,27.1696,309,2.2,1.152,2493.523,301096,5033,0
1:04:43,304.9,311,111,88.2,75,20.3772,27.1696,309,3.1,1.152,2493.523,301096,5033,0
1:04:54,305.1,310,111,88.2,75,20.3772,27.1696,309,3.8,1.152,2493.523,301096,5033,0
1:05:05,305.2,310,111,88.2,75,19.7404,26.3206,308,2.5,1.116,2415.601,301096,5032,0
1:05:16,305.4,309,104,58.8,50,19.7404,39.4808,308,3.2,1.116,2415.601,301096,5032,0
1:05:27,305.4,309,111,58.8,50,19.7404,39.4808,308,3.5,1.116,2415.601,301096,5032,0
1:05:39,305.4,308,111,58.8,50,19.7404,39.4808,308,3.5,1.116,2415.601,301096,5032,0
1:05:50,305.6,308,111,58.8,50,19.7404,39.4808,308,3.6,1.116,2415.601,301096,5032,0
1:06:01,305.6,308,111,58.8,50,19.7404,39.4808,308,3.9,1.116,2415.601,301096,5032,0
1:06:14,305.6,308,111,29.4,25,19.7404,78.9617,308,3.9,1.116,2415.601,301096,5032,0
1:06:25,305.6,308,111,29.4,25,19.7404,78.9617,307,2.6,1.116,2415.601,301096,5032,0
1:06:36,305.6,307,111,29.4,25,19.1036,76.4145,306,2.1,1.08,2337.678,301096,5031,0
1:06:47,305.6,307,104,29.4,25,19.1036,76.4145,305,1.7,1.08,2337.678,301096,5031,0
1:06:58,306,306,111,29.4,25,19.1036,76.4145,304,1.2,1.08,2337.678,301096,5031,0
1:07:09,306,306,111,29.4,25,19.1036,76.4145,303,0.3,1.08,2337.678,301096,5031,0
1:07:20,306,305,111,58.8,50,19.1036,38.2073,303,2.4,1.08,2337.678,301096,5031,0
1:07:31,306,304,111,58.8,50,19.1036,38.2073,303,3.4,1.08,2337.678,301096,5031,0
1:07:42,306,304,111,58.8,50,19.1036,38.2073,302,0.8,1.08,2337.678,301096,5031,0
1:07:53,305.6,303,111,58.8,50,19.1036,38.2073,302,2.1,1.08,2337.678,301096,5031,0
1:08:04,305.6,303,111,58.8,50,19.1036,38.2073,302,3,1.08,2337.678,301096,5031,0
1:08:15,305.6,302,111,88.2,75,19.7404,26.3206,302,2.6,1.116,2415.601,301096,5032,0
1:08:26,305.4,302,111,88.2,75,19.7404,26.3206,302,3.1,1.116,2415.601,301096,5032,0
1:08:37,305.2,302,111,88.2,75,19.7404,26.3206,302,3.1,1.116,2415.601,301096,5032,0
1:08:48,305.1,302,111,88.2,75,19.7404,26.3206,303,4.8,1.116,2415.601,301096,5032,0
1:08:59,304.7,302,111,88.2,75,19.7404,26.3206,303,3.5,1.116,2415.601,301096,5032,0
1:09:10,304.7,302,111,88.2,75,19.7404,26.3206,303,3.8,1.116,2415.601,301096,5032,0
1:09:21,304.5,303,111,117.61,100,19.7404,19.7404,321,33,1.116,2415.601,301096,5032,0
1:09:32,304.3,307,111,117.61,100,19.7404,19.7404,338,42.4,1.116,2415.601,301096,5032,0
1:09:43,304.1,319,111,117.61,100,19.7404,19.7404,362,50.9,1.116,2415.601,301096,5032,0
1:09:54,304,332,111,117.61,100,19.7404,19.7404,385,62.8,1.116,2415.601,301096,5032,0
1:10:05,303.8,347,111,117.61,100,19.7404,19.7404,403,67.5,1.116,2415.601,301096,5032,0
1:10:16,304.1,365,111,58.8,50,19.7404,39.4808,420,64.6,1.116,2415.601,301096,5032,0
1:10:27,304.7,381,111,58.8,50,19.1036,38.2073,420,45.1,1.08,2337.678,301096,5031,0
1:10:38,305.4,392,111,58.8,50,19.1036,38.2073,420,41.7,1.08,2337.678,301096,5031,0
1:10:49,306.5,401,111,58.8,50,19.1036,38.2073,419,39.3,1.08,2337.678,301096,5031,0
1:11:00,307.9,407,111,58.8,50,19.1036,38.2073,419,34.7,1.08,2337.678,301096,5031,0
1:11:11,309.4,411,111,58.8,50,19.1036,38.2073,419,30.9,1.08,2337.678,301096,5031,0
1:11:22,311,416,111,58.8,50,19.1036,38.2073,419,28.2,1.08,2337.678,301096,5031,0
1:11:33,312.8,419,104,58.8,50,19.1036,38.2073,419,25.7,1.08,2337.678,301096,5031,0
1:11:44,314.8,421,111,58.8,50,19.1036,38.2073,418,21.9,1.08,2337.678,301096,5031,0
1:11:55,316.4,422,104,58.8,50,19.1036,38.2073,418,21.5,1.08,2337.678,301096,5031,0
1:12:06,318.8,423,111,58.8,50,19.1036,38.2073,418,20.8,1.08,2337.678,301096,5031,0
1:12:17,320.7,424,111,58.8,50,19.1036,38.2073,418,19.8,1.08,2337.678,301096,5031,0
1:12:28,322.6,424,104,58.8,50,19.1036,38.2073,418,18.3,1.08,2337.678,301096,5031,0
1:12:39,324.9,424,111,58.8,50,19.1036,38.2073,418,17.4,1.08,2337.678,301096,5031,0
1:12:50,326.9,424,111,58.8,50,19.1036,38.2073,417,15.7,1.08,2337.678,301096,5031,0
1:13:01,328.9,424,111,58.8,50,19.1036,38.2073,417,15.9,1.08,2337.678,301096,5031,0
1:13:12,331.6,423,111,58.8,50,19.1036,38.2073,417,15.6,1.08,2337.678,301096,5031,0
1:13:23,333.6,423,114,58.8,50,19.1036,38.2073,417,15.3,1.08,2337.678,301096,5031,0
1:13:34,335.9,422,111,58.8,50,19.1036,38.2073,417,14.8,1.08,2337.678,301096,5031,0
1:13:45,338.4,422,114,58.8,50,19.1036,38.2073,416,12.5,1.08,2337.678,301096,5031,0
1:13:56,340.6,422,111,58.8,50,19.1036,38.2073,416,12.8,1.08,2337.678,301096,5031,0
1:14:08,342.8,421,111,58.8,50,19.1036,38.2073,416,13.3,1.08,2337.678,301096,5031,0
1:14:19,345.3,421,111,58.8,50,19.1036,38.2073,416,12.4,1.08,2337.678,301096,5031,0
1:14:30,347.3,420,114,58.8,50,19.1036,38.2073,416,12.5,1.08,2337.678,301096,5031,0
1:14:41,349.3,420,114,58.8,50,19.1036,38.2073,416,12,1.08,2337.678,301096,5031,0
1:14:52,351.4,419,114,58.8,50,18.4669,36.9337,415,10.9,1.044,2259.756,301096,5030,0
1:15:03,353.2,419,111,58.8,50,18.4669,36.9337,415,11.6,1.044,2259.756,301096,5030,0
1:15:14,355,418,114,58.8,50,18.4669,36.9337,415,10.8,1.044,2259.756,301096,5030,0
1:15:25,356.8,418,114,58.8,50,18.4669,36.9337,415,10.9,1.044,2259.756,301096,5030,0
1:15:36,358.6,418,111,58.8,50,18.4669,36.9337,415,10.8,1.044,2259.756,301096,5030,0
1:15:47,360.1,417,111,58.8,50,18.4669,36.9337,414,9.3,1.044,2259.756,301096,5030,0
1:15:58,361.7,417,114,58.8,50,18.4669,36.9337,414,10.1,1.044,2259.756,301096,5030,0
1:16:09,363.1,417,114,58.8,50,18.4669,36.9337,414,10.5,1.044,2259.756,301096,5030,0
1:16:20,364.6,416,114,58.8,50,18.4669,36.9337,414,9.8,1.044,2259.756,301096,5030,0
1:16:31,366.9,416,114,58.8,50,18.4669,36.9337,414,10.4,1.044,2259.756,301096,5030,0
1:16:42,368.2,416,114,58.8,50,18.4669,36.9337,414,10.1,1.044,2259.756,301096,5030,0
1:16:53,369.5,415,114,58.8,50,18.4669,36.9337,413,9.2,1.044,2259.756,301096,5030,0
1:17:04,370.9,415,114,58.8,50,18.4669,36.9337,413,9.8,1.044,2259.756,301096,5030,0
1:17:15,372.2,415,114,58.8,50,18.4669,36.9337,413,9.8,1.044,2259.756,301096,5030,0
1:17:26,373.2,414,114,58.8,50,18.4669,36.9337,413,9.3,1.044,2259.756,301096,5030,0
1:17:37,374.5,414,114,58.8,50,18.4669,36.9337,413,9.6,1.044,2259.756,301096,5030,0
1:17:48,375.6,414,111,58.8,50,18.4669,36.9337,412,7.9,1.044,2259.756,301096,5030,0
1:17:59,376.7,414,114,58.8,50,18.4669,36.9337,412,8.9,1.044,2259.756,301096,5030,0
1:18:10,377.8,413,114,58.8,50,18.4669,36.9337,412,9.1,1.044,2259.756,301096,5030,0
1:18:21,378.7,413,114,58.8,50,18.4669,36.9337,412,8.6,1.044,2259.756,301096,5030,0
1:18:32,379.4,413,114,58.8,50,18.4669,36.9337,412,8.9,1.044,2259.756,301096,5030,0
1:18:43,380.5,413,114,58.8,50,18.4669,36.9337,411,7.1,1.044,2259.756,301096,5030,0
1:18:54,381.2,413,114,58.8,50,17.8301,35.6601,411,7.8,1.008,2181.834,301096,5029,0
1:19:05,381.9,412,111,58.8,50,17.8301,35.6601,411,9.1,1.008,2181.834,301096,5029,0
1:19:16,382.8,412,114,58.8,50,17.8301,35.6601,411,8.3,1.008,2181.834,301096,5029,0
1:19:27,383.5,412,114,58.8,50,17.8301,35.6601,411,8.3,1.008,2181.834,301096,5029,0
1:19:38,384.3,412,114,58.8,50,17.1933,34.3866,411,8.7,0.972,2103.912,301096,5028,0
1:19:49,385,411,114,58.8,50,17.1933,34.3866,410,7,0.972,2103.912,301096,5028,0
1:20:00,385.7,411,114,58.8,50,17.1933,34.3866,410,7.8,0.972,2103.912,301096,5028,0
1:20:11,386.2,411,114,58.8,50,17.1933,34.3866,410,8,0.972,2103.912,301096,5028,0
1:20:22,387,411,114,117.61,100,17.8301,17.8301,408,4.9,1.008,2181.834,301096,5029,0
1:20:33,387.7,410,111,117.61,100,17.8301,17.8301,407,4.7,1.008,2181.834,301096,5029,0
1:20:44,388.2,409,111,117.61,100,17.8301,17.8301,405,4.6,1.008,2181.834,301096,5029,0
1:20:55,388.8,408,111,117.61,100,17.8301,17.8301,403,3.3,1.008,2181.834,301096,5029,0
1:21:06,389.3,406,111,117.61,100,17.8301,17.8301,401,2.2,1.008,2181.834,301096,5029,0
1:21:17,389.8,405,104,88.2,75,17.8301,23.7734,400,3.3,1.008,2181.834,301096,5029,0
1:21:28,390.2,403,104,88.2,75,17.1933,22.9244,399,2.9,0.972,2103.912,301096,5028,0
1:21:39,390.4,402,111,88.2,75,17.1933,22.9244,398,2.5,0.972,2103.912,301096,5028,0
1:21:50,390.7,401,104,88.2,75,17.1933,22.9244,398,4.1,0.972,2103.912,301096,5028,0
1:22:01,391.1,400,111,88.2,75,17.1933,22.9244,397,3.3,0.972,2103.912,301096,5028,0
1:22:12,391.3,399,111,58.8,50,17.1933,22.9244,396,2.4,0.972,2103.912,301096,5028,0
1:22:23,391.6,398,111,58.8,50,17.1933,34.3866,396,4.4,0.972,2103.912,301096,5028,0
1:22:34,391.8,397,111,58.8,50,17.1933,34.3866,396,4.6,0.972,2103.912,301096,5028,0
1:22:45,392,397,104,58.8,50,17.1933,34.3866,395,2.9,0.972,2103.912,301096,5028,0
1:22:56,392.2,396,111,58.8,50,17.1933,34.3866,395,4.4,0.972,2103.912,301096,5028,0
1:23:07,392.2,396,111,58.8,50,17.1933,34.3866,395,5.2,0.972,2103.912,301096,5028,0
1:23:18,392.2,395,111,29.4,25,17.1933,68.7731,395,5.1,0.972,2103.912,301096,5028,0
1:23:29,392.2,395,111,29.4,25,17.1933,68.7731,395,5.1,0.972,2103.912,301096,5028,0
1:23:40,392.4,395,111,29.4,25,17.1933,68.7731,395,5.4,0.972,2103.912,301096,5028,0
1:23:51,392.4,395,111,29.4,25,17.1933,68.7731,394,3.8,0.972,2103.912,301096,5028,0
1:24:02,392.4,394,111,29.4,25,17.1933,68.7731,394,5.5,0.972,2103.912,301096,5028,0
1:24:13,392.4,394,111,29.4,25,17.1933,68.7731,394,5.8,0.972,2103.912,301096,5028,0
1:24:24,392.4,394,111,58.8,50,16.5565,33.113,394,5.6,0.936,2025.99,301096,5027,0
1:24:36,392.4,394,111,58.8,50,16.5565,33.113,394,5.9,0.936,2025.99,301096,5027,0
1:24:47,392.2,394,111,58.8,50,16.5565,33.113,393,4.4,0.936,2025.99,301096,5027,0
1:24:59,392,393,111,58.8,50,16.5565,33.113,393,5.1,0.936,2025.99,301096,5027,0
1:25:11,392,393,114,58.8,50,16.5565,33.113,393,5.4,0.936,2025.99,301096,5027,0
1:25:22,391.8,393,111,88.2,75,16.5565,22.0753,393,5.4,0.936,2025.99,301096,5027,0
1:25:33,391.6,393,111,88.2,75,16.5565,22.0753,393,5.3,0.936,2025.99,301096,5027,0
1:25:44,391.3,393,111,88.2,75,16.5565,22.0753,393,6,0.936,2025.99,301096,5027,0
1:25:56,391.1,393,111,88.2,75,16.5565,22.0753,394,6.8,0.936,2025.99,301096,5027,0
1:26:08,390.9,393,111,88.2,75,16.5565,22.0753,394,5.9,0.936,2025.99,301096,5027,0
1:26:19,390.7,393,104,117.61,100,16.5565,16.5565,401,8.7,0.936,2025.99,301096,5027,0
1:26:30,390.6,395,104,117.61,100,16.5565,16.5565,416,37.7,0.936,2025.99,301096,5027,0
1:26:41,390.4,403,111,117.61,100,16.5565,16.5565,437,45.9,0.936,2025.99,301096,5027,0
1:26:52,390.2,413,101,117.61,100,16.5565,16.5565,459,58.9,0.936,2025.99,301096,5027,0
1:27:03,390.2,425,104,117.61,100,16.5565,16.5565,475,62.3,0.936,2025.99,301096,5027,0
1:27:14,390.2,441,101,117.61,100,16.5565,16.5565,496,70,0.936,2025.99,301096,5027,0
1:27:25,390.6,457,101,58.8,50,16.5565,33.113,500,51.9,0.936,2025.99,301096,5027,0
1:27:36,391.1,469,104,58.8,50,16.5565,33.113,500,44,0.936,2025.99,301096,5027,0
1:27:47,392,478,104,58.8,50,16.5565,33.113,500,44.8,0.936,2025.99,301096,5027,0
1:27:58,393.5,484,104,58.8,50,16.5565,33.113,500,40.7,0.936,2025.99,301096,5027,0
1:28:09,395.3,489,111,58.8,50,16.5565,33.113,500,37.1,0.936,2025.99,301096,5027,0
1:28:20,398,494,111,58.8,50,16.5565,33.113,500,34,0.936,2025.99,301096,5027,0
1:28:31,401.4,497,104,58.8,50,16.5565,33.113,500,32.8,0.936,2025.99,301096,5027,0
1:28:42,405,499,111,58.8,50,16.5565,33.113,500,30.1,0.936,2025.99,301096,5027,0
1:28:53,408.8,501,111,58.8,50,8.9151,17.8301,500,28.5,0.504,1090.922,301096,5015,0
1:29:05,413.3,503,111,58.8,50,12.7358,25.4716,500,26.5,0.72,1558.456,301096,5021,0
1:29:16,417.4,504,111,58.8,50,12.7358,25.4716,500,25.8,0.72,1558.456,301096,5021,0
1:29:29,422.3,504,111,58.8,50,12.7358,25.4716,500,24.5,0.72,1558.456,301096,5021,0
1:30:02,435.1,505,114,58.8,50,12.7358,25.4716,490,6.5,0.72,1558.456,301096,5021,0
1:30:14,439.8,501,114,58.8,50,12.7358,25.4716,490,18.2,0.72,1558.456,301096,5021,0
1:30:25,443.8,499,114,58.8,50,12.7358,25.4716,490,16.8,0.72,1558.456,301096,5021,0
1:30:36,447.9,499,114,58.8,50,12.7358,25.4716,490,14,0.72,1558.456,301096,5021,0
1:30:47,451,498,114,58.8,50,12.7358,25.4716,490,15.3,0.72,1558.456,301096,5021,0
1:30:58,453.5,496,114,58.8,50,12.7358,25.4716,490,15.3,0.72,1558.456,301096,5021,0
1:31:09,456.1,496,114,58.8,50,12.099,24.198,490,14.2,0.684,1480.533,301096,5020,0
1:31:20,458,495,114,58.8,50,12.099,24.198,490,15,0.684,1480.533,301096,5020,0
1:31:31,459.7,495,114,58.8,50,12.099,24.198,490,14.4,0.684,1480.533,301096,5020,0
1:31:42,461.3,494,114,58.8,50,12.099,24.198,490,14.3,0.684,1480.533,301096,5020,0
1:31:53,462.6,494,111,58.8,50,12.099,24.198,490,14.1,0.684,1480.533,301096,5020,0
1:32:04,463.5,494,114,58.8,50,12.099,24.198,490,13.9,0.684,1480.533,301096,5020,0
1:32:15,464.5,493,114,58.8,50,11.4622,22.9244,490,13.1,0.648,1402.611,301096,5019,0
1:32:26,465.4,493,114,58.8,50,11.4622,22.9244,490,13.7,0.648,1402.611,301096,5019,0
1:32:37,466.3,493,114,58.8,50,11.4622,22.9244,490,13.4,0.648,1402.611,301096,5019,0
1:32:48,467.1,493,114,58.8,50,11.4622,22.9244,490,12.4,0.648,1402.611,301096,5019,0
1:32:59,467.8,492,114,58.8,50,10.1886,20.3773,490,12.3,0.576,1246.766,301096,5017,0
1:33:10,468.3,492,114,58.8,50,11.4622,22.9244,490,13.2,0.648,1402.611,301096,5019,0
1:33:21,468.9,492,114,58.8,50,11.4622,22.9244,490,12.8,0.648,1402.611,301096,5019,0
1:33:32,469.4,492,114,58.8,50,11.4622,22.9244,490,12.7,0.648,1402.611,301096,5019,0
1:33:43,469.9,492,114,58.8,50,11.4622,22.9244,490,12.9,0.648,1402.611,301096,5019,0
1:33:54,470.5,492,111,58.8,50,11.4622,22.9244,490,12.5,0.648,1402.611,301096,5019,0
1:34:05,470.7,491,114,58.8,50,11.4622,22.9244,490,12.4,0.648,1402.611,301096,5019,0
1:34:16,471,491,114,58.8,50,11.4622,22.9244,490,12.5,0.648,1402.611,301096,5019,0
1:34:27,471.6,491,114,58.8,50,11.4622,22.9244,490,12.4,0.648,1402.611,301096,5019,0
1:34:38,471.9,491,114,58.8,50,11.4622,22.9244,490,12.2,0.648,1402.611,301096,5019,0
1:34:49,472.3,491,114,58.8,50,11.4622,22.9244,490,11.8,0.648,1402.611,301096,5019,0
1:35:00,472.7,491,111,58.8,50,11.4622,22.9244,490,12,0.648,1402.611,301096,5019,0
1:35:11,472.8,491,114,58.8,50,11.4622,22.9244,490,11.8,0.648,1402.611,301096,5019,0
1:35:22,473.2,491,114,58.8,50,11.4622,22.9244,490,11.7,0.648,1402.611,301096,5019,0
1:35:33,473.4,491,114,58.8,50,11.4622,22.9244,490,11.4,0.648,1402.611,301096,5019,0
1:35:45,473.7,491,114,58.8,50,11.4622,22.9244,490,11.3,0.648,1402.611,301096,5019,0
1:35:56,474.1,491,111,58.8,50,11.4622,22.9244,490,11.8,0.648,1402.611,301096,5019,0
1:36:07,474.1,491,111,58.8,50,11.4622,22.9244,490,11.2,0.648,1402.611,301096,5019,0
1:36:19,474.3,491,111,58.8,50,11.4622,22.9244,490,11.4,0.648,1402.611,301096,5019,0
1:36:30,474.6,491,111,58.8,50,11.4622,22.9244,490,11.3,0.648,1402.611,301096,5019,0
1:36:41,475,491,111,58.8,50,11.4622,22.9244,490,11.1,0.648,1402.611,301096,5019,0
1:36:52,475,491,111,58.8,50,11.4622,22.9244,490,11.2,0.648,1402.611,301096,5019,0
1:37:03,475.2,491,111,58.8,50,11.4622,22.9244,490,11.5,0.648,1402.611,301096,5019,0
1:37:14,475.5,491,111,58.8,50,11.4622,22.9244,490,10.3,0.648,1402.611,301096,5019,0
1:37:25,475.5,491,114,117.61,100,11.4622,11.4622,490,11.1,0.648,1402.611,301096,5019,0
1:37:36,476.1,490,114,117.61,100,11.4622,11.4622,490,10.8,0.648,1402.611,301096,5019,0
1:37:47,476.3,491,114,117.61,100,11.4622,11.4622,490,10.8,0.648,1402.611,301096,5019,0
1:37:58,476.4,490,111,117.61,100,11.4622,11.4622,490,10.8,0.648,1402.611,301096,5019,0
1:38:09,476.8,490,114,117.61,100,11.4622,11.4622,490,10.6,0.648,1402.611,301096,5019,0
1:38:20,477,490,111,88.2,75,11.4622,15.283,489,8.8,0.648,1402.611,301096,5019,0
1:38:31,477.2,490,111,88.2,75,11.4622,15.283,487,6.5,0.648,1402.611,301096,5019,0
1:38:42,477.3,489,111,88.2,75,11.4622,15.283,486,7.1,0.648,1402.611,301096,5019,0
1:38:53,477.3,489,111,88.2,75,11.4622,15.283,484,5.7,0.648,1402.611,301096,5019,0
1:39:04,477.7,487,111,88.2,75,11.4622,15.283,482,4.3,0.648,1402.611,301096,5019,0
1:39:15,477.7,486,111,58.8,50,11.4622,22.9244,480,3.6,0.648,1402.611,301096,5019,0
1:39:27,477.7,484,114,58.8,50,11.4622,22.9244,480,5.9,0.648,1402.611,301096,5019,0
1:39:38,477.7,483,114,58.8,50,11.4622,22.9244,480,6.3,0.648,1402.611,301096,5019,0
1:39:49,477.7,482,117,58.8,50,11.4622,22.9244,480,6.2,0.648,1402.611,301096,5019,0
1:40:00,477.5,482,114,58.8,50,11.4622,22.9244,480,7.1,0.648,1402.611,301096,5019,0
1:40:11,477.2,481,117,58.8,50,11.4622,22.9244,480,7.4,0.648,1402.611,301096,5019,0
1:40:22,476.8,481,117,29.4,25,11.4622,45.8489,480,7.5,0.648,1402.611,301096,5019,0
1:40:33,476.4,481,111,29.4,25,10.8254,43.3017,480,7.3,0.612,1324.689,301096,5018,0
1:40:44,476.3,480,114,29.4,25,10.8254,43.3017,480,7.7,0.612,1324.689,301096,5018,0
1:40:56,475.9,480,111,29.4,25,10.8254,43.3017,480,7.9,0.612,1324.689,301096,5018,0
1:41:07,475.7,480,114,29.4,25,10.8254,43.3017,480,7.8,0.612,1324.689,301096,5018,0
1:41:18,475.4,480,111,58.8,50,10.8254,21.6509,480,8.2,0.612,1324.689,301096,5018,0
1:41:29,475.2,480,114,58.8,50,11.4622,22.9244,480,8.3,0.648,1402.611,301096,5019,0
1:41:41,475,480,111,58.8,50,11.4622,22.9244,480,8,0.648,1402.611,301096,5019,0
1:41:52,474.6,480,111,58.8,50,11.4622,22.9244,480,8,0.648,1402.611,301096,5019,0
1:42:03,474.3,480,111,58.8,50,11.4622,22.9244,480,8.1,0.648,1402.611,301096,5019,0
1:42:14,474.1,480,111,58.8,50,11.4622,22.9244,480,8.8,0.648,1402.611,301096,5019,0
1:42:26,473.7,480,111,88.2,75,11.4622,15.283,480,8.1,0.648,1402.611,301096,5019,0
1:42:38,473.6,480,114,88.2,75,11.4622,15.283,480,8.7,0.648,1402.611,301096,5019,0
1:42:49,473.2,480,114,88.2,75,11.4622,15.283,480,8.5,0.648,1402.611,301096,5019,0
1:43:01,473.2,480,111,88.2,75,11.4622,15.283,480,8.6,0.648,1402.611,301096,5019,0
1:43:12,472.8,480,104,88.2,75,11.4622,15.283,480,8.6,0.648,1402.611,301096,5019,0
1:43:24,472.8,480,111,117.61,100,11.4622,11.4622,480,8.7,0.648,1402.611,301096,5019,0
1:43:35,472.5,480,111,117.61,100,12.099,12.099,480,8.8,0.684,1480.533,301096,5020,0
1:43:46,472.5,480,111,117.61,100,12.099,12.099,480,8.4,0.684,1480.533,301096,5020,0
1:43:57,472.3,480,111,117.61,100,12.099,12.099,480,9,0.684,1480.533,301096,5020,0
1:44:08,472.1,480,111,117.61,100,12.099,12.099,480,8.8,0.684,1480.533,301096,5020,0
1:44:14,472.1,480,111,117.61,100,11.4622,11.4622,480,8.8,0.648,1402.611,301096,5019,0