File: data/hpybr-cons-P.csv
Elapsed Time,Sample Temp,Heater Temp,Pressure,Rotor Speed,Shear Rate,Shear Stress,Viscosity,Temperature Setpoint,T Output,Bob Deflection,Torque,Motor Temp,Raw Encoder Value,Aux1
(hh:mm:ss),(°F),(°F),(PSIg),(RPM),(1/s),(dyne/cm²),(cP),(°F),(%),(deg.),(dyne-cm),(°C),(cts),
1.16E-05,92.7,96,101,0,0,1.9104,0,32,0,0.108,233.7767,301096,5004,0
0.000138889,92.9,96,101,0,0,2.5472,0,32,0,0.144,311.6989,301096,5005,0
8.10185E-05,93.1,96,111,117.61,100,685.2439,685.2439,77,0,37.368,83852.11,301096,6039,0
0.000208333,93.1,96,111,117.61,100,683.1661,683.1661,77,0,37.26,83597.85,301096,6036,0
0.000335648,93.1,96,111,117.61,100,681.7808,681.7808,77,0,37.188,83428.33,301096,6034,0
0.000462963,93.1,96,111,117.61,100,684.5513,684.5513,77,0,37.332,83767.35,301096,6038,0
0.000590278,93.1,95,111,117.61,100,682.4734,682.4734,77,0,37.224,83513.09,301096,6035,0
0.000717593,93.1,95,111,88.2,75,685.2439,685.2439,77,0,37.368,83852.11,301096,6039,0
0.000844907,93.1,95,111,88.2,75,517.9901,690.6534,77,0,28.404,63385.54,301096,5790,0
0.000972222,93.1,95,111,88.2,75,517.9901,690.6534,77,0,28.404,63385.54,301096,5790,0
0.001099537,93.1,95,111,88.2,75,518.6543,691.5391,77,0,28.44,63466.83,301096,5791,0
0.001226852,93.1,95,111,88.2,75,518.6543,691.5391,77,0,28.44,63466.83,301096,5791,0
0.001354167,93.2,95,111,88.2,75,518.6543,691.5391,77,0,28.44,63466.83,301096,5791,0
0.001481481,93.2,95,111,58.8,50,349.7277,699.4553,77,0,19.224,42795.57,301096,5535,0
0.001608796,93.2,95,111,58.8,50,350.3728,700.7457,77,0,19.26,42874.52,301096,5536,0
0.001736111,93.2,95,111,58.8,50,349.7277,699.4553,77,0,19.224,42795.57,301096,5535,0
0.001863426,93.4,94,111,58.8,50,350.3728,700.7457,77,0,19.26,42874.52,301096,5536,0
0.001990741,93.2,94,111,58.8,50,350.3728,700.7457,77,0,19.26,42874.52,301096,5536,0
0.002118056,93.4,94,111,29.4,25,171.4854,685.9417,77,0,9.468,20984.38,301096,5264,0
0.00224537,93.4,94,111,29.4,25,178.7479,714.9916,77,0,9.864,21873.07,301096,5275,0
0.002372685,93.4,94,111,29.4,25,178.7479,714.9916,77,0,9.864,21873.07,301096,5275,0
0.0025,93.4,94,111,29.4,25,178.7479,714.9916,77,0,9.864,21873.07,301096,5275,0
0.002627315,93.4,94,111,29.4,25,178.7479,714.9916,77,0,9.864,21873.07,301096,5275,0
0.00275463,93.4,94,104,29.4,25,178.7479,714.9916,77,0,9.864,21873.07,301096,5275,0
0.002893519,93.4,94,104,58.8,50,352.9346,705.8691,77,0,19.404,43187.99,301096,5540,0
0.003020833,93.4,94,111,58.8,50,352.9346,705.8691,77,0,19.404,43187.99,301096,5540,0
0.003148148,93.4,94,111,58.8,50,352.9346,705.8691,77,0,19.404,43187.99,301096,5540,0
0.003275463,93.4,94,104,58.8,50,352.9346,705.8691,77,0,19.404,43187.99,301096,5540,0
0.003402778,93.4,93,104,58.8,50,353.575,707.15,77,0,19.44,43266.36,301096,5541,0
0.003530093,93.4,93,104,88.2,75,526.6473,702.1965,77,0,28.872,64444.92,301096,5803,0
0.003657407,93.4,93,104,88.2,75,527.322,703.096,77,0,28.908,64527.48,301096,5804,0
0.003784722,93.2,93,104,88.2,75,527.322,703.096,77,0,28.908,64527.48,301096,5804,0
0.003912037,93.4,93,111,88.2,75,527.9966,703.9955,77,0,28.944,64610.04,301096,5805,0
0.004039352,93.2,93,111,88.2,75,527.322,703.096,77,0,28.908,64527.48,301096,5804,0
0.004166667,93.4,93,111,88.2,75,527.9966,703.9955,77,0,28.944,64610.04,301096,5805,0
0.004293981,93.2,93,111,117.61,100,709.4858,709.4858,81,0,38.628,86818.55,301096,6074,0
0.004421296,93.4,93,111,117.61,100,709.4858,709.4858,92,0,38.628,86818.55,301096,6074,0
0.004548611,93.2,93,104,117.61,100,710.871,710.871,103,13.1,38.7,86988.05,301096,6076,0
0.004675926,93.2,95,111,117.61,100,709.4858,709.4858,111,15.5,38.628,86818.55,301096,6074,0
0.004803241,93.2,101,111,117.61,100,702.5595,702.5595,121,14.4,38.268,85970.99,301096,6064,0
0.004930556,93.1,107,111,58.8,50,330.1089,660.2178,130,19.9,18.144,40394.85,301096,5505,0
0.00505787,93.2,114,104,58.8,50,317.6837,635.3673,130,10,17.46,38874.4,301096,5486,0
0.005185185,93.2,118,104,58.8,50,300.2254,600.4507,130,9.2,16.524,36738.06,301096,5460,0
0.0053125,93.2,121,104,58.8,50,278.0832,556.1664,130,10.3,15.336,34028.56,301096,5427,0
0.005439815,93.4,124,104,58.8,50,259.4821,518.9643,129,5.8,14.292,31752.38,301096,5398,0
0.00556713,93.4,125,104,58.8,50,242.7377,485.4755,129,6.6,13.356,29703.4,301096,5372,0
0.005694444,93.6,126,104,58.8,50,231.4983,462.9965,129,6.3,12.744,28328.04,301096,5355,0
0.005821759,94.1,127,104,58.8,50,218.9365,437.873,129,5,12.06,26790.88,301096,5336,0
0.005949074,94.5,128,111,58.8,50,209.6821,419.3642,129,5.1,11.556,25658.44,301096,5322,0
0.006076389,95.1,129,111,58.8,50,201.784,403.5681,129,4.6,11.124,24691.96,301096,5310,0
0.006203704,95.6,129,111,58.8,50,191.9114,383.8228,129,4.2,10.584,23483.87,301096,5295,0
0.006331019,96.3,129,111,58.8,50,187.9624,375.9247,128,3.1,10.368,23000.63,301096,5289,0
0.006458333,96.7,129,111,58.8,50,184.6715,369.343,128,3.5,10.188,22597.93,301096,5284,0
0.006585648,97.4,129,111,58.8,50,181.3806,362.7612,128,3.2,10.008,22195.23,301096,5279,0
0.006712963,98.1,129,111,58.8,50,178.0898,356.1795,128,3.4,9.828,21792.54,301096,5274,0
0.006840278,98.8,129,111,58.8,50,175.4571,350.9141,128,2.9,9.684,21470.38,301096,5270,0
0.006967593,99.6,129,111,58.8,50,172.1477,344.2954,128,2.8,9.504,21065.42,301096,5265,0
0.007094907,100.3,129,111,58.8,50,170.1609,340.3217,127,0.9,9.396,20822.29,301096,5262,0
0.007222222,100.8,129,111,58.8,50,168.1741,336.3481,127,1.9,9.288,20579.17,301096,5259,0
0.007349537,101.5,128,111,58.8,50,166.8495,333.699,127,2.9,9.216,20417.08,301096,5257,0
0.007476852,102.3,128,111,58.8,50,165.5249,331.0499,127,2.3,9.144,20255,301096,5255,0
0.007604167,102.8,128,111,58.8,50,164.2004,328.4008,127,1.9,9.072,20092.92,301096,5253,0
0.007731481,103.5,128,111,58.8,50,163.5381,327.0762,127,2.6,9.036,20011.87,301096,5252,0
0.007858796,104.3,128,111,58.8,50,162.2135,324.4271,127,2,8.964,19849.79,301096,5250,0
0.007986111,104.8,128,111,58.8,50,161.5513,323.1025,126,0.4,8.928,19768.75,301096,5249,0
0.008113426,105.3,127,104,58.8,50,160.889,321.778,126,1.6,8.892,19687.71,301096,5248,0
0.008240741,105.9,127,104,58.8,50,160.2267,320.4534,126,1.9,8.856,19606.67,301096,5247,0
0.008368056,106.4,127,104,58.8,50,159.5644,319.1289,126,1.7,8.82,19525.62,301096,5246,0
0.00849537,107,127,111,58.8,50,158.9022,317.8043,126,1.3,8.784,19444.58,301096,5245,0
0.008622685,107.5,127,111,58.8,50,158.2399,316.4798,126,2,8.748,19363.54,301096,5244,0
0.00875,107.9,126,104,58.8,50,157.5776,315.1552,126,1.9,8.712,19282.5,301096,5243,0
0.008877315,108.4,126,111,58.8,50,156.9153,313.8307,125,0,8.676,19201.46,301096,5242,0
0.00900463,108.9,126,111,58.8,50,156.2531,312.5061,125,0.5,8.64,19120.42,301096,5241,0
0.009131944,109.3,126,101,58.8,50,156.2531,312.5061,125,1.7,8.64,19120.42,301096,5241,0
0.009259259,109.8,126,111,58.8,50,155.5908,311.1816,125,1.3,8.604,19039.38,301096,5240,0
0.009386574,110.2,126,104,58.8,50,154.9285,309.857,125,1.1,8.568,18958.33,301096,5239,0
0.009513889,110.6,125,104,58.8,50,154.9285,309.857,125,1.8,8.568,18958.33,301096,5239,0
0.009641204,111.1,125,111,58.8,50,154.2662,308.5324,125,1.3,8.532,18877.29,301096,5238,0
0.009768519,111.3,125,101,58.8,50,153.6039,307.2079,124,0,8.496,18796.25,301096,5237,0
0.009895833,111.6,125,104,58.8,50,153.6039,307.2079,124,1.4,8.496,18796.25,301096,5237,0
0.010023148,112,125,111,58.8,50,152.9417,305.8833,124,1.3,8.46,18715.21,301096,5236,0
0.010150463,112.4,124,104,58.8,50,152.9417,305.8833,124,1.7,8.46,18715.21,301096,5236,0
0.010277778,112.7,124,111,58.8,50,152.2794,304.5588,124,1.2,8.424,18634.16,301096,5235,0
0.010405093,112.9,124,111,58.8,50,152.2794,304.5588,124,0.8,8.424,18634.16,301096,5235,0
0.010532407,113.3,124,101,58.8,50,152.2794,304.5588,124,1.3,8.424,18634.16,301096,5235,0
0.010659722,113.5,124,111,58.8,50,152.2794,304.5588,123,0,8.424,18634.16,301096,5235,0
0.010787037,113.8,124,111,58.8,50,151.6171,303.2342,123,1.4,8.388,18553.12,301096,5234,0
0.010914352,114.2,123,101,58.8,50,151.6171,303.2342,123,0.7,8.388,18553.12,301096,5234,0
0.011041667,114.4,123,104,58.8,50,151.6171,303.2342,123,0.7,8.388,18553.12,301096,5234,0
0.011168981,114.7,123,111,58.8,50,150.9548,301.9097,123,0.9,8.352,18472.08,301096,5233,0
0.011296296,114.9,123,101,58.8,50,150.9548,301.9097,123,0.3,8.352,18472.08,301096,5233,0
0.011423611,115.1,123,111,58.8,50,150.9548,301.9097,122,0,8.352,18472.08,301096,5233,0
0.011550926,115.3,123,111,58.8,50,150.9548,301.9097,122,0.2,8.352,18472.08,301096,5233,0
0.011678241,115.4,123,104,58.8,50,150.2926,300.5851,122,0.4,8.316,18391.04,301096,5232,0
0.011805556,115.6,122,101,58.8,50,150.2926,300.5851,122,0.8,8.316,18391.04,301096,5232,0
0.01193287,115.8,122,104,117.61,100,270.3862,270.3862,122,0,14.904,33086.7,301096,5415,0
0.012060185,116,122,104,117.61,100,270.3862,270.3862,122,0.1,14.904,33086.7,301096,5415,0
0.0121875,116.2,122,104,117.61,100,269.7448,269.7448,122,1.2,14.868,33008.21,301096,5414,0
0.012314815,116.5,122,104,117.61,100,269.7448,269.7448,122,0.4,14.868,33008.21,301096,5414,0
0.012453704,116.7,122,111,117.61,100,269.7448,269.7448,122,0.4,14.868,33008.21,301096,5414,0
0.012731481,117.1,122,111,117.61,100,269.7448,269.7448,122,0.3,14.868,33008.21,301096,5414,0
0.012858796,117.2,122,104,117.61,100,269.1034,269.1034,122,0.7,14.832,32929.71,301096,5413,0
0.012986111,117.4,122,111,117.61,100,269.1034,269.1034,122,0.5,14.832,32929.71,301096,5413,0
0.013113426,117.4,122,104,117.61,100,269.1034,269.1034,122,0.7,14.832,32929.71,301096,5413,0
0.013240741,117.8,122,104,117.61,100,268.462,268.462,122,0.7,14.796,32851.23,301096,5412,0
0.013368056,117.8,122,104,117.61,100,269.1034,269.1034,122,1,14.832,32929.71,301096,5413,0
0.013506944,118,122,104,117.61,100,268.462,268.462,122,0.9,14.796,32851.23,301096,5412,0
0.013703704,118,122,104,117.61,100,267.8206,267.8206,122,0.9,14.76,32772.74,301096,5411,0
0.013831019,118,122,104,117.61,100,267.1791,267.1791,122,0.8,14.724,32694.25,301096,5410,0
0.013969907,118.3,122,104,117.61,100,267.1791,267.1791,122,0.7,14.724,32694.25,301096,5410,0
0.014212963,118.3,122,104,117.61,100,265.8963,265.8963,125,5.6,14.652,32537.27,301096,5408,0
0.014340278,118.7,123,104,117.61,100,265.8963,265.8963,125,3.2,14.652,32537.27,301096,5408,0
0.014467593,118.7,124,104,117.61,100,265.2549,265.2549,125,0.6,14.616,32458.78,301096,5407,0
0.014594907,118.7,124,104,117.61,100,263.3306,263.3306,125,1.9,14.508,32223.31,301096,5404,0
0.014722222,118.7,124,104,117.61,100,262.0478,262.0478,125,1.9,14.436,32066.34,301096,5402,0
0.014849537,118.9,124,104,117.61,100,260.1236,260.1236,125,1.5,14.328,31830.87,301096,5399,0
0.014976852,118.9,125,104,117.61,100,259.4821,259.4821,125,1.4,14.292,31752.38,301096,5398,0
0.015115741,119,125,101,117.61,100,258.1993,258.1993,125,1.4,14.22,31595.4,301096,5396,0
0.015243056,119.2,125,104,117.61,100,256.9165,256.9165,125,1.1,14.148,31438.42,301096,5394,0
0.015393519,119.4,125,111,88.2,75,187.9624,250.6165,125,0.8,10.368,23000.63,301096,5289,0
0.015543981,119.6,125,104,88.2,75,187.3042,249.7389,125,1.2,10.332,22920.09,301096,5288,0
0.015671296,119.6,125,104,88.2,75,187.3042,249.7389,125,1.2,10.332,22920.09,301096,5288,0
0.015798611,119.8,125,104,88.2,75,187.3042,249.7389,125,0.7,10.332,22920.09,301096,5288,0
0.0159375,119.8,125,104,88.2,75,187.3042,249.7389,125,1.2,10.332,22920.09,301096,5288,0
0.016064815,119.8,125,104,58.8,50,130.6448,261.2897,125,1.1,7.236,15986.78,301096,5202,0
0.01619213,120.1,125,111,58.8,50,130.6448,261.2897,124,0,7.236,15986.78,301096,5202,0
0.016319444,120.3,125,104,58.8,50,130.6448,261.2897,124,0.4,7.236,15986.78,301096,5202,0
0.016446759,120.3,125,104,58.8,50,130.6448,261.2897,123,0,7.236,15986.78,301096,5202,0
0.016574074,120.3,124,104,58.8,50,129.9978,259.9955,123,0,7.2,15907.6,301096,5201,0
0.016701389,120.5,124,104,58.8,50,130.6448,261.2897,122,0,7.236,15986.78,301096,5202,0
0.016828704,120.5,124,104,29.4,25,71.3236,285.2944,122,0,3.96,8727.746,301096,5111,0
0.016956019,120.7,123,101,29.4,25,71.3236,285.2944,122,0,3.96,8727.746,301096,5111,0
0.017083333,120.7,123,104,29.4,25,71.3236,285.2944,122,0,3.96,8727.746,301096,5111,0
0.017210648,120.7,123,111,29.4,25,71.3236,285.2944,122,0,3.96,8727.746,301096,5111,0
0.017337963,120.9,123,111,29.4,25,71.3236,285.2944,122,0,3.96,8727.746,301096,5111,0
0.017465278,121,123,104,58.8,50,121.5859,243.1719,122,0,6.732,14878.26,301096,5188,0
0.017592593,120.9,123,104,58.8,50,122.233,244.466,122,0,6.768,14957.44,301096,5189,0
0.017719907,121,122,104,58.8,50,122.233,244.466,122,0,6.768,14957.44,301096,5189,0
0.017847222,121,122,104,58.8,50,122.233,244.466,122,0.3,6.768,14957.44,301096,5189,0
0.017974537,121,122,101,58.8,50,122.233,244.466,122,0,6.768,14957.44,301096,5189,0
0.018101852,121,122,104,58.8,50,180.7225,361.4449,122,0.5,9.972,22114.69,301096,5278,0
0.018229167,121,122,104,88.2,75,179.4061,239.2081,122,0.4,9.9,21953.61,301096,5276,0
0.018356481,121,122,104,88.2,75,179.4061,239.2081,122,0.4,9.9,21953.61,301096,5276,0
0.018483796,121.2,122,104,88.2,75,179.4061,239.2081,122,0.6,9.9,21953.61,301096,5276,0
0.018611111,121.2,122,104,88.2,75,179.4061,239.2081,122,0.7,9.9,21953.61,301096,5276,0
0.018738426,121.2,122,104,88.2,75,179.4061,239.2081,122,0.3,9.9,21953.61,301096,5276,0
0.018865741,121.2,122,104,117.61,100,238.7709,238.7709,129,11.5,13.14,29217.98,301096,5366,0
0.018993056,121.2,123,104,117.61,100,238.7709,238.7709,144,30.9,13.14,29217.98,301096,5366,0
0.01912037,121,132,104,117.61,100,238.7709,238.7709,163,30.1,13.14,29217.98,301096,5366,0
0.019247685,121,143,104,117.61,100,232.8206,232.8206,182,39,12.816,28489.85,301096,5357,0
0.019375,121.4,155,104,117.61,100,223.5645,223.5645,196,42.4,12.312,27357.2,301096,5343,0
0.019502315,121.6,170,104,58.8,50,193.2278,193.2278,216,48.7,10.656,23644.95,301096,5297,0
0.01962963,121.6,184,104,58.8,50,87.713,175.426,218,30.8,4.86,10733.29,301096,5136,0
0.019756944,121.9,195,104,58.8,50,79.1905,158.381,218,26.5,4.392,9690.407,301096,5123,0
0.019884259,122.5,202,104,58.8,50,70.668,141.3361,218,26.1,3.924,8647.524,301096,5110,0
0.020011574,123.2,207,104,58.8,50,63.4099,126.8199,218,21.7,3.528,7759.363,301096,5099,0
0.020138889,124.1,212,104,58.8,50,60.109,120.218,218,19.5,3.348,7355.436,301096,5094,0
0.020266204,125.2,215,104,58.8,50,56.8081,113.6162,217,15.7,3.168,6951.509,301096,5089,0
0.020393519,127.2,217,104,58.8,50,54.1674,108.3347,217,15.3,3.024,6628.367,301096,5085,0
0.020520833,128.6,218,111,58.8,50,52.1868,104.3736,217,13.6,2.916,6386.011,301096,5082,0
0.020648148,130.4,220,104,58.8,50,48.8859,97.7718,217,12.3,2.736,5982.084,301096,5077,0
0.020775463,132.6,220,104,58.8,50,46.2452,92.4904,217,11.4,2.592,5658.942,301096,5073,0
0.020902778,134.6,221,104,58.8,50,44.9248,89.8496,217,10.8,2.52,5497.372,301096,5071,0
0.021030093,136.5,221,104,58.8,50,44.2646,88.5293,217,10.2,2.484,5416.586,301096,5070,0
0.021157407,138.9,221,104,58.8,50,43.6045,87.2089,217,9.7,2.448,5335.8,301096,5069,0
0.021284722,140.9,221,104,58.8,50,42.9443,85.8885,217,8.8,2.412,5255.015,301096,5068,0
0.021412037,143,221,101,58.8,50,42.2841,84.5682,217,8.4,2.376,5174.229,301096,5067,0
0.021539352,145,221,104,58.8,50,41.6239,83.2478,217,8.5,2.34,5093.444,301096,5066,0
0.021666667,147.4,221,104,58.8,50,41.6239,83.2478,216,6.6,2.34,5093.444,301096,5066,0
0.021805556,149.4,220,104,58.8,50,40.9637,81.9274,216,7.4,2.304,5012.659,301096,5065,0
0.02193287,151.2,220,104,58.8,50,39.6434,79.2867,216,7.4,2.232,4851.088,301096,5063,0
0.022060185,153.1,220,104,58.8,50,39.6434,79.2867,216,7.2,2.232,4851.088,301096,5063,0
0.0221875,154.9,219,111,58.8,50,38.9832,77.9663,216,6.7,2.196,4770.303,301096,5062,0
0.022314815,156.8,219,104,58.8,50,38.9832,77.9663,216,6.9,2.196,4770.303,301096,5062,0
0.02244213,158.6,219,111,58.8,50,38.9832,77.9663,216,6.5,2.196,4770.303,301096,5062,0
0.022569444,160.2,218,104,58.8,50,38.9832,77.9663,216,6.3,2.196,4770.303,301096,5062,0
0.022696759,161.8,218,104,58.8,50,38.9832,77.9663,216,6.4,2.196,4770.303,301096,5062,0
0.022824074,163.4,218,104,58.8,50,38.9832,77.9663,216,6.4,2.196,4770.303,301096,5062,0
0.022951389,164.9,218,104,58.8,50,38.9832,77.9663,216,6.1,2.196,4770.303,301096,5062,0
0.023078704,166.3,218,104,58.8,50,38.323,76.646,215,4.5,2.16,4689.518,301096,5061,0
0.023206019,167.9,217,111,58.8,50,38.323,76.646,215,5.8,2.16,4689.518,301096,5061,0
0.023333333,169.2,217,104,58.8,50,38.323,76.646,215,5.8,2.16,4689.518,301096,5061,0
0.023460648,170.5,217,104,58.8,50,37.6628,75.3256,215,5.4,2.124,4608.732,301096,5060,0
0.023587963,171.9,216,104,58.8,50,37.6628,75.3256,215,5.3,2.124,4608.732,301096,5060,0
0.023715278,173,216,111,58.8,50,37.6628,75.3256,215,5.8,2.124,4608.732,301096,5060,0
0.023842593,174.4,216,104,58.8,50,37.6628,75.3256,215,5.3,2.124,4608.732,301096,5060,0
0.023969907,175.5,216,111,58.8,50,37.6628,75.3256,215,5,2.124,4608.732,301096,5060,0
0.024097222,176.4,216,104,58.8,50,37.0026,74.0052,215,5.4,2.088,4527.947,301096,5059,0
0.024236111,177.9,216,104,58.8,50,37.0026,74.0052,215,5.3,2.088,4527.947,301096,5059,0
0.024363426,178.8,216,111,58.8,50,37.0026,74.0052,215,5.1,2.088,4527.947,301096,5059,0
0.024490741,180,216,101,58.8,50,37.0026,74.0052,214,3.6,2.088,4527.947,301096,5059,0
0.024618056,180.9,215,104,58.8,50,37.0026,74.0052,214,5,2.088,4527.947,301096,5059,0
0.02474537,182,215,104,58.8,50,37.0026,74.0052,214,4.4,2.088,4527.947,301096,5059,0
0.024872685,182.9,215,101,58.8,50,37.0026,74.0052,214,4.5,2.088,4527.947,301096,5059,0
0.025,183.6,215,111,58.8,50,36.3424,72.6849,214,4.6,2.052,4447.161,301096,5058,0
0.025127315,184.5,215,101,58.8,50,36.3424,72.6849,214,4.6,2.052,4447.161,301096,5058,0
0.02525463,185.4,215,104,58.8,50,36.3424,72.6849,214,4.3,2.052,4447.161,301096,5058,0
0.025381944,186.2,215,104,58.8,50,36.3424,72.6849,214,4.2,2.052,4447.161,301096,5058,0
0.025520833,187.1,215,104,58.8,50,36.3424,72.6849,214,4.3,2.052,4447.161,301096,5058,0
0.025659722,188,214,104,58.8,50,35.6823,71.3645,214,4.2,2.016,4366.375,301096,5057,0
0.025844907,189,214,104,58.8,50,35.6823,71.3645,213,2.3,2.016,4366.375,301096,5057,0
0.025972222,189.8,215,111,58.8,50,34.3865,68.773,219,10.9,1.944,4207.814,301096,5055,0
0.02625,191.2,216,104,58.8,50,34.3865,68.773,219,4.5,1.944,4207.814,301096,5055,0
0.026377315,191.8,218,104,58.8,50,34.3865,68.773,222,9,1.944,4207.814,301096,5055,0
0.02650463,192.5,220,104,58.8,50,33.7497,67.4994,222,5.1,1.908,4129.891,301096,5054,0
0.026631944,193.2,221,101,58.8,50,33.7497,67.4994,222,6.4,1.908,4129.891,301096,5054,0
0.026759259,193.7,221,101,58.8,50,33.7497,67.4994,222,6.4,1.908,4129.891,301096,5054,0
0.026886574,194.5,222,104,58.8,50,33.7497,67.4994,222,5.1,1.908,4129.891,301096,5054,0
0.027013889,195.2,222,101,58.8,50,33.7497,67.4994,221,3.9,1.908,4129.891,301096,5054,0
0.027141204,195.7,222,104,58.8,50,33.7497,67.4994,221,5.4,1.908,4129.891,301096,5054,0
0.027268519,196.4,222,104,58.8,50,33.7497,67.4994,221,4.3,1.908,4129.891,301096,5054,0
0.027395833,197.2,222,104,58.8,50,33.1129,66.2258,221,4,1.872,4051.969,301096,5053,0
0.027523148,197.7,222,104,58.8,50,33.1129,66.2258,221,4.9,1.872,4051.969,301096,5053,0
0.027650463,198.4,222,104,58.8,50,33.1129,66.2258,221,4.5,1.872,4051.969,301096,5053,0
0.027777778,199.1,222,104,58.8,50,33.1129,66.2258,221,4,1.872,4051.969,301096,5053,0
0.027905093,199.7,221,104,58.8,50,33.1129,66.2258,220,3.5,1.872,4051.969,301096,5053,0
0.028032407,200.2,221,104,58.8,50,33.1129,66.2258,220,4,1.872,4051.969,301096,5053,0
0.028159722,200.8,221,104,58.8,50,33.1129,66.2258,220,4,1.872,4051.969,301096,5053,0
0.028287037,201.3,221,101,58.8,50,33.1129,66.2258,220,3.6,1.872,4051.969,301096,5053,0
0.028414352,201.9,221,104,58.8,50,33.1129,66.2258,220,3.4,1.872,4051.969,301096,5053,0
0.028541667,202.6,221,104,58.8,50,33.1129,66.2258,220,3.6,1.872,4051.969,301096,5053,0
0.028668981,202.8,221,104,58.8,50,33.1129,66.2258,219,2.1,1.872,4051.969,301096,5053,0
0.028796296,203.5,220,104,58.8,50,33.1129,66.2258,219,2.7,1.872,4051.969,301096,5053,0
0.028923611,203.8,220,104,58.8,50,33.1129,66.2258,219,3.5,1.872,4051.969,301096,5053,0
0.029050926,204.4,220,104,58.8,50,33.1129,66.2258,219,3.6,1.872,4051.969,301096,5053,0
0.029178241,204.7,220,104,58.8,50,33.1129,66.2258,219,3.1,1.872,4051.969,301096,5053,0
0.029305556,205.3,220,101,58.8,50,32.4761,64.9522,219,3.2,1.836,3974.047,301096,5052,0
0.02943287,205.5,219,101,58.8,50,32.4761,64.9522,219,3.5,1.836,3974.047,301096,5052,0
0.029560185,205.8,219,101,58.8,50,32.4761,64.9522,218,1.6,1.836,3974.047,301096,5052,0
0.0296875,206.4,219,104,58.8,50,32.4761,64.9522,218,2.8,1.836,3974.047,301096,5052,0
0.029814815,206.7,219,104,58.8,50,32.4761,64.9522,218,3.1,1.836,3974.047,301096,5052,0
0.02994213,207.1,219,104,117.61,100,34.3865,34.3865,218,2.6,1.944,4207.814,301096,5055,0
0.030069444,207.3,218,101,117.61,100,35.0233,35.0233,218,2.8,1.98,4285.736,301096,5056,0
0.030196759,207.6,218,104,117.61,100,35.0233,35.0233,218,3,1.98,4285.736,301096,5056,0
0.030324074,208.2,218,101,117.61,100,35.0233,35.0233,218,3.4,1.98,4285.736,301096,5056,0
0.030462963,208.4,218,104,117.61,100,35.0233,35.0233,218,3.1,1.98,4285.736,301096,5056,0
0.030590278,208.7,218,101,117.61,100,35.0233,35.0233,218,3.5,1.98,4285.736,301096,5056,0
0.030717593,208.9,218,101,88.2,75,33.7497,44.9996,218,2.8,1.908,4129.891,301096,5054,0
0.030844907,209.1,218,104,88.2,75,33.7497,44.9996,218,3.1,1.908,4129.891,301096,5054,0
0.030972222,209.4,218,101,88.2,75,33.7497,44.9996,218,2.8,1.908,4129.891,301096,5054,0
0.031111111,209.6,218,104,88.2,75,33.7497,44.9996,218,2.7,1.908,4129.891,301096,5054,0
0.03125,209.8,218,104,88.2,75,33.7497,44.9996,218,3,1.908,4129.891,301096,5054,0
0.031377315,210.2,218,104,58.8,50,32.4761,64.9522,218,3,1.836,3974.047,301096,5052,0
0.03150463,210.3,218,104,58.8,50,31.8393,63.6787,218,3.1,1.8,3896.124,301096,5051,0
0.031631944,210.5,218,104,58.8,50,31.8393,63.6787,218,2.9,1.8,3896.124,301096,5051,0
0.031759259,210.7,218,104,58.8,50,31.8393,63.6787,218,3.1,1.8,3896.124,301096,5051,0
0.031886574,210.9,218,104,58.8,50,31.8393,63.6787,218,3.1,1.8,3896.124,301096,5051,0
0.032013889,210.9,218,104,29.4,25,31.8393,63.6787,218,3,1.8,3896.124,301096,5051,0
0.032141204,211.2,218,101,29.4,25,28.6554,114.6216,218,2.9,1.62,3506.513,301096,5046,0
0.032268519,211.2,218,104,29.4,25,28.0186,112.0745,218,2.8,1.584,3428.591,301096,5045,0
0.032395833,211.4,218,104,29.4,25,28.0186,112.0745,218,2.7,1.584,3428.591,301096,5045,0
0.032523148,211.6,218,104,29.4,25,28.0186,112.0745,218,2.8,1.584,3428.591,301096,5045,0
0.032650463,211.8,218,104,29.4,25,27.3818,109.5274,218,2.9,1.548,3350.668,301096,5044,0
0.032777778,212,218,104,58.8,50,28.0186,56.0373,218,2.7,1.584,3428.591,301096,5045,0
0.032905093,212.1,218,104,58.8,50,28.0186,56.0373,217,1.7,1.584,3428.591,301096,5045,0
0.033032407,212.1,218,104,58.8,50,28.0186,56.0373,216,0.8,1.584,3428.591,301096,5045,0
0.033159722,212.3,217,104,58.8,50,28.0186,56.0373,215,0,1.584,3428.591,301096,5045,0
0.033287037,212.5,217,101,58.8,50,28.0186,56.0373,214,0,1.584,3428.591,301096,5045,0
0.033414352,212.7,216,104,58.8,50,28.0186,56.0373,213,0,1.584,3428.591,301096,5045,0
0.033541667,212.7,215,104,88.2,75,29.2922,39.0563,213,1.1,1.656,3584.435,301096,5047,0
0.033668981,212.7,214,104,88.2,75,29.2922,39.0563,213,1.2,1.656,3584.435,301096,5047,0
0.033796296,212.9,214,101,88.2,75,29.2922,39.0563,212,0,1.656,3584.435,301096,5047,0
0.033923611,213,213,104,88.2,75,29.2922,39.0563,212,0.7,1.656,3584.435,301096,5047,0
0.034050926,213,213,104,88.2,75,29.2922,39.0563,212,1.5,1.656,3584.435,301096,5047,0
0.034189815,213,213,104,117.61,100,31.8393,31.8393,218,4.8,1.8,3896.124,301096,5051,0
0.03431713,213,214,104,117.61,100,32.4761,32.4761,233,28.4,1.836,3974.047,301096,5052,0
0.034444444,213,222,104,117.61,100,32.4761,32.4761,252,32.6,1.836,3974.047,301096,5052,0
0.034571759,212.9,232,104,117.61,100,32.4761,32.4761,271,42.8,1.836,3974.047,301096,5052,0
0.034699074,212.9,243,104,117.61,100,32.4761,32.4761,286,48.1,1.836,3974.047,301096,5052,0
0.034826389,213,258,104,117.61,100,31.8393,31.8393,305,53.1,1.8,3896.124,301096,5051,0
0.034953704,213.4,272,104,58.8,50,28.0186,56.0373,308,37.2,1.584,3428.591,301096,5045,0
0.035092593,213.8,283,101,58.8,50,26.7451,53.4901,308,30.9,1.512,3272.746,301096,5043,0
0.035393519,216.1,299,104,58.8,50,25.4715,50.943,308,24.4,1.44,3116.901,301096,5041,0
0.035520833,217.6,303,101,58.8,50,25.4715,50.943,320,36.9,1.44,3116.901,301096,5041,0
0.035648148,219,310,104,58.8,50,25.4715,50.943,320,23,1.44,3116.901,301096,5041,0
0.035775463,220.8,315,104,58.8,50,25.4715,50.943,320,22.7,1.44,3116.901,301096,5041,0
0.035902778,222.8,318,104,58.8,50,24.8347,49.6694,320,22.2,1.404,3038.979,301096,5040,0
0.036030093,224.8,320,104,58.8,50,24.8347,49.6694,320,19.4,1.404,3038.979,301096,5040,0
0.036157407,226.8,322,104,58.8,50,24.8347,49.6694,320,17.9,1.404,3038.979,301096,5040,0
0.036284722,228.9,323,104,58.8,50,24.8347,49.6694,320,16.9,1.404,3038.979,301096,5040,0
0.036412037,230.9,324,104,58.8,50,24.8347,49.6694,320,15.7,1.404,3038.979,301096,5040,0
0.036539352,232.9,324,104,58.8,50,24.1979,48.3958,320,14.7,1.368,2961.057,301096,5039,0
0.036666667,235.2,325,104,58.8,50,24.1979,48.3958,320,13.8,1.368,2961.057,301096,5039,0
0.036793981,237,325,104,58.8,50,24.1979,48.3958,320,13.8,1.368,2961.057,301096,5039,0
0.036921296,239.2,325,104,58.8,50,24.1979,48.3958,320,12.4,1.368,2961.057,301096,5039,0
0.037048611,241.5,325,104,58.8,50,24.1979,48.3958,320,12.4,1.368,2961.057,301096,5039,0
0.037175926,243.4,325,104,58.8,50,24.1979,48.3958,320,11.4,1.368,2961.057,301096,5039,0
0.037314815,245.5,324,104,58.8,50,24.1979,48.3958,320,11.6,1.368,2961.057,301096,5039,0
0.03744213,247.5,324,111,58.8,50,24.1979,48.3958,320,11.3,1.368,2961.057,301096,5039,0
0.037569444,249.7,324,104,58.8,50,23.5611,47.1223,320,10.6,1.332,2883.135,301096,5038,0
0.037696759,251.5,324,101,58.8,50,23.5611,47.1223,320,10.7,1.332,2883.135,301096,5038,0
0.037824074,253.1,323,104,58.8,50,23.5611,47.1223,320,10.7,1.332,2883.135,301096,5038,0
0.037951389,255.3,323,104,58.8,50,23.5611,47.1223,320,9.7,1.332,2883.135,301096,5038,0
0.038078704,256.9,323,104,58.8,50,23.5611,47.1223,320,9.8,1.332,2883.135,301096,5038,0
0.038206019,258.5,323,104,58.8,50,23.5611,47.1223,320,9.9,1.332,2883.135,301096,5038,0
0.038333333,260.3,323,104,58.8,50,23.5611,47.1223,320,9.5,1.332,2883.135,301096,5038,0
0.038460648,261.9,322,104,58.8,50,23.5611,47.1223,320,9.2,1.332,2883.135,301096,5038,0
0.038587963,263.6,322,111,58.8,50,23.5611,47.1223,320,9.1,1.332,2883.135,301096,5038,0
0.038715278,265.2,322,111,58.8,50,23.5611,47.1223,320,9.1,1.332,2883.135,301096,5038,0
0.038842593,266.6,322,111,58.8,50,23.5611,47.1223,320,8.6,1.332,2883.135,301096,5038,0
0.038969907,268.2,322,104,58.8,50,23.5611,47.1223,320,8.9,1.332,2883.135,301096,5038,0
0.039097222,269.7,322,104,58.8,50,23.5611,47.1223,320,8.5,1.332,2883.135,301096,5038,0
0.039224537,271.1,322,104,58.8,50,22.9244,45.8487,320,8.4,1.296,2805.212,301096,5037,0
0.039351852,272.6,321,104,58.8,50,22.9244,45.8487,320,8.4,1.296,2805.212,301096,5037,0
0.039479167,274,321,101,58.8,50,22.9244,45.8487,320,8.3,1.296,2805.212,301096,5037,0
0.039606481,275.3,321,101,58.8,50,22.9244,45.8487,320,8,1.296,2805.212,301096,5037,0
0.039733796,276.4,321,101,58.8,50,22.9244,45.8487,320,7.8,1.296,2805.212,301096,5037,0
0.039861111,277.8,321,101,58.8,50,22.9244,45.8487,320,7.8,1.296,2805.212,301096,5037,0
0.039988426,278.9,321,101,58.8,50,22.9244,45.8487,320,7.6,1.296,2805.212,301096,5037,0
0.040115741,280.2,321,101,58.8,50,22.9244,45.8487,320,7.4,1.296,2805.212,301096,5037,0
0.040243056,281.2,321,104,58.8,50,22.9244,45.8487,320,7.8,1.296,2805.212,301096,5037,0
0.04037037,282.5,321,104,58.8,50,22.9244,45.8487,320,7.8,1.296,2805.212,301096,5037,0
0.040497685,283.4,321,101,58.8,50,22.9244,45.8487,320,7.2,1.296,2805.212,301096,5037,0
0.040625,284.7,321,101,58.8,50,22.9244,45.8487,320,7.4,1.296,2805.212,301096,5037,0
0.040752315,285.6,321,104,58.8,50,22.9244,45.8487,320,7.3,1.296,2805.212,301096,5037,0
0.04087963,286.5,321,104,58.8,50,22.9244,45.8487,320,7.5,1.296,2805.212,301096,5037,0
0.041006944,287.6,321,104,58.8,50,22.9244,45.8487,320,7.4,1.296,2805.212,301096,5037,0
0.041134259,288.5,321,104,58.8,50,22.9244,45.8487,320,7.1,1.296,2805.212,301096,5037,0
0.041261574,289.4,321,101,58.8,50,22.9244,45.8487,320,7.2,1.296,2805.212,301096,5037,0
0.041412037,290.3,321,101,58.8,50,22.2876,44.5751,320,7.1,1.26,2727.29,301096,5036,0
0.041666667,292.1,321,104,58.8,50,22.2876,44.5751,320,6.6,1.26,2727.29,301096,5036,0
0.041793981,293,320,101,58.8,50,22.2876,44.5751,320,6.9,1.26,2727.29,301096,5036,0
0.04193287,293.7,320,104,58.8,50,21.014,42.028,320,6.8,1.188,2571.445,301096,5034,0
0.042071759,294.6,320,101,58.8,50,21.014,42.028,320,6.5,1.188,2571.445,301096,5034,0
0.042407407,296.4,320,101,58.8,50,21.014,42.028,316,0,1.188,2571.445,301096,5034,0
0.042534722,296.9,319,104,58.8,50,21.014,42.028,316,4.6,1.188,2571.445,301096,5034,0
0.042673611,297.7,318,104,58.8,50,21.014,42.028,316,5.2,1.188,2571.445,301096,5034,0
0.042951389,298.4,318,104,58.8,50,21.014,42.028,316,4,1.188,2571.445,301096,5034,0
0.043090278,299.5,317,101,58.8,50,21.014,42.028,315,3.8,1.188,2571.445,301096,5034,0
0.043229167,300.2,316,101,58.8,50,20.3772,40.7544,315,4.9,1.152,2493.523,301096,5033,0
0.043368056,300.5,316,101,58.8,50,20.3772,40.7544,315,4.9,1.152,2493.523,301096,5033,0
0.043530093,301.1,316,104,58.8,50,20.3772,40.7544,315,4.6,1.152,2493.523,301096,5033,0
0.043668981,301.6,315,104,58.8,50,20.3772,40.7544,315,5.3,1.152,2493.523,301096,5033,0
0.04380787,302.2,315,101,58.8,50,19.7404,39.4808,315,4.8,1.116,2415.601,301096,5032,0
0.043958333,302.5,315,104,117.61,100,21.014,21.014,315,5.4,1.188,2571.445,301096,5034,0
0.044097222,302.9,315,111,117.61,100,20.3772,20.3772,314,4.1,1.152,2493.523,301096,5033,0
0.044282407,303.4,315,111,117.61,100,20.3772,20.3772,313,3.5,1.152,2493.523,301096,5033,0
0.044421296,303.8,314,111,117.61,100,20.3772,20.3772,311,1.6,1.152,2493.523,301096,5033,0
0.044571759,304.1,313,111,117.61,100,20.3772,20.3772,310,1.8,1.152,2493.523,301096,5033,0
0.044814815,304.7,311,111,88.2,75,20.3772,27.1696,309,2.2,1.152,2493.523,301096,5033,0
0.04494213,304.9,311,111,88.2,75,20.3772,27.1696,309,3.1,1.152,2493.523,301096,5033,0
0.045069444,305.1,310,111,88.2,75,20.3772,27.1696,309,3.8,1.152,2493.523,301096,5033,0
0.045196759,305.2,310,111,88.2,75,19.7404,26.3206,308,2.5,1.116,2415.601,301096,5032,0
0.045324074,305.4,309,104,58.8,50,19.7404,39.4808,308,3.2,1.116,2415.601,301096,5032,0
0.045451389,305.4,309,111,58.8,50,19.7404,39.4808,308,3.5,1.116,2415.601,301096,5032,0
0.045590278,305.4,308,111,58.8,50,19.7404,39.4808,308,3.5,1.116,2415.601,301096,5032,0
0.045717593,305.6,308,111,58.8,50,19.7404,39.4808,308,3.6,1.116,2415.601,301096,5032,0
0.045844907,305.6,308,111,58.8,50,19.7404,39.4808,308,3.9,1.116,2415.601,301096,5032,0
0.04599537,305.6,308,111,29.4,25,19.7404,78.9617,308,3.9,1.116,2415.601,301096,5032,0
0.046122685,305.6,308,111,29.4,25,19.7404,78.9617,307,2.6,1.116,2415.601,301096,5032,0
0.04625,305.6,307,111,29.4,25,19.1036,76.4145,306,2.1,1.08,2337.678,301096,5031,0
0.046377315,305.6,307,104,29.4,25,19.1036,76.4145,305,1.7,1.08,2337.678,301096,5031,0
0.04650463,306,306,111,29.4,25,19.1036,76.4145,304,1.2,1.08,2337.678,301096,5031,0
0.046631944,306,306,111,29.4,25,19.1036,76.4145,303,0.3,1.08,2337.678,301096,5031,0
0.046759259,306,305,111,58.8,50,19.1036,38.2073,303,2.4,1.08,2337.678,301096,5031,0
0.046886574,306,304,111,58.8,50,19.1036,38.2073,303,3.4,1.08,2337.678,301096,5031,0
0.047013889,306,304,111,58.8,50,19.1036,38.2073,302,0.8,1.08,2337.678,301096,5031,0
0.047141204,305.6,303,111,58.8,50,19.1036,38.2073,302,2.1,1.08,2337.678,301096,5031,0
0.047268519,305.6,303,111,58.8,50,19.1036,38.2073,302,3,1.08,2337.678,301096,5031,0
0.047395833,305.6,302,111,88.2,75,19.7404,26.3206,302,2.6,1.116,2415.601,301096,5032,0
0.047523148,305.4,302,111,88.2,75,19.7404,26.3206,302,3.1,1.116,2415.601,301096,5032,0
0.047650463,305.2,302,111,88.2,75,19.7404,26.3206,302,3.1,1.116,2415.601,301096,5032,0
0.047777778,305.1,302,111,88.2,75,19.7404,26.3206,303,4.8,1.116,2415.601,301096,5032,0
0.047905093,304.7,302,111,88.2,75,19.7404,26.3206,303,3.5,1.116,2415.601,301096,5032,0
0.048032407,304.7,302,111,88.2,75,19.7404,26.3206,303,3.8,1.116,2415.601,301096,5032,0
0.048159722,304.5,303,111,117.61,100,19.7404,19.7404,321,33,1.116,2415.601,301096,5032,0
0.048287037,304.3,307,111,117.61,100,19.7404,19.7404,338,42.4,1.116,2415.601,301096,5032,0
0.048414352,304.1,319,111,117.61,100,19.7404,19.7404,362,50.9,1.116,2415.601,301096,5032,0
0.048541667,304,332,111,117.61,100,19.7404,19.7404,385,62.8,1.116,2415.601,301096,5032,0
0.048668981,303.8,347,111,117.61,100,19.7404,19.7404,403,67.5,1.116,2415.601,301096,5032,0
0.048796296,304.1,365,111,58.8,50,19.7404,39.4808,420,64.6,1.116,2415.601,301096,5032,0
0.048923611,304.7,381,111,58.8,50,19.1036,38.2073,420,45.1,1.08,2337.678,301096,5031,0
0.049050926,305.4,392,111,58.8,50,19.1036,38.2073,420,41.7,1.08,2337.678,301096,5031,0
0.049178241,306.5,401,111,58.8,50,19.1036,38.2073,419,39.3,1.08,2337.678,301096,5031,0
0.049305556,307.9,407,111,58.8,50,19.1036,38.2073,419,34.7,1.08,2337.678,301096,5031,0
0.04943287,309.4,411,111,58.8,50,19.1036,38.2073,419,30.9,1.08,2337.678,301096,5031,0
0.049560185,311,416,111,58.8,50,19.1036,38.2073,419,28.2,1.08,2337.678,301096,5031,0
0.0496875,312.8,419,104,58.8,50,19.1036,38.2073,419,25.7,1.08,2337.678,301096,5031,0
0.049814815,314.8,421,111,58.8,50,19.1036,38.2073,418,21.9,1.08,2337.678,301096,5031,0
0.04994213,316.4,422,104,58.8,50,19.1036,38.2073,418,21.5,1.08,2337.678,301096,5031,0
0.050069444,318.8,423,111,58.8,50,19.1036,38.2073,418,20.8,1.08,2337.678,301096,5031,0
0.050196759,320.7,424,111,58.8,50,19.1036,38.2073,418,19.8,1.08,2337.678,301096,5031,0
0.050324074,322.6,424,104,58.8,50,19.1036,38.2073,418,18.3,1.08,2337.678,301096,5031,0
0.050451389,324.9,424,111,58.8,50,19.1036,38.2073,418,17.4,1.08,2337.678,301096,5031,0
0.050578704,326.9,424,111,58.8,50,19.1036,38.2073,417,15.7,1.08,2337.678,301096,5031,0
0.050706019,328.9,424,111,58.8,50,19.1036,38.2073,417,15.9,1.08,2337.678,301096,5031,0
0.050833333,331.6,423,111,58.8,50,19.1036,38.2073,417,15.6,1.08,2337.678,301096,5031,0
0.050960648,333.6,423,114,58.8,50,19.1036,38.2073,417,15.3,1.08,2337.678,301096,5031,0
0.051087963,335.9,422,111,58.8,50,19.1036,38.2073,417,14.8,1.08,2337.678,301096,5031,0
0.051215278,338.4,422,114,58.8,50,19.1036,38.2073,416,12.5,1.08,2337.678,301096,5031,0
0.051342593,340.6,422,111,58.8,50,19.1036,38.2073,416,12.8,1.08,2337.678,301096,5031,0
0.051481481,342.8,421,111,58.8,50,19.1036,38.2073,416,13.3,1.08,2337.678,301096,5031,0
0.051608796,345.3,421,111,58.8,50,19.1036,38.2073,416,12.4,1.08,2337.678,301096,5031,0
0.051736111,347.3,420,114,58.8,50,19.1036,38.2073,416,12.5,1.08,2337.678,301096,5031,0
0.051863426,349.3,420,114,58.8,50,19.1036,38.2073,416,12,1.08,2337.678,301096,5031,0
0.051990741,351.4,419,114,58.8,50,18.4669,36.9337,415,10.9,1.044,2259.756,301096,5030,0
0.052118056,353.2,419,111,58.8,50,18.4669,36.9337,415,11.6,1.044,2259.756,301096,5030,0
0.05224537,355,418,114,58.8,50,18.4669,36.9337,415,10.8,1.044,2259.756,301096,5030,0
0.052372685,356.8,418,114,58.8,50,18.4669,36.9337,415,10.9,1.044,2259.756,301096,5030,0
0.0525,358.6,418,111,58.8,50,18.4669,36.9337,415,10.8,1.044,2259.756,301096,5030,0
0.052627315,360.1,417,111,58.8,50,18.4669,36.9337,414,9.3,1.044,2259.756,301096,5030,0
0.05275463,361.7,417,114,58.8,50,18.4669,36.9337,414,10.1,1.044,2259.756,301096,5030,0
0.052881944,363.1,417,114,58.8,50,18.4669,36.9337,414,10.5,1.044,2259.756,301096,5030,0
0.053009259,364.6,416,114,58.8,50,18.4669,36.9337,414,9.8,1.044,2259.756,301096,5030,0
0.053136574,366.9,416,114,58.8,50,18.4669,36.9337,414,10.4,1.044,2259.756,301096,5030,0
0.053263889,368.2,416,114,58.8,50,18.4669,36.9337,414,10.1,1.044,2259.756,301096,5030,0
0.053391204,369.5,415,114,58.8,50,18.4669,36.9337,413,9.2,1.044,2259.756,301096,5030,0
0.053518519,370.9,415,114,58.8,50,18.4669,36.9337,413,9.8,1.044,2259.756,301096,5030,0
0.053645833,372.2,415,114,58.8,50,18.4669,36.9337,413,9.8,1.044,2259.756,301096,5030,0
0.053773148,373.2,414,114,58.8,50,18.4669,36.9337,413,9.3,1.044,2259.756,301096,5030,0
0.053900463,374.5,414,114,58.8,50,18.4669,36.9337,413,9.6,1.044,2259.756,301096,5030,0
0.054027778,375.6,414,111,58.8,50,18.4669,36.9337,412,7.9,1.044,2259.756,301096,5030,0
0.054155093,376.7,414,114,58.8,50,18.4669,36.9337,412,8.9,1.044,2259.756,301096,5030,0
0.054282407,377.8,413,114,58.8,50,18.4669,36.9337,412,9.1,1.044,2259.756,301096,5030,0
0.054409722,378.7,413,114,58.8,50,18.4669,36.9337,412,8.6,1.044,2259.756,301096,5030,0
0.054537037,379.4,413,114,58.8,50,18.4669,36.9337,412,8.9,1.044,2259.756,301096,5030,0
0.054664352,380.5,413,114,58.8,50,18.4669,36.9337,411,7.1,1.044,2259.756,301096,5030,0
0.054791667,381.2,413,114,58.8,50,17.8301,35.6601,411,7.8,1.008,2181.834,301096,5029,0
0.054918981,381.9,412,111,58.8,50,17.8301,35.6601,411,9.1,1.008,2181.834,301096,5029,0
0.055046296,382.8,412,114,58.8,50,17.8301,35.6601,411,8.3,1.008,2181.834,301096,5029,0
0.055173611,383.5,412,114,58.8,50,17.8301,35.6601,411,8.3,1.008,2181.834,301096,5029,0
0.055300926,384.3,412,114,58.8,50,17.1933,34.3866,411,8.7,0.972,2103.912,301096,5028,0
0.055428241,385,411,114,58.8,50,17.1933,34.3866,410,7,0.972,2103.912,301096,5028,0
0.055555556,385.7,411,114,58.8,50,17.1933,34.3866,410,7.8,0.972,2103.912,301096,5028,0
0.05568287,386.2,411,114,58.8,50,17.1933,34.3866,410,8,0.972,2103.912,301096,5028,0
0.055810185,387,411,114,117.61,100,17.8301,17.8301,408,4.9,1.008,2181.834,301096,5029,0
0.0559375,387.7,410,111,117.61,100,17.8301,17.8301,407,4.7,1.008,2181.834,301096,5029,0
0.056064815,388.2,409,111,117.61,100,17.8301,17.8301,405,4.6,1.008,2181.834,301096,5029,0
0.05619213,388.8,408,111,117.61,100,17.8301,17.8301,403,3.3,1.008,2181.834,301096,5029,0
0.056319444,389.3,406,111,117.61,100,17.8301,17.8301,401,2.2,1.008,2181.834,301096,5029,0
0.056446759,389.8,405,104,88.2,75,17.8301,23.7734,400,3.3,1.008,2181.834,301096,5029,0
0.056574074,390.2,403,104,88.2,75,17.1933,22.9244,399,2.9,0.972,2103.912,301096,5028,0
0.056701389,390.4,402,111,88.2,75,17.1933,22.9244,398,2.5,0.972,2103.912,301096,5028,0
0.056828704,390.7,401,104,88.2,75,17.1933,22.9244,398,4.1,0.972,2103.912,301096,5028,0
0.056956019,391.1,400,111,88.2,75,17.1933,22.9244,397,3.3,0.972,2103.912,301096,5028,0
0.057083333,391.3,399,111,58.8,50,17.1933,22.9244,396,2.4,0.972,2103.912,301096,5028,0
0.057210648,391.6,398,111,58.8,50,17.1933,34.3866,396,4.4,0.972,2103.912,301096,5028,0
0.057337963,391.8,397,111,58.8,50,17.1933,34.3866,396,4.6,0.972,2103.912,301096,5028,0
0.057465278,392,397,104,58.8,50,17.1933,34.3866,395,2.9,0.972,2103.912,301096,5028,0
0.057592593,392.2,396,111,58.8,50,17.1933,34.3866,395,4.4,0.972,2103.912,301096,5028,0
0.057719907,392.2,396,111,58.8,50,17.1933,34.3866,395,5.2,0.972,2103.912,301096,5028,0
0.057847222,392.2,395,111,29.4,25,17.1933,68.7731,395,5.1,0.972,2103.912,301096,5028,0
0.057974537,392.2,395,111,29.4,25,17.1933,68.7731,395,5.1,0.972,2103.912,301096,5028,0
0.058101852,392.4,395,111,29.4,25,17.1933,68.7731,395,5.4,0.972,2103.912,301096,5028,0
0.058229167,392.4,395,111,29.4,25,17.1933,68.7731,394,3.8,0.972,2103.912,301096,5028,0
0.058356481,392.4,394,111,29.4,25,17.1933,68.7731,394,5.5,0.972,2103.912,301096,5028,0
0.058483796,392.4,394,111,29.4,25,17.1933,68.7731,394,5.8,0.972,2103.912,301096,5028,0
0.058611111,392.4,394,111,58.8,50,16.5565,33.113,394,5.6,0.936,2025.99,301096,5027,0
0.05875,392.4,394,111,58.8,50,16.5565,33.113,394,5.9,0.936,2025.99,301096,5027,0
0.058877315,392.2,394,111,58.8,50,16.5565,33.113,393,4.4,0.936,2025.99,301096,5027,0
0.059016204,392,393,111,58.8,50,16.5565,33.113,393,5.1,0.936,2025.99,301096,5027,0
0.059155093,392,393,114,58.8,50,16.5565,33.113,393,5.4,0.936,2025.99,301096,5027,0
0.059282407,391.8,393,111,88.2,75,16.5565,22.0753,393,5.4,0.936,2025.99,301096,5027,0
0.059409722,391.6,393,111,88.2,75,16.5565,22.0753,393,5.3,0.936,2025.99,301096,5027,0
0.059537037,391.3,393,111,88.2,75,16.5565,22.0753,393,6,0.936,2025.99,301096,5027,0
0.059675926,391.1,393,111,88.2,75,16.5565,22.0753,394,6.8,0.936,2025.99,301096,5027,0
0.059814815,390.9,393,111,88.2,75,16.5565,22.0753,394,5.9,0.936,2025.99,301096,5027,0
0.05994213,390.7,393,104,117.61,100,16.5565,16.5565,401,8.7,0.936,2025.99,301096,5027,0
0.060069444,390.6,395,104,117.61,100,16.5565,16.5565,416,37.7,0.936,2025.99,301096,5027,0
0.060196759,390.4,403,111,117.61,100,16.5565,16.5565,437,45.9,0.936,2025.99,301096,5027,0
0.060324074,390.2,413,101,117.61,100,16.5565,16.5565,459,58.9,0.936,2025.99,301096,5027,0
0.060451389,390.2,425,104,117.61,100,16.5565,16.5565,475,62.3,0.936,2025.99,301096,5027,0
0.060578704,390.2,441,101,117.61,100,16.5565,16.5565,496,70,0.936,2025.99,301096,5027,0
0.060706019,390.6,457,101,58.8,50,16.5565,33.113,500,51.9,0.936,2025.99,301096,5027,0
0.060833333,391.1,469,104,58.8,50,16.5565,33.113,500,44,0.936,2025.99,301096,5027,0
0.060960648,392,478,104,58.8,50,16.5565,33.113,500,44.8,0.936,2025.99,301096,5027,0
0.061087963,393.5,484,104,58.8,50,16.5565,33.113,500,40.7,0.936,2025.99,301096,5027,0
0.061215278,395.3,489,111,58.8,50,16.5565,33.113,500,37.1,0.936,2025.99,301096,5027,0
0.061342593,398,494,111,58.8,50,16.5565,33.113,500,34,0.936,2025.99,301096,5027,0
0.061469907,401.4,497,104,58.8,50,16.5565,33.113,500,32.8,0.936,2025.99,301096,5027,0
0.061597222,405,499,111,58.8,50,16.5565,33.113,500,30.1,0.936,2025.99,301096,5027,0
0.061724537,408.8,501,111,58.8,50,8.9151,17.8301,500,28.5,0.504,1090.922,301096,5015,0
0.061863426,413.3,503,111,58.8,50,12.7358,25.4716,500,26.5,0.72,1558.456,301096,5021,0
0.061990741,417.4,504,111,58.8,50,12.7358,25.4716,500,25.8,0.72,1558.456,301096,5021,0
0.062141204,422.3,504,111,58.8,50,12.7358,25.4716,500,24.5,0.72,1558.456,301096,5021,0
0.062523148,435.1,505,114,58.8,50,12.7358,25.4716,490,6.5,0.72,1558.456,301096,5021,0
0.062662037,439.8,501,114,58.8,50,12.7358,25.4716,490,18.2,0.72,1558.456,301096,5021,0
0.062789352,443.8,499,114,58.8,50,12.7358,25.4716,490,16.8,0.72,1558.456,301096,5021,0
0.062916667,447.9,499,114,58.8,50,12.7358,25.4716,490,14,0.72,1558.456,301096,5021,0
0.063043981,451,498,114,58.8,50,12.7358,25.4716,490,15.3,0.72,1558.456,301096,5021,0
0.063171296,453.5,496,114,58.8,50,12.7358,25.4716,490,15.3,0.72,1558.456,301096,5021,0
0.063298611,456.1,496,114,58.8,50,12.099,24.198,490,14.2,0.684,1480.533,301096,5020,0
0.063425926,458,495,114,58.8,50,12.099,24.198,490,15,0.684,1480.533,301096,5020,0
0.063553241,459.7,495,114,58.8,50,12.099,24.198,490,14.4,0.684,1480.533,301096,5020,0
0.063680556,461.3,494,114,58.8,50,12.099,24.198,490,14.3,0.684,1480.533,301096,5020,0
0.06380787,462.6,494,111,58.8,50,12.099,24.198,490,14.1,0.684,1480.533,301096,5020,0
0.063935185,463.5,494,114,58.8,50,12.099,24.198,490,13.9,0.684,1480.533,301096,5020,0
0.0640625,464.5,493,114,58.8,50,11.4622,22.9244,490,13.1,0.648,1402.611,301096,5019,0
0.064189815,465.4,493,114,58.8,50,11.4622,22.9244,490,13.7,0.648,1402.611,301096,5019,0
0.06431713,466.3,493,114,58.8,50,11.4622,22.9244,490,13.4,0.648,1402.611,301096,5019,0
0.064444444,467.1,493,114,58.8,50,11.4622,22.9244,490,12.4,0.648,1402.611,301096,5019,0
0.064571759,467.8,492,114,58.8,50,10.1886,20.3773,490,12.3,0.576,1246.766,301096,5017,0
0.064699074,468.3,492,114,58.8,50,11.4622,22.9244,490,13.2,0.648,1402.611,301096,5019,0
0.064826389,468.9,492,114,58.8,50,11.4622,22.9244,490,12.8,0.648,1402.611,301096,5019,0
0.064953704,469.4,492,114,58.8,50,11.4622,22.9244,490,12.7,0.648,1402.611,301096,5019,0
0.065081019,469.9,492,114,58.8,50,11.4622,22.9244,490,12.9,0.648,1402.611,301096,5019,0
0.065208333,470.5,492,111,58.8,50,11.4622,22.9244,490,12.5,0.648,1402.611,301096,5019,0
0.065335648,470.7,491,114,58.8,50,11.4622,22.9244,490,12.4,0.648,1402.611,301096,5019,0
0.065462963,471,491,114,58.8,50,11.4622,22.9244,490,12.5,0.648,1402.611,301096,5019,0
0.065590278,471.6,491,114,58.8,50,11.4622,22.9244,490,12.4,0.648,1402.611,301096,5019,0
0.065717593,471.9,491,114,58.8,50,11.4622,22.9244,490,12.2,0.648,1402.611,301096,5019,0
0.065844907,472.3,491,114,58.8,50,11.4622,22.9244,490,11.8,0.648,1402.611,301096,5019,0
0.065972222,472.7,491,111,58.8,50,11.4622,22.9244,490,12,0.648,1402.611,301096,5019,0
0.066099537,472.8,491,114,58.8,50,11.4622,22.9244,490,11.8,0.648,1402.611,301096,5019,0
0.066226852,473.2,491,114,58.8,50,11.4622,22.9244,490,11.7,0.648,1402.611,301096,5019,0
0.066354167,473.4,491,114,58.8,50,11.4622,22.9244,490,11.4,0.648,1402.611,301096,5019,0
0.066493056,473.7,491,114,58.8,50,11.4622,22.9244,490,11.3,0.648,1402.611,301096,5019,0
0.06662037,474.1,491,111,58.8,50,11.4622,22.9244,490,11.8,0.648,1402.611,301096,5019,0
0.066747685,474.1,491,111,58.8,50,11.4622,22.9244,490,11.2,0.648,1402.611,301096,5019,0
0.066886574,474.3,491,111,58.8,50,11.4622,22.9244,490,11.4,0.648,1402.611,301096,5019,0
0.067013889,474.6,491,111,58.8,50,11.4622,22.9244,490,11.3,0.648,1402.611,301096,5019,0
0.067141204,475,491,111,58.8,50,11.4622,22.9244,490,11.1,0.648,1402.611,301096,5019,0
0.067268519,475,491,111,58.8,50,11.4622,22.9244,490,11.2,0.648,1402.611,301096,5019,0
0.067395833,475.2,491,111,58.8,50,11.4622,22.9244,490,11.5,0.648,1402.611,301096,5019,0
0.067523148,475.5,491,111,58.8,50,11.4622,22.9244,490,10.3,0.648,1402.611,301096,5019,0
0.067650463,475.5,491,114,117.61,100,11.4622,11.4622,490,11.1,0.648,1402.611,301096,5019,0
0.067777778,476.1,490,114,117.61,100,11.4622,11.4622,490,10.8,0.648,1402.611,301096,5019,0
0.067905093,476.3,491,114,117.61,100,11.4622,11.4622,490,10.8,0.648,1402.611,301096,5019,0
0.068032407,476.4,490,111,117.61,100,11.4622,11.4622,490,10.8,0.648,1402.611,301096,5019,0
0.068159722,476.8,490,114,117.61,100,11.4622,11.4622,490,10.6,0.648,1402.611,301096,5019,0
0.068287037,477,490,111,88.2,75,11.4622,15.283,489,8.8,0.648,1402.611,301096,5019,0
0.068414352,477.2,490,111,88.2,75,11.4622,15.283,487,6.5,0.648,1402.611,301096,5019,0
0.068541667,477.3,489,111,88.2,75,11.4622,15.283,486,7.1,0.648,1402.611,301096,5019,0
0.068668981,477.3,489,111,88.2,75,11.4622,15.283,484,5.7,0.648,1402.611,301096,5019,0
0.068796296,477.7,487,111,88.2,75,11.4622,15.283,482,4.3,0.648,1402.611,301096,5019,0
0.068923611,477.7,486,111,58.8,50,11.4622,22.9244,480,3.6,0.648,1402.611,301096,5019,0
0.0690625,477.7,484,114,58.8,50,11.4622,22.9244,480,5.9,0.648,1402.611,301096,5019,0
0.069189815,477.7,483,114,58.8,50,11.4622,22.9244,480,6.3,0.648,1402.611,301096,5019,0
0.06931713,477.7,482,117,58.8,50,11.4622,22.9244,480,6.2,0.648,1402.611,301096,5019,0
0.069444444,477.5,482,114,58.8,50,11.4622,22.9244,480,7.1,0.648,1402.611,301096,5019,0
0.069571759,477.2,481,117,58.8,50,11.4622,22.9244,480,7.4,0.648,1402.611,301096,5019,0
0.069699074,476.8,481,117,29.4,25,11.4622,45.8489,480,7.5,0.648,1402.611,301096,5019,0
0.069826389,476.4,481,111,29.4,25,10.8254,43.3017,480,7.3,0.612,1324.689,301096,5018,0
0.069953704,476.3,480,114,29.4,25,10.8254,43.3017,480,7.7,0.612,1324.689,301096,5018,0
0.070092593,475.9,480,111,29.4,25,10.8254,43.3017,480,7.9,0.612,1324.689,301096,5018,0
0.070219907,475.7,480,114,29.4,25,10.8254,43.3017,480,7.8,0.612,1324.689,301096,5018,0
0.070347222,475.4,480,111,58.8,50,10.8254,21.6509,480,8.2,0.612,1324.689,301096,5018,0
0.070474537,475.2,480,114,58.8,50,11.4622,22.9244,480,8.3,0.648,1402.611,301096,5019,0
0.070613426,475,480,111,58.8,50,11.4622,22.9244,480,8,0.648,1402.611,301096,5019,0
0.070740741,474.6,480,111,58.8,50,11.4622,22.9244,480,8,0.648,1402.611,301096,5019,0
0.070868056,474.3,480,111,58.8,50,11.4622,22.9244,480,8.1,0.648,1402.611,301096,5019,0
0.07099537,474.1,480,111,58.8,50,11.4622,22.9244,480,8.8,0.648,1402.611,301096,5019,0
0.071134259,473.7,480,111,88.2,75,11.4622,15.283,480,8.1,0.648,1402.611,301096,5019,0
0.071273148,473.6,480,114,88.2,75,11.4622,15.283,480,8.7,0.648,1402.611,301096,5019,0
0.071400463,473.2,480,114,88.2,75,11.4622,15.283,480,8.5,0.648,1402.611,301096,5019,0
0.071539352,473.2,480,111,88.2,75,11.4622,15.283,480,8.6,0.648,1402.611,301096,5019,0
0.071666667,472.8,480,104,88.2,75,11.4622,15.283,480,8.6,0.648,1402.611,301096,5019,0
0.071805556,472.8,480,111,117.61,100,11.4622,11.4622,480,8.7,0.648,1402.611,301096,5019,0
0.07193287,472.5,480,111,117.61,100,12.099,12.099,480,8.8,0.684,1480.533,301096,5020,0
0.072060185,472.5,480,111,117.61,100,12.099,12.099,480,8.4,0.684,1480.533,301096,5020,0
0.0721875,472.3,480,111,117.61,100,12.099,12.099,480,9,0.684,1480.533,301096,5020,0
0.072314815,472.1,480,111,117.61,100,12.099,12.099,480,8.8,0.684,1480.533,301096,5020,0
0.072384259,472.1,480,111,117.61,100,11.4622,11.4622,480,8.8,0.648,1402.611,301096,5019,0