File: data/hpybf4-AA-cons-T.csv
Elapsed Time,Sample Temp,Heater Temp,Pressure,Rotor Speed,Shear Rate,Shear Stress,Viscosity,Temperature Setpoint,T Output,Bob Deflection,Torque,Motor Temp,Raw Encoder Value,Aux1
(hh:mm:ss),(°F),(°F),(PSIg),(RPM),(1/s),(dyne/cm²),(cP),(°F),(%),(deg.),(dyne-cm),(°C),(cts),
1.16E-05,396.4,345,99,0,0,0.0002,0,32,0,0,0.0238,30,11,0
4.63E-05,395.9,345,99,58.8,50,0.5121,1.0243,410,0,0.036,62.6684,30,12,0
8.10E-05,395.5,345,99,58.8,50,0.5121,1.0243,410,70,0.036,62.6684,30,12,0
0.000115741,395.5,345,99,58.8,50,0.5121,1.0243,410,70,0.036,62.6684,30,12,0
0.000150463,395.4,346,99,58.8,50,0.5121,1.0243,409,70,0.036,62.6684,30,12,0
0.000185185,395.2,346,99,58.8,50,0.5121,1.0243,409,70,0.036,62.6684,30,12,0
0.000231481,395,346,99,58.8,50,0.5121,1.0243,409,70,0.036,62.6684,30,12,0
0.000266204,394.5,346,99,58.8,50,0.5121,1.0243,409,70,0.036,62.6684,30,12,0
0.000300926,394.1,346,99,58.8,50,0.5121,1.0243,409,70,0.036,62.6684,30,12,0
0.000335648,393.4,346,99,58.8,50,0.5121,1.0243,408,70,0.036,62.6684,30,12,0
0.00037037,392.8,346,99,58.8,50,0.5121,1.0243,408,70,0.036,62.6684,30,12,0
0.000405093,391.9,346,96,58.8,50,0.5121,1.0243,408,70,0.036,62.6684,30,12,0
0.000439815,391.4,346,99,58.8,50,0.5121,1.0243,408,70,0.036,62.6684,30,12,0
0.000474537,390.5,346,99,58.8,50,0.5121,1.0243,408,70,0.036,62.6684,30,12,0
0.000520833,389.6,346,99,58.8,50,0.5121,1.0243,408,70,0.036,62.6684,30,12,0
0.000555556,388.9,346,99,58.8,50,0.5121,1.0243,407,70,0.036,62.6684,30,12,0
0.000590278,388.2,346,99,58.8,50,0.5121,1.0243,407,70,0.036,62.6684,30,12,0
0.000625,387.6,346,99,58.8,50,0.5121,1.0243,407,70,0.036,62.6684,30,12,0
0.000659722,386.9,346,96,58.8,50,0.5121,1.0243,407,70,0.036,62.6684,30,12,0
0.000694444,386.2,346,99,58.8,50,0.5121,1.0243,407,70,0.036,62.6684,30,12,0
0.000740741,385.5,346,99,58.8,50,0.5121,1.0243,406,70,0.036,62.6684,30,12,0
0.000775463,384.9,346,99,58.8,50,0.5121,1.0243,406,70,0.036,62.6684,30,12,0
0.000810185,384.4,346,99,58.8,50,1.0241,2.0481,406,70,0.072,125.3129,30,13,0
0.000844907,384,346,99,58.8,50,0.5121,1.0243,406,70,0.036,62.6684,30,12,0
0.00087963,383.3,346,99,58.8,50,0.5121,1.0243,406,70,0.036,62.6684,30,12,0
0.000914352,383,348,99,58.8,50,0.5121,1.0243,405,70,0.036,62.6684,30,12,0
0.000949074,382.6,352,99,58.8,50,0.5121,1.0243,405,70,0.036,62.6684,30,12,0
0.000983796,382.1,357,99,58.8,50,0.5121,1.0243,405,70,0.036,62.6684,30,12,0
0.001018519,381.5,362,99,58.8,50,0.5121,1.0243,405,70,0.036,62.6684,30,12,0
0.001064815,381.2,367,99,58.8,50,0.5121,1.0243,405,70,0.036,62.6684,30,12,0
0.001099537,380.8,373,99,58.8,50,0.5121,1.0243,405,70,0.036,62.6684,30,12,0
0.001134259,380.4,378,99,58.8,50,0.5121,1.0243,404,70,0.036,62.6684,30,12,0
0.001168981,379.9,384,99,58.8,50,1.0241,2.0481,404,70,0.072,125.3129,30,13,0
0.001203704,379.7,390,99,58.8,50,0.5121,1.0243,404,70,0.036,62.6684,30,12,0
0.00125,379.4,396,99,58.8,50,0.5121,1.0243,404,70,0.036,62.6684,30,12,0
0.001284722,378.8,403,99,58.8,50,0.5121,1.0243,404,70,0.036,62.6684,30,12,0
0.001331019,378.5,410,99,58.8,50,0.5121,1.0243,403,68.6,0.036,62.6684,30,12,0
0.001365741,378.5,415,99,58.8,50,0.5121,1.0243,403,60.1,0.036,62.6684,30,12,0
0.001412037,378.3,419,99,58.8,50,0.5121,1.0243,403,52.7,0.036,62.6684,30,12,0
0.001446759,378.1,424,99,58.8,50,0.5121,1.0243,403,46.7,0.036,62.6684,30,12,0
0.001493056,378.1,429,99,58.8,50,0.5121,1.0243,403,40.7,0.036,62.6684,30,12,0
0.001527778,377.9,434,99,58.8,50,0.5121,1.0243,402,33.6,0.036,62.6684,30,12,0
0.0015625,378.1,438,99,58.8,50,0.5121,1.0243,402,31.3,0.036,62.6684,30,12,0
0.001597222,378.1,441,99,58.8,50,0.5121,1.0243,402,30.5,0.036,62.6684,30,12,0
0.001631944,378.3,442,99,58.8,50,0.5121,1.0243,402,29.7,0.036,62.6684,30,12,0
0.001666667,378.5,444,99,58.8,50,1.0241,2.0481,402,28,0.072,125.3129,30,13,0
0.001701389,378.6,445,99,58.8,50,0.5121,1.0243,401,24.8,0.036,62.6684,30,12,0
0.001736111,379,446,99,58.8,50,0.5121,1.0243,401,23.3,0.036,62.6684,30,12,0
0.001782407,379,448,99,58.8,50,0.5121,1.0243,401,21.5,0.036,62.6684,30,12,0
0.00181713,379.4,448,102,58.8,50,0.5121,1.0243,401,19.7,0.036,62.6684,30,12,0
0.001851852,379.7,449,99,58.8,50,0.5121,1.0243,401,18,0.036,62.6684,30,12,0
0.001886574,380.1,449,99,58.8,50,0.5121,1.0243,400,15.4,0.036,62.6684,30,12,0
0.001921296,380.4,450,99,58.8,50,1.0241,2.0481,400,13.5,0.072,125.3129,30,13,0
0.001956019,380.8,450,102,58.8,50,1.0241,2.0481,400,13.2,0.072,125.3129,30,13,0
0.001990741,381.2,450,99,58.8,50,0.5121,1.0243,400,11.2,0.036,62.6684,30,12,0
0.002025463,381.5,450,99,58.8,50,0.5121,1.0243,400,10.3,0.036,62.6684,30,12,0
0.002060185,381.9,449,99,58.8,50,0.5121,1.0243,400,9.4,0.036,62.6684,30,12,0
0.002094907,382.4,449,99,58.8,50,0.5121,1.0243,399,7,0.036,62.6684,30,12,0
0.00212963,382.8,449,102,58.8,50,0.5121,1.0243,399,6,0.036,62.6684,30,12,0
0.002164352,383.1,448,99,58.8,50,0.5121,1.0243,399,5.2,0.036,62.6684,30,12,0
0.002199074,383.7,448,99,58.8,50,0.5121,1.0243,399,4.8,0.036,62.6684,30,12,0
0.002233796,384,447,99,58.8,50,0.5121,1.0243,399,4.8,0.036,62.6684,30,12,0
0.002268519,384.4,446,99,58.8,50,0.5121,1.0243,398,2.7,0.036,62.6684,30,12,0
0.002303241,384.9,445,99,58.8,50,0.5121,1.0243,398,1.8,0.036,62.6684,30,12,0
0.002337963,385.3,445,102,58.8,50,0.5121,1.0243,398,1.4,0.036,62.6684,30,12,0
0.002372685,385.7,444,99,58.8,50,0.5121,1.0243,398,1.3,0.036,62.6684,30,12,0
0.002418981,386,443,99,58.8,50,0.5121,1.0243,398,1.2,0.036,62.6684,30,12,0
0.002453704,386.6,442,99,58.8,50,0.5121,1.0243,398,1.2,0.036,62.6684,30,12,0
0.002488426,386.9,441,99,58.8,50,0.5121,1.0243,397,0,0.036,62.6684,30,12,0
0.002523148,387.3,440,99,58.8,50,0.5121,1.0243,397,0,0.036,62.6684,30,12,0
0.00255787,387.8,439,99,58.8,50,0.5121,1.0243,397,0,0.036,62.6684,30,12,0
0.002592593,388,438,99,58.8,50,0.5121,1.0243,397,0,0.036,62.6684,30,12,0
0.002627315,388.4,437,99,58.8,50,0.5121,1.0243,397,0,0.036,62.6684,30,12,0
0.002662037,388.9,436,99,58.8,50,0.5121,1.0243,396,0,0.036,62.6684,30,12,0
0.002696759,389.3,435,102,58.8,50,0.5121,1.0243,396,0,0.036,62.6684,30,12,0
0.002731481,389.6,434,99,58.8,50,0.5121,1.0243,396,0,0.036,62.6684,30,12,0
0.002766204,389.8,433,99,58.8,50,0.5121,1.0243,396,0,0.036,62.6684,30,12,0
0.002800926,390.2,432,99,58.8,50,0.5121,1.0243,396,0,0.036,62.6684,30,12,0
0.002847222,390.7,431,99,58.8,50,0.5121,1.0243,396,0,0.036,62.6684,30,12,0
0.002881944,391.1,430,99,58.8,50,0.5121,1.0243,395,0,0.036,62.6684,30,12,0
0.002916667,391.4,429,99,58.8,50,0.5121,1.0243,395,0,0.036,62.6684,30,12,0
0.002951389,391.6,428,99,58.8,50,0.5121,1.0243,395,0,0.036,62.6684,30,12,0
0.002986111,391.9,428,102,58.8,50,0.5121,1.0243,395,0,0.036,62.6684,30,12,0
0.003020833,392.3,427,99,58.8,50,0.5121,1.0243,395,0,0.036,62.6684,30,12,0
0.003055556,392.7,426,99,58.8,50,0.5121,1.0243,394,0,0.036,62.6684,30,12,0
0.003090278,392.8,425,99,58.8,50,0.5121,1.0243,394,0,0.036,62.6684,30,12,0
0.003125,393.2,424,99,58.8,50,0.5121,1.0243,394,0,0.036,62.6684,30,12,0
0.003159722,393.4,424,99,58.8,50,0.5121,1.0243,394,0,0.036,62.6684,30,12,0
0.003194444,393.7,423,99,58.8,50,0.5121,1.0243,394,0,0.036,62.6684,30,12,0
0.003229167,394.1,422,99,58.8,50,0.5121,1.0243,393,0,0.036,62.6684,30,12,0
0.003263889,394.3,421,99,58.8,50,0.5121,1.0243,393,0,0.036,62.6684,30,12,0
0.003298611,394.6,421,99,58.8,50,0.5121,1.0243,393,0,0.036,62.6684,30,12,0
0.003333333,394.8,420,99,58.8,50,0.5121,1.0243,393,0,0.036,62.6684,30,12,0
0.003368056,395.2,419,99,58.8,50,0.5121,1.0243,393,0,0.036,62.6684,30,12,0
0.003402778,395.2,419,99,58.8,50,0.5121,1.0243,393,0,0.036,62.6684,30,12,0
0.0034375,395.5,418,99,58.8,50,0.5121,1.0243,392,0,0.036,62.6684,30,12,0
0.003483796,395.7,417,96,58.8,50,0.5121,1.0243,392,0,0.036,62.6684,30,12,0
0.003518519,395.9,417,99,58.8,50,0.5121,1.0243,392,0,0.036,62.6684,30,12,0
0.003553241,396.1,416,99,58.8,50,0.5121,1.0243,392,0,0.036,62.6684,30,12,0
0.003587963,396.3,415,99,58.8,50,0.5121,1.0243,392,0,0.036,62.6684,30,12,0
0.003622685,396.6,415,99,58.8,50,0.5121,1.0243,392,0,0.036,62.6684,30,12,0
0.003657407,396.6,414,99,58.8,50,0.5121,1.0243,392,0,0.036,62.6684,30,12,0
0.00369213,396.8,413,99,58.8,50,0.5121,1.0243,392,0,0.036,62.6684,30,12,0
0.003726852,397,413,99,58.8,50,0.5121,1.0243,392,0,0.036,62.6684,30,12,0
0.003761574,397.2,412,99,58.8,50,0.5121,1.0243,392,0,0.036,62.6684,30,12,0
0.003796296,397.3,411,99,58.8,50,0.5121,1.0243,392,0,0.036,62.6684,30,12,0
0.003831019,397.3,411,99,58.8,50,0.5121,1.0243,392,0,0.036,62.6684,30,12,0
0.003865741,397.7,410,99,58.8,50,0.5121,1.0243,392,0,0.036,62.6684,30,12,0
0.003900463,397.7,410,99,58.8,50,1.0241,2.0481,392,0,0.072,125.3129,30,13,0
0.003935185,397.9,409,99,58.8,50,0.5121,1.0243,392,0,0.036,62.6684,30,12,0
0.003969907,397.9,408,99,58.8,50,0.5121,1.0243,392,0,0.036,62.6684,30,12,0
0.00400463,398.2,408,99,58.8,50,0.5121,1.0243,392,0,0.036,62.6684,30,12,0
0.004039352,398.2,407,99,58.8,50,0.5121,1.0243,392,0,0.036,62.6684,30,12,0
0.004074074,398.2,407,99,58.8,50,0.5121,1.0243,392,0,0.036,62.6684,30,12,0
0.004108796,398.4,406,99,58.8,50,0.5121,1.0243,392,0,0.036,62.6684,30,12,0
0.004143519,398.6,406,99,58.8,50,0.5121,1.0243,392,0,0.036,62.6684,30,12,0
0.004189815,398.6,405,99,58.8,50,0.5121,1.0243,392,0,0.036,62.6684,30,12,0
0.004224537,398.6,405,99,58.8,50,0.5121,1.0243,392,0,0.036,62.6684,30,12,0
0.004259259,398.8,404,99,58.8,50,0.5121,1.0243,392,0,0.036,62.6684,30,12,0
0.004293981,398.8,404,99,58.8,50,0.5121,1.0243,392,0,0.036,62.6684,30,12,0
0.004328704,398.8,403,99,58.8,50,0.5121,1.0243,392,0,0.036,62.6684,30,12,0
0.004363426,398.8,403,99,58.8,50,0.5121,1.0243,392,0,0.036,62.6684,30,12,0
0.004398148,399,402,99,58.8,50,0.5121,1.0243,392,0,0.036,62.6684,30,12,0
0.00443287,399,402,99,58.8,50,0.5121,1.0243,392,0,0.036,62.6684,30,12,0
0.004467593,399.1,401,99,58.8,50,0.5121,1.0243,392,0,0.036,62.6684,30,12,0
0.004502315,399.1,401,99,58.8,50,0.5121,1.0243,392,0,0.036,62.6684,30,12,0
0.004537037,399.1,400,99,58.8,50,0.5121,1.0243,392,0,0.036,62.6684,30,12,0
0.004571759,399.1,400,99,58.8,50,0.5121,1.0243,392,0,0.036,62.6684,30,12,0
0.004606481,399.1,399,99,58.8,50,0.5121,1.0243,392,0,0.036,62.6684,30,12,0
0.004641204,399.1,399,99,58.8,50,0.5121,1.0243,392,0,0.036,62.6684,30,12,0
0.004675926,399.1,398,99,58.8,50,0.5121,1.0243,392,0.1,0.036,62.6684,30,12,0
0.004710648,399.1,398,99,58.8,50,0.5121,1.0243,392,0.4,0.036,62.6684,30,12,0
0.00474537,399.1,397,99,58.8,50,0.5121,1.0243,392,0.6,0.036,62.6684,30,12,0
0.004780093,399.1,397,99,58.8,50,0.5121,1.0243,392,1.2,0.036,62.6684,30,12,0
0.004814815,399.1,397,99,58.8,50,0.5121,1.0243,392,1.4,0.036,62.6684,30,12,0
0.004849537,399.1,396,99,58.8,50,0.5121,1.0243,392,1.7,0.036,62.6684,30,12,0
0.004895833,399.1,396,96,58.8,50,0.5121,1.0243,392,1.8,0.036,62.6684,30,12,0
0.004930556,399,395,96,58.8,50,0.5121,1.0243,392,2.2,0.036,62.6684,30,12,0
0.004965278,399.1,395,99,58.8,50,0.5121,1.0243,392,2.4,0.036,62.6684,30,12,0
0.005,399,395,99,58.8,50,0.5121,1.0243,392,2.6,0.036,62.6684,30,12,0
0.005034722,399,395,99,58.8,50,0.5121,1.0243,392,2.5,0.036,62.6684,30,12,0
0.005069444,398.8,394,99,58.8,50,0.5121,1.0243,392,2.7,0.036,62.6684,30,12,0
0.005104167,398.8,394,99,58.8,50,0.5121,1.0243,392,2.7,0.036,62.6684,30,12,0
0.005138889,398.8,394,99,58.8,50,0.5121,1.0243,392,3.1,0.036,62.6684,30,12,0
0.005173611,398.8,394,99,58.8,50,0.5121,1.0243,392,2.8,0.036,62.6684,30,12,0
0.005208333,398.6,393,99,58.8,50,0.5121,1.0243,392,2.6,0.036,62.6684,30,12,0
0.005243056,398.6,393,96,58.8,50,0.5121,1.0243,392,3,0.036,62.6684,30,12,0
0.005277778,398.6,393,99,58.8,50,0.5121,1.0243,392,3.6,0.036,62.6684,30,12,0
0.0053125,398.4,393,99,58.8,50,0.5121,1.0243,392,3.7,0.036,62.6684,30,12,0
0.005347222,398.4,393,99,58.8,50,0.5121,1.0243,392,3.8,0.036,62.6684,30,12,0
0.005381944,398.2,393,99,58.8,50,0.5121,1.0243,392,4.1,0.036,62.6684,30,12,0
0.005416667,398.2,392,96,58.8,50,0.5121,1.0243,392,3.9,0.036,62.6684,30,12,0
0.005451389,398.1,392,99,58.8,50,0.5121,1.0243,392,3.7,0.036,62.6684,30,12,0
0.005497685,398.1,392,99,58.8,50,0.5121,1.0243,392,3.4,0.036,62.6684,30,12,0
0.005532407,397.9,392,99,58.8,50,0.5121,1.0243,392,4,0.036,62.6684,30,12,0
0.00556713,397.9,392,99,58.8,50,0.5121,1.0243,392,4,0.036,62.6684,30,12,0
0.005601852,397.9,392,99,58.8,50,0.5121,1.0243,392,4.2,0.036,62.6684,30,12,0
0.005636574,397.7,392,96,58.8,50,0.5121,1.0243,392,4.3,0.036,62.6684,30,12,0
0.005671296,397.7,392,99,58.8,50,0.5121,1.0243,392,4.5,0.036,62.6684,30,12,0
0.005706019,397.5,392,99,58.8,50,0.5121,1.0243,392,4.5,0.036,62.6684,30,12,0
0.005740741,397.5,392,99,58.8,50,0.5121,1.0243,392,4.3,0.036,62.6684,30,12,0
0.005775463,397.3,392,96,58.8,50,1.0241,2.0481,392,4.3,0.072,125.3129,30,13,0
0.005810185,397.3,392,96,58.8,50,0.5121,1.0243,392,4.6,0.036,62.6684,30,12,0
0.005844907,397.2,391,99,58.8,50,0.5121,1.0243,392,4.9,0.036,62.6684,30,12,0
0.00587963,397,391,99,58.8,50,0.5121,1.0243,392,4.6,0.036,62.6684,30,12,0
0.005914352,397,391,99,58.8,50,0.5121,1.0243,392,4.6,0.036,62.6684,30,12,0
0.005949074,397,391,99,58.8,50,0.5121,1.0243,392,4.2,0.036,62.6684,30,12,0
0.005983796,396.8,391,99,58.8,50,0.5121,1.0243,392,4.8,0.036,62.6684,30,12,0
0.006030093,396.8,391,99,58.8,50,0.5121,1.0243,392,4.8,0.036,62.6684,30,12,0
0.006064815,396.6,391,99,58.8,50,0.5121,1.0243,392,4.8,0.036,62.6684,30,12,0
0.006099537,396.6,391,99,58.8,50,0.5121,1.0243,392,4.8,0.036,62.6684,30,12,0
0.006134259,396.4,391,99,58.8,50,0.5121,1.0243,392,4.8,0.036,62.6684,30,12,0
0.006168981,396.3,391,99,58.8,50,0.5121,1.0243,392,5,0.036,62.6684,30,12,0
0.006203704,396.1,391,99,58.8,50,0.5121,1.0243,392,5,0.036,62.6684,30,12,0
0.006238426,396.1,391,99,58.8,50,0.5121,1.0243,392,5,0.036,62.6684,30,12,0
0.006273148,396.1,391,99,58.8,50,0.5121,1.0243,392,5.3,0.036,62.6684,30,12,0
0.00630787,395.9,391,96,58.8,50,0.5121,1.0243,392,5.5,0.036,62.6684,30,12,0
0.006342593,395.7,391,99,58.8,50,0.5121,1.0243,392,5.1,0.036,62.6684,30,12,0
0.006377315,395.7,391,99,58.8,50,0.5121,1.0243,392,4.9,0.036,62.6684,30,12,0
0.006412037,395.5,391,99,58.8,50,0.5121,1.0243,392,5.2,0.036,62.6684,30,12,0
0.006446759,395.5,391,99,58.8,50,0.5121,1.0243,392,5.3,0.036,62.6684,30,12,0
0.006481481,395.4,391,99,58.8,50,0.5121,1.0243,392,5.3,0.036,62.6684,30,12,0
0.006516204,395.4,391,96,58.8,50,0.5121,1.0243,392,5.2,0.036,62.6684,30,12,0
0.006550926,395.2,391,99,58.8,50,0.5121,1.0243,392,5,0.036,62.6684,30,12,0
0.006585648,395.2,391,99,58.8,50,0.5121,1.0243,392,5.4,0.036,62.6684,30,12,0
0.00662037,395,391,99,58.8,50,0.5121,1.0243,392,5.2,0.036,62.6684,30,12,0
0.006655093,395,391,99,58.8,50,0.5121,1.0243,392,5.2,0.036,62.6684,30,12,0
0.006689815,394.8,391,99,58.8,50,0.5121,1.0243,392,5.2,0.036,62.6684,30,12,0
0.006736111,394.8,391,99,58.8,50,0.5121,1.0243,392,5.4,0.036,62.6684,30,12,0
0.006770833,394.6,391,99,58.8,50,0.5121,1.0243,392,5.4,0.036,62.6684,30,12,0
0.006805556,394.6,391,99,58.8,50,0.5121,1.0243,392,5.8,0.036,62.6684,30,12,0
0.006840278,394.6,391,99,58.8,50,0.5121,1.0243,392,5.4,0.036,62.6684,30,12,0
0.006875,394.3,391,99,58.8,50,0.5121,1.0243,392,5.3,0.036,62.6684,30,12,0
0.006909722,394.3,391,99,58.8,50,0.5121,1.0243,392,5.3,0.036,62.6684,30,12,0
0.006944444,394.3,391,99,58.8,50,0.5121,1.0243,392,5.4,0.036,62.6684,30,12,0
0.006979167,394.1,391,99,117.61,100,0.5121,0.5121,392,5.5,0.036,62.6684,30,12,0
0.007013889,394.1,391,99,117.61,100,1.0241,1.0241,392,5.5,0.072,125.3129,30,13,0
0.007048611,394.1,391,96,117.61,100,1.0241,1.0241,392,5.8,0.072,125.3129,30,13,0
0.007083333,393.9,391,96,88.2,75,1.0241,1.0241,392,5.6,0.072,125.3129,30,13,0
0.007118056,393.7,391,99,88.2,75,1.0241,1.3654,392,5.4,0.072,125.3129,30,13,0
0.007152778,393.7,391,99,88.2,75,1.0241,1.3654,392,5.5,0.072,125.3129,30,13,0
0.0071875,393.4,391,96,58.8,50,1.0241,2.0481,392,5.8,0.072,125.3129,30,13,0
0.007222222,393.4,391,99,58.8,50,1.0241,2.0481,392,5.5,0.072,125.3129,30,13,0
0.007256944,393.4,391,99,58.8,50,1.0241,2.0481,392,5.4,0.072,125.3129,30,13,0
0.007291667,393.2,391,99,29.4,25,1.0241,2.0481,392,5.4,0.072,125.3129,30,13,0
0.007326389,393.2,391,99,29.4,25,0.5121,2.0485,392,5.3,0.036,62.6684,30,12,0
0.007361111,393.2,391,99,29.4,25,0.5121,2.0485,392,6.2,0.036,62.6684,30,12,0
0.007395833,393,391,99,58.8,50,0.5121,1.0243,392,5.7,0.036,62.6684,30,12,0
0.007430556,392.8,391,96,58.8,50,0.5121,1.0243,392,5.5,0.036,62.6684,30,12,0
0.007465278,392.8,391,99,58.8,50,0.5121,1.0243,392,5.6,0.036,62.6684,30,12,0
0.0075,392.8,392,96,88.2,75,0.5121,1.0243,392,5.5,0.036,62.6684,30,12,0
0.007534722,392.8,392,99,88.2,75,0.5121,0.6828,392,5.5,0.036,62.6684,30,12,0
0.007569444,392.8,391,99,88.2,75,0.5121,0.6828,392,5.8,0.036,62.6684,30,12,0
0.007615741,392.7,392,99,117.61,100,0.5121,0.5121,392,5.7,0.036,62.6684,30,12,0
0.007650463,392.7,392,99,117.61,100,1.0241,1.0241,392,5.3,0.072,125.3129,30,13,0
0.007685185,392.5,392,99,117.61,100,1.0241,1.0241,392,5.3,0.072,125.3129,30,13,0
0.007719907,392.5,392,99,58.8,50,1.0241,1.0241,392,5.6,0.072,125.3129,30,13,0
0.00775463,392.3,392,99,58.8,50,1.0241,2.0481,392,5.9,0.072,125.3129,30,13,0
0.007789352,392.3,392,99,58.8,50,1.0241,2.0481,392,5.5,0.072,125.3129,30,13,0
0.007824074,392.3,392,99,58.8,50,1.0241,2.0481,392,6,0.072,125.3129,30,13,0
0.007858796,392.1,392,99,58.8,50,1.0241,2.0481,392,5.3,0.072,125.3129,30,13,0
0.007893519,392.5,392,183,58.8,50,1.0241,2.0481,392,5.7,0.072,125.3129,30,13,0
0.007928241,392.7,392,332,58.8,50,1.0241,2.0481,392,5.6,0.072,125.3129,30,13,0
0.007962963,392.7,392,385,58.8,50,1.0241,2.0481,392,5.5,0.072,125.3129,30,13,0
0.007997685,392.5,392,410,58.8,50,1.0241,2.0481,392,5.4,0.072,125.3129,30,13,0
0.008032407,392.5,392,438,58.8,50,1.0241,2.0481,392,5.5,0.072,125.3129,30,13,0
0.00806713,392.3,392,475,58.8,50,1.0241,2.0481,392,5.4,0.072,125.3129,30,13,0
0.008101852,392.1,392,475,58.8,50,1.0241,2.0481,392,5.7,0.072,125.3129,30,13,0
0.008136574,391.9,392,481,58.8,50,1.0241,2.0481,392,5.8,0.072,125.3129,30,13,0
0.008171296,391.9,392,481,58.8,50,1.0241,2.0481,392,5.3,0.072,125.3129,30,13,0
0.008206019,391.8,392,481,58.8,50,1.0241,2.0481,392,5.7,0.072,125.3129,30,13,0
0.008240741,391.6,392,478,58.8,50,1.0241,2.0481,392,5.9,0.072,125.3129,30,13,0
0.008275463,391.6,392,478,58.8,50,1.0241,2.0481,392,5.7,0.072,125.3129,30,13,0
0.008310185,391.6,392,475,58.8,50,1.0241,2.0481,392,5.7,0.072,125.3129,30,13,0
0.008344907,391.6,392,475,58.8,50,1.0241,2.0481,392,6.2,0.072,125.3129,30,13,0
0.00837963,391.4,392,475,58.8,50,1.0241,2.0481,392,5.9,0.072,125.3129,30,13,0
0.008414352,391.4,392,472,58.8,50,0.5121,1.0243,392,5.5,0.036,62.6684,30,12,0
0.008449074,391.4,392,472,58.8,50,1.0241,2.0481,392,5.2,0.072,125.3129,30,13,0
0.008483796,391.4,392,472,58.8,50,1.0241,2.0481,392,6,0.072,125.3129,30,13,0
0.008518519,391.4,392,472,58.8,50,1.0241,2.0481,392,5.8,0.072,125.3129,30,13,0
0.008564815,391.4,392,472,58.8,50,0.5121,1.0243,392,5.7,0.036,62.6684,30,12,0
0.008599537,391.1,392,472,58.8,50,1.0241,2.0481,392,5.6,0.072,125.3129,30,13,0
0.008634259,391.2,392,472,58.8,50,1.0241,2.0481,392,5.7,0.072,125.3129,30,13,0
0.008668981,391.1,392,472,58.8,50,1.0241,2.0481,392,5.8,0.072,125.3129,30,13,0
0.008703704,391.1,392,472,58.8,50,1.0241,2.0481,392,5.9,0.072,125.3129,30,13,0
0.008738426,391.1,392,472,58.8,50,1.0241,2.0481,392,5.9,0.072,125.3129,30,13,0
0.008773148,391.1,392,472,58.8,50,1.0241,2.0481,392,5.9,0.072,125.3129,30,13,0
0.00880787,391.1,392,472,58.8,50,1.0241,2.0481,392,5.8,0.072,125.3129,30,13,0
0.008842593,390.9,392,472,58.8,50,1.0241,2.0481,392,6.4,0.072,125.3129,30,13,0
0.008877315,390.7,392,472,58.8,50,1.0241,2.0481,392,6,0.072,125.3129,30,13,0
0.008912037,390.7,392,472,58.8,50,0.5121,1.0243,392,5.7,0.036,62.6684,30,12,0
0.008946759,390.7,392,472,58.8,50,1.0241,2.0481,392,5.9,0.072,125.3129,30,13,0
0.008981481,390.9,392,522,58.8,50,1.536,3.072,392,5.7,0.108,187.9575,30,14,0
0.009016204,390.7,392,522,58.8,50,1.0241,2.0481,392,5.7,0.072,125.3129,30,13,0
0.009050926,390.7,392,522,58.8,50,1.0241,2.0481,392,5.8,0.072,125.3129,30,13,0
0.009097222,390.5,392,522,58.8,50,1.0241,2.0481,392,6,0.072,125.3129,30,13,0
0.009131944,390.5,392,522,58.8,50,1.0241,2.0481,392,5.9,0.072,125.3129,30,13,0
0.009166667,390.5,392,522,58.8,50,1.0241,2.0481,392,6,0.072,125.3129,30,13,0
0.009201389,390.5,392,522,58.8,50,1.0241,2.0481,392,5.9,0.072,125.3129,30,13,0
0.009236111,390.5,392,522,58.8,50,1.0241,2.0481,392,5.9,0.072,125.3129,30,13,0
0.009270833,390.3,392,522,58.8,50,1.0241,2.0481,392,5.8,0.072,125.3129,30,13,0
0.009305556,390.2,392,525,58.8,50,1.0241,2.0481,392,6.4,0.072,125.3129,30,13,0
0.009340278,390.3,392,525,58.8,50,1.0241,2.0481,392,6.3,0.072,125.3129,30,13,0
0.009375,390.2,392,525,58.8,50,1.0241,2.0481,392,6,0.072,125.3129,30,13,0
0.009409722,390.2,392,525,58.8,50,1.0241,2.0481,392,6.3,0.072,125.3129,30,13,0
0.009444444,390.2,392,525,58.8,50,1.0241,2.0481,392,5.7,0.072,125.3129,30,13,0
0.009479167,390.2,392,525,58.8,50,1.0241,2.0481,392,5.9,0.072,125.3129,30,13,0
0.009513889,390,392,525,58.8,50,1.0241,2.0481,392,5.7,0.072,125.3129,30,13,0
0.009548611,390.2,392,525,58.8,50,1.0241,2.0481,392,6.1,0.072,125.3129,30,13,0
0.009583333,390,392,528,58.8,50,1.0241,2.0481,392,5.9,0.072,125.3129,30,13,0
0.009618056,389.8,392,528,58.8,50,1.0241,2.0481,392,6,0.072,125.3129,30,13,0
0.009652778,390,392,525,58.8,50,1.0241,2.0481,392,6.4,0.072,125.3129,30,13,0
0.0096875,389.8,392,528,58.8,50,1.0241,2.0481,392,6,0.072,125.3129,30,13,0
0.009722222,389.8,392,528,58.8,50,1.0241,2.0481,392,6,0.072,125.3129,30,13,0
0.009768519,389.8,392,528,58.8,50,1.0241,2.0481,392,6.2,0.072,125.3129,30,13,0
0.009803241,389.8,392,528,58.8,50,1.0241,2.0481,392,6.3,0.072,125.3129,30,13,0
0.009837963,389.6,392,528,117.61,100,1.0241,1.0241,392,6.1,0.072,125.3129,30,13,0
0.009872685,389.6,392,528,117.61,100,1.536,1.536,392,6.1,0.108,187.9575,30,14,0
0.009907407,389.6,392,531,88.2,75,1.536,1.536,392,6,0.108,187.9575,30,14,0
0.00994213,389.6,392,528,88.2,75,1.536,2.048,392,6,0.108,187.9575,30,14,0
0.009976852,389.4,392,528,88.2,75,1.536,2.048,392,6,0.108,187.9575,30,14,0
0.010011574,389.4,392,531,88.2,75,1.536,2.048,392,6.1,0.108,187.9575,30,14,0
0.010046296,389.3,392,531,58.8,50,1.536,3.072,392,6.4,0.108,187.9575,30,14,0
0.010081019,389.3,392,531,58.8,50,1.536,3.072,392,6.3,0.108,187.9575,30,14,0
0.010115741,389.3,392,531,29.4,25,1.0241,4.0963,392,6.4,0.072,125.3129,30,13,0
0.010150463,389.3,392,531,29.4,25,1.0241,4.0963,392,6.5,0.072,125.3129,30,13,0
0.010196759,389.3,392,531,29.4,25,1.0241,4.0963,392,6.1,0.072,125.3129,30,13,0
0.010231481,389.1,392,531,58.8,50,1.0241,4.0963,392,6.2,0.072,125.3129,30,13,0
0.010266204,389.3,392,531,58.8,50,1.0241,2.0481,392,5.8,0.072,125.3129,30,13,0
0.010300926,389.1,392,531,58.8,50,1.0241,2.0481,392,6.1,0.072,125.3129,30,13,0
0.010335648,389.1,392,531,88.2,75,1.0241,1.3654,392,6,0.072,125.3129,30,13,0
0.01037037,389.1,392,531,88.2,75,1.0241,1.3654,392,6,0.072,125.3129,30,13,0
0.010405093,389.1,392,531,88.2,75,1.0241,1.3654,392,5.7,0.072,125.3129,30,13,0
0.010439815,389.1,392,537,117.61,100,1.0241,1.3654,392,6.2,0.072,125.3129,30,13,0
0.010474537,389.1,392,537,117.61,100,1.536,1.536,392,6.1,0.108,187.9575,30,14,0
0.010509259,388.9,392,537,117.61,100,1.536,1.536,392,6,0.108,187.9575,30,14,0
0.010543981,388.9,392,537,117.61,100,1.536,1.536,392,6.3,0.108,187.9575,30,14,0
0.010578704,388.9,392,537,58.8,50,1.536,3.072,392,6.1,0.108,187.9575,30,14,0
0.010625,388.7,392,537,58.8,50,1.0241,2.0481,392,6,0.072,125.3129,30,13,0
0.010659722,388.7,392,540,58.8,50,1.0241,2.0481,392,6.6,0.072,125.3129,30,13,0
0.010694444,388.9,392,565,58.8,50,1.0241,2.0481,392,6.5,0.072,125.3129,30,13,0
0.010729167,388.9,392,627,58.8,50,1.536,3.072,392,5.8,0.108,187.9575,30,14,0
0.010763889,388.9,392,658,58.8,50,1.0241,2.0481,392,6.1,0.072,125.3129,30,13,0
0.010798611,388.9,392,674,58.8,50,1.0241,2.0481,392,6.1,0.072,125.3129,30,13,0
0.010833333,388.9,392,696,58.8,50,1.536,3.072,392,6.1,0.108,187.9575,30,14,0
0.010868056,388.9,392,717,58.8,50,1.0241,2.0481,392,6.2,0.072,125.3129,30,13,0
0.010902778,388.9,392,733,58.8,50,1.536,3.072,392,6,0.108,187.9575,30,14,0
0.0109375,388.9,392,742,58.8,50,1.536,3.072,392,5.9,0.108,187.9575,30,14,0
0.010972222,388.7,392,742,58.8,50,1.0241,2.0481,392,6.4,0.072,125.3129,30,13,0
0.011006944,388.7,392,752,58.8,50,1.0241,2.0481,392,6.7,0.072,125.3129,30,13,0
0.011041667,388.7,392,758,58.8,50,1.0241,2.0481,392,6.3,0.072,125.3129,30,13,0
0.011076389,388.5,392,758,58.8,50,1.536,3.072,392,6.2,0.108,187.9575,30,14,0
0.011111111,388.7,392,761,58.8,50,1.536,3.072,392,6.3,0.108,187.9575,30,14,0
0.011145833,388.5,392,764,58.8,50,1.0241,2.0481,392,5.8,0.072,125.3129,30,13,0
0.011180556,388.5,392,767,58.8,50,1.0241,2.0481,392,6,0.072,125.3129,30,13,0
0.011215278,388.5,392,767,58.8,50,1.536,3.072,392,5.9,0.108,187.9575,30,14,0
0.01125,388.4,392,770,58.8,50,1.536,3.072,392,6.5,0.108,187.9575,30,14,0
0.011296296,388.5,392,776,58.8,50,1.536,3.072,392,6.1,0.108,187.9575,30,14,0
0.011331019,388.5,392,780,58.8,50,1.536,3.072,392,6.1,0.108,187.9575,30,14,0
0.011365741,388.4,392,783,58.8,50,1.0241,2.0481,392,6.3,0.072,125.3129,30,13,0
0.011400463,388.4,392,786,58.8,50,1.536,3.072,392,6.5,0.108,187.9575,30,14,0
0.011435185,388.4,392,786,58.8,50,1.536,3.072,392,6.3,0.108,187.9575,30,14,0
0.011469907,388.4,392,792,58.8,50,1.536,3.072,392,6.4,0.108,187.9575,30,14,0
0.01150463,388.4,392,792,58.8,50,1.0241,2.0481,392,6.9,0.072,125.3129,30,13,0
0.011539352,388.4,392,795,58.8,50,1.536,3.072,392,6.3,0.108,187.9575,30,14,0
0.011574074,388.4,392,795,58.8,50,1.536,3.072,392,6.2,0.108,187.9575,30,14,0
0.011608796,388.4,392,798,58.8,50,1.536,3.072,392,6.2,0.108,187.9575,30,14,0
0.011643519,388.2,392,798,58.8,50,1.536,3.072,392,6.1,0.108,187.9575,30,14,0
0.011678241,388.2,392,798,58.8,50,1.536,3.072,392,6,0.108,187.9575,30,14,0
0.011712963,388.2,392,798,58.8,50,1.536,3.072,392,6.2,0.108,187.9575,30,14,0
0.011747685,388.2,392,801,58.8,50,1.536,3.072,392,6.6,0.108,187.9575,30,14,0
0.011782407,388,392,801,58.8,50,1.0241,2.0481,392,6.7,0.072,125.3129,30,13,0
0.01181713,388.2,392,811,58.8,50,1.0241,2.0481,392,6.3,0.072,125.3129,30,13,0
0.011851852,388,392,811,58.8,50,1.0241,2.0481,392,5.9,0.072,125.3129,30,13,0
0.011886574,388,392,811,58.8,50,1.0241,2.0481,392,6.3,0.072,125.3129,30,13,0
0.011921296,388,392,811,58.8,50,1.0241,2.0481,392,6.4,0.072,125.3129,30,13,0
0.011956019,388,392,811,58.8,50,1.0241,2.0481,392,6.7,0.072,125.3129,30,13,0
0.011990741,388,392,814,58.8,50,1.0241,2.0481,392,6.3,0.072,125.3129,30,13,0
0.012025463,388,392,814,58.8,50,1.536,3.072,392,6.2,0.108,187.9575,30,14,0
0.012071759,388,392,814,58.8,50,1.0241,2.0481,392,6.6,0.072,125.3129,30,13,0
0.012106481,388,392,814,58.8,50,1.536,3.072,392,6.6,0.108,187.9575,30,14,0
0.012141204,387.8,392,814,58.8,50,1.536,3.072,392,6.1,0.108,187.9575,30,14,0
0.012175926,388,392,814,58.8,50,1.536,3.072,392,6.4,0.108,187.9575,30,14,0
0.012210648,387.8,392,817,58.8,50,1.0241,2.0481,392,6.3,0.072,125.3129,30,13,0
0.01224537,387.8,392,817,58.8,50,1.0241,2.0481,392,6.3,0.072,125.3129,30,13,0
0.012280093,387.8,392,817,58.8,50,1.0241,2.0481,392,6.2,0.072,125.3129,30,13,0
0.012314815,387.8,392,817,58.8,50,1.536,3.072,392,6.4,0.108,187.9575,30,14,0
0.012349537,387.8,392,817,58.8,50,1.0241,2.0481,392,6.5,0.072,125.3129,30,13,0
0.012384259,387.8,392,817,58.8,50,1.0241,2.0481,392,6.1,0.072,125.3129,30,13,0
0.012418981,387.8,392,820,58.8,50,1.0241,2.0481,392,6.6,0.072,125.3129,30,13,0
0.012453704,387.8,392,820,58.8,50,1.0241,2.0481,392,6.5,0.072,125.3129,30,13,0
0.012488426,387.6,392,820,58.8,50,1.536,3.072,392,6.8,0.108,187.9575,30,14,0
0.012523148,387.6,392,820,58.8,50,1.0241,2.0481,392,6.2,0.072,125.3129,30,13,0
0.012569444,387.6,392,820,58.8,50,1.536,3.072,392,6.3,0.108,187.9575,30,14,0
0.012604167,387.6,392,820,58.8,50,1.0241,2.0481,392,6,0.072,125.3129,30,13,0
0.012638889,387.6,392,820,58.8,50,1.536,3.072,392,6,0.108,187.9575,30,14,0
0.012673611,387.6,392,826,117.61,100,1.0241,1.0241,392,6.4,0.072,125.3129,30,13,0
0.012708333,387.6,392,820,117.61,100,1.536,1.536,392,6.3,0.108,187.9575,30,14,0
0.012743056,387.5,392,826,117.61,100,1.536,1.536,392,6.4,0.108,187.9575,30,14,0
0.012777778,387.6,392,826,88.2,75,1.536,2.048,392,6.3,0.108,187.9575,30,14,0
0.0128125,387.5,392,826,88.2,75,1.536,2.048,392,6.7,0.108,187.9575,30,14,0
0.012847222,387.5,392,826,88.2,75,1.536,2.048,392,6.9,0.108,187.9575,30,14,0
0.012881944,387.5,392,829,58.8,50,1.536,3.072,392,6.8,0.108,187.9575,30,14,0
0.012916667,387.5,392,826,58.8,50,1.0241,2.0481,392,6.6,0.072,125.3129,30,13,0
0.012951389,387.3,392,826,58.8,50,1.0241,2.0481,392,6.3,0.072,125.3129,30,13,0
0.012986111,387.3,392,826,29.4,25,1.0241,4.0963,392,6.3,0.072,125.3129,30,13,0
0.013020833,387.3,392,826,29.4,25,1.0241,4.0963,392,6.4,0.072,125.3129,30,13,0
0.013055556,387.3,392,829,29.4,25,1.0241,4.0963,392,6,0.072,125.3129,30,13,0
0.013090278,387.3,392,829,58.8,50,1.0241,2.0481,392,6.6,0.072,125.3129,30,13,0
0.013125,387.1,392,829,58.8,50,1.0241,2.0481,392,6.3,0.072,125.3129,30,13,0
0.013171296,387.1,392,829,58.8,50,1.0241,2.0481,392,6.3,0.072,125.3129,30,13,0
0.013206019,387.3,392,829,88.2,75,1.0241,1.3654,392,6.7,0.072,125.3129,30,13,0
0.013240741,387.1,392,829,88.2,75,1.0241,1.3654,392,6.5,0.072,125.3129,30,13,0
0.013275463,387.1,392,829,88.2,75,1.0241,1.3654,392,6.2,0.072,125.3129,30,13,0
0.013310185,387.1,392,829,117.61,100,1.536,1.536,392,6.2,0.108,187.9575,30,14,0
0.013344907,387.1,392,829,117.61,100,1.536,1.536,392,6.4,0.108,187.9575,30,14,0
0.01337963,387.1,392,829,117.61,100,1.536,1.536,392,6.6,0.108,187.9575,30,14,0
0.013414352,387.1,392,832,58.8,50,1.536,3.072,392,6.6,0.108,187.9575,30,14,0
0.013449074,387.1,392,829,58.8,50,1.536,3.072,392,6.5,0.108,187.9575,30,14,0
0.013483796,386.9,392,832,58.8,50,1.0241,2.0481,392,6.8,0.072,125.3129,30,13,0
0.013518519,387.1,392,901,58.8,50,1.536,3.072,392,6.4,0.108,187.9575,30,14,0
0.013553241,387.5,392,1006,58.8,50,1.536,3.072,392,6.5,0.108,187.9575,30,14,0
0.013587963,387.8,392,1087,58.8,50,1.536,3.072,392,6.2,0.108,187.9575,30,14,0
0.013622685,388,392,1227,58.8,50,1.536,3.072,392,6.7,0.108,187.9575,30,14,0
0.013657407,387.8,392,1239,58.8,50,1.536,3.072,392,6.6,0.108,187.9575,30,14,0
0.013703704,387.5,392,1242,58.8,50,1.536,3.072,392,6.7,0.108,187.9575,30,14,0
0.013738426,387.3,392,1252,58.8,50,1.536,3.072,392,6.8,0.108,187.9575,30,14,0
0.013773148,387.3,392,1258,58.8,50,1.0241,2.0481,392,6.5,0.072,125.3129,30,13,0
0.01380787,387.1,392,1264,58.8,50,1.0241,2.0481,392,6.5,0.072,125.3129,30,13,0
0.013842593,387.1,392,1273,58.8,50,1.0241,2.0481,392,6.6,0.072,125.3129,30,13,0
0.013877315,387.1,392,1286,58.8,50,1.536,3.072,392,6.4,0.108,187.9575,30,14,0
0.013912037,387.1,392,1295,58.8,50,1.536,3.072,392,6.2,0.108,187.9575,30,14,0
0.013946759,387.1,392,1304,58.8,50,1.0241,2.0481,392,6.5,0.072,125.3129,30,13,0
0.013981481,387.1,392,1307,58.8,50,1.536,3.072,392,6.5,0.108,187.9575,30,14,0
0.014016204,387.1,392,1311,58.8,50,1.0241,2.0481,392,6.5,0.072,125.3129,30,13,0
0.014050926,387.1,392,1311,58.8,50,1.536,3.072,392,6.6,0.108,187.9575,30,14,0
0.014085648,387.1,392,1311,58.8,50,1.536,3.072,392,6.4,0.108,187.9575,30,14,0
0.01412037,386.9,392,1314,58.8,50,1.0241,2.0481,392,6.6,0.072,125.3129,30,13,0
0.014166667,387.1,392,1314,58.8,50,1.536,3.072,392,6.4,0.108,187.9575,30,14,0
0.014201389,387.1,392,1314,58.8,50,1.536,3.072,392,6.8,0.108,187.9575,30,14,0
0.014236111,386.9,392,1314,58.8,50,1.536,3.072,392,6.7,0.108,187.9575,30,14,0
0.014270833,386.9,392,1320,58.8,50,1.0241,2.0481,392,6.3,0.072,125.3129,30,13,0
0.014305556,386.9,392,1320,58.8,50,1.536,3.072,392,6.5,0.108,187.9575,30,14,0
0.014340278,386.9,392,1320,58.8,50,1.536,3.072,392,6.3,0.108,187.9575,30,14,0
0.014375,386.9,392,1320,58.8,50,1.536,3.072,392,6.3,0.108,187.9575,30,14,0
0.014409722,386.9,392,1323,58.8,50,1.0241,2.0481,392,6.6,0.072,125.3129,30,13,0
0.014444444,386.9,392,1320,58.8,50,1.0241,2.0481,392,6.7,0.072,125.3129,30,13,0
0.014479167,386.9,392,1320,58.8,50,1.536,3.072,392,6.8,0.108,187.9575,30,14,0
0.014513889,386.9,392,1323,58.8,50,1.536,3.072,392,6.7,0.108,187.9575,30,14,0
0.014548611,386.9,392,1323,58.8,50,1.536,3.072,392,6.5,0.108,187.9575,30,14,0
0.014583333,386.9,392,1323,58.8,50,1.0241,2.0481,392,6.5,0.072,125.3129,30,13,0
0.01462963,386.9,392,1323,58.8,50,1.536,3.072,392,6.5,0.108,187.9575,30,14,0
0.014664352,386.7,392,1326,58.8,50,1.536,3.072,392,6.8,0.108,187.9575,30,14,0
0.014699074,386.9,392,1323,58.8,50,1.536,3.072,392,6.5,0.108,187.9575,30,14,0
0.014733796,386.7,392,1326,58.8,50,1.0241,2.0481,392,6.5,0.072,125.3129,30,13,0
0.014768519,386.7,392,1323,58.8,50,1.536,3.072,392,6.8,0.108,187.9575,30,14,0
0.014803241,386.9,392,1326,58.8,50,1.536,3.072,392,6.7,0.108,187.9575,30,14,0
0.014837963,386.7,392,1326,58.8,50,1.536,3.072,392,6.8,0.108,187.9575,30,14,0
0.014872685,386.7,392,1326,58.8,50,1.536,3.072,392,6.7,0.108,187.9575,30,14,0
0.014907407,386.7,392,1326,58.8,50,1.536,3.072,392,6.5,0.108,187.9575,30,14,0
0.01494213,386.7,392,1326,58.8,50,1.0241,2.0481,392,6.4,0.072,125.3129,30,13,0
0.014976852,386.6,392,1326,58.8,50,1.536,3.072,392,6.3,0.108,187.9575,30,14,0
0.015011574,386.6,392,1329,58.8,50,1.0241,2.0481,392,6.6,0.072,125.3129,30,13,0
0.015046296,386.6,392,1329,58.8,50,1.0241,2.0481,392,7.2,0.072,125.3129,30,13,0
0.015081019,386.6,392,1326,58.8,50,1.0241,2.0481,392,6.5,0.072,125.3129,30,13,0
0.015115741,386.6,392,1329,58.8,50,1.536,3.072,392,6.9,0.108,187.9575,30,14,0
0.015150463,386.6,392,1329,58.8,50,1.536,3.072,392,6.8,0.108,187.9575,30,14,0
0.015196759,386.6,392,1329,58.8,50,1.0241,2.0481,392,6.4,0.072,125.3129,30,13,0
0.015231481,386.6,392,1329,58.8,50,1.536,3.072,392,6.4,0.108,187.9575,30,14,0
0.015266204,386.6,392,1329,58.8,50,1.536,3.072,392,6.5,0.108,187.9575,30,14,0
0.015300926,386.6,392,1329,58.8,50,1.0241,2.0481,392,6.6,0.072,125.3129,30,13,0
0.015335648,386.6,392,1329,58.8,50,1.0241,2.0481,392,6.7,0.072,125.3129,30,13,0
0.01537037,386.6,392,1329,58.8,50,1.0241,2.0481,392,6.6,0.072,125.3129,30,13,0
0.015405093,386.6,392,1332,58.8,50,1.0241,2.0481,392,6.6,0.072,125.3129,30,13,0
0.015439815,386.6,392,1329,58.8,50,1.0241,2.0481,392,6.7,0.072,125.3129,30,13,0
0.015474537,386.6,392,1332,117.61,100,1.0241,1.0241,392,6.9,0.072,125.3129,30,13,0
0.015509259,386.6,392,1332,117.61,100,1.536,1.536,392,6.6,0.108,187.9575,30,14,0
0.015555556,386.6,392,1332,117.61,100,1.536,1.536,392,6.5,0.108,187.9575,30,14,0
0.015590278,386.6,392,1339,117.61,100,1.536,1.536,392,6.6,0.108,187.9575,30,14,0
0.015625,386.6,392,1332,88.2,75,1.536,2.048,392,6.6,0.108,187.9575,30,14,0
0.015659722,386.4,392,1332,88.2,75,1.536,2.048,392,6.9,0.108,187.9575,30,14,0
0.015694444,386.2,392,1332,58.8,50,1.536,3.072,392,6.6,0.108,187.9575,30,14,0
0.015729167,386.2,392,1332,58.8,50,1.536,3.072,392,6.8,0.108,187.9575,30,14,0
0.015763889,386.2,392,1332,58.8,50,1.536,3.072,392,6.6,0.108,187.9575,30,14,0
0.015798611,386.2,392,1332,58.8,50,1.536,3.072,392,7,0.108,187.9575,30,14,0
0.015833333,386.2,392,1332,29.4,25,1.0241,4.0963,392,6.4,0.072,125.3129,30,13,0
0.015868056,386.2,392,1339,29.4,25,1.0241,4.0963,392,6.5,0.072,125.3129,30,13,0
0.015902778,386.2,392,1339,29.4,25,1.0241,4.0963,392,6.6,0.072,125.3129,30,13,0
0.0159375,386.2,392,1339,58.8,50,1.0241,2.0481,392,6.7,0.072,125.3129,30,13,0
0.015972222,386.2,392,1339,58.8,50,1.536,3.072,392,6.5,0.108,187.9575,30,14,0
0.016006944,386.2,392,1332,58.8,50,1.0241,2.0481,392,6.5,0.072,125.3129,30,13,0
0.016041667,386.2,392,1332,88.2,75,1.536,2.048,392,6.8,0.108,187.9575,30,14,0
0.016076389,386.2,392,1339,88.2,75,1.536,2.048,392,6.6,0.108,187.9575,30,14,0
0.016122685,386.2,392,1339,88.2,75,1.536,2.048,392,6.8,0.108,187.9575,30,14,0
0.016157407,386.2,392,1339,117.61,100,1.536,1.536,392,6.6,0.108,187.9575,30,14,0
0.01619213,386.2,392,1342,117.61,100,1.536,1.536,392,6.6,0.108,187.9575,30,14,0
0.016226852,386.2,392,1342,117.61,100,1.536,1.536,392,6.7,0.108,187.9575,30,14,0
0.016261574,386.2,392,1342,58.8,50,1.536,3.072,392,6.7,0.108,187.9575,30,14,0
0.016296296,386.2,392,1339,58.8,50,1.536,3.072,392,6.6,0.108,187.9575,30,14,0
0.016331019,386.2,392,1339,58.8,50,1.536,3.072,392,6.7,0.108,187.9575,30,14,0
0.016377315,386,392,1357,58.8,50,1.0241,2.0481,392,7,0.072,125.3129,30,13,0
0.016412037,386.7,392,1519,58.8,50,1.0241,2.0481,392,6.9,0.072,125.3129,30,13,0
0.016446759,386.9,392,1612,58.8,50,1.536,3.072,392,6.8,0.108,187.9575,30,14,0
0.016481481,386.9,392,1702,58.8,50,1.536,3.072,392,6.7,0.108,187.9575,30,14,0
0.016516204,386.7,392,1730,58.8,50,1.536,3.072,392,6.7,0.108,187.9575,30,14,0
0.016550926,386.6,392,1733,58.8,50,1.536,3.072,392,6.5,0.108,187.9575,30,14,0
0.016585648,386.6,392,1748,58.8,50,1.0241,2.0481,392,6.7,0.072,125.3129,30,13,0
0.01662037,386.4,392,1773,58.8,50,1.536,3.072,392,6.8,0.108,187.9575,30,14,0
0.016655093,386.4,392,1801,58.8,50,1.536,3.072,392,7.1,0.108,187.9575,30,14,0
0.016689815,386.4,392,1814,58.8,50,1.0241,2.0481,392,6.7,0.072,125.3129,30,13,0
0.016724537,386.2,392,1817,58.8,50,1.0241,2.0481,392,6.7,0.072,125.3129,30,13,0
0.016759259,386.2,392,1820,58.8,50,1.536,3.072,392,6.6,0.108,187.9575,30,14,0
0.016793981,386.2,392,1820,58.8,50,1.0241,2.0481,392,6.3,0.072,125.3129,30,13,0
0.016828704,386.2,392,1823,58.8,50,1.536,3.072,392,6.4,0.108,187.9575,30,14,0
0.016863426,386.2,392,1823,58.8,50,1.0241,2.0481,392,6.8,0.072,125.3129,30,13,0
0.016898148,386.2,392,1820,58.8,50,1.536,3.072,392,6.5,0.108,187.9575,30,14,0
0.01693287,386.2,392,1820,58.8,50,1.536,3.072,392,6.5,0.108,187.9575,30,14,0
0.016967593,386.2,392,1820,58.8,50,1.536,3.072,392,6.7,0.108,187.9575,30,14,0
0.017002315,386.2,392,1820,58.8,50,1.536,3.072,392,6.8,0.108,187.9575,30,14,0
0.017037037,386.2,392,1820,58.8,50,1.0241,2.0481,392,6.9,0.072,125.3129,30,13,0
0.017083333,386.2,392,1823,58.8,50,1.0241,2.0481,392,7.1,0.072,125.3129,30,13,0
0.017118056,386.2,392,1820,58.8,50,1.536,3.072,392,6.9,0.108,187.9575,30,14,0
0.017152778,386,392,1820,58.8,50,1.0241,2.0481,392,6.7,0.072,125.3129,30,13,0
0.0171875,386,392,1820,58.8,50,1.0241,2.0481,392,6.5,0.072,125.3129,30,13,0
0.017222222,386,392,1820,58.8,50,1.536,3.072,392,6.5,0.108,187.9575,30,14,0
0.017256944,386,392,1820,58.8,50,1.0241,2.0481,392,6.6,0.072,125.3129,30,13,0
0.017291667,386.2,392,1820,58.8,50,1.0241,2.0481,392,6.6,0.072,125.3129,30,13,0
0.017326389,386,392,1820,58.8,50,1.0241,2.0481,392,6.7,0.072,125.3129,30,13,0
0.017361111,386,392,1820,58.8,50,1.0241,2.0481,392,6.8,0.072,125.3129,30,13,0
0.017395833,386,392,1820,58.8,50,1.0241,2.0481,392,6.8,0.072,125.3129,30,13,0
0.017430556,386.2,392,1820,58.8,50,1.536,3.072,392,6.8,0.108,187.9575,30,14,0
0.017465278,386.2,392,1820,58.8,50,1.536,3.072,392,6.8,0.108,187.9575,30,14,0
0.0175,386,392,1820,58.8,50,1.536,3.072,392,6.9,0.108,187.9575,30,14,0
0.017534722,386,392,1820,58.8,50,1.536,3.072,392,6.9,0.108,187.9575,30,14,0
0.017569444,386,392,1820,58.8,50,1.536,3.072,392,7.4,0.108,187.9575,30,14,0
0.017615741,386,392,1820,58.8,50,1.0241,2.0481,392,6.3,0.072,125.3129,30,13,0
0.017650463,386,392,1820,58.8,50,1.536,3.072,392,6.6,0.108,187.9575,30,14,0
0.017685185,386,392,1823,58.8,50,1.0241,2.0481,392,6.8,0.072,125.3129,30,13,0
0.017719907,386,392,1823,58.8,50,1.0241,2.0481,392,6.8,0.072,125.3129,30,13,0
0.01775463,386,392,1820,58.8,50,1.0241,2.0481,392,7,0.072,125.3129,30,13,0
0.017789352,386,392,1820,58.8,50,1.0241,2.0481,392,7,0.072,125.3129,30,13,0
0.017824074,386,392,1820,58.8,50,1.0241,2.0481,392,6.8,0.072,125.3129,30,13,0
0.017858796,386,392,1820,58.8,50,1.0241,2.0481,392,6.7,0.072,125.3129,30,13,0
0.017893519,386,392,1820,58.8,50,1.536,3.072,392,6.7,0.108,187.9575,30,14,0
0.017928241,386,392,1820,58.8,50,1.536,3.072,392,6.7,0.108,187.9575,30,14,0
0.017962963,386,392,1820,58.8,50,1.536,3.072,392,6.8,0.108,187.9575,30,14,0
0.017997685,386,392,1820,58.8,50,1.536,3.072,392,6.7,0.108,187.9575,30,14,0
0.018032407,386,392,1820,58.8,50,1.536,3.072,392,7,0.108,187.9575,30,14,0
0.018078704,385.8,392,1820,58.8,50,1.0241,2.0481,392,6.9,0.072,125.3129,30,13,0
0.018113426,386,392,1820,58.8,50,1.0241,2.0481,392,6.5,0.072,125.3129,30,13,0
0.018148148,386,392,1820,58.8,50,1.0241,2.0481,392,6.9,0.072,125.3129,30,13,0
0.01818287,385.8,392,1820,58.8,50,1.536,3.072,392,6.9,0.108,187.9575,30,14,0
0.018217593,386,392,1820,58.8,50,1.536,3.072,392,6.9,0.108,187.9575,30,14,0
0.018252315,385.8,392,1820,58.8,50,1.536,3.072,392,6.7,0.108,187.9575,30,14,0
0.018287037,385.8,392,1820,58.8,50,1.0241,2.0481,392,6.8,0.072,125.3129,30,13,0
0.018321759,385.8,392,1820,117.61,100,1.536,3.072,392,7,0.108,187.9575,30,14,0
0.018356481,385.8,392,1820,117.61,100,1.536,1.536,392,7.2,0.108,187.9575,30,14,0
0.018391204,385.8,392,1820,117.61,100,1.536,1.536,392,6.8,0.108,187.9575,30,14,0
0.018425926,385.8,392,1823,88.2,75,1.536,2.048,392,6.8,0.108,187.9575,30,14,0
0.018460648,386,392,1823,88.2,75,1.536,2.048,392,6.8,0.108,187.9575,30,14,0
0.018506944,385.7,392,1820,88.2,75,1.536,2.048,392,6.6,0.108,187.9575,30,14,0
0.018541667,385.7,392,1820,58.8,50,1.536,2.048,392,6.4,0.108,187.9575,30,14,0
0.018576389,385.7,392,1820,58.8,50,1.536,3.072,392,6.6,0.108,187.9575,30,14,0
0.018611111,385.7,392,1820,58.8,50,1.0241,2.0481,392,6.7,0.072,125.3129,30,13,0
0.018645833,385.7,392,1820,58.8,50,1.0241,2.0481,392,7,0.072,125.3129,30,13,0
0.018680556,385.7,392,1820,29.4,25,1.0241,4.0963,392,7.3,0.072,125.3129,30,13,0
0.018715278,385.7,392,1820,29.4,25,1.0241,4.0963,392,7.5,0.072,125.3129,30,13,0
0.01875,385.7,392,1820,58.8,50,1.0241,4.0963,392,7,0.072,125.3129,30,13,0
0.018784722,385.7,392,1820,58.8,50,1.536,3.072,392,6.8,0.108,187.9575,30,14,0
0.018819444,385.7,392,1820,58.8,50,1.536,3.072,392,6.5,0.108,187.9575,30,14,0
0.018854167,385.7,392,1820,58.8,50,1.536,3.072,392,6.4,0.108,187.9575,30,14,0
0.018888889,385.7,392,1820,88.2,75,1.536,2.048,392,6.4,0.108,187.9575,30,14,0
0.018923611,385.7,392,1820,88.2,75,1.536,2.048,392,6.6,0.108,187.9575,30,14,0
0.018958333,385.7,392,1820,117.61,100,1.536,2.048,392,6.8,0.108,187.9575,30,14,0
0.018993056,385.7,392,1820,117.61,100,1.536,1.536,392,6.9,0.108,187.9575,30,14,0
0.019027778,385.7,392,1820,117.61,100,1.536,1.536,392,7,0.108,187.9575,30,14,0
0.0190625,385.7,392,1823,117.61,100,1.536,1.536,392,7.4,0.108,187.9575,30,14,0
0.019108796,385.7,392,1823,58.8,50,1.536,3.072,392,7,0.108,187.9575,30,14,0
0.019143519,385.7,392,1820,58.8,50,1.536,3.072,392,7,0.108,187.9575,30,14,0
0.019178241,385.7,392,1820,58.8,50,1.536,3.072,392,6.9,0.108,187.9575,30,14,0
0.019212963,385.7,392,1820,58.8,50,1.536,3.072,392,6.7,0.108,187.9575,30,14,0
0.019247685,385.5,392,1820,58.8,50,1.536,3.072,392,6.8,0.108,187.9575,30,14,0
0.019282407,385.7,392,1820,58.8,50,1.0241,2.0481,392,6.7,0.072,125.3129,30,13,0
0.01931713,385.5,392,1820,58.8,50,1.536,3.072,392,6.9,0.108,187.9575,30,14,0
0.019351852,385.7,392,1820,58.8,50,1.0241,2.0481,392,7.2,0.072,125.3129,30,13,0
0.019386574,385.7,392,1820,58.8,50,1.536,3.072,392,6.9,0.108,187.9575,30,14,0
0.019421296,385.7,392,1820,58.8,50,1.536,3.072,392,6.8,0.108,187.9575,30,14,0
0.019456019,385.7,392,1820,58.8,50,1.536,3.072,392,7,0.108,187.9575,30,14,0
0.019490741,385.7,392,1820,58.8,50,1.536,3.072,392,6.7,0.108,187.9575,30,14,0
0.019525463,385.7,392,1820,58.8,50,1.0241,2.0481,392,6.6,0.072,125.3129,30,13,0
0.019560185,385.7,392,1820,58.8,50,1.536,3.072,392,6.7,0.108,187.9575,30,14,0
0.019594907,385.7,392,1817,58.8,50,1.536,3.072,392,7,0.108,187.9575,30,14,0
0.01962963,385.7,392,1820,58.8,50,1.536,3.072,392,6.6,0.108,187.9575,30,14,0
0.019664352,385.7,392,1820,58.8,50,1.536,3.072,392,6.8,0.108,187.9575,30,14,0
0.019699074,385.7,392,1820,58.8,50,1.536,3.072,392,6.7,0.108,187.9575,30,14,0
0.019733796,385.5,392,1817,58.8,50,1.536,3.072,392,7.1,0.108,187.9575,30,14,0
0.019768519,385.5,392,1820,58.8,50,1.536,3.072,392,7,0.108,187.9575,30,14,0
0.019803241,385.5,392,1820,58.8,50,1.536,3.072,392,6.9,0.108,187.9575,30,14,0
0.019837963,385.5,392,1820,58.8,50,1.536,3.072,392,6.9,0.108,187.9575,30,14,0
0.019884259,385.5,392,1820,58.8,50,1.536,3.072,392,6.6,0.108,187.9575,30,14,0
0.019918981,385.5,392,1820,58.8,50,1.536,3.072,392,6.4,0.108,187.9575,30,14,0
0.019953704,385.5,392,1820,58.8,50,1.536,3.072,392,6.7,0.108,187.9575,30,14,0
0.019988426,385.5,392,1820,58.8,50,1.536,3.072,392,6.5,0.108,187.9575,30,14,0
0.020023148,385.5,392,1820,58.8,50,1.536,3.072,392,6.8,0.108,187.9575,30,14,0
0.02005787,385.7,392,1820,58.8,50,1.0241,2.0481,392,7.2,0.072,125.3129,30,13,0
0.020092593,385.5,392,1820,58.8,50,1.0241,2.0481,392,7.2,0.072,125.3129,30,13,0
0.020127315,385.5,392,1817,58.8,50,1.0241,2.0481,392,7.3,0.072,125.3129,30,13,0
0.020162037,385.7,392,1817,58.8,50,1.0241,2.0481,392,6.7,0.072,125.3129,30,13,0
0.020196759,385.5,392,1817,58.8,50,1.536,3.072,392,6.7,0.108,187.9575,30,14,0
0.020231481,385.5,392,1820,58.8,50,1.536,3.072,392,7,0.108,187.9575,30,14,0
0.020266204,385.5,392,1817,58.8,50,1.536,3.072,392,6.8,0.108,187.9575,30,14,0
0.020300926,385.5,392,1820,58.8,50,1.536,3.072,392,6.5,0.108,187.9575,30,14,0
0.020335648,385.5,392,1820,58.8,50,1.536,3.072,392,6.6,0.108,187.9575,30,14,0
0.02037037,385.5,392,1817,58.8,50,1.536,3.072,392,6.9,0.108,187.9575,30,14,0
0.020405093,385.5,392,1820,58.8,50,1.536,3.072,392,6.6,0.108,187.9575,30,14,0
0.020451389,385.5,392,1817,58.8,50,1.536,3.072,392,7.1,0.108,187.9575,30,14,0
0.020486111,385.5,392,1817,58.8,50,1.0241,2.0481,392,7,0.072,125.3129,30,13,0
0.020520833,385.5,392,1820,58.8,50,1.536,3.072,392,7.2,0.108,187.9575,30,14,0
0.020555556,385.5,392,1820,58.8,50,1.0241,2.0481,392,6.8,0.072,125.3129,30,13,0
0.020590278,385.5,392,1817,58.8,50,1.536,3.072,392,7.1,0.108,187.9575,30,14,0
0.020636574,385.3,392,1817,58.8,50,1.536,3.072,392,6.7,0.108,187.9575,30,14,0
0.020671296,385.5,392,1817,58.8,50,1.536,3.072,392,6.8,0.108,187.9575,30,14,0
0.020706019,385.5,392,1817,58.8,50,1.536,3.072,392,6.8,0.108,187.9575,30,14,0
0.020740741,385.3,392,1817,58.8,50,1.0241,2.0481,392,6.9,0.072,125.3129,30,13,0
0.020775463,385.5,392,1817,58.8,50,1.536,3.072,392,6.7,0.108,187.9575,30,14,0
0.020810185,385.5,392,1817,58.8,50,1.0241,2.0481,392,6.8,0.072,125.3129,30,13,0
0.020844907,385.5,392,1817,58.8,50,1.0241,2.0481,392,6.9,0.072,125.3129,30,13,0
0.02087963,385.5,392,1817,58.8,50,1.0241,2.0481,392,6.9,0.072,125.3129,30,13,0
0.020914352,385.5,392,1817,58.8,50,1.536,3.072,392,6.9,0.108,187.9575,30,14,0
0.020949074,385.5,392,1817,58.8,50,1.0241,2.0481,392,6.6,0.072,125.3129,30,13,0
0.020983796,385.5,392,1817,58.8,50,1.0241,2.0481,392,6.9,0.072,125.3129,30,13,0
0.021018519,385.5,392,1817,58.8,50,1.0241,2.0481,392,6.9,0.072,125.3129,30,13,0
0.021053241,385.3,392,1817,58.8,50,1.536,3.072,392,6.8,0.108,187.9575,30,14,0
0.021087963,385.3,392,1814,58.8,50,1.536,3.072,392,7.1,0.108,187.9575,30,14,0
0.021122685,385.5,392,1817,58.8,50,1.536,3.072,392,6.7,0.108,187.9575,30,14,0
0.021134259,385.5,392,1817,58.8,50,1.536,3.072,392,6.8,0.108,187.9575,30,14,0