File: data/hpybr-AA-cons-T.csv
Elapsed Time,Sample Temp,Heater Temp,Pressure,Rotor Speed,Shear Rate,Shear Stress,Viscosity,Temperature Setpoint,T Output,Bob Deflection,Torque,Motor Temp,Raw Encoder Value,Aux1
(hh:mm:ss),(°F),(°F),(PSIg),(RPM),(1/s),(dyne/cm²),(cP),(°F),(%),(deg.),(dyne-cm),(°C),(cts),
1.16E-05,174.8,398,130,58.8,50,0.0005,0,32,0,0,0.0612,30,9,0
6.94E-05,176.7,394,130,58.8,50,1.5363,3.0726,32,0,0.108,187.9949,30,12,0
0.000127315,178.5,391,127,58.8,50,1.5363,3.0726,32,0,0.108,187.9949,30,12,0
0.000185185,180.9,386,130,58.8,50,1.5363,3.0726,32,0,0.108,187.9949,30,12,0
0.000243056,184.3,382,127,58.8,50,1.5363,3.0726,32,0,0.108,187.9949,30,12,0
0.0003125,186.8,379,127,58.8,50,2.0482,4.0965,32,0,0.144,250.6395,30,13,0
0.00037037,189.2,375,127,58.8,50,1.5363,3.0726,32,0,0.108,187.9949,30,12,0
0.000428241,192,372,127,58.8,50,1.5363,3.0726,32,0,0.108,187.9949,30,12,0
0.000486111,194.2,369,130,58.8,50,2.0482,4.0965,32,0,0.144,250.6395,30,13,0
0.000543981,196.9,367,127,58.8,50,1.5363,3.0726,32,0,0.108,187.9949,30,12,0
0.000601852,199,364,127,58.8,50,1.0244,2.0487,32,0,0.072,125.3503,30,11,0
0.000659722,201.2,362,127,58.8,50,1.5363,3.0726,32,0,0.108,187.9949,30,12,0
0.000717593,203.2,359,127,58.8,50,1.5363,3.0726,32,0,0.108,187.9949,30,12,0
0.000775463,205.9,356,127,58.8,50,1.5363,3.0726,32,0,0.108,187.9949,30,12,0
0.000833333,207.7,354,127,58.8,50,1.5363,3.0726,32,0,0.108,187.9949,30,12,0
0.000891204,209.8,351,127,58.8,50,1.5363,3.0726,32,0,0.108,187.9949,30,12,0
0.000960648,212.3,349,127,58.8,50,1.5363,3.0726,32,0,0.108,187.9949,30,12,0
0.001018519,214.3,347,121,58.8,50,1.5363,3.0726,32,0,0.108,187.9949,30,12,0
0.001076389,216.3,345,127,58.8,50,2.0482,4.0965,32,0,0.144,250.6395,30,13,0
0.001134259,218.6,343,127,58.8,50,1.5363,3.0726,32,0,0.108,187.9949,30,12,0
0.00119213,220.3,341,121,58.8,50,1.5363,3.0726,32,0,0.108,187.9949,30,12,0
0.00125,222.1,339,121,58.8,50,1.5363,3.0726,32,0,0.108,187.9949,30,12,0
0.00130787,224.4,337,121,58.8,50,1.5363,3.0726,32,0,0.108,187.9949,30,12,0
0.001365741,226.2,336,121,58.8,50,1.5363,3.0726,32,0,0.108,187.9949,30,12,0
0.001423611,227.8,334,121,58.8,50,1.5363,3.0726,32,0,0.108,187.9949,30,12,0
0.001481481,230,332,118,58.8,50,2.5602,5.1203,32,0,0.18,313.2841,30,14,0
0.001550926,231.6,331,118,58.8,50,1.5363,3.0726,32,0,0.108,187.9949,30,12,0
0.001608796,233.2,329,118,58.8,50,1.5363,3.0726,32,0,0.108,187.9949,30,12,0
0.001666667,235.2,327,118,58.8,50,1.5363,3.0726,32,0,0.108,187.9949,30,12,0
0.001724537,236.6,326,118,58.8,50,1.5363,3.0726,32,0,0.108,187.9949,30,12,0
0.001782407,238.2,324,118,58.8,50,1.5363,3.0726,32,0,0.108,187.9949,30,12,0
0.001840278,240,323,118,58.8,50,1.5363,3.0726,32,0,0.108,187.9949,30,12,0
0.001898148,241.5,322,118,58.8,50,1.5363,3.0726,32,0,0.108,187.9949,30,12,0
0.001956019,242.7,320,115,58.8,50,1.5363,3.0726,32,0,0.108,187.9949,30,12,0
0.002013889,244.5,319,115,58.8,50,1.5363,3.0726,32,0,0.108,187.9949,30,12,0
0.002071759,245.8,318,115,58.8,50,1.5363,3.0726,32,0,0.108,187.9949,30,12,0
0.00212963,246.9,317,115,58.8,50,1.5363,3.0726,32,0,0.108,187.9949,30,12,0
0.0021875,248.7,315,112,58.8,50,1.5363,3.0726,32,0,0.108,187.9949,30,12,0
0.00224537,249.9,314,112,58.8,50,1.5363,3.0726,32,0,0.108,187.9949,30,12,0
0.002314815,250.8,313,112,58.8,50,1.5363,3.0726,32,0,0.108,187.9949,30,12,0
0.002372685,252.4,312,112,58.8,50,1.5363,3.0726,32,0,0.108,187.9949,30,12,0
0.002430556,253.5,311,112,58.8,50,1.5363,3.0726,32,0,0.108,187.9949,30,12,0
0.002488426,254.4,310,112,58.8,50,1.5363,3.0726,32,0,0.108,187.9949,30,12,0
0.002546296,256,309,112,58.8,50,1.5363,3.0726,32,0,0.108,187.9949,30,12,0
0.002604167,256.9,308,112,58.8,50,1.5363,3.0726,32,0,0.108,187.9949,30,12,0
0.002662037,257.8,307,112,58.8,50,1.5363,3.0726,32,0,0.108,187.9949,30,12,0
0.002719907,259.3,306,112,58.8,50,1.5363,3.0726,32,0,0.108,187.9949,30,12,0
0.002777778,260,305,106,58.8,50,1.5363,3.0726,32,0,0.108,187.9949,30,12,0
0.002835648,261.1,304,106,58.8,50,1.5363,3.0726,32,0,0.108,187.9949,30,12,0
0.002893519,262,303,106,58.8,50,1.5363,3.0726,32,0,0.108,187.9949,30,12,0
0.002951389,262.9,302,106,58.8,50,1.5363,3.0726,32,0,0.108,187.9949,30,12,0
0.003020833,263.8,301,106,58.8,50,1.5363,3.0726,32,0,0.108,187.9949,30,12,0
0.003078704,264.7,300,106,58.8,50,1.5363,3.0726,32,0,0.108,187.9949,30,12,0
0.003136574,265.4,300,106,58.8,50,1.5363,3.0726,32,0,0.108,187.9949,30,12,0
0.003194444,266.1,299,106,58.8,50,1.5363,3.0726,32,0,0.108,187.9949,30,12,0
0.003252315,267,298,106,58.8,50,1.5363,3.0726,32,0,0.108,187.9949,30,12,0
0.003310185,267.7,297,106,58.8,50,1.5363,3.0726,32,0,0.108,187.9949,30,12,0
0.003368056,268.3,296,102,58.8,50,1.5363,3.0726,32,0,0.108,187.9949,30,12,0
0.003425926,269.2,296,102,58.8,50,1.5363,3.0726,32,0,0.108,187.9949,30,12,0
0.003483796,269.7,295,102,58.8,50,1.5363,3.0726,32,0,0.108,187.9949,30,12,0
0.003541667,270.2,294,102,58.8,50,1.5363,3.0726,32,0,0.108,187.9949,30,12,0
0.003599537,271,294,102,58.8,50,1.5363,3.0726,32,0,0.108,187.9949,30,12,0
0.003657407,271.3,293,102,58.8,50,1.5363,3.0726,32,0,0.108,187.9949,30,12,0
0.003726852,272,292,102,58.8,50,1.5363,3.0726,32,0,0.108,187.9949,30,12,0
0.003784722,272.4,292,102,58.8,50,1.5363,3.0726,32,0,0.108,187.9949,30,12,0
0.003842593,272.9,291,102,58.8,50,1.5363,3.0726,32,0,0.108,187.9949,30,12,0
0.003900463,273.3,290,99,58.8,50,1.5363,3.0726,32,0,0.108,187.9949,30,12,0
0.003958333,273.8,290,102,58.8,50,1.5363,3.0726,32,0,0.108,187.9949,30,12,0
0.004016204,274.2,289,102,58.8,50,1.5363,3.0726,32,0,0.108,187.9949,30,12,0
0.004074074,274.6,288,99,58.8,50,1.5363,3.0726,32,0,0.108,187.9949,30,12,0
0.004131944,275.1,288,99,58.8,50,1.5363,3.0726,32,0,0.108,187.9949,30,12,0
0.004189815,275.4,287,99,58.8,50,1.5363,3.0726,32,0,0.108,187.9949,30,12,0
0.004247685,275.6,287,102,58.8,50,1.5363,3.0726,32,0,0.108,187.9949,30,12,0
0.004305556,276.2,286,99,58.8,50,1.5363,3.0726,32,0,0.108,187.9949,30,12,0
0.004363426,276.3,286,99,58.8,50,1.5363,3.0726,32,0,0.108,187.9949,30,12,0
0.00443287,276.5,285,99,58.8,50,1.5363,3.0726,32,0,0.108,187.9949,30,12,0
0.004490741,276.9,284,99,58.8,50,1.5363,3.0726,32,0,0.108,187.9949,30,12,0
0.004548611,277.1,284,99,58.8,50,1.5363,3.0726,32,0,0.108,187.9949,30,12,0
0.004606481,277.4,283,99,58.8,50,1.5363,3.0726,32,0,0.108,187.9949,30,12,0
0.004664352,277.4,283,99,58.8,50,1.5363,3.0726,32,0,0.108,187.9949,30,12,0
0.004722222,277.8,283,99,58.8,50,1.5363,3.0726,32,0,0.108,187.9949,30,12,0
0.004780093,278,282,96,58.8,50,1.5363,3.0726,32,0,0.108,187.9949,30,12,0
0.004837963,278.1,282,96,58.8,50,1.5363,3.0726,32,0,0.108,187.9949,30,12,0
0.004895833,278.3,281,96,58.8,50,1.5363,3.0726,32,0,0.108,187.9949,30,12,0
0.004953704,278.3,281,96,58.8,50,1.5363,3.0726,32,0,0.108,187.9949,30,12,0
0.005011574,278.7,280,96,58.8,50,1.5363,3.0726,32,0,0.108,187.9949,30,12,0
0.005081019,278.7,280,96,58.8,50,2.0482,4.0965,32,0,0.144,250.6395,30,13,0
0.005138889,278.9,279,96,58.8,50,2.0482,4.0965,32,0,0.144,250.6395,30,13,0
0.005196759,279,279,96,58.8,50,1.5363,3.0726,32,0,0.108,187.9949,30,12,0
0.00525463,279,278,96,58.8,50,2.0482,4.0965,32,0,0.144,250.6395,30,13,0
0.0053125,279,278,96,58.8,50,2.0482,4.0965,32,0,0.144,250.6395,30,13,0
0.00537037,279,277,96,58.8,50,2.0482,4.0965,32,0,0.144,250.6395,30,13,0
0.005428241,279.2,277,96,58.8,50,2.0482,4.0965,32,0,0.144,250.6395,30,13,0
0.005486111,279.2,276,96,58.8,50,2.0482,4.0965,32,0,0.144,250.6395,30,13,0
0.005543981,279.2,276,96,58.8,50,2.0482,4.0965,32,0,0.144,250.6395,30,13,0
0.005601852,279.2,276,96,58.8,50,2.0482,4.0965,32,0,0.144,250.6395,30,13,0
0.005659722,279.2,275,96,58.8,50,2.0482,4.0965,32,0,0.144,250.6395,30,13,0
0.005717593,279.2,275,96,58.8,50,2.0482,4.0965,32,0,0.144,250.6395,30,13,0
0.005775463,279.2,275,96,58.8,50,2.0482,4.0965,32,0,0.144,250.6395,30,13,0
0.005844907,279.2,274,96,58.8,50,2.0482,4.0965,32,0,0.144,250.6395,30,13,0
0.005902778,279.2,274,96,58.8,50,2.0482,4.0965,32,0,0.144,250.6395,30,13,0
0.005960648,279.2,273,96,58.8,50,2.0482,4.0965,32,0,0.144,250.6395,30,13,0
0.006018519,279.2,273,96,58.8,50,2.0482,4.0965,32,0,0.144,250.6395,30,13,0
0.006076389,279.2,273,93,58.8,50,2.0482,4.0965,32,0,0.144,250.6395,30,13,0
0.006134259,279,272,96,58.8,50,2.0482,4.0965,32,0,0.144,250.6395,30,13,0
0.00619213,279.2,272,96,58.8,50,2.0482,4.0965,32,0,0.144,250.6395,30,13,0
0.00625,279,272,96,58.8,50,2.0482,4.0965,32,0,0.144,250.6395,30,13,0
0.00630787,279,271,93,58.8,50,2.0482,4.0965,32,0,0.144,250.6395,30,13,0
0.006365741,279,271,93,58.8,50,2.0482,4.0965,32,0,0.144,250.6395,30,13,0
0.006423611,278.9,271,96,58.8,50,2.0482,4.0965,32,0,0.144,250.6395,30,13,0
0.006481481,278.7,270,93,58.8,50,2.0482,4.0965,32,0,0.144,250.6395,30,13,0
0.006550926,278.7,270,93,58.8,50,2.0482,4.0965,32,0,0.144,250.6395,30,13,0
0.006608796,278.7,269,96,58.8,50,2.0482,4.0965,32,0,0.144,250.6395,30,13,0
0.006666667,278.5,269,93,58.8,50,2.0482,4.0965,32,0,0.144,250.6395,30,13,0
0.006724537,278.3,269,93,58.8,50,2.0482,4.0965,32,0,0.144,250.6395,30,13,0
0.006782407,278.1,269,93,58.8,50,2.0482,4.0965,32,0,0.144,250.6395,30,13,0
0.006840278,278.1,268,93,58.8,50,2.0482,4.0965,32,0,0.144,250.6395,30,13,0
0.006898148,278,268,93,58.8,50,2.0482,4.0965,32,0,0.144,250.6395,30,13,0
0.006956019,277.8,268,93,58.8,50,2.0482,4.0965,32,0,0.144,250.6395,30,13,0
0.007013889,277.8,267,93,58.8,50,2.0482,4.0965,32,0,0.144,250.6395,30,13,0
0.007083333,277.6,267,93,58.8,50,2.0482,4.0965,32,0,0.144,250.6395,30,13,0
0.007141204,277.4,267,93,58.8,50,2.0482,4.0965,32,0,0.144,250.6395,30,13,0
0.007199074,277.2,266,93,58.8,50,2.0482,4.0965,32,0,0.144,250.6395,30,13,0
0.007256944,277.2,266,93,58.8,50,2.0482,4.0965,32,0,0.144,250.6395,30,13,0
0.007314815,277.1,266,93,58.8,50,2.0482,4.0965,32,0,0.144,250.6395,30,13,0
0.007372685,276.9,265,93,58.8,50,2.0482,4.0965,32,0,0.144,250.6395,30,13,0
0.007430556,276.9,265,93,58.8,50,2.0482,4.0965,32,0,0.144,250.6395,30,13,0
0.007488426,276.5,265,93,58.8,50,2.0482,4.0965,32,0,0.144,250.6395,30,13,0
0.00755787,276.5,264,99,58.8,50,2.0482,4.0965,32,0,0.144,250.6395,30,13,0
0.007615741,276.5,264,106,58.8,50,2.0482,4.0965,32,0,0.144,250.6395,30,13,0
0.007673611,276.3,264,106,58.8,50,2.0482,4.0965,32,0,0.144,250.6395,30,13,0
0.007731481,276,264,106,58.8,50,2.0482,4.0965,32,0,0.144,250.6395,30,13,0
0.007789352,276,263,106,58.8,50,2.0482,4.0965,32,0,0.144,250.6395,30,13,0
0.007847222,275.6,263,112,58.8,50,2.0482,4.0965,32,0,0.144,250.6395,30,13,0
0.007905093,275.4,263,112,58.8,50,2.0482,4.0965,32,0,0.144,250.6395,30,13,0
0.007962963,275.3,262,112,58.8,50,2.0482,4.0965,32,0,0.144,250.6395,30,13,0
0.008020833,275.1,262,112,58.8,50,2.5602,5.1203,32,0,0.18,313.2841,30,14,0
0.008078704,274.9,262,112,58.8,50,2.0482,4.0965,32,0,0.144,250.6395,30,13,0
0.008136574,274.7,262,112,58.8,50,2.0482,4.0965,32,0,0.144,250.6395,30,13,0
0.008206019,274.6,261,115,58.8,50,2.0482,4.0965,32,0,0.144,250.6395,30,13,0
0.008263889,274.6,261,115,58.8,50,2.5602,5.1203,32,0,0.18,313.2841,30,14,0
0.008321759,274.2,261,112,58.8,50,2.0482,4.0965,32,0,0.144,250.6395,30,13,0
0.00837963,274,261,112,58.8,50,2.5602,5.1203,32,0,0.18,313.2841,30,14,0
0.0084375,273.8,260,112,58.8,50,2.5602,5.1203,32,0,0.18,313.2841,30,14,0
0.00849537,273.7,260,115,58.8,50,2.0482,4.0965,32,0,0.144,250.6395,30,13,0
0.008553241,273.5,260,115,58.8,50,2.5602,5.1203,32,0,0.18,313.2841,30,14,0
0.008611111,273.3,259,115,58.8,50,2.5602,5.1203,32,0,0.18,313.2841,30,14,0
0.008668981,272.9,259,115,58.8,50,2.5602,5.1203,32,0,0.18,313.2841,30,14,0
0.008726852,272.9,259,115,58.8,50,2.5602,5.1203,32,0,0.18,313.2841,30,14,0
0.008784722,272.8,259,115,58.8,50,2.5602,5.1203,32,0,0.18,313.2841,30,14,0
0.008842593,272.4,258,115,58.8,50,2.5602,5.1203,32,0,0.18,313.2841,30,14,0
0.008900463,272.4,258,115,58.8,50,2.5602,5.1203,32,0,0.18,313.2841,30,14,0
0.008958333,272,258,115,58.8,50,2.5602,5.1203,32,0,0.18,313.2841,30,14,0
0.009016204,271.9,258,115,58.8,50,2.5602,5.1203,32,0,0.18,313.2841,30,14,0
0.009074074,271.9,257,115,58.8,50,2.5602,5.1203,32,0,0.18,313.2841,30,14,0
0.009143519,271.5,257,115,58.8,50,2.5602,5.1203,32,0,0.18,313.2841,30,14,0
0.009201389,271.1,257,115,58.8,50,2.5602,5.1203,32,0,0.18,313.2841,30,14,0
0.009259259,271.1,257,115,58.8,50,2.5602,5.1203,32,0,0.18,313.2841,30,14,0
0.00931713,271,256,115,58.8,50,2.5602,5.1203,32,0,0.18,313.2841,30,14,0
0.009375,270.6,256,115,58.8,50,2.5602,5.1203,32,0,0.18,313.2841,30,14,0
0.00943287,270.2,256,115,58.8,50,2.5602,5.1203,32,0,0.18,313.2841,30,14,0
0.009490741,270.2,256,115,58.8,50,2.5602,5.1203,32,0,0.18,313.2841,30,14,0
0.009548611,270.1,255,115,58.8,50,2.5602,5.1203,32,0,0.18,313.2841,30,14,0
0.009606481,269.7,255,115,58.8,50,2.5602,5.1203,32,0,0.18,313.2841,30,14,0
0.009664352,269.5,255,115,58.8,50,2.5602,5.1203,32,0,0.18,313.2841,30,14,0
0.009722222,269.3,255,115,58.8,50,2.5602,5.1203,32,0,0.18,313.2841,30,14,0
0.009780093,269.2,254,115,58.8,50,2.5602,5.1203,32,0,0.18,313.2841,30,14,0
0.009849537,269,254,115,58.8,50,2.5602,5.1203,409,0,0.18,313.2841,30,14,0
0.009907407,268.8,255,115,58.8,50,2.5602,5.1203,409,70,0.18,313.2841,30,14,0
0.009965278,268.4,259,115,58.8,50,2.5602,5.1203,409,70,0.18,313.2841,30,14,0
0.010023148,268.3,269,115,58.8,50,2.5602,5.1203,408,70,0.18,313.2841,30,14,0
0.010081019,267.9,277,115,58.8,50,2.5602,5.1203,408,70,0.18,313.2841,30,14,0
0.010138889,267.9,287,118,58.8,50,2.5602,5.1203,408,70,0.18,313.2841,30,14,0
0.010196759,267.5,295,115,58.8,50,2.5602,5.1203,408,70,0.18,313.2841,30,14,0
0.01025463,267.5,308,115,58.8,50,2.0482,4.0965,407,70,0.144,250.6395,30,13,0
0.0103125,267.5,316,118,58.8,50,3.0721,6.1442,407,70,0.216,375.9286,30,15,0
0.01037037,267.5,324,118,58.8,50,2.5602,5.1203,407,70,0.18,313.2841,30,14,0
0.010439815,267.5,335,118,58.8,50,2.0482,4.0965,407,70,0.144,250.6395,30,13,0
0.010497685,267.7,343,118,58.8,50,2.5602,5.1203,406,70,0.18,313.2841,30,14,0
0.010555556,267.9,353,118,58.8,50,2.0482,4.0965,406,70,0.144,250.6395,30,13,0
0.010613426,268.4,359,118,58.8,50,2.0482,4.0965,406,70,0.144,250.6395,30,13,0
0.010671296,268.8,366,118,58.8,50,2.0482,4.0965,406,70,0.144,250.6395,30,13,0
0.010729167,269.5,373,118,58.8,50,2.0482,4.0965,405,70,0.144,250.6395,30,13,0
0.010787037,270.1,382,118,58.8,50,2.0482,4.0965,405,70,0.144,250.6395,30,13,0
0.010844907,271,388,118,58.8,50,2.0482,4.0965,405,70,0.144,250.6395,30,13,0
0.010902778,271.7,394,118,58.8,50,2.0482,4.0965,405,70,0.144,250.6395,30,13,0
0.010960648,272.4,403,118,58.8,50,2.0482,4.0965,404,70,0.144,250.6395,30,13,0
0.011018519,273.7,409,118,58.8,50,2.0482,4.0965,404,70,0.144,250.6395,30,13,0
0.011076389,274.4,415,118,58.8,50,1.5363,3.0726,404,70,0.108,187.9949,30,12,0
0.011134259,275.4,422,118,58.8,50,1.5363,3.0726,404,67,0.108,187.9949,30,12,0
0.01119213,276.5,429,118,58.8,50,1.5363,3.0726,403,55.1,0.108,187.9949,30,12,0
0.01125,277.6,434,118,58.8,50,1.5363,3.0726,403,46.5,0.108,187.9949,30,12,0
0.01130787,278.7,439,118,58.8,50,1.5363,3.0726,403,40.5,0.108,187.9949,30,12,0
0.011365741,279.9,442,118,58.8,50,1.5363,3.0726,403,39.2,0.108,187.9949,30,12,0
0.011423611,281.2,444,121,58.8,50,1.5363,3.0726,402,38.3,0.108,187.9949,30,12,0
0.011481481,282.3,446,118,58.8,50,1.5363,3.0726,402,33.8,0.108,187.9949,30,12,0
0.011550926,283.7,447,121,58.8,50,1.5363,3.0726,402,31.3,0.108,187.9949,30,12,0
0.011608796,285,448,121,58.8,50,1.5363,3.0726,402,28.4,0.108,187.9949,30,12,0
0.011678241,287.1,448,121,58.8,50,1.0244,2.0487,402,26.4,0.072,125.3503,30,11,0
0.011793981,288.9,448,121,58.8,50,1.0244,2.0487,401,20.3,0.072,125.3503,30,11,0
0.011863426,293.1,448,121,58.8,50,1.5363,3.0726,410,36.4,0.108,187.9949,30,12,0
0.011921296,294.7,447,121,58.8,50,1.0244,2.0487,410,31.4,0.072,125.3503,30,11,0
0.011979167,297.4,448,118,58.8,50,1.0244,2.0487,410,23.6,0.072,125.3503,30,11,0
0.012037037,299.4,448,121,58.8,50,1.0244,2.0487,410,19.2,0.072,125.3503,30,11,0
0.012094907,301.3,448,121,58.8,50,1.0244,2.0487,410,16.7,0.072,125.3503,30,11,0
0.012152778,303.7,448,121,58.8,50,1.0244,2.0487,410,16,0.072,125.3503,30,11,0
0.012210648,305.7,447,121,58.8,50,1.5363,3.0726,409,14.2,0.108,187.9949,30,12,0
0.012268519,307.5,446,121,58.8,50,1.0244,2.0487,409,14.8,0.072,125.3503,30,11,0
0.012326389,309.1,445,121,58.8,50,1.0244,2.0487,409,14.5,0.072,125.3503,30,11,0
0.012384259,311.6,444,121,58.8,50,1.5363,3.0726,409,13.8,0.108,187.9949,30,12,0
0.01244213,313.4,443,118,58.8,50,1.0244,2.0487,408,10.5,0.072,125.3503,30,11,0
0.0125,315.5,442,121,58.8,50,1.0244,2.0487,408,10,0.072,125.3503,30,11,0
0.012569444,317,440,121,58.8,50,1.0244,2.0487,408,10.2,0.072,125.3503,30,11,0
0.012627315,318.8,439,121,58.8,50,1.0244,2.0487,408,9.7,0.072,125.3503,30,11,0
0.012685185,320.9,438,121,58.8,50,1.0244,2.0487,408,10.5,0.072,125.3503,30,11,0
0.012743056,322.4,436,121,58.8,50,1.0244,2.0487,408,9.7,0.072,125.3503,30,11,0
0.012800926,324.4,435,121,58.8,50,1.0244,2.0487,407,7.5,0.072,125.3503,30,11,0
0.012858796,325.8,434,121,58.8,50,1.0244,2.0487,407,7.7,0.072,125.3503,30,11,0
0.012916667,327.2,432,121,58.8,50,1.0244,2.0487,407,8.1,0.072,125.3503,30,11,0
0.012974537,329,431,121,58.8,50,1.0244,2.0487,407,8.4,0.072,125.3503,30,11,0
0.013032407,330.3,430,118,58.8,50,1.0244,2.0487,407,8.1,0.072,125.3503,30,11,0
0.013090278,331.7,429,121,58.8,50,1.0244,2.0487,406,6.4,0.072,125.3503,30,11,0
0.013148148,333.3,428,121,58.8,50,1.0244,2.0487,406,6.3,0.072,125.3503,30,11,0
0.013217593,334.6,427,121,58.8,50,1.0244,2.0487,406,6.4,0.072,125.3503,30,11,0
0.013275463,335.7,425,121,58.8,50,1.0244,2.0487,406,7.3,0.072,125.3503,30,11,0
0.013333333,337.5,424,121,58.8,50,1.0244,2.0487,406,7.5,0.072,125.3503,30,11,0
0.013391204,338.4,423,121,58.8,50,1.0244,2.0487,405,6,0.072,125.3503,30,11,0
0.013449074,339.8,422,121,58.8,50,1.0244,2.0487,405,5.9,0.072,125.3503,30,11,0
0.013506944,340.7,421,118,58.8,50,1.0244,2.0487,405,6.8,0.072,125.3503,30,11,0
0.013564815,342,420,121,58.8,50,1.0244,2.0487,405,7.2,0.072,125.3503,30,11,0
0.013622685,343,419,121,58.8,50,1.0244,2.0487,405,7.4,0.072,125.3503,30,11,0
0.013680556,344.1,418,118,58.8,50,1.0244,2.0487,404,5.5,0.072,125.3503,30,11,0
0.013738426,345.2,417,118,58.8,50,1.0244,2.0487,404,5.9,0.072,125.3503,30,11,0
0.013796296,346.5,416,121,58.8,50,1.0244,2.0487,404,6.5,0.072,125.3503,30,11,0
0.013865741,347.4,415,118,58.8,50,1.0244,2.0487,404,6.7,0.072,125.3503,30,11,0
0.013923611,348.3,414,118,58.8,50,1.0244,2.0487,404,7.4,0.072,125.3503,30,11,0
0.013981481,349.3,414,118,58.8,50,1.0244,2.0487,403,5.5,0.072,125.3503,30,11,0
0.014039352,350.2,413,118,58.8,50,1.0244,2.0487,403,5.9,0.072,125.3503,30,11,0
0.014097222,351.1,412,118,58.8,50,1.0244,2.0487,403,6.8,0.072,125.3503,30,11,0
0.014155093,352.2,411,118,58.8,50,1.0244,2.0487,403,7.3,0.072,125.3503,30,11,0
0.014212963,352.9,411,118,58.8,50,1.0244,2.0487,403,7.4,0.072,125.3503,30,11,0
0.014270833,353.7,410,118,58.8,50,1.0244,2.0487,402,5.7,0.072,125.3503,30,11,0
0.014328704,354.7,410,118,58.8,50,1.0244,2.0487,402,5.9,0.072,125.3503,30,11,0
0.014386574,355.6,409,118,58.8,50,1.0244,2.0487,402,7,0.072,125.3503,30,11,0
0.014444444,356.5,408,118,58.8,50,1.0244,2.0487,402,7.2,0.072,125.3503,30,11,0
0.014513889,357.3,408,118,58.8,50,1.0244,2.0487,402,7.6,0.072,125.3503,30,11,0
0.014571759,358.2,407,118,58.8,50,1.0244,2.0487,401,5.9,0.072,125.3503,30,11,0
0.01462963,358.7,407,118,58.8,50,1.0244,2.0487,401,5.9,0.072,125.3503,30,11,0
0.0146875,359.6,406,118,58.8,50,1.0244,2.0487,401,6,0.072,125.3503,30,11,0
0.01474537,360.1,406,118,58.8,50,1.0244,2.0487,401,7.5,0.072,125.3503,30,11,0
0.014803241,361,405,115,58.8,50,1.0244,2.0487,401,8,0.072,125.3503,30,11,0
0.014861111,361.7,405,115,58.8,50,1.0244,2.0487,401,7.8,0.072,125.3503,30,11,0
0.014918981,362.3,405,115,58.8,50,1.0244,2.0487,400,5.7,0.072,125.3503,30,11,0
0.014976852,362.8,404,115,58.8,50,1.0244,2.0487,400,6.4,0.072,125.3503,30,11,0
0.015034722,363.7,404,118,58.8,50,1.0244,2.0487,400,7.3,0.072,125.3503,30,11,0
0.015092593,364.4,403,118,58.8,50,1.0244,2.0487,400,7.6,0.072,125.3503,30,11,0
0.015150463,364.8,403,115,58.8,50,1.0244,2.0487,399,6.3,0.072,125.3503,30,11,0
0.015208333,365.5,403,115,58.8,50,1.0244,2.0487,399,6.2,0.072,125.3503,30,11,0
0.015266204,367,402,118,58.8,50,1.0244,2.0487,399,6.3,0.072,125.3503,30,11,0
0.015324074,367.7,402,115,58.8,50,1.0244,2.0487,399,7.4,0.072,125.3503,30,11,0
0.015381944,368.2,402,115,58.8,50,1.0244,2.0487,399,7.3,0.072,125.3503,30,11,0
0.015451389,368.6,401,115,58.8,50,1.0244,2.0487,399,7.7,0.072,125.3503,30,11,0
0.015509259,369.1,401,115,58.8,50,1.5363,3.0726,398,6.1,0.108,187.9949,30,12,0
0.01556713,369.7,401,115,58.8,50,1.0244,2.0487,398,6.3,0.072,125.3503,30,11,0
0.015625,370,400,115,58.8,50,1.0244,2.0487,398,6.9,0.072,125.3503,30,11,0
0.01568287,370.7,400,115,58.8,50,1.0244,2.0487,398,7,0.072,125.3503,30,11,0
0.015740741,371.1,400,115,58.8,50,1.0244,2.0487,398,7.6,0.072,125.3503,30,11,0
0.015798611,371.5,400,115,58.8,50,1.0244,2.0487,397,5.9,0.072,125.3503,30,11,0
0.015856481,372,399,115,58.8,50,1.0244,2.0487,397,6.5,0.072,125.3503,30,11,0
0.015914352,372.4,399,115,58.8,50,1.0244,2.0487,397,7,0.072,125.3503,30,11,0
0.015972222,372.7,399,115,58.8,50,1.0244,2.0487,397,7.1,0.072,125.3503,30,11,0
0.016030093,373.3,398,115,58.8,50,1.0244,2.0487,397,7.5,0.072,125.3503,30,11,0
0.016087963,373.6,398,112,58.8,50,1.0244,2.0487,396,5.7,0.072,125.3503,30,11,0
0.016145833,374,398,115,58.8,50,1.0244,2.0487,401,14.1,0.072,125.3503,30,11,0
0.016203704,374.3,398,112,58.8,50,1.0244,2.0487,420,38.8,0.072,125.3503,30,11,0
0.016261574,374.5,399,115,58.8,50,1.5363,3.0726,420,39.7,0.108,187.9949,30,12,0
0.016331019,374.9,402,115,58.8,50,1.0244,2.0487,420,24.6,0.072,125.3503,30,11,0
0.016388889,375.4,405,115,58.8,50,1.0244,2.0487,420,16.7,0.072,125.3503,30,11,0
0.016446759,375.6,408,112,58.8,50,1.0244,2.0487,420,13.6,0.072,125.3503,30,11,0
0.01650463,375.9,410,112,58.8,50,1.0244,2.0487,420,15.2,0.072,125.3503,30,11,0
0.0165625,376.3,411,115,58.8,50,1.0244,2.0487,420,17.6,0.072,125.3503,30,11,0
0.01662037,376.7,412,112,58.8,50,1.0244,2.0487,428,32.3,0.072,125.3503,30,11,0
0.016678241,377,413,112,58.8,50,1.0244,2.0487,430,33.1,0.072,125.3503,30,11,0
0.016736111,377.2,415,115,58.8,50,1.0244,2.0487,430,27.2,0.072,125.3503,30,11,0
0.016793981,377.7,417,112,58.8,50,1.0244,2.0487,430,21.4,0.072,125.3503,30,11,0
0.016851852,377.9,420,115,58.8,50,1.0244,2.0487,430,17.5,0.072,125.3503,30,11,0
0.016909722,378.5,422,112,58.8,50,1.0244,2.0487,430,17.3,0.072,125.3503,30,11,0
0.016967593,378.8,423,115,58.8,50,1.0244,2.0487,430,18.3,0.072,125.3503,30,11,0
0.017025463,379.2,424,112,58.8,50,1.0244,2.0487,430,19,0.072,125.3503,30,11,0
0.017083333,379.7,425,112,58.8,50,1.0244,2.0487,430,18.6,0.072,125.3503,30,11,0
0.017141204,379.9,426,112,58.8,50,1.0244,2.0487,430,17.1,0.072,125.3503,30,11,0
0.017210648,380.6,427,115,58.8,50,0,0,430,16.5,-0.036,0,30,8,0
0.017268519,380.8,427,115,58.8,50,1.5363,3.0726,430,16.3,0.108,187.9949,30,12,0
0.017326389,381.2,428,115,58.8,50,1.0244,2.0487,430,15.1,0.072,125.3503,30,11,0
0.017384259,381.7,429,112,58.8,50,1.0244,2.0487,430,14.7,0.072,125.3503,30,11,0
0.01744213,382.2,429,112,58.8,50,1.0244,2.0487,392,15,0.072,125.3503,30,11,0
0.0175,382.6,429,112,58.8,50,1.0244,2.0487,430,16.6,0.072,125.3503,30,11,0
0.01755787,383.3,429,112,58.8,50,1.0244,2.0487,427,12.7,0.072,125.3503,30,11,0
0.017615741,383.5,429,115,58.8,50,1.0244,2.0487,420,0.5,0.072,125.3503,30,11,0
0.017673611,384.2,429,112,58.8,50,1.0244,2.0487,392,0,0.072,125.3503,30,11,0
0.017731481,384.8,428,112,58.8,50,1.0244,2.0487,392,0,0.072,125.3503,30,11,0
0.017789352,385.1,427,112,58.8,50,1.5363,3.0726,392,0,0.108,187.9949,30,12,0
0.017847222,385.5,425,112,58.8,50,1.0244,2.0487,392,0,0.072,125.3503,30,11,0
0.017905093,386,424,112,58.8,50,1.0244,2.0487,392,0,0.072,125.3503,30,11,0
0.017962963,386.6,422,112,58.8,50,1.0244,2.0487,392,0,0.072,125.3503,30,11,0
0.018032407,386.9,420,112,58.8,50,1.5363,3.0726,392,0,0.108,187.9949,30,12,0
0.018090278,387.3,419,112,58.8,50,1.5363,3.0726,392,0,0.108,187.9949,30,12,0
0.018148148,387.8,418,115,58.8,50,1.0244,2.0487,392,0,0.072,125.3503,30,11,0
0.018206019,388.2,416,115,58.8,50,1.0244,2.0487,392,0,0.072,125.3503,30,11,0
0.018263889,388.5,415,112,58.8,50,1.0244,2.0487,392,0,0.072,125.3503,30,11,0
0.018321759,388.9,414,115,58.8,50,1.0244,2.0487,392,0,0.072,125.3503,30,11,0
0.01837963,389.4,413,112,58.8,50,1.0244,2.0487,392,0,0.072,125.3503,30,11,0
0.0184375,389.8,411,115,58.8,50,1.0244,2.0487,392,0,0.072,125.3503,30,11,0
0.01849537,390.2,410,112,58.8,50,1.0244,2.0487,392,0,0.072,125.3503,30,11,0
0.018553241,390.3,409,112,58.8,50,1.0244,2.0487,392,0,0.072,125.3503,30,11,0
0.018611111,390.7,408,112,58.8,50,1.0244,2.0487,392,0,0.072,125.3503,30,11,0
0.018668981,391.1,407,112,58.8,50,1.0244,2.0487,392,0,0.072,125.3503,30,11,0
0.018726852,391.1,406,112,58.8,50,1.0244,2.0487,392,0,0.072,125.3503,30,11,0
0.018796296,391.4,405,112,58.8,50,1.0244,2.0487,392,0,0.072,125.3503,30,11,0
0.018854167,391.6,404,112,58.8,50,1.0244,2.0487,392,0,0.072,125.3503,30,11,0
0.018912037,391.9,403,112,58.8,50,1.0244,2.0487,392,0,0.072,125.3503,30,11,0
0.018969907,392.1,402,112,58.8,50,1.0244,2.0487,392,0,0.072,125.3503,30,11,0
0.019027778,392.3,401,112,58.8,50,1.0244,2.0487,392,0,0.072,125.3503,30,11,0
0.019085648,392.5,400,112,58.8,50,1.0244,2.0487,392,0,0.072,125.3503,30,11,0
0.019143519,392.5,399,112,58.8,50,1.0244,2.0487,392,0,0.072,125.3503,30,11,0
0.019201389,392.7,398,112,58.8,50,1.0244,2.0487,392,0,0.072,125.3503,30,11,0
0.019259259,392.8,397,112,58.8,50,0.5124,1.0249,392,0,0.036,62.7058,30,10,0
0.01931713,392.8,396,112,58.8,50,1.0244,2.0487,392,0.4,0.072,125.3503,30,11,0
0.019375,393,395,112,58.8,50,1.0244,2.0487,392,1.7,0.072,125.3503,30,11,0
0.01943287,393,394,112,58.8,50,0.5124,1.0249,392,2.3,0.036,62.7058,30,10,0
0.019490741,393.2,394,112,58.8,50,1.0244,2.0487,392,2.8,0.072,125.3503,30,11,0
0.019548611,393.2,393,112,58.8,50,1.0244,2.0487,392,3.1,0.072,125.3503,30,11,0
0.019618056,393.2,393,112,58.8,50,1.0244,2.0487,392,3.4,0.072,125.3503,30,11,0
0.019675926,393.2,392,112,58.8,50,1.0244,2.0487,392,3.3,0.072,125.3503,30,11,0
0.01974537,393.2,392,112,58.8,50,1.0244,2.0487,392,3.5,0.072,125.3503,30,11,0
0.019803241,393.2,392,112,58.8,50,1.0244,2.0487,392,4.2,0.072,125.3503,30,11,0
0.019861111,393.2,391,112,58.8,50,1.0244,2.0487,392,4.4,0.072,125.3503,30,11,0
0.019930556,393,391,112,58.8,50,1.0244,2.0487,392,4.6,0.072,125.3503,30,11,0
0.019988426,392.8,391,112,58.8,50,1.0244,2.0487,392,5,0.072,125.3503,30,11,0
0.020046296,392.8,391,112,58.8,50,1.0244,2.0487,392,5.3,0.072,125.3503,30,11,0
0.020104167,392.8,391,112,58.8,50,1.0244,2.0487,392,4.9,0.072,125.3503,30,11,0
0.020173611,392.8,390,106,58.8,50,1.0244,2.0487,392,5.3,0.072,125.3503,30,11,0
0.02025463,392.5,390,112,58.8,50,1.0244,2.0487,392,5.8,0.072,125.3503,30,11,0
0.0203125,392.5,390,112,58.8,50,1.0244,2.0487,392,5.3,0.072,125.3503,30,11,0
0.020393519,392.5,390,106,58.8,50,1.0244,2.0487,392,5.4,0.072,125.3503,30,11,0
0.020462963,392.5,390,112,58.8,50,1.0244,2.0487,392,5.8,0.072,125.3503,30,11,0
0.020532407,392.3,390,112,58.8,50,1.0244,2.0487,392,5.9,0.072,125.3503,30,11,0
0.020601852,392.1,390,112,58.8,50,1.0244,2.0487,392,6.2,0.072,125.3503,30,11,0
0.020671296,391.9,390,112,58.8,50,1.0244,2.0487,392,5.9,0.072,125.3503,30,11,0
0.020729167,391.9,390,106,58.8,50,1.0244,2.0487,392,5.8,0.072,125.3503,30,11,0
0.020787037,391.8,390,112,58.8,50,1.0244,2.0487,392,6.2,0.072,125.3503,30,11,0
0.020844907,391.6,390,112,58.8,50,1.0244,2.0487,392,6.3,0.072,125.3503,30,11,0
0.020902778,391.6,390,112,117.61,100,1.5363,1.5363,392,6.2,0.108,187.9949,30,12,0
0.020972222,391.4,390,106,88.2,75,1.5363,2.0484,392,6.1,0.108,187.9949,30,12,0
0.021030093,391.1,391,106,88.2,75,1.5363,2.0484,392,6.3,0.108,187.9949,30,12,0
0.021087963,391.1,390,112,58.8,50,1.0244,2.0487,392,6.7,0.072,125.3503,30,11,0
0.021145833,390.9,391,112,58.8,50,1.0244,2.0487,392,6.3,0.072,125.3503,30,11,0
0.021215278,390.7,391,112,29.4,25,0.5124,2.0497,392,6.1,0.036,62.7058,30,10,0
0.021273148,390.7,391,112,29.4,25,0.5124,2.0497,392,6.3,0.036,62.7058,30,10,0
0.021331019,390.5,391,112,58.8,50,1.0244,2.0487,392,6.4,0.072,125.3503,30,11,0
0.021400463,390.5,391,112,58.8,50,1.0244,2.0487,392,6.4,0.072,125.3503,30,11,0
0.021481481,390.5,391,106,88.2,75,1.0244,1.3658,392,6.4,0.072,125.3503,30,11,0
0.021539352,390.3,391,106,117.61,100,1.5363,1.5363,392,6.2,0.108,187.9949,30,12,0
0.021608796,390.2,391,112,117.61,100,1.5363,1.5363,392,6.8,0.108,187.9949,30,12,0
0.021666667,389.8,391,112,58.8,50,1.0244,2.0487,392,6.3,0.072,125.3503,30,11,0
0.021724537,389.8,391,112,58.8,50,1.0244,2.0487,392,6.4,0.072,125.3503,30,11,0
0.021782407,389.8,391,112,58.8,50,0.5124,1.0249,392,6.4,0.036,62.7058,30,10,0
0.021851852,389.8,391,112,58.8,50,0.5124,1.0249,392,6.3,0.036,62.7058,30,10,0
0.021909722,390.5,391,298,58.8,50,1.0244,2.0487,392,6.6,0.072,125.3503,30,11,0
0.021967593,391.1,391,425,58.8,50,1.5363,3.0726,392,6.5,0.108,187.9949,30,12,0
0.022025463,390.5,391,460,58.8,50,1.5363,3.0726,392,6.2,0.108,187.9949,30,12,0
0.022083333,390.2,391,475,58.8,50,1.5363,3.0726,392,6.3,0.108,187.9949,30,12,0
0.022141204,390,391,494,58.8,50,1.0244,2.0487,392,6.5,0.072,125.3503,30,11,0
0.022210648,389.8,391,497,58.8,50,1.0244,2.0487,392,6.4,0.072,125.3503,30,11,0
0.022268519,389.6,391,506,58.8,50,1.0244,2.0487,392,6.2,0.072,125.3503,30,11,0
0.022326389,389.4,392,509,58.8,50,1.0244,2.0487,392,6.2,0.072,125.3503,30,11,0
0.022384259,389.4,392,509,58.8,50,1.0244,2.0487,392,6.6,0.072,125.3503,30,11,0
0.022465278,389.3,392,512,58.8,50,1.0244,2.0487,392,6.3,0.072,125.3503,30,11,0
0.022581019,389.3,392,512,58.8,50,1.0244,2.0487,392,6.6,0.072,125.3503,30,11,0
0.022673611,389.1,392,512,58.8,50,1.5363,3.0726,392,6.4,0.108,187.9949,30,12,0
0.022743056,388.9,392,512,58.8,50,1.0244,2.0487,392,6.3,0.072,125.3503,30,11,0
0.0228125,388.9,392,512,58.8,50,1.0244,2.0487,392,6.5,0.072,125.3503,30,11,0
0.022893519,388.7,392,512,58.8,50,1.0244,2.0487,392,6.9,0.072,125.3503,30,11,0
0.022962963,388.7,392,512,58.8,50,1.0244,2.0487,392,6.6,0.072,125.3503,30,11,0
0.023032407,388.7,392,512,58.8,50,1.0244,2.0487,392,6.5,0.072,125.3503,30,11,0
0.023113426,388.7,392,512,58.8,50,1.0244,2.0487,392,6.8,0.072,125.3503,30,11,0
0.02318287,388.5,392,512,58.8,50,1.0244,2.0487,392,6.5,0.072,125.3503,30,11,0
0.023252315,388.5,392,512,58.8,50,1.0244,2.0487,392,6.6,0.072,125.3503,30,11,0
0.023333333,388.4,392,512,58.8,50,1.0244,2.0487,392,6.7,0.072,125.3503,30,11,0
0.023391204,388.4,392,512,58.8,50,1.0244,2.0487,392,6.4,0.072,125.3503,30,11,0
0.023460648,388.4,392,512,58.8,50,1.0244,2.0487,392,6.5,0.072,125.3503,30,11,0
0.023518519,388.2,392,512,58.8,50,1.0244,2.0487,392,6.6,0.072,125.3503,30,11,0
0.023576389,388.2,392,512,58.8,50,1.5363,3.0726,392,6.5,0.108,187.9949,30,12,0
0.023657407,388.2,392,512,58.8,50,1.0244,2.0487,392,6.8,0.072,125.3503,30,11,0
0.023726852,388,392,512,117.61,100,1.5363,1.5363,392,6.6,0.108,187.9949,30,12,0
0.023784722,388,392,509,117.61,100,1.5363,1.5363,392,6.4,0.108,187.9949,30,12,0
0.023854167,388,392,512,88.2,75,1.5363,2.0484,392,6.3,0.108,187.9949,30,12,0
0.023912037,387.8,392,512,58.8,50,1.5363,2.0484,392,6.7,0.108,187.9949,30,12,0
0.023969907,387.8,392,512,58.8,50,1.5363,3.0726,392,7.1,0.108,187.9949,30,12,0
0.024039352,387.8,392,512,29.4,25,1.5363,6.1452,392,7,0.108,187.9949,30,12,0
0.024097222,387.6,392,512,29.4,25,1.0244,4.0975,392,6.8,0.072,125.3503,30,11,0
0.024155093,387.6,392,509,58.8,50,1.0244,4.0975,392,6.7,0.072,125.3503,30,11,0
0.024236111,387.8,392,509,58.8,50,1.0244,2.0487,392,7,0.072,125.3503,30,11,0
0.024328704,387.6,392,509,88.2,75,1.5363,2.0484,392,6.3,0.108,187.9949,30,12,0
0.024386574,387.6,392,509,117.61,100,1.5363,1.5363,392,6.2,0.108,187.9949,30,12,0
0.024444444,387.5,392,509,117.61,100,1.5363,1.5363,392,6.7,0.108,187.9949,30,12,0
0.024513889,387.5,392,509,58.8,50,1.0244,2.0487,392,6.7,0.072,125.3503,30,11,0
0.024571759,387.5,392,512,58.8,50,1.0244,2.0487,392,6.6,0.072,125.3503,30,11,0
0.02462963,387.5,392,509,58.8,50,0.5124,1.0249,392,6.5,0.036,62.7058,30,10,0
0.0246875,387.3,392,512,58.8,50,1.0244,2.0487,392,6.5,0.072,125.3503,30,11,0
0.02474537,388.4,392,736,58.8,50,1.0244,2.0487,392,6.3,0.072,125.3503,30,11,0
0.024803241,388,392,770,58.8,50,1.0244,2.0487,392,6.4,0.072,125.3503,30,11,0
0.024861111,387.8,392,820,58.8,50,2.0482,4.0965,392,6.6,0.144,250.6395,30,13,0
0.024930556,387.6,392,820,58.8,50,1.0244,2.0487,392,7,0.072,125.3503,30,11,0
0.024988426,387.5,392,820,58.8,50,1.0244,2.0487,392,6.5,0.072,125.3503,30,11,0
0.025046296,387.3,392,817,58.8,50,1.0244,2.0487,392,6.3,0.072,125.3503,30,11,0
0.025104167,387.3,392,817,58.8,50,1.5363,3.0726,392,6.9,0.108,187.9949,30,12,0
0.025162037,387.1,392,817,58.8,50,1.0244,2.0487,392,6.9,0.072,125.3503,30,11,0
0.025231481,387.1,392,814,58.8,50,1.0244,2.0487,392,6.6,0.072,125.3503,30,11,0
0.025289352,387.1,392,814,58.8,50,1.0244,2.0487,392,6.6,0.072,125.3503,30,11,0
0.025347222,387.1,392,814,58.8,50,1.0244,2.0487,392,6.6,0.072,125.3503,30,11,0
0.025405093,387.1,392,811,58.8,50,1.0244,2.0487,392,6.6,0.072,125.3503,30,11,0
0.025462963,387.1,392,811,58.8,50,1.0244,2.0487,392,6.6,0.072,125.3503,30,11,0
0.025520833,386.9,392,801,58.8,50,1.0244,2.0487,392,6.6,0.072,125.3503,30,11,0
0.025578704,386.9,392,811,58.8,50,1.5363,3.0726,392,6.8,0.108,187.9949,30,12,0
0.025659722,386.9,392,801,58.8,50,1.0244,2.0487,392,6.7,0.072,125.3503,30,11,0
0.025729167,386.9,392,798,58.8,50,1.0244,2.0487,392,6.4,0.072,125.3503,30,11,0
0.025810185,386.9,392,798,58.8,50,1.0244,2.0487,392,7,0.072,125.3503,30,11,0
0.025902778,386.9,392,798,58.8,50,1.0244,2.0487,392,6.9,0.072,125.3503,30,11,0
0.025960648,386.9,392,795,58.8,50,1.5363,3.0726,392,6.6,0.108,187.9949,30,12,0
0.026018519,386.7,392,795,58.8,50,1.0244,2.0487,392,7.1,0.072,125.3503,30,11,0
0.026076389,386.7,392,795,58.8,50,1.0244,2.0487,392,6.9,0.072,125.3503,30,11,0
0.026134259,386.6,392,792,58.8,50,1.5363,3.0726,392,6.7,0.108,187.9949,30,12,0
0.02619213,386.7,392,792,58.8,50,1.0244,2.0487,392,6.8,0.072,125.3503,30,11,0
0.02625,386.6,392,792,58.8,50,1.5363,3.0726,392,6.8,0.108,187.9949,30,12,0
0.02630787,386.7,392,786,58.8,50,1.0244,2.0487,392,6.7,0.072,125.3503,30,11,0
0.026365741,386.6,392,786,58.8,50,1.0244,2.0487,392,6.6,0.072,125.3503,30,11,0
0.026435185,386.6,392,786,58.8,50,1.0244,2.0487,392,6.5,0.072,125.3503,30,11,0
0.026493056,386.6,392,795,58.8,50,1.0244,2.0487,392,6.8,0.072,125.3503,30,11,0
0.026550926,386.7,392,826,58.8,50,1.5363,3.0726,392,6.5,0.108,187.9949,30,12,0
0.026608796,386.6,392,839,117.61,100,2.0482,2.0482,392,7,0.144,250.6395,30,13,0
0.026678241,386.6,392,851,88.2,75,2.0482,2.0482,392,6.8,0.144,250.6395,30,13,0
0.026736111,386.6,392,854,88.2,75,1.5363,2.0484,392,7.5,0.108,187.9949,30,12,0
0.026793981,386.6,392,854,58.8,50,1.5363,3.0726,392,6.5,0.108,187.9949,30,12,0
0.026851852,386.4,392,860,58.8,50,1.5363,3.0726,392,6.8,0.108,187.9949,30,12,0
0.026909722,386.4,392,860,29.4,25,1.0244,4.0975,392,6.6,0.072,125.3503,30,11,0
0.026967593,386.4,392,860,29.4,25,1.0244,4.0975,392,6.7,0.072,125.3503,30,11,0
0.027025463,386.4,392,863,58.8,50,1.0244,2.0487,392,6.6,0.072,125.3503,30,11,0
0.027083333,386.2,392,860,58.8,50,1.0244,2.0487,392,6.8,0.072,125.3503,30,11,0
0.027141204,386.4,392,860,88.2,75,1.5363,2.0484,392,6.9,0.108,187.9949,30,12,0
0.027199074,386.2,392,860,88.2,75,1.5363,2.0484,392,6.7,0.108,187.9949,30,12,0
0.027256944,386.4,392,863,117.61,100,1.5363,1.5363,392,6.7,0.108,187.9949,30,12,0
0.027326389,386.2,392,863,58.8,50,2.0482,2.0482,392,6.7,0.144,250.6395,30,13,0
0.027384259,386.2,392,863,58.8,50,1.5363,3.0726,392,6.7,0.108,187.9949,30,12,0
0.02744213,386.2,392,860,58.8,50,1.0244,2.0487,392,7.1,0.072,125.3503,30,11,0
0.0275,386.2,392,873,58.8,50,2.0482,4.0965,392,6.6,0.144,250.6395,30,13,0
0.02755787,386.6,392,1009,58.8,50,1.0244,2.0487,392,7,0.072,125.3503,30,11,0
0.027615741,387.3,392,1196,58.8,50,1.0244,2.0487,392,6.8,0.072,125.3503,30,11,0
0.027673611,386.7,392,1258,58.8,50,1.5363,3.0726,392,6.5,0.108,187.9949,30,12,0
0.027743056,386.6,392,1286,58.8,50,1.5363,3.0726,392,6.6,0.108,187.9949,30,12,0
0.027800926,386.6,392,1326,58.8,50,1.5363,3.0726,392,7,0.108,187.9949,30,12,0
0.027858796,386.4,392,1323,58.8,50,1.5363,3.0726,392,6.8,0.108,187.9949,30,12,0
0.027916667,386.2,392,1323,58.8,50,1.5363,3.0726,392,6.7,0.108,187.9949,30,12,0
0.027986111,386.2,392,1323,58.8,50,1.5363,3.0726,392,6.9,0.108,187.9949,30,12,0
0.028043981,386.2,392,1320,58.8,50,1.0244,2.0487,392,6.7,0.072,125.3503,30,11,0
0.028101852,386.2,392,1320,58.8,50,1.0244,2.0487,392,6.9,0.072,125.3503,30,11,0
0.028171296,386.2,392,1320,58.8,50,1.0244,2.0487,392,6.8,0.072,125.3503,30,11,0
0.028229167,386.2,392,1320,58.8,50,1.5363,3.0726,392,6.7,0.108,187.9949,30,12,0
0.028298611,386.2,392,1320,58.8,50,1.0244,2.0487,392,6.6,0.072,125.3503,30,11,0
0.028356481,386,392,1320,58.8,50,1.5363,3.0726,392,6.7,0.108,187.9949,30,12,0
0.028414352,386.2,392,1320,58.8,50,1.0244,2.0487,392,7,0.072,125.3503,30,11,0
0.028472222,386.2,392,1314,58.8,50,1.5363,3.0726,392,6.6,0.108,187.9949,30,12,0
0.028530093,386.2,392,1314,58.8,50,1.5363,3.0726,392,6.5,0.108,187.9949,30,12,0
0.028587963,386,392,1314,58.8,50,1.5363,3.0726,392,7,0.108,187.9949,30,12,0
0.028645833,386.2,392,1311,58.8,50,1.5363,3.0726,392,6.7,0.108,187.9949,30,12,0
0.028703704,386,392,1314,58.8,50,1.5363,3.0726,392,6.8,0.108,187.9949,30,12,0
0.028761574,386,392,1311,58.8,50,1.5363,3.0726,392,6.7,0.108,187.9949,30,12,0
0.028819444,386,392,1311,58.8,50,1.5363,3.0726,392,6.5,0.108,187.9949,30,12,0
0.028877315,386,392,1311,58.8,50,1.0244,2.0487,392,6.9,0.072,125.3503,30,11,0
0.028935185,386,392,1311,58.8,50,1.5363,3.0726,392,7.1,0.108,187.9949,30,12,0
0.028993056,386,392,1307,58.8,50,1.5363,3.0726,392,6.9,0.108,187.9949,30,12,0
0.0290625,386,392,1311,58.8,50,1.5363,3.0726,392,6.8,0.108,187.9949,30,12,0
0.02912037,386,392,1307,58.8,50,1.5363,3.0726,392,6.6,0.108,187.9949,30,12,0
0.029178241,386,392,1307,58.8,50,1.0244,2.0487,392,6.5,0.072,125.3503,30,11,0
0.029236111,386,392,1307,58.8,50,2.0482,4.0965,392,6.8,0.144,250.6395,30,13,0
0.029293981,386,392,1304,58.8,50,1.0244,2.0487,392,6.8,0.072,125.3503,30,11,0
0.029351852,386,392,1307,58.8,50,1.5363,3.0726,392,7,0.108,187.9949,30,12,0
0.029409722,386,392,1304,117.61,100,1.5363,1.5363,392,6.9,0.108,187.9949,30,12,0
0.029467593,386,392,1307,117.61,100,2.0482,2.0482,392,6.5,0.144,250.6395,30,13,0
0.029525463,386,392,1307,88.2,75,1.5363,2.0484,392,7.1,0.108,187.9949,30,12,0
0.029583333,386,392,1304,88.2,75,1.5363,2.0484,392,6.9,0.108,187.9949,30,12,0
0.029641204,385.8,392,1304,58.8,50,1.5363,3.0726,392,6.8,0.108,187.9949,30,12,0
0.029710648,385.7,392,1304,58.8,50,1.5363,3.0726,392,6.9,0.108,187.9949,30,12,0
0.029768519,385.7,392,1304,29.4,25,1.0244,4.0975,392,6.5,0.072,125.3503,30,11,0
0.029826389,385.7,392,1304,58.8,50,1.0244,2.0487,392,6.7,0.072,125.3503,30,11,0
0.029884259,385.7,392,1298,58.8,50,1.0244,2.0487,392,6.8,0.072,125.3503,30,11,0
0.02994213,385.7,392,1298,88.2,75,1.5363,3.0726,392,6.4,0.108,187.9949,30,12,0
0.03,385.8,392,1298,88.2,75,1.5363,2.0484,392,7.1,0.108,187.9949,30,12,0
0.03005787,385.8,392,1298,117.61,100,1.5363,1.5363,392,7.2,0.108,187.9949,30,12,0
0.030115741,385.7,392,1298,117.61,100,2.0482,2.0482,392,6.9,0.144,250.6395,30,13,0
0.030173611,385.7,392,1298,58.8,50,1.5363,3.0726,392,6.9,0.108,187.9949,30,12,0
0.030231481,385.7,392,1298,58.8,50,1.5363,3.0726,392,7.1,0.108,187.9949,30,12,0
0.030289352,385.7,392,1295,58.8,50,1.5363,3.0726,392,6.9,0.108,187.9949,30,12,0
0.030358796,385.7,392,1295,58.8,50,1.0244,2.0487,392,7.1,0.072,125.3503,30,11,0
0.030416667,385.7,392,1295,58.8,50,1.0244,2.0487,392,6.7,0.072,125.3503,30,11,0
0.030474537,385.7,392,1295,58.8,50,1.0244,2.0487,392,6.6,0.072,125.3503,30,11,0
0.030532407,385.7,392,1295,58.8,50,1.5363,3.0726,392,6.9,0.108,187.9949,30,12,0
0.030590278,385.7,392,1289,58.8,50,1.5363,3.0726,392,7.2,0.108,187.9949,30,12,0
0.030648148,385.7,392,1289,58.8,50,1.5363,3.0726,392,7.1,0.108,187.9949,30,12,0
0.030706019,385.7,392,1289,58.8,50,1.5363,3.0726,392,6.6,0.108,187.9949,30,12,0
0.030763889,386.6,392,1497,58.8,50,1.5363,3.0726,392,6.5,0.108,187.9949,30,12,0
0.030821759,386.6,392,1720,58.8,50,1.0244,2.0487,392,6.9,0.072,125.3503,30,11,0
0.03087963,386.4,392,1817,58.8,50,1.5363,3.0726,392,7.3,0.108,187.9949,30,12,0
0.0309375,386,392,1814,58.8,50,1.5363,3.0726,392,7.1,0.108,187.9949,30,12,0
0.031018519,385.8,392,1807,58.8,50,1.5363,3.0726,392,6.8,0.108,187.9949,30,12,0
0.031087963,385.8,392,1807,58.8,50,1.5363,3.0726,392,6.5,0.108,187.9949,30,12,0
0.031145833,385.8,392,1807,58.8,50,1.5363,3.0726,392,6.7,0.108,187.9949,30,12,0
0.031203704,385.8,392,1804,58.8,50,1.5363,3.0726,392,7.1,0.108,187.9949,30,12,0
0.031261574,385.8,392,1807,58.8,50,1.5363,3.0726,392,6.9,0.108,187.9949,30,12,0
0.031319444,385.7,392,1804,58.8,50,1.5363,3.0726,392,7.1,0.108,187.9949,30,12,0
0.031377315,385.7,392,1807,58.8,50,1.5363,3.0726,392,6.8,0.108,187.9949,30,12,0
0.031435185,385.7,392,1804,58.8,50,1.5363,3.0726,392,6.6,0.108,187.9949,30,12,0
0.031493056,385.7,392,1804,58.8,50,1.5363,3.0726,392,6.9,0.108,187.9949,30,12,0
0.031550926,385.7,392,1807,58.8,50,1.5363,3.0726,392,6.9,0.108,187.9949,30,12,0
0.031608796,385.7,392,1804,58.8,50,1.5363,3.0726,392,6.9,0.108,187.9949,30,12,0
0.031666667,385.7,392,1804,58.8,50,1.5363,3.0726,392,6.9,0.108,187.9949,30,12,0
0.031736111,385.7,392,1807,58.8,50,1.5363,3.0726,392,6.9,0.108,187.9949,30,12,0
0.031793981,385.7,392,1807,58.8,50,1.5363,3.0726,392,6.9,0.108,187.9949,30,12,0
0.031851852,385.7,392,1807,58.8,50,1.5363,3.0726,392,6.7,0.108,187.9949,30,12,0
0.031909722,385.7,392,1804,58.8,50,1.5363,3.0726,392,6.9,0.108,187.9949,30,12,0
0.031967593,385.7,392,1804,58.8,50,1.0244,2.0487,392,6.9,0.072,125.3503,30,11,0
0.032025463,385.7,392,1807,58.8,50,1.5363,3.0726,392,6.7,0.108,187.9949,30,12,0
0.032083333,385.7,392,1807,58.8,50,2.0482,4.0965,392,7.1,0.144,250.6395,30,13,0
0.032141204,385.7,392,1807,58.8,50,1.5363,3.0726,392,7.3,0.108,187.9949,30,12,0
0.032199074,385.7,392,1807,58.8,50,1.5363,3.0726,392,6.6,0.108,187.9949,30,12,0
0.032256944,385.7,392,1804,117.61,100,1.5363,1.5363,392,6.9,0.108,187.9949,30,12,0
0.032314815,385.7,392,1804,117.61,100,2.0482,2.0482,392,6.7,0.144,250.6395,30,13,0
0.032372685,385.7,392,1807,88.2,75,2.0482,2.731,392,6.9,0.144,250.6395,30,13,0
0.032430556,385.5,392,1807,88.2,75,2.0482,2.731,392,7.2,0.144,250.6395,30,13,0
0.032488426,385.7,392,1807,58.8,50,1.5363,3.0726,392,7.1,0.108,187.9949,30,12,0
0.032546296,385.5,392,1807,58.8,50,1.5363,3.0726,392,6.7,0.108,187.9949,30,12,0
0.032604167,385.5,392,1807,29.4,25,1.5363,6.1452,392,7.2,0.108,187.9949,30,12,0
0.032673611,385.5,392,1807,58.8,50,1.5363,6.1452,392,7.2,0.108,187.9949,30,12,0
0.032731481,385.5,392,1807,58.8,50,2.0482,4.0965,392,7,0.144,250.6395,30,13,0
0.032789352,385.5,392,1807,88.2,75,1.5363,3.0726,392,6.7,0.108,187.9949,30,12,0
0.032847222,385.7,392,1807,88.2,75,1.5363,2.0484,392,6.9,0.108,187.9949,30,12,0
0.032905093,385.7,392,1807,117.61,100,2.0482,2.731,392,6.7,0.144,250.6395,30,13,0
0.032962963,385.5,392,1814,117.61,100,2.0482,2.0482,392,6.8,0.144,250.6395,30,13,0
0.033020833,385.5,392,1807,58.8,50,2.0482,4.0965,392,7.3,0.144,250.6395,30,13,0
0.033078704,385.3,392,1804,58.8,50,2.0482,4.0965,392,7.3,0.144,250.6395,30,13,0
0.033136574,385.3,392,1804,58.8,50,1.0244,2.0487,392,7.2,0.072,125.3503,30,11,0
0.033194444,385.3,392,1807,58.8,50,2.0482,4.0965,392,6.8,0.144,250.6395,30,13,0
0.033252315,385.3,392,1807,58.8,50,1.0244,2.0487,392,6.4,0.072,125.3503,30,11,0
0.033321759,385.3,392,1804,58.8,50,1.5363,3.0726,392,7.1,0.108,187.9949,30,12,0
0.03337963,385.3,392,1807,58.8,50,1.5363,3.0726,392,7,0.108,187.9949,30,12,0
0.0334375,385.3,392,1804,58.8,50,1.5363,3.0726,392,7,0.108,187.9949,30,12,0
0.03349537,385.3,392,1804,58.8,50,1.5363,3.0726,392,7.2,0.108,187.9949,30,12,0
0.033553241,385.3,392,1807,58.8,50,1.5363,3.0726,392,7,0.108,187.9949,30,12,0
0.033611111,385.3,392,1804,58.8,50,1.5363,3.0726,392,7.1,0.108,187.9949,30,12,0
0.033668981,385.3,392,1804,58.8,50,1.5363,3.0726,392,7,0.108,187.9949,30,12,0
0.033726852,385.3,392,1807,58.8,50,1.5363,3.0726,392,6.5,0.108,187.9949,30,12,0
0.033784722,385.3,392,1807,58.8,50,1.5363,3.0726,392,6.9,0.108,187.9949,30,12,0
0.033842593,385.3,392,1807,58.8,50,1.0244,2.0487,392,7,0.072,125.3503,30,11,0
0.033900463,385.3,392,1807,58.8,50,1.5363,3.0726,392,6.7,0.108,187.9949,30,12,0
0.033958333,385.3,392,1807,58.8,50,2.0482,4.0965,392,6.7,0.144,250.6395,30,13,0
0.034027778,385.3,392,1807,58.8,50,1.5363,3.0726,392,6.7,0.108,187.9949,30,12,0
0.034085648,385.3,392,1804,58.8,50,1.5363,3.0726,392,6.9,0.108,187.9949,30,12,0
0.034143519,385.3,392,1807,58.8,50,1.5363,3.0726,392,7.3,0.108,187.9949,30,12,0
0.034201389,385.3,392,1807,58.8,50,1.5363,3.0726,392,7.5,0.108,187.9949,30,12,0
0.034259259,385.3,392,1804,58.8,50,1.5363,3.0726,392,7,0.108,187.9949,30,12,0
0.03431713,385.3,392,1807,58.8,50,1.5363,3.0726,392,7.1,0.108,187.9949,30,12,0
0.034375,385.3,392,1807,58.8,50,1.5363,3.0726,392,6.8,0.108,187.9949,30,12,0
0.03443287,385.3,392,1807,58.8,50,1.5363,3.0726,392,7.2,0.108,187.9949,30,12,0
0.034502315,385.3,392,1804,58.8,50,1.5363,3.0726,392,6.6,0.108,187.9949,30,12,0
0.034571759,385.3,392,1804,58.8,50,2.0482,4.0965,392,7,0.144,250.6395,30,13,0
0.03462963,385.3,392,1804,58.8,50,1.5363,3.0726,392,7.2,0.108,187.9949,30,12,0
0.0346875,385.3,392,1804,58.8,50,1.5363,3.0726,392,6.9,0.108,187.9949,30,12,0
0.034756944,385.3,392,1807,58.8,50,1.5363,3.0726,392,6.7,0.108,187.9949,30,12,0
0.034814815,385.3,392,1807,58.8,50,1.5363,3.0726,392,7.5,0.108,187.9949,30,12,0
0.034872685,385.3,392,1807,58.8,50,1.0244,2.0487,392,7.1,0.072,125.3503,30,11,0
0.034930556,385.3,392,1804,58.8,50,1.0244,2.0487,392,7,0.072,125.3503,30,11,0
0.034988426,385.1,392,1804,58.8,50,1.5363,3.0726,392,7,0.108,187.9949,30,12,0
0.035046296,385.1,392,1804,58.8,50,2.0482,4.0965,392,7.1,0.144,250.6395,30,13,0
0.035069444,385.1,392,1804,58.8,50,1.5363,3.0726,392,6.9,0.108,187.9949,30,12,0