File: data/opybr-AA-cons-P.csv
Elapsed Time,Sample Temp,Heater Temp,Pressure,Rotor Speed,Shear Rate,Shear Stress,Viscosity,Temperature Setpoint,T Output,Bob Deflection,Torque,Motor Temp,Raw Encoder Value,Aux1
(hh:mm:ss),(°F),(°F),(PSIg),(RPM),(1/s),(dyne/cm²),(cP),(°F),(%),(deg.),(dyne-cm),(°C),(cts),
1.16E-05,86.9,119,115,58.8,50,0,0,32,0,-0.0001,0,30,55530,0
0.000115741,87.4,119,118,58.8,50,183.6419,367.2838,77,0,12.8159,22471.94,30,55886,0
0.000219907,88.1,119,118,58.8,50,183.1325,366.265,77,0,12.7799,22409.61,30,55885,0
0.000324074,88.8,119,118,58.8,50,183.1325,366.265,77,0,12.7799,22409.61,30,55885,0
0.000439815,89.7,119,118,58.8,50,182.6231,365.2462,77,0,12.7439,22347.27,30,55884,0
0.000543981,90.5,119,118,58.8,50,181.6043,363.2086,77,0,12.6719,22222.6,30,55882,0
0.000648148,91.2,119,118,58.8,50,180.0761,360.1521,77,0,12.5639,22035.6,30,55879,0
0.000752315,91.9,119,121,58.8,50,178.0385,356.0769,77,0,12.4199,21786.26,30,55875,0
0.000856481,92.4,119,121,58.8,50,176.5102,353.0205,77,0,12.3119,21599.25,30,55872,0
0.000960648,93.1,119,121,58.8,50,175.4914,350.9828,77,0,12.2399,21474.58,30,55870,0
0.001076389,93.7,119,127,58.8,50,173.4538,346.9076,77,0,12.0959,21225.24,30,55866,0
0.001180556,94.2,119,127,58.8,50,172.435,344.87,77,0,12.0239,21100.57,30,55864,0
0.001284722,94.8,119,127,58.8,50,170.9068,341.8135,77,0,11.9159,20913.56,30,55861,0
0.001388889,95.3,119,127,58.8,50,169.888,339.7759,77,0,11.8439,20788.9,30,55859,0
0.001493056,95.8,119,127,58.8,50,168.8691,337.7383,77,0,11.7719,20664.22,30,55857,0
0.001597222,96.4,119,127,58.8,50,167.8503,335.7007,77,0,11.6999,20539.55,30,55855,0
0.001701389,96.7,118,127,58.8,50,166.8315,333.6631,77,0,11.6279,20414.88,30,55853,0
0.001805556,97.3,119,127,58.8,50,165.8127,331.6254,77,0,11.5559,20290.21,30,55851,0
0.001909722,97.6,118,127,58.8,50,164.2845,328.569,77,0,11.4479,20103.21,30,55848,0
0.002013889,98.4,118,118,58.8,50,163.7751,327.5502,77,0,11.4119,20040.88,30,55847,0
0.00212963,98.7,118,106,117.61,100,311.131,311.131,77,0,21.6359,38072.57,30,56131,0
0.002233796,99.3,118,99,88.2,75,235.8962,314.5283,77,0,16.4519,28866.21,30,55987,0
0.002337963,99.8,118,93,58.8,50,157.6614,315.3228,77,0,10.9799,19292.76,30,55835,0
0.00244213,100.2,118,87,29.4,25,80.5834,322.3335,77,0,5.6159,9860.848,30,55686,0
0.002546296,100.3,118,84,58.8,50,153.0758,306.1516,77,0,10.6559,18731.62,30,55826,0
0.002662037,100.9,118,84,88.2,75,225.9973,301.3297,77,0,15.7679,27654.9,30,55968,0
0.002766204,101.2,118,84,117.61,100,303.3175,303.3175,77,0,21.0959,37116.44,30,56116,0
0.00287037,101.6,118,84,58.8,50,125.4536,250.9073,130,21.4,8.7119,15351.54,30,55772,0
0.002974537,102,120,84,58.8,50,151.0377,302.0755,130,10.9,10.5119,18482.23,30,55822,0
0.003078704,102.5,123,118,58.8,50,149.5092,299.0184,130,0,10.4039,18295.18,30,55819,0
0.003194444,102.9,125,121,58.8,50,147.4711,294.9423,130,0.7,10.2599,18045.79,30,55815,0
0.003298611,103,125,127,58.8,50,144.9236,289.8472,130,3.8,10.0799,17734.05,30,55810,0
0.003402778,103.4,125,130,58.8,50,143.395,286.79,129,0.3,9.9719,17547,30,55807,0
0.003506944,103.8,126,130,58.8,50,141.357,282.7139,129,0.5,9.8279,17297.61,30,55803,0
0.003622685,104.3,126,130,58.8,50,139.3189,278.6378,129,1.7,9.6839,17048.21,30,55799,0
0.003726852,104.7,126,130,58.8,50,137.7904,275.5807,129,1.4,9.5759,16861.17,30,55796,0
0.003831019,104.8,126,130,58.8,50,136.2618,272.5237,129,1.4,9.4679,16674.12,30,55793,0
0.003935185,105.4,126,130,58.8,50,135.2428,270.4856,129,1.3,9.3959,16549.43,30,55791,0
0.004039352,105.7,126,130,58.8,50,133.7142,267.4285,129,1.7,9.2879,16362.38,30,55788,0
0.004155093,106.3,127,130,58.8,50,132.1857,264.3714,129,1.6,9.1799,16175.34,30,55785,0
0.004259259,106.6,127,130,58.8,50,130.6572,261.3144,129,1.6,9.0719,15988.29,30,55782,0
0.004363426,107.2,127,130,58.8,50,129.6382,259.2763,129,1.4,8.9999,15863.6,30,55780,0
0.004467593,107.5,127,127,58.8,50,128.6034,257.2069,128,0,8.9279,15736.98,30,55778,0
0.004571759,107.9,127,127,58.8,50,127.5535,255.107,128,0.7,8.8559,15608.5,30,55776,0
0.004675926,108.3,127,121,58.8,50,126.5036,253.0071,128,1.4,8.7839,15480.02,30,55774,0
0.004791667,108.6,127,118,58.8,50,125.4536,250.9073,128,1.1,8.7119,15351.54,30,55772,0
0.004895833,109.1,127,115,58.8,50,124.4037,248.8074,128,1,8.6399,15223.06,30,55770,0
0.005,109.3,127,112,58.8,50,123.8787,247.7574,128,0.9,8.6039,15158.82,30,55769,0
0.005104167,109.9,127,106,58.8,50,122.8288,245.6576,128,0.9,8.5319,15030.34,30,55767,0
0.005219907,110.2,127,102,58.8,50,122.3038,244.6076,128,1.2,8.4959,14966.11,30,55766,0
0.005324074,110.6,127,102,58.8,50,121.2539,242.5078,128,1.1,8.4239,14837.63,30,55764,0
0.005428241,110.9,127,99,58.8,50,120.7289,241.4578,128,0.9,8.3879,14773.39,30,55763,0
0.005532407,111.3,127,96,58.8,50,119.679,239.358,127,0,8.3159,14644.91,30,55761,0
0.005636574,111.7,127,96,58.8,50,119.154,238.308,127,0.2,8.2799,14580.67,30,55760,0
0.005740741,112,127,96,58.8,50,118.629,237.2581,127,0,8.2439,14516.43,30,55759,0
0.005856481,112.4,127,96,58.8,50,118.1041,236.2081,127,0.5,8.2079,14452.19,30,55758,0
0.005960648,112.6,127,96,58.8,50,117.5791,235.1582,127,0.9,8.1719,14387.95,30,55757,0
0.006064815,112.9,127,96,58.8,50,117.0541,234.1083,127,0.1,8.1359,14323.71,30,55756,0
0.006168981,113.3,127,96,58.8,50,116.5292,233.0583,127,0,8.0999,14259.47,30,55755,0
0.006273148,113.6,127,96,58.8,50,116.0042,232.0084,127,0.4,8.0639,14195.23,30,55754,0
0.006377315,113.8,127,96,58.8,50,115.4792,230.9585,127,0.8,8.0279,14130.99,30,55753,0
0.006493056,114.2,127,96,58.8,50,115.4792,230.9585,127,0.5,8.0279,14130.99,30,55753,0
0.006597222,114.5,127,96,58.8,50,114.9543,229.9085,126,0,7.9919,14066.75,30,55752,0
0.006701389,114.7,127,96,58.8,50,114.4293,228.8586,126,0,7.9559,14002.51,30,55751,0
0.006805556,114.9,127,96,58.8,50,114.4293,228.8586,126,0,7.9559,14002.51,30,55751,0
0.006909722,115.3,127,96,58.8,50,113.9043,227.8087,126,0,7.9199,13938.28,30,55750,0
0.007025463,115.4,126,96,58.8,50,113.9043,227.8087,126,0.4,7.9199,13938.28,30,55750,0
0.00712963,115.8,126,96,58.8,50,113.3794,226.7587,126,0.2,7.8839,13874.04,30,55749,0
0.007233796,116,126,96,58.8,50,113.3794,226.7587,126,0.6,7.8839,13874.04,30,55749,0
0.007349537,116.3,126,96,58.8,50,112.8544,225.7088,126,0.5,7.8479,13809.8,30,55748,0
0.007453704,116.3,126,93,58.8,50,112.8544,225.7088,126,0,7.8479,13809.8,30,55748,0
0.007569444,116.9,126,96,58.8,50,112.3294,224.6588,125,0,7.8119,13745.56,30,55747,0
0.007673611,116.9,126,93,58.8,50,112.3294,224.6588,125,0,7.8119,13745.56,30,55747,0
0.007777778,117.2,126,93,58.8,50,111.8045,223.6089,125,0,7.7759,13681.32,30,55746,0
0.007881944,117.2,126,96,58.8,50,111.8045,223.6089,125,0,7.7759,13681.32,30,55746,0
0.007997685,117.6,126,96,58.8,50,111.8045,223.6089,125,0,7.7759,13681.32,30,55746,0
0.008101852,117.8,125,96,58.8,50,111.2795,222.559,125,0,7.7399,13617.08,30,55745,0
0.008206019,118,126,93,58.8,50,111.2795,222.559,125,0,7.7399,13617.08,30,55745,0
0.008310185,118.1,126,93,58.8,50,111.2795,222.559,125,0,7.7399,13617.08,30,55745,0
0.008414352,118.3,125,93,58.8,50,110.7545,221.509,125,0,7.7039,13552.84,30,55744,0
0.008518519,118.3,125,93,58.8,50,110.7545,221.509,125,0.1,7.7039,13552.84,30,55744,0
0.008634259,118.7,125,93,58.8,50,110.7545,221.509,124,0,7.7039,13552.84,30,55744,0
0.008738426,118.9,125,93,58.8,50,110.2296,220.4591,124,0,7.6679,13488.6,30,55743,0
0.008842593,119,125,93,58.8,50,110.2296,220.4591,124,0,7.6679,13488.6,30,55743,0
0.008946759,119,125,99,58.8,50,110.2296,220.4591,124,0,7.6679,13488.6,30,55743,0
0.009050926,119.2,125,118,58.8,50,110.2296,220.4591,124,0,7.6679,13488.6,30,55743,0
0.009166667,119.6,125,121,58.8,50,110.2296,220.4591,124,0,7.6679,13488.6,30,55743,0
0.009270833,119.6,125,127,58.8,50,110.2296,220.4591,124,0,7.6679,13488.6,30,55743,0
0.009375,119.6,124,127,58.8,50,110.2296,220.4591,124,0,7.6679,13488.6,30,55743,0
0.009479167,119.9,124,130,58.8,50,110.2296,220.4591,124,0,7.6679,13488.6,30,55743,0
0.009583333,119.9,124,134,58.8,50,110.2296,220.4591,124,0,7.6679,13488.6,30,55743,0
0.0096875,119.9,124,134,58.8,50,110.2296,220.4591,123,0,7.6679,13488.6,30,55743,0
0.009803241,120.1,124,134,58.8,50,110.2296,220.4591,123,0,7.6679,13488.6,30,55743,0
0.009907407,120.1,124,134,58.8,50,109.7046,219.4092,123,0,7.6319,13424.36,30,55742,0
0.010011574,120.3,124,134,58.8,50,109.7046,219.4092,123,0,7.6319,13424.36,30,55742,0
0.010115741,120.5,124,134,58.8,50,109.7046,219.4092,123,0,7.6319,13424.36,30,55742,0
0.010219907,120.5,124,149,58.8,50,109.7046,219.4092,123,0,7.6319,13424.36,30,55742,0
0.010335648,120.7,124,149,58.8,50,109.7046,219.4092,123,0,7.6319,13424.36,30,55742,0
0.010439815,120.7,124,149,58.8,50,109.7046,219.4092,123,0,7.6319,13424.36,30,55742,0
0.010543981,120.8,123,149,58.8,50,109.7046,219.4092,123,0,7.6319,13424.36,30,55742,0
0.010648148,120.8,123,149,58.8,50,109.7046,219.4092,123,0,7.6319,13424.36,30,55742,0
0.010752315,120.8,123,149,58.8,50,109.7046,219.4092,122,0,7.6319,13424.36,30,55742,0
0.010856481,121,123,152,58.8,50,109.7046,219.4092,122,0,7.6319,13424.36,30,55742,0
0.010960648,121,123,149,58.8,50,109.7046,219.4092,122,0,7.6319,13424.36,30,55742,0
0.011076389,121,123,149,58.8,50,109.7046,219.4092,122,0,7.6319,13424.36,30,55742,0
0.011180556,121,123,152,58.8,50,109.7046,219.4092,122,0,7.6319,13424.36,30,55742,0
0.011284722,121.2,123,152,58.8,50,110.2296,220.4591,122,0,7.6679,13488.6,30,55743,0
0.011388889,121.4,123,152,58.8,50,109.7046,219.4092,122,0,7.6319,13424.36,30,55742,0
0.011493056,121.2,123,152,58.8,50,110.2296,220.4591,122,0,7.6679,13488.6,30,55743,0
0.011608796,121.4,123,152,58.8,50,110.2296,220.4591,122,0,7.6679,13488.6,30,55743,0
0.011712963,121.4,123,152,58.8,50,110.2296,220.4591,122,0,7.6679,13488.6,30,55743,0
0.01181713,121.4,122,152,58.8,50,110.2296,220.4591,121,0,7.6679,13488.6,30,55743,0
0.011921296,121.6,122,152,58.8,50,110.2296,220.4591,121,0,7.6679,13488.6,30,55743,0
0.012037037,121.6,122,155,58.8,50,109.7046,219.4092,121,0,7.6319,13424.36,30,55742,0
0.012141204,121.6,122,155,58.8,50,110.2296,220.4591,121,0,7.6679,13488.6,30,55743,0
0.01224537,121.6,122,155,58.8,50,109.7046,219.4092,121,0,7.6319,13424.36,30,55742,0
0.012349537,121.6,122,155,58.8,50,110.2296,220.4591,121,0,7.6679,13488.6,30,55743,0
0.012453704,121.6,122,152,58.8,50,110.2296,220.4591,121,0,7.6679,13488.6,30,55743,0
0.01255787,121.6,122,134,58.8,50,110.2296,220.4591,121,0,7.6679,13488.6,30,55743,0
0.012662037,121.6,122,130,58.8,50,110.2296,220.4591,121,0,7.6679,13488.6,30,55743,0
0.012766204,121.6,122,127,58.8,50,110.2296,220.4591,121,0,7.6679,13488.6,30,55743,0
0.012881944,121.7,122,118,58.8,50,110.2296,220.4591,120,0,7.6679,13488.6,30,55743,0
0.012986111,121.6,122,118,58.8,50,110.2296,220.4591,120,0,7.6679,13488.6,30,55743,0
0.013090278,121.7,122,112,58.8,50,110.2296,220.4591,120,0,7.6679,13488.6,30,55743,0
0.013194444,121.6,122,106,58.8,50,110.2296,220.4591,120,0,7.6679,13488.6,30,55743,0
0.013310185,121.7,121,102,117.61,100,203.6889,203.6889,120,0,14.2199,24925.06,30,55925,0
0.013414352,121.6,121,102,58.8,50,123.3538,246.7075,120,0,8.5679,15094.59,30,55768,0
0.013518519,121.7,121,102,29.4,25,60.4095,241.6379,120,0,4.2119,7392.203,30,55647,0
0.013622685,121.7,121,102,58.8,50,90.3911,180.7822,120,0,6.2999,11061,30,55705,0
0.013726852,121.7,121,99,88.2,75,156.6424,313.2848,120,0,10.9079,19168.06,30,55833,0
0.013831019,121.7,121,102,117.61,100,154.6043,154.6043,120,0,10.7639,18918.67,30,55829,0
0.013935185,121.7,122,99,58.8,50,92.4559,92.4559,212,70,6.4439,11313.67,30,55709,0
0.014050926,121.7,135,99,58.8,50,106.5548,213.1095,250,70,7.4159,13038.92,30,55736,0
0.014155093,121.7,156,99,58.8,50,100.7801,201.5602,249,70,7.0199,12332.29,30,55725,0
0.014259259,121.7,178,102,58.8,50,90.9073,181.8146,249,58.2,6.3359,11124.17,30,55706,0
0.014363426,121.7,196,99,58.8,50,78.0024,156.0048,249,41.9,5.4359,9545.017,30,55681,0
0.014467593,121.9,209,99,58.8,50,67.1623,134.3246,249,43.6,4.6799,8218.531,30,55660,0
0.014571759,122.3,218,102,58.8,50,57.8021,115.6043,248,41.2,4.0319,7073.147,30,55642,0
0.0146875,122.8,226,102,58.8,50,50.5016,101.0032,248,35.3,3.5279,6179.792,30,55628,0
0.014791667,123.7,232,102,58.8,50,44.7654,89.5309,248,31,3.1319,5477.869,30,55617,0
0.014895833,125.1,238,102,58.8,50,40.0722,80.1445,247,26.5,2.8079,4903.568,30,55608,0
0.015,126.6,242,102,58.8,50,36.9434,73.8868,247,23.9,2.5919,4520.702,30,55602,0
0.015104167,128.4,245,102,58.8,50,34.3361,68.6722,247,21.9,2.4119,4201.646,30,55597,0
0.015219907,130.2,248,99,58.8,50,32.7717,65.5433,246,18.3,2.3039,4010.213,30,55594,0
0.015324074,132.2,249,102,58.8,50,31.2272,62.4544,246,16.8,2.1959,3821.217,30,55591,0
0.015428241,134.3,251,102,58.8,50,30.2033,60.4066,246,16.3,2.1239,3695.928,30,55589,0
0.015532407,136.5,251,99,58.8,50,29.6914,59.3828,246,15.2,2.0879,3633.284,30,55588,0
0.015636574,138.8,252,102,58.8,50,28.6675,57.335,245,12.6,2.0159,3507.994,30,55586,0
0.015740741,141,252,102,58.8,50,28.1556,56.3112,245,12.3,1.9799,3445.35,30,55585,0
0.015856481,143.3,252,99,58.8,50,27.6437,55.2873,245,12.2,1.9439,3382.705,30,55584,0
0.015960648,145.6,252,102,58.8,50,27.1317,54.2634,244,9.8,1.9079,3320.061,30,55583,0
0.016064815,148,252,99,58.8,50,26.6198,53.2396,244,10.3,1.8719,3257.416,30,55582,0
0.016168981,150.3,251,99,58.8,50,26.6198,53.2396,244,10.4,1.8719,3257.416,30,55582,0
0.016273148,152.5,251,99,58.8,50,26.1078,52.2157,243,7.8,1.8359,3194.771,30,55581,0
0.016388889,154.6,250,99,58.8,50,25.5959,51.1918,243,8.9,1.7999,3132.127,30,55580,0
0.016493056,156.8,250,99,58.8,50,25.5959,51.1918,243,8.7,1.7999,3132.127,30,55580,0
0.016597222,158.8,249,99,58.8,50,25.5959,51.1918,242,7.3,1.7999,3132.127,30,55580,0
0.016701389,160.7,249,99,58.8,50,25.084,50.168,242,6.9,1.7639,3069.482,30,55579,0
0.016805556,162.7,248,99,58.8,50,25.084,50.168,242,8.8,1.7639,3069.482,30,55579,0
0.016909722,164.7,247,99,58.8,50,25.084,50.168,242,7.9,1.7639,3069.482,30,55579,0
0.017013889,166.7,247,99,58.8,50,24.572,49.1441,241,6.6,1.7279,3006.838,30,55578,0
0.01712963,168.5,246,99,58.8,50,24.572,49.1441,241,6.9,1.7279,3006.838,30,55578,0
0.017233796,170.1,245,96,58.8,50,24.572,49.1441,241,7.7,1.7279,3006.838,30,55578,0
0.017337963,171.9,245,99,58.8,50,24.0601,48.1202,240,5.8,1.6919,2944.193,30,55577,0
0.01744213,173.5,244,99,58.8,50,24.0601,48.1202,240,6.4,1.6919,2944.193,30,55577,0
0.017546296,175.3,244,99,58.8,50,24.0601,48.1202,240,6.8,1.6919,2944.193,30,55577,0
0.017650463,176.7,243,96,58.8,50,24.0601,48.1202,239,5.3,1.6919,2944.193,30,55577,0
0.017766204,178.4,243,96,58.8,50,24.0601,48.1202,239,6,1.6919,2944.193,30,55577,0
0.01787037,179.8,242,99,58.8,50,23.5482,47.0963,239,6.8,1.6559,2881.549,30,55576,0
0.017974537,181.2,242,96,58.8,50,23.5482,47.0963,238,4.6,1.6559,2881.549,30,55576,0
0.018078704,182.7,241,96,58.8,50,23.5482,47.0963,238,5.3,1.6559,2881.549,30,55576,0
0.01818287,183.9,241,96,58.8,50,23.5482,47.0963,238,6.1,1.6559,2881.549,30,55576,0
0.018298611,185.6,240,96,58.8,50,23.5482,47.0963,238,5.7,1.6559,2881.549,30,55576,0
0.018402778,186.6,240,96,58.8,50,23.0362,46.0725,237,4.4,1.6199,2818.904,30,55575,0
0.018506944,187.9,239,96,58.8,50,23.0362,46.0725,237,5.9,1.6199,2818.904,30,55575,0
0.018611111,189.2,239,96,58.8,50,23.0362,46.0725,237,5.6,1.6199,2818.904,30,55575,0
0.018715278,190.4,239,96,58.8,50,23.0362,46.0725,236,4.2,1.6199,2818.904,30,55575,0
0.018819444,191.5,238,93,58.8,50,22.5243,45.0486,236,5,1.5839,2756.26,30,55574,0
0.018923611,192.7,238,96,58.8,50,22.5243,45.0486,236,5.3,1.5839,2756.26,30,55574,0
0.019039352,193.8,237,96,58.8,50,22.5243,45.0486,235,3.1,1.5839,2756.26,30,55574,0
0.019143519,194.7,237,96,58.8,50,22.5243,45.0486,235,4,1.5839,2756.26,30,55574,0
0.019247685,195.8,237,96,58.8,50,22.5243,45.0486,235,4.9,1.5839,2756.26,30,55574,0
0.019351852,196.9,236,93,58.8,50,22.5243,45.0486,234,3.2,1.5839,2756.26,30,55574,0
0.019456019,197.8,236,93,58.8,50,22.0124,44.0247,234,3.6,1.5479,2693.615,30,55573,0
0.019571759,198.7,235,96,58.8,50,22.0124,44.0247,234,4.8,1.5479,2693.615,30,55573,0
0.019675926,199.6,235,96,58.8,50,22.0124,44.0247,234,4.6,1.5479,2693.615,30,55573,0
0.019780093,200.5,235,93,58.8,50,22.0124,44.0247,233,2.9,1.5479,2693.615,30,55573,0
0.019884259,201.2,234,93,58.8,50,22.0124,44.0247,233,4.5,1.5479,2693.615,30,55573,0
0.019988426,202.1,234,93,58.8,50,22.0124,44.0247,233,4.8,1.5479,2693.615,30,55573,0
0.020092593,202.8,234,96,58.8,50,22.0124,44.0247,232,2.3,1.5479,2693.615,30,55573,0
0.020208333,203.7,233,93,58.8,50,22.0124,44.0247,232,4,1.5479,2693.615,30,55573,0
0.0203125,204.4,233,93,58.8,50,22.0124,44.0247,232,4.7,1.5479,2693.615,30,55573,0
0.020416667,205.2,233,93,58.8,50,22.0124,44.0247,231,2.5,1.5479,2693.615,30,55573,0
0.020520833,205.9,233,93,58.8,50,22.0124,44.0247,231,2.7,1.5479,2693.615,30,55573,0
0.020636574,206.4,232,93,58.8,50,22.0124,44.0247,231,4.2,1.5479,2693.615,30,55573,0
0.020740741,207.1,232,93,58.8,50,22.0124,44.0247,231,4.1,1.5479,2693.615,30,55573,0
0.020844907,207.7,232,93,58.8,50,22.0124,44.0247,230,2.2,1.5479,2693.615,30,55573,0
0.020949074,208.4,231,87,58.8,50,22.0124,44.0247,230,3.6,1.5479,2693.615,30,55573,0
0.021053241,208.9,231,93,58.8,50,22.0124,44.0247,230,3.9,1.5479,2693.615,30,55573,0
0.021157407,209.5,231,87,58.8,50,21.5004,43.0009,229,2.1,1.5119,2630.97,30,55572,0
0.021261574,210,230,87,58.8,50,21.5004,43.0009,229,3.4,1.5119,2630.97,30,55572,0
0.021377315,210.4,230,87,58.8,50,21.5004,43.0009,229,3.8,1.5119,2630.97,30,55572,0
0.021481481,210.9,230,87,58.8,50,21.5004,43.0009,228,1.6,1.5119,2630.97,30,55572,0
0.021585648,211.4,229,93,58.8,50,21.5004,43.0009,228,3,1.5119,2630.97,30,55572,0
0.021689815,211.8,229,87,58.8,50,21.5004,43.0009,228,3.7,1.5119,2630.97,30,55572,0
0.021805556,212.3,229,87,58.8,50,21.5004,43.0009,227,1.3,1.5119,2630.97,30,55572,0
0.021909722,212.7,228,93,58.8,50,21.5004,43.0009,227,1.8,1.5119,2630.97,30,55572,0
0.022013889,213.2,228,93,58.8,50,21.5004,43.0009,227,3.3,1.5119,2630.97,30,55572,0
0.022118056,213.6,228,93,58.8,50,21.5004,43.0009,227,3.5,1.5119,2630.97,30,55572,0
0.022222222,214,227,87,58.8,50,21.5004,43.0009,226,1.5,1.5119,2630.97,30,55572,0
0.022326389,214.1,227,87,58.8,50,21.5004,43.0009,226,2.6,1.5119,2630.97,30,55572,0
0.02244213,214.5,227,87,58.8,50,20.9885,41.977,226,2.8,1.4759,2568.326,30,55571,0
0.02255787,214.9,226,87,58.8,50,21.5004,43.0009,225,1.5,1.5119,2630.97,30,55572,0
0.022685185,215.2,226,93,58.8,50,21.5004,43.0009,225,2.4,1.5119,2630.97,30,55572,0
0.022789352,215.4,226,87,58.8,50,21.5004,43.0009,225,3,1.5119,2630.97,30,55572,0
0.022893519,215.8,225,87,58.8,50,21.5004,43.0009,224,1,1.5119,2630.97,30,55572,0
0.022997685,216.1,225,93,58.8,50,20.9885,41.977,224,2.1,1.4759,2568.326,30,55571,0
0.023113426,216.3,225,102,58.8,50,20.9885,41.977,224,3.1,1.4759,2568.326,30,55571,0
0.023217593,216.7,224,118,58.8,50,20.9885,41.977,223,1.4,1.4759,2568.326,30,55571,0
0.023321759,216.8,224,127,58.8,50,20.9885,41.977,223,1.8,1.4759,2568.326,30,55571,0
0.023425926,217,224,127,58.8,50,20.9885,41.977,223,2.6,1.4759,2568.326,30,55571,0
0.023530093,217,223,127,58.8,50,20.9885,41.977,222,0.6,1.4759,2568.326,30,55571,0
0.023645833,217.2,223,130,58.8,50,20.9885,41.977,222,1.7,1.4759,2568.326,30,55571,0
0.02375,217.4,223,130,58.8,50,20.9885,41.977,222,2.6,1.4759,2568.326,30,55571,0
0.023854167,217.6,222,130,58.8,50,20.9885,41.977,222,2.5,1.4759,2568.326,30,55571,0
0.023958333,217.7,222,130,58.8,50,20.9885,41.977,221,1.3,1.4759,2568.326,30,55571,0
0.0240625,217.9,222,130,58.8,50,20.9885,41.977,221,1.7,1.4759,2568.326,30,55571,0
0.024178241,217.9,221,134,58.8,50,20.9885,41.977,221,2.3,1.4759,2568.326,30,55571,0
0.024282407,217.9,221,134,58.8,50,20.9885,41.977,220,0.5,1.4759,2568.326,30,55571,0
0.024386574,218.1,221,130,117.61,100,28.1556,28.1556,220,1.4,1.9799,3445.35,30,55585,0
0.024490741,218.3,221,130,88.2,75,24.572,32.7627,220,2.2,1.7279,3006.838,30,55578,0
0.024594907,218.1,220,130,58.8,50,19.9646,39.9293,220,2.1,1.4039,2443.036,30,55569,0
0.024699074,218.3,220,130,29.4,25,12.2856,49.1424,220,2,0.8639,1503.368,30,55554,0
0.024803241,218.5,220,130,58.8,50,14.8453,29.6906,220,2.1,1.0439,1816.591,30,55559,0
0.024907407,218.5,220,130,88.2,75,20.4766,27.3021,220,2.3,1.4399,2505.681,30,55570,0
0.025011574,218.5,220,130,117.61,100,20.9885,27.9847,220,2.3,1.4759,2568.326,30,55571,0
0.025127315,218.5,221,130,58.8,50,24.0601,48.1202,306,70,1.6919,2944.193,30,55577,0
0.025231481,218.5,231,130,58.8,50,16.893,33.786,340,70,1.1879,2067.169,30,55563,0
0.025335648,218.5,250,127,58.8,50,16.893,33.786,339,70,1.1879,2067.169,30,55563,0
0.025439815,218.5,269,127,58.8,50,16.3811,32.7622,339,68,1.1519,2004.524,30,55562,0
0.025543981,218.6,285,127,58.8,50,16.3811,32.7622,339,50.8,1.1519,2004.524,30,55562,0
0.025648148,219,299,127,58.8,50,15.8692,31.7383,339,42.8,1.1159,1941.88,30,55561,0
0.025752315,219.5,309,127,58.8,50,15.3572,30.7144,338,41.5,1.0799,1879.235,30,55560,0
0.025868056,220.3,315,127,58.8,50,14.8453,29.6906,338,41.1,1.0439,1816.591,30,55559,0
0.025972222,221.2,322,127,58.8,50,14.3333,28.6667,338,35.7,1.0079,1753.946,30,55558,0
0.026087963,222.6,328,127,58.8,50,13.8214,27.6428,337,29.2,0.9719,1691.302,30,55557,0
0.02619213,223.9,331,127,58.8,50,13.8214,27.6428,337,27.3,0.9719,1691.302,30,55557,0
0.026296296,225.3,335,127,58.8,50,13.8214,27.6428,337,25.5,0.9719,1691.302,30,55557,0
0.026400463,227.1,337,127,58.8,50,13.3095,26.6189,336,21.3,0.9359,1628.657,30,55556,0
0.02650463,228.9,339,127,58.8,50,13.3095,26.6189,336,20.3,0.9359,1628.657,30,55556,0
0.026608796,230.7,340,121,58.8,50,13.3095,26.6189,336,19.6,0.9359,1628.657,30,55556,0
0.026724537,232.8,341,121,58.8,50,12.7975,25.5951,336,18.3,0.8999,1566.012,30,55555,0
0.026828704,234.6,342,121,58.8,50,12.7975,25.5951,335,15,0.8999,1566.012,30,55555,0
0.02693287,236.6,342,121,58.8,50,12.7975,25.5951,335,15.9,0.8999,1566.012,30,55555,0
0.027037037,238.4,342,121,58.8,50,12.7975,25.5951,335,15,0.8999,1566.012,30,55555,0
0.027141204,240.4,342,118,58.8,50,12.7975,25.5951,334,12.2,0.8999,1566.012,30,55555,0
0.02724537,242.4,342,118,58.8,50,12.2856,24.5712,334,13,0.8639,1503.368,30,55554,0
0.027349537,244.2,342,118,58.8,50,12.2856,24.5712,334,12.6,0.8639,1503.368,30,55554,0
0.027465278,246.3,341,118,58.8,50,12.2856,24.5712,333,10.8,0.8639,1503.368,30,55554,0
0.027569444,247.9,341,118,58.8,50,12.2856,24.5712,333,11,0.8639,1503.368,30,55554,0
0.027673611,249.9,340,115,58.8,50,12.2856,24.5712,333,11.3,0.8639,1503.368,30,55554,0
0.027777778,251.7,339,115,58.8,50,12.2856,24.5712,332,9.4,0.8639,1503.368,30,55554,0
0.027881944,253.5,339,115,58.8,50,12.2856,24.5712,332,9.8,0.8639,1503.368,30,55554,0
0.027986111,255.3,338,115,58.8,50,12.2856,24.5712,332,10.6,0.8639,1503.368,30,55554,0
0.028090278,257.1,337,115,58.8,50,12.2856,24.5712,332,10.2,0.8639,1503.368,30,55554,0
0.028206019,258.5,337,115,58.8,50,12.2856,24.5712,331,8.6,0.8639,1503.368,30,55554,0
0.028310185,260.3,336,115,58.8,50,12.2856,24.5712,331,9.8,0.8639,1503.368,30,55554,0
0.028414352,262,335,112,58.8,50,12.2856,24.5712,331,10,0.8639,1503.368,30,55554,0
0.028518519,263.6,335,115,58.8,50,12.2856,24.5712,330,7.9,0.8639,1503.368,30,55554,0
0.028622685,265,334,112,58.8,50,12.2856,24.5712,330,8.8,0.8639,1503.368,30,55554,0
0.028726852,266.6,334,112,58.8,50,12.2856,24.5712,330,9.1,0.8639,1503.368,30,55554,0
0.028831019,268.3,333,112,58.8,50,12.2856,24.5712,329,7.6,0.8639,1503.368,30,55554,0
0.028946759,269.7,333,112,58.8,50,11.7737,23.5473,329,7.7,0.8279,1440.723,30,55553,0
0.029050926,271,332,106,58.8,50,11.7737,23.5473,329,8.9,0.8279,1440.723,30,55553,0
0.029155093,272.4,332,112,58.8,50,11.7737,23.5473,329,8.9,0.8279,1440.723,30,55553,0
0.029259259,273.8,331,106,58.8,50,11.7737,23.5473,328,7.2,0.8279,1440.723,30,55553,0
0.029363426,275.1,331,106,58.8,50,11.7737,23.5473,328,8.1,0.8279,1440.723,30,55553,0
0.029467593,276.5,330,106,58.8,50,11.7737,23.5473,328,8.6,0.8279,1440.723,30,55553,0
0.029571759,277.8,330,106,58.8,50,11.7737,23.5473,327,6.8,0.8279,1440.723,30,55553,0
0.0296875,279,329,106,58.8,50,11.7737,23.5473,327,7.7,0.8279,1440.723,30,55553,0
0.029791667,280.1,329,102,58.8,50,11.7737,23.5473,327,7.9,0.8279,1440.723,30,55553,0
0.029895833,281.4,329,102,58.8,50,11.7737,23.5473,326,6.3,0.8279,1440.723,30,55553,0
0.03,282.5,328,102,58.8,50,11.7737,23.5473,326,6.9,0.8279,1440.723,30,55553,0
0.030104167,283.5,328,102,58.8,50,11.7737,23.5473,326,7.6,0.8279,1440.723,30,55553,0
0.030208333,284.6,328,102,58.8,50,11.7737,23.5473,325,5.7,0.8279,1440.723,30,55553,0
0.0303125,285.7,327,102,58.8,50,11.7737,23.5473,325,5.9,0.8279,1440.723,30,55553,0
0.030428241,286.6,327,102,58.8,50,11.7737,23.5473,325,6.9,0.8279,1440.723,30,55553,0
0.030532407,287.7,326,102,58.8,50,11.7737,23.5473,325,7.2,0.8279,1440.723,30,55553,0
0.030636574,288.6,326,102,58.8,50,11.7737,23.5473,324,5.4,0.8279,1440.723,30,55553,0
0.030740741,289.5,326,99,58.8,50,11.7737,23.5473,324,6.5,0.8279,1440.723,30,55553,0
0.030844907,290.4,325,99,58.8,50,11.7737,23.5473,324,7.2,0.8279,1440.723,30,55553,0
0.030949074,291.3,325,99,58.8,50,11.7737,23.5473,323,4.8,0.8279,1440.723,30,55553,0
0.031053241,292.2,325,99,58.8,50,11.7737,23.5473,323,5.8,0.8279,1440.723,30,55553,0
0.031157407,292.9,324,96,58.8,50,11.7737,23.5473,323,6.8,0.8279,1440.723,30,55553,0
0.031273148,293.6,324,99,58.8,50,11.7737,23.5473,322,4.7,0.8279,1440.723,30,55553,0
0.031377315,294.3,324,96,58.8,50,11.7737,23.5473,322,5.2,0.8279,1440.723,30,55553,0
0.031481481,295.2,323,96,58.8,50,11.7737,23.5473,322,6.6,0.8279,1440.723,30,55553,0
0.031585648,295.8,323,96,58.8,50,11.7737,23.5473,321,4.3,0.8279,1440.723,30,55553,0
0.031689815,296.3,323,96,58.8,50,11.7737,23.5473,321,4.6,0.8279,1440.723,30,55553,0
0.031793981,297.2,322,96,58.8,50,11.7737,23.5473,321,5.8,0.8279,1440.723,30,55553,0
0.031909722,297.7,322,96,58.8,50,11.7737,23.5473,321,5.9,0.8279,1440.723,30,55553,0
0.032013889,298.5,322,96,58.8,50,11.7737,23.5473,320,4.3,0.8279,1440.723,30,55553,0
0.032118056,299,321,93,58.8,50,11.7737,23.5473,320,5.8,0.8279,1440.723,30,55553,0
0.032233796,299.4,321,96,58.8,50,11.7737,23.5473,320,5.6,0.8279,1440.723,30,55553,0
0.032337963,299.9,321,93,58.8,50,11.7737,23.5473,319,3.9,0.8279,1440.723,30,55553,0
0.03244213,300.6,320,96,58.8,50,11.7737,23.5473,319,5.4,0.8279,1440.723,30,55553,0
0.032546296,301,320,93,58.8,50,11.7737,23.5473,319,5.6,0.8279,1440.723,30,55553,0
0.032650463,301.5,320,93,58.8,50,11.7737,23.5473,318,3.2,0.8279,1440.723,30,55553,0
0.03275463,301.9,319,93,58.8,50,11.7737,23.5473,318,4.2,0.8279,1440.723,30,55553,0
0.03287037,302.4,319,93,58.8,50,11.7737,23.5473,318,5.4,0.8279,1440.723,30,55553,0
0.032974537,302.8,319,93,58.8,50,11.7737,23.5473,317,3.3,0.8279,1440.723,30,55553,0
0.033078704,303,318,93,58.8,50,11.7737,23.5473,317,4,0.8279,1440.723,30,55553,0
0.03318287,303.3,318,93,58.8,50,11.7737,23.5473,317,4.8,0.8279,1440.723,30,55553,0
0.033287037,303.9,318,93,58.8,50,11.7737,23.5473,316,3,0.8279,1440.723,30,55553,0
0.033391204,304.2,317,87,58.8,50,11.7737,23.5473,316,3.9,0.8279,1440.723,30,55553,0
0.03349537,304.4,317,93,58.8,50,11.7737,23.5473,316,4.5,0.8279,1440.723,30,55553,0
0.033599537,304.8,317,87,58.8,50,11.7737,23.5473,316,4.9,0.8279,1440.723,30,55553,0
0.033703704,305.1,316,87,58.8,50,11.7737,23.5473,315,3.1,0.8279,1440.723,30,55553,0
0.033819444,305.3,316,87,58.8,50,11.7737,23.5473,315,4.3,0.8279,1440.723,30,55553,0
0.033923611,305.7,316,87,58.8,50,11.7737,23.5473,315,4.8,0.8279,1440.723,30,55553,0
0.034027778,305.8,316,87,58.8,50,11.7737,23.5473,314,2.9,0.8279,1440.723,30,55553,0
0.034131944,306,315,87,58.8,50,11.7737,23.5473,314,3.8,0.8279,1440.723,30,55553,0
0.034236111,306.2,315,87,58.8,50,11.7737,23.5473,314,4.7,0.8279,1440.723,30,55553,0
0.034340278,306.6,314,87,58.8,50,11.7737,23.5473,313,2.8,0.8279,1440.723,30,55553,0
0.034444444,306.6,314,87,58.8,50,11.7737,23.5473,313,3.2,0.8279,1440.723,30,55553,0
0.034560185,306.7,314,87,58.8,50,11.7737,23.5473,313,4.3,0.8279,1440.723,30,55553,0
0.034664352,306.9,313,84,58.8,50,11.7737,23.5473,313,4.7,0.8279,1440.723,30,55553,0
0.034768519,307.1,313,84,58.8,50,11.7737,23.5473,312,2.5,0.8279,1440.723,30,55553,0
0.034872685,307.1,313,87,58.8,50,11.7737,23.5473,312,3.1,0.8279,1440.723,30,55553,0
0.034976852,307.3,313,87,58.8,50,11.7737,23.5473,312,4.5,0.8279,1440.723,30,55553,0
0.035081019,307.5,312,87,58.8,50,11.7737,23.5473,311,2.2,0.8279,1440.723,30,55553,0
0.035185185,307.5,312,87,58.8,50,11.7737,23.5473,311,3,0.8279,1440.723,30,55553,0
0.035289352,307.6,312,84,58.8,50,11.7737,23.5473,311,4.2,0.8279,1440.723,30,55553,0
0.035405093,307.8,311,84,58.8,50,11.7737,23.5473,310,4.1,0.8279,1440.723,30,55553,0
0.035509259,307.8,311,84,58.8,50,11.7737,23.5473,310,2.8,0.8279,1440.723,30,55553,0
0.035613426,307.8,311,87,117.61,100,12.7975,12.7975,310,4,0.8999,1566.012,30,55555,0
0.035717593,307.8,310,84,88.2,75,12.2856,16.3808,310,4.1,0.8639,1503.368,30,55554,0
0.035821759,307.8,310,84,58.8,50,11.7737,23.5473,310,3.9,0.8279,1440.723,30,55553,0
0.0359375,307.8,310,84,29.4,25,10.7498,42.9992,310,3.7,0.7559,1315.434,30,55551,0
0.036041667,307.8,310,84,58.8,50,11.2617,22.5235,310,4.4,0.7919,1378.079,30,55552,0
0.036145833,307.8,310,84,88.2,75,11.7737,15.6982,310,4,0.8279,1440.723,30,55553,0
0.03625,307.8,310,81,117.61,100,12.2856,12.2856,365,22.5,0.8639,1503.368,30,55554,0
0.036354167,307.8,314,84,58.8,50,11.2617,22.5235,445,70,0.7919,1378.079,30,55552,0
0.036458333,307.8,328,84,58.8,50,11.2617,22.5235,445,70,0.7919,1378.079,30,55552,0
0.036574074,307.8,344,84,58.8,50,11.2617,22.5235,444,70,0.7919,1378.079,30,55552,0
0.036678241,307.8,360,84,58.8,50,11.2617,22.5235,444,70,0.7919,1378.079,30,55552,0
0.036782407,308,375,81,58.8,50,11.2617,22.5235,443,70,0.7919,1378.079,30,55552,0
0.036886574,308.4,389,84,58.8,50,10.7498,21.4996,443,65,0.7559,1315.434,30,55551,0
0.036990741,308.9,403,84,58.8,50,10.7498,21.4996,443,53.5,0.7559,1315.434,30,55551,0
0.037094907,309.8,413,84,58.8,50,10.7498,21.4996,442,47.2,0.7559,1315.434,30,55551,0
0.037210648,310.9,421,84,58.8,50,10.2379,20.4757,442,44.7,0.7199,1252.79,30,55550,0
0.037314815,312.3,427,115,58.8,50,10.2379,20.4757,442,42.5,0.7199,1252.79,30,55550,0
0.037430556,313.7,433,121,58.8,50,9.7259,19.4519,441,36.8,0.6839,1190.145,30,55549,0
0.037534722,315.5,437,121,58.8,50,10.2379,20.4757,441,34.2,0.7199,1252.79,30,55550,0
0.037638889,317.2,440,121,58.8,50,9.7259,19.4519,441,31.7,0.6839,1190.145,30,55549,0
0.037743056,318.8,442,127,58.8,50,9.7259,19.4519,440,28.6,0.6839,1190.145,30,55549,0
0.037858796,320.6,444,127,58.8,50,9.7259,19.4519,440,27.5,0.6839,1190.145,30,55549,0
0.037962963,322.4,445,127,58.8,50,9.7259,19.4519,439,24,0.6839,1190.145,30,55549,0
0.03806713,324.2,446,127,58.8,50,9.7259,19.4519,439,23.3,0.6839,1190.145,30,55549,0
0.038171296,326.7,447,130,58.8,50,9.7259,19.4519,439,22.9,0.6839,1190.145,30,55549,0
0.038287037,329,447,130,58.8,50,9.7259,19.4519,438,19.5,0.6839,1190.145,30,55549,0
0.038391204,331.4,447,130,58.8,50,9.7259,19.4519,438,19.1,0.6839,1190.145,30,55549,0
0.03849537,334.1,447,130,58.8,50,9.7259,19.4519,438,19,0.6839,1190.145,30,55549,0
0.038599537,336.6,447,134,58.8,50,9.7259,19.4519,437,16.5,0.6839,1190.145,30,55549,0
0.038703704,338.9,446,130,58.8,50,9.7259,19.4519,437,16.9,0.6839,1190.145,30,55549,0
0.038819444,341.3,446,134,58.8,50,9.7259,19.4519,437,16.2,0.6839,1190.145,30,55549,0
0.038923611,343.8,445,134,58.8,50,9.7259,19.4519,436,14.2,0.6839,1190.145,30,55549,0
0.039027778,345.7,445,134,58.8,50,9.7259,19.4519,436,15.3,0.6839,1190.145,30,55549,0
0.039131944,348.1,444,134,58.8,50,9.7259,19.4519,436,15.5,0.6839,1190.145,30,55549,0
0.039236111,350.2,443,134,58.8,50,9.7259,19.4519,435,13.1,0.6839,1190.145,30,55549,0
0.039340278,352.4,443,134,58.8,50,9.7259,19.4519,435,13.6,0.6839,1190.145,30,55549,0
0.039444444,354.6,442,134,58.8,50,9.7259,19.4519,435,13.5,0.6839,1190.145,30,55549,0
0.039548611,356.4,441,134,58.8,50,9.7259,19.4519,434,11.7,0.6839,1190.145,30,55549,0
0.039664352,358.3,441,134,58.8,50,9.7259,19.4519,434,12.3,0.6839,1190.145,30,55549,0
0.039768519,360.1,440,134,58.8,50,9.7259,19.4519,433,11.2,0.6839,1190.145,30,55549,0
0.039872685,361.7,439,134,58.8,50,9.7259,19.4519,433,11.2,0.6839,1190.145,30,55549,0
0.039976852,363.4,438,149,58.8,50,9.7259,19.4519,433,12.3,0.6839,1190.145,30,55549,0
0.040081019,365.2,438,134,58.8,50,9.7259,19.4519,432,10.4,0.6839,1190.145,30,55549,0
0.040196759,367.7,437,149,58.8,50,9.7259,19.4519,432,10.7,0.6839,1190.145,30,55549,0
0.040300926,368.9,436,149,58.8,50,9.7259,19.4519,432,11.6,0.6839,1190.145,30,55549,0
0.040405093,370.7,436,149,58.8,50,9.7259,19.4519,431,9.9,0.6839,1190.145,30,55549,0
0.040509259,372.4,435,149,58.8,50,9.7259,19.4519,431,10.6,0.6839,1190.145,30,55549,0
0.040613426,373.8,435,149,58.8,50,9.7259,19.4519,431,11.1,0.6839,1190.145,30,55549,0
0.040729167,375.2,434,149,58.8,50,9.7259,19.4519,430,9.3,0.6839,1190.145,30,55549,0
0.040833333,376.7,433,149,58.8,50,9.7259,19.4519,430,10.8,0.6839,1190.145,30,55549,0
0.0409375,378.1,433,149,58.8,50,9.7259,19.4519,430,11.1,0.6839,1190.145,30,55549,0
0.041041667,379.4,433,149,58.8,50,9.214,18.428,429,8.9,0.6479,1127.5,30,55548,0
0.041145833,380.8,432,149,58.8,50,9.7259,19.4519,429,10,0.6839,1190.145,30,55549,0
0.04125,382.1,431,149,58.8,50,9.7259,19.4519,428,9,0.6839,1190.145,30,55549,0
0.041365741,383.3,431,149,58.8,50,9.7259,19.4519,428,8.9,0.6839,1190.145,30,55549,0
0.041469907,384.4,430,149,58.8,50,9.7259,19.4519,428,10.2,0.6839,1190.145,30,55549,0
0.041574074,385.7,430,149,58.8,50,9.7259,19.4519,427,7.7,0.6839,1190.145,30,55549,0
0.041678241,386.9,430,149,58.8,50,9.7259,19.4519,427,8.5,0.6839,1190.145,30,55549,0
0.041782407,388,429,149,58.8,50,9.7259,19.4519,427,9,0.6839,1190.145,30,55549,0
0.041886574,388.9,429,134,58.8,50,9.7259,19.4519,426,8.1,0.6839,1190.145,30,55549,0
0.041990741,390.2,428,134,58.8,50,9.7259,19.4519,426,8.7,0.6839,1190.145,30,55549,0
0.042094907,390.9,428,134,58.8,50,9.7259,19.4519,426,8.4,0.6839,1190.145,30,55549,0
0.042210648,391.9,428,149,58.8,50,9.7259,19.4519,425,7.3,0.6839,1190.145,30,55549,0
0.042314815,392.8,427,134,58.8,50,9.7259,19.4519,425,8.3,0.6839,1190.145,30,55549,0
0.042418981,393.7,427,134,58.8,50,9.7259,19.4519,425,8.9,0.6839,1190.145,30,55549,0
0.042523148,394.6,426,134,58.8,50,9.7259,19.4519,424,6.8,0.6839,1190.145,30,55549,0
0.042638889,395.4,426,134,58.8,50,9.7259,19.4519,424,8.1,0.6839,1190.145,30,55549,0
0.042743056,396.1,425,134,58.8,50,9.7259,19.4519,424,8.7,0.6839,1190.145,30,55549,0
0.042847222,397,425,134,58.8,50,9.7259,19.4519,423,7.1,0.6839,1190.145,30,55549,0
0.042951389,397.7,425,134,58.8,50,9.214,18.428,423,7.8,0.6479,1127.5,30,55548,0
0.043055556,398.2,424,134,58.8,50,9.214,18.428,422,6.1,0.6479,1127.5,30,55548,0
0.043159722,399,424,134,58.8,50,9.7259,19.4519,422,6.5,0.6839,1190.145,30,55549,0
0.043275463,399.7,423,134,58.8,50,9.7259,19.4519,422,8.1,0.6839,1190.145,30,55549,0
0.043391204,400.4,423,130,58.8,50,9.7259,19.4519,421,6.6,0.6839,1190.145,30,55549,0
0.04349537,400.9,423,130,58.8,50,9.7259,19.4519,421,6.4,0.6839,1190.145,30,55549,0
0.043599537,401.5,422,130,58.8,50,9.214,18.428,421,7.7,0.6479,1127.5,30,55548,0
0.043703704,402,422,130,58.8,50,9.7259,19.4519,420,6.3,0.6839,1190.145,30,55549,0
0.04380787,402.4,421,130,58.8,50,9.7259,19.4519,420,6.9,0.6839,1190.145,30,55549,0
0.043923611,403.1,421,130,58.8,50,9.7259,19.4519,419,5.9,0.6839,1190.145,30,55549,0
0.044027778,403.6,421,130,58.8,50,9.7259,19.4519,419,5.9,0.6839,1190.145,30,55549,0
0.044131944,404,420,127,58.8,50,9.7259,19.4519,419,7.2,0.6839,1190.145,30,55549,0
0.044236111,404.4,420,127,58.8,50,9.7259,19.4519,418,5.5,0.6839,1190.145,30,55549,0
0.044340278,404.9,420,127,58.8,50,9.7259,19.4519,418,6,0.6839,1190.145,30,55549,0
0.044444444,405.1,419,127,58.8,50,9.7259,19.4519,418,6.8,0.6839,1190.145,30,55549,0
0.044548611,405.4,419,127,58.8,50,9.7259,19.4519,417,5.7,0.6839,1190.145,30,55549,0
0.044664352,405.8,418,127,58.8,50,9.7259,19.4519,417,5.9,0.6839,1190.145,30,55549,0
0.044768519,406,418,127,58.8,50,9.7259,19.4519,417,6.7,0.6839,1190.145,30,55549,0
0.044872685,406.2,418,121,58.8,50,9.7259,19.4519,416,5,0.6839,1190.145,30,55549,0
0.044976852,406.3,417,127,58.8,50,9.7259,19.4519,416,6,0.6839,1190.145,30,55549,0
0.045081019,406.7,417,127,58.8,50,9.7259,19.4519,416,6.6,0.6839,1190.145,30,55549,0
0.045196759,406.9,417,127,58.8,50,9.7259,19.4519,415,5.2,0.6839,1190.145,30,55549,0
0.045300926,406.9,416,121,58.8,50,9.7259,19.4519,415,6.1,0.6839,1190.145,30,55549,0
0.045416667,407.2,416,121,58.8,50,9.214,18.428,415,6.2,0.6479,1127.5,30,55548,0
0.045520833,407.2,415,121,58.8,50,9.7259,19.4519,414,5,0.6839,1190.145,30,55549,0
0.045625,407.4,415,121,58.8,50,9.7259,19.4519,414,6.2,0.6839,1190.145,30,55549,0
0.045729167,407.6,415,121,58.8,50,9.7259,19.4519,413,5.1,0.6839,1190.145,30,55549,0
0.045844907,407.6,414,121,58.8,50,9.7259,19.4519,413,5.3,0.6839,1190.145,30,55549,0
0.045949074,407.6,414,121,58.8,50,9.7259,19.4519,413,6.4,0.6839,1190.145,30,55549,0
0.046053241,407.8,414,121,58.8,50,9.7259,19.4519,412,4.8,0.6839,1190.145,30,55549,0
0.046157407,407.8,413,118,58.8,50,9.7259,19.4519,412,5,0.6839,1190.145,30,55549,0
0.046273148,407.8,413,118,58.8,50,9.214,18.428,412,5.6,0.6479,1127.5,30,55548,0
0.046377315,407.8,412,118,58.8,50,9.7259,19.4519,411,4.7,0.6839,1190.145,30,55549,0
0.046481481,407.8,412,118,58.8,50,9.7259,19.4519,411,5.6,0.6839,1190.145,30,55549,0
0.046585648,407.8,412,118,58.8,50,9.7259,19.4519,410,5.9,0.6839,1190.145,30,55549,0
0.046689815,407.8,411,118,58.8,50,9.7259,19.4519,410,4.4,0.6839,1190.145,30,55549,0
0.046805556,407.6,411,118,117.61,100,9.7259,9.7259,410,5.9,0.6839,1190.145,30,55549,0
0.046909722,407.6,411,118,88.2,75,9.7259,12.9679,410,5.6,0.6839,1190.145,30,55549,0
0.047013889,407.4,410,115,58.8,50,9.7259,19.4519,410,5.7,0.6839,1190.145,30,55549,0
0.047118056,407.2,410,118,29.4,25,9.214,36.856,410,6.2,0.6479,1127.5,30,55548,0
0.047222222,407.2,410,118,58.8,50,9.7259,19.4519,410,5.7,0.6839,1190.145,30,55549,0
0.047337963,407.2,410,115,88.2,75,9.7259,12.9679,410,6.8,0.6839,1190.145,30,55549,0
0.04744213,407.1,410,115,117.61,100,9.7259,9.7259,439,53.9,0.6839,1190.145,30,55549,0
0.047546296,406.9,412,115,58.8,50,9.7259,19.4519,500,70,0.6839,1190.145,30,55549,0
0.047650463,406.7,424,115,58.8,50,9.7259,19.4519,500,70,0.6839,1190.145,30,55549,0
0.047766204,406.7,439,115,58.8,50,9.7259,19.4519,500,66.1,0.6839,1190.145,30,55549,0
0.04787037,406.5,455,118,58.8,50,9.7259,19.4519,499,45.6,0.6839,1190.145,30,55549,0
0.047974537,406.7,465,115,58.8,50,9.7259,19.4519,499,44,0.6839,1190.145,30,55549,0
0.048090278,406.9,472,118,58.8,50,9.7259,19.4519,499,43.7,0.6839,1190.145,30,55549,0
0.048194444,407.4,479,118,58.8,50,9.7259,19.4519,499,39.7,0.6839,1190.145,30,55549,0
0.048298611,408.3,484,121,58.8,50,9.7259,19.4519,499,35.6,0.6839,1190.145,30,55549,0
0.048402778,409.6,488,121,58.8,50,9.7259,19.4519,498,31.9,0.6839,1190.145,30,55549,0
0.048506944,411.2,492,127,58.8,50,9.7259,19.4519,498,31.1,0.6839,1190.145,30,55549,0
0.048622685,413.5,494,127,58.8,50,9.7259,19.4519,498,29.8,0.6839,1190.145,30,55549,0
0.048726852,415.9,496,127,58.8,50,9.7259,19.4519,498,28.3,0.6839,1190.145,30,55549,0
0.048831019,418.7,498,127,58.8,50,9.7259,19.4519,497,24.9,0.6839,1190.145,30,55549,0
0.048946759,421.8,499,130,58.8,50,9.7259,19.4519,497,24.6,0.6839,1190.145,30,55549,0
0.049050926,425,500,130,58.8,50,9.7259,19.4519,497,24.1,0.6839,1190.145,30,55549,0
0.049155093,428.4,500,134,58.8,50,9.7259,19.4519,497,23.1,0.6839,1190.145,30,55549,0
0.049259259,432,501,134,58.8,50,9.7259,19.4519,497,22.6,0.6839,1190.145,30,55549,0
0.049375,435.1,501,134,58.8,50,9.214,18.428,496,20.1,0.6479,1127.5,30,55548,0
0.049490741,438.3,501,134,58.8,50,9.7259,19.4519,496,20.6,0.6839,1190.145,30,55549,0
0.049594907,441,501,149,58.8,50,9.7259,19.4519,496,20.6,0.6839,1190.145,30,55549,0
0.049699074,443.7,501,149,58.8,50,9.214,18.428,496,19.7,0.6479,1127.5,30,55548,0
0.049803241,446.2,501,149,58.8,50,9.214,18.428,496,19.2,0.6479,1127.5,30,55548,0
0.049918981,448.9,501,152,58.8,50,9.214,18.428,495,17.2,0.6479,1127.5,30,55548,0
0.050034722,450.9,500,152,58.8,50,8.7021,17.4041,495,17.2,0.6119,1064.856,30,55547,0
0.050138889,452.9,500,155,58.8,50,8.7021,17.4041,495,18.1,0.6119,1064.856,30,55547,0
0.05025463,454.7,500,155,58.8,50,8.7021,17.4041,495,17.4,0.6119,1064.856,30,55547,0
0.050358796,456.3,499,152,58.8,50,9.214,18.428,495,17.1,0.6479,1127.5,30,55548,0
0.050462963,457.8,499,155,58.8,50,8.7021,17.4041,494,15.2,0.6119,1064.856,30,55547,0
0.05056713,459,499,152,58.8,50,8.7021,17.4041,494,16.3,0.6119,1064.856,30,55547,0
0.050671296,460.4,498,152,58.8,50,9.214,18.428,494,16.3,0.6479,1127.5,30,55548,0
0.050787037,461.7,498,152,58.8,50,9.214,18.428,494,16,0.6479,1127.5,30,55548,0
0.050891204,463,497,152,58.8,50,9.214,18.428,494,15.7,0.6479,1127.5,30,55548,0
0.05099537,463.9,497,149,58.8,50,9.214,18.428,493,13.9,0.6479,1127.5,30,55548,0
0.051111111,464.6,497,149,58.8,50,9.214,18.428,493,15.2,0.6479,1127.5,30,55548,0
0.051215278,465.3,496,134,58.8,50,9.214,18.428,493,15.5,0.6479,1127.5,30,55548,0
0.051319444,466,496,134,58.8,50,9.214,18.428,493,14.9,0.6479,1127.5,30,55548,0
0.051423611,466.6,496,134,58.8,50,9.214,18.428,492,13.4,0.6479,1127.5,30,55548,0
0.051527778,467.1,495,134,58.8,50,9.214,18.428,492,13.9,0.6479,1127.5,30,55548,0
0.051643519,467.6,495,130,58.8,50,9.214,18.428,492,14.9,0.6479,1127.5,30,55548,0
0.051747685,468.4,494,134,58.8,50,9.214,18.428,492,14.4,0.6479,1127.5,30,55548,0
0.051851852,468.7,494,134,58.8,50,9.7259,19.4519,492,14.4,0.6839,1190.145,30,55549,0
0.051956019,469.3,494,130,58.8,50,9.7259,19.4519,491,13.1,0.6839,1190.145,30,55549,0
0.052071759,469.6,493,127,58.8,50,9.7259,19.4519,491,13.2,0.6839,1190.145,30,55549,0
0.052175926,470.2,493,127,58.8,50,9.7259,19.4519,491,13.8,0.6839,1190.145,30,55549,0
0.052280093,470.3,493,121,58.8,50,9.7259,19.4519,491,14.2,0.6839,1190.145,30,55549,0
0.052384259,470.7,492,121,58.8,50,9.7259,19.4519,491,13.8,0.6839,1190.145,30,55549,0
0.052488426,471.1,492,127,58.8,50,9.7259,19.4519,490,12.4,0.6839,1190.145,30,55549,0
0.052604167,471.4,492,121,58.8,50,9.7259,19.4519,490,13.1,0.6839,1190.145,30,55549,0
0.052708333,471.6,492,121,58.8,50,9.7259,19.4519,490,14.2,0.6839,1190.145,30,55549,0
0.0528125,472,491,121,58.8,50,9.7259,19.4519,490,13.9,0.6839,1190.145,30,55549,0
0.052916667,472.1,491,118,58.8,50,9.7259,19.4519,490,13.7,0.6839,1190.145,30,55549,0
0.053020833,472.3,491,118,58.8,50,9.7259,19.4519,489,11.7,0.6839,1190.145,30,55549,0
0.053125,472.5,491,118,58.8,50,9.7259,19.4519,489,12.5,0.6839,1190.145,30,55549,0
0.053229167,472.7,490,118,58.8,50,9.7259,19.4519,489,13.7,0.6839,1190.145,30,55549,0
0.053344907,472.9,490,115,58.8,50,9.7259,19.4519,489,13.3,0.6839,1190.145,30,55549,0
0.053449074,473.2,490,115,58.8,50,9.7259,19.4519,489,14,0.6839,1190.145,30,55549,0
0.053553241,473.2,490,115,58.8,50,9.7259,19.4519,488,11.8,0.6839,1190.145,30,55549,0
0.053668981,473.4,489,115,58.8,50,9.7259,19.4519,488,12.8,0.6839,1190.145,30,55549,0
0.053773148,473.6,489,115,58.8,50,9.7259,19.4519,488,13.7,0.6839,1190.145,30,55549,0
0.053877315,473.8,489,118,58.8,50,9.7259,19.4519,488,13.6,0.6839,1190.145,30,55549,0
0.053981481,473.9,489,118,58.8,50,9.7259,19.4519,488,13.4,0.6839,1190.145,30,55549,0
0.054085648,474.1,488,118,58.8,50,9.7259,19.4519,487,11.6,0.6839,1190.145,30,55549,0
0.054189815,474.1,488,118,58.8,50,9.7259,19.4519,487,13.1,0.6839,1190.145,30,55549,0
0.054305556,474.1,488,118,58.8,50,9.7259,19.4519,487,13.2,0.6839,1190.145,30,55549,0
0.054409722,474.3,488,121,58.8,50,9.7259,19.4519,487,12.7,0.6839,1190.145,30,55549,0
0.054513889,474.3,488,121,58.8,50,9.7259,19.4519,487,13,0.6839,1190.145,30,55549,0
0.054618056,474.5,487,121,58.8,50,9.7259,19.4519,486,11.6,0.6839,1190.145,30,55549,0
0.054722222,474.5,487,127,58.8,50,9.7259,19.4519,486,11.6,0.6839,1190.145,30,55549,0
0.054826389,474.5,487,127,58.8,50,9.7259,19.4519,486,12.8,0.6839,1190.145,30,55549,0
0.05494213,474.7,487,121,58.8,50,9.7259,19.4519,486,12.1,0.6839,1190.145,30,55549,0
0.055046296,474.7,487,127,58.8,50,9.7259,19.4519,486,12.3,0.6839,1190.145,30,55549,0
0.055150463,474.7,487,121,58.8,50,9.7259,19.4519,485,10.5,0.6839,1190.145,30,55549,0
0.05525463,474.7,486,121,58.8,50,9.7259,19.4519,485,11.7,0.6839,1190.145,30,55549,0
0.055358796,474.7,486,127,58.8,50,9.7259,19.4519,485,11.4,0.6839,1190.145,30,55549,0
0.055474537,474.7,486,127,58.8,50,10.2379,20.4757,485,12,0.7199,1252.79,30,55550,0
0.055578704,474.7,486,127,58.8,50,10.2379,20.4757,485,12.4,0.7199,1252.79,30,55550,0
0.05568287,474.7,485,127,58.8,50,9.7259,19.4519,484,10.5,0.6839,1190.145,30,55549,0
0.055787037,474.7,485,127,58.8,50,10.2379,20.4757,484,11.2,0.7199,1252.79,30,55550,0
0.055891204,474.7,485,130,58.8,50,10.2379,20.4757,484,12,0.7199,1252.79,30,55550,0
0.056006944,474.5,485,127,58.8,50,10.2379,20.4757,484,11.9,0.7199,1252.79,30,55550,0
0.056111111,474.5,484,130,58.8,50,10.2379,20.4757,484,11.6,0.7199,1252.79,30,55550,0
0.056215278,474.5,484,127,58.8,50,10.2379,20.4757,483,10.3,0.7199,1252.79,30,55550,0
0.056319444,474.3,484,130,58.8,50,10.2379,20.4757,483,11.8,0.7199,1252.79,30,55550,0
0.056435185,474.3,484,127,58.8,50,10.2379,20.4757,483,12.3,0.7199,1252.79,30,55550,0
0.056539352,474.3,483,127,58.8,50,10.2379,20.4757,483,11.5,0.7199,1252.79,30,55550,0
0.056643519,474.3,483,130,58.8,50,10.2379,20.4757,482,10.6,0.7199,1252.79,30,55550,0
0.056747685,474.3,483,130,58.8,50,10.2379,20.4757,482,11.2,0.7199,1252.79,30,55550,0
0.056851852,474.1,483,130,58.8,50,10.2379,20.4757,482,11.4,0.7199,1252.79,30,55550,0
0.056956019,474.1,482,134,58.8,50,10.2379,20.4757,482,11.5,0.7199,1252.79,30,55550,0
0.057071759,473.9,482,134,58.8,50,10.2379,20.4757,482,11.7,0.7199,1252.79,30,55550,0
0.057175926,473.8,482,134,58.8,50,10.2379,20.4757,481,10,0.7199,1252.79,30,55550,0
0.057280093,473.8,482,134,58.8,50,10.2379,20.4757,481,10.8,0.7199,1252.79,30,55550,0
0.057384259,473.6,482,134,58.8,50,10.2379,20.4757,481,11.9,0.7199,1252.79,30,55550,0
0.057488426,473.4,481,130,58.8,50,10.2379,20.4757,481,11.3,0.7199,1252.79,30,55550,0
0.057592593,473.4,481,130,58.8,50,10.2379,20.4757,481,11.3,0.7199,1252.79,30,55550,0
0.057696759,473.2,481,130,58.8,50,10.2379,20.4757,480,9.9,0.7199,1252.79,30,55550,0
0.0578125,473.2,481,130,58.8,50,10.2379,20.4757,480,10.5,0.7199,1252.79,30,55550,0
0.057916667,473,481,134,58.8,50,10.2379,20.4757,480,11.4,0.7199,1252.79,30,55550,0
0.058020833,472.9,480,130,88.2,75,10.2379,13.6505,480,11.3,0.7199,1252.79,30,55550,0
0.058125,472.7,480,134,88.2,75,10.2379,13.6505,480,11.3,0.7199,1252.79,30,55550,0
0.058240741,472.5,480,134,58.8,50,10.2379,20.4757,480,11.6,0.7199,1252.79,30,55550,0
0.058344907,472.5,480,134,29.4,25,10.2379,40.9515,480,11.4,0.7199,1252.79,30,55550,0
0.058449074,472.3,480,134,58.8,50,10.2379,20.4757,480,11.7,0.7199,1252.79,30,55550,0
0.058553241,472.1,480,134,88.2,75,10.2379,13.6505,480,11.7,0.7199,1252.79,30,55550,0
0.058657407,472,480,134,117.61,100,10.2379,10.2379,480,11.3,0.7199,1252.79,30,55550,0
0.058680556,472,480,134,117.61,100,10.2379,10.2379,480,11.7,0.7199,1252.79,30,55550,0