File: data/opybr-AA-cons-P-2.csv
Elapsed Time,Sample Temp,Heater Temp,Pressure,Rotor Speed,Shear Rate,Shear Stress,Viscosity,Temperature Setpoint,T Output,Bob Deflection,Torque,Motor Temp,Raw Encoder Value,Aux1
(hh:mm:ss),(°F),(°F),(PSIg),(RPM),(1/s),(dyne/cm²),(cP),(°F),(%),(deg.),(dyne-cm),(°C),(cts),
1.16E-05,84.9,91,102,58.8,50,0.0017,0,77,0,0.0001,0.2039,30,1990,0
0.000115741,85.1,91,102,58.8,50,535.4268,1070.854,77,0,36.7921,65519.25,30,3012,0
0.000208333,85.1,91,99,58.8,50,534.8699,1069.74,77,0,36.7561,65451.1,30,3011,0
0.0003125,85.4,91,99,58.8,50,534.8699,1069.74,77,0,36.7561,65451.1,30,3011,0
0.000405093,85.6,90,102,58.8,50,534.8699,1069.74,77,0,36.7561,65451.1,30,3011,0
0.000497685,85.6,90,102,58.8,50,534.8699,1069.74,77,0,36.7561,65451.1,30,3011,0
0.000590278,85.8,90,102,58.8,50,534.8699,1069.74,77,0,36.7561,65451.1,30,3011,0
0.00068287,86,90,99,58.8,50,534.8699,1069.74,77,0,36.7561,65451.1,30,3011,0
0.000787037,86,90,102,58.8,50,534.8699,1069.74,77,0,36.7561,65451.1,30,3011,0
0.00087963,86.3,90,102,58.8,50,534.8699,1069.74,77,0,36.7561,65451.1,30,3011,0
0.000972222,86.3,90,102,58.8,50,534.8699,1069.74,77,0,36.7561,65451.1,30,3011,0
0.001076389,86.3,90,102,58.8,50,534.8699,1069.74,77,0,36.7561,65451.1,30,3011,0
0.001168981,86.5,90,102,58.8,50,534.8699,1069.74,77,0,36.7561,65451.1,30,3011,0
0.001273148,86.7,90,102,58.8,50,534.8699,1069.74,77,0,36.7561,65451.1,30,3011,0
0.001365741,86.7,90,102,58.8,50,534.8699,1069.74,77,0,36.7561,65451.1,30,3011,0
0.001458333,86.9,90,99,58.8,50,534.8699,1069.74,77,0,36.7561,65451.1,30,3011,0
0.001550926,86.9,90,102,58.8,50,534.3128,1068.626,77,0,36.7201,65382.93,30,3010,0
0.001643519,86.9,90,102,58.8,50,534.3128,1068.626,77,0,36.7201,65382.93,30,3010,0
0.001747685,87,90,102,58.8,50,534.3128,1068.626,77,0,36.7201,65382.93,30,3010,0
0.001840278,87.2,90,102,58.8,50,534.3128,1068.626,77,0,36.7201,65382.93,30,3010,0
0.00193287,87.4,90,99,58.8,50,534.3128,1068.626,77,0,36.7201,65382.93,30,3010,0
0.002025463,87.2,90,102,58.8,50,534.3128,1068.626,77,0,36.7201,65382.93,30,3010,0
0.002118056,87.6,90,99,117.61,100,534.8699,534.8699,77,0,36.7561,65451.1,30,3011,0
0.002222222,87.6,90,99,88.2,75,534.3128,534.3128,77,0,36.7201,65382.93,30,3010,0
0.002314815,87.6,90,102,58.8,50,534.3128,712.4171,77,0,36.7201,65382.93,30,3010,0
0.002407407,87.8,90,102,58.8,50,533.7558,1067.512,77,0,36.6841,65314.77,30,3009,0
0.002511574,87.8,90,102,29.4,25,532.0849,2128.34,77,0,36.5761,65110.31,30,3006,0
0.002604167,87.9,90,102,58.8,50,533.1989,1066.398,77,0,36.6481,65246.62,30,3008,0
0.002696759,87.9,90,99,88.2,75,533.1989,710.9318,77,0,36.6481,65246.62,30,3008,0
0.002800926,88.1,90,102,117.61,100,533.7558,533.7558,94,5.4,36.6841,65314.77,30,3009,0
0.002893519,88.1,91,102,58.8,50,533.1989,1066.398,129,59.7,36.6481,65246.62,30,3008,0
0.002986111,88.5,96,102,58.8,50,533.1989,1066.398,130,33.8,36.6481,65246.62,30,3008,0
0.003090278,88.3,107,102,58.8,50,533.1989,1066.398,130,7.5,36.6481,65246.62,30,3008,0
0.00318287,88.5,112,99,58.8,50,532.6418,1065.284,130,10.4,36.6121,65178.46,30,3007,0
0.003275463,88.7,116,102,58.8,50,532.6418,1065.284,130,13.9,36.6121,65178.46,30,3007,0
0.003368056,88.7,118,102,58.8,50,532.6418,1065.284,130,11.5,36.6121,65178.46,30,3007,0
0.003472222,89,121,102,58.8,50,532.6418,1065.284,129,7.8,36.6121,65178.46,30,3007,0
0.003564815,89.4,123,102,58.8,50,532.6418,1065.284,129,7.4,36.6121,65178.46,30,3007,0
0.003668981,89.7,124,102,58.8,50,532.0849,1064.17,129,7.3,36.5761,65110.31,30,3006,0
0.003773148,90.5,126,102,58.8,50,532.0849,1064.17,129,6,36.5761,65110.31,30,3006,0
0.003865741,90.8,127,102,58.8,50,532.0849,1064.17,129,5.9,36.5761,65110.31,30,3006,0
0.003969907,91.4,127,102,58.8,50,532.0849,1064.17,129,5.7,36.5761,65110.31,30,3006,0
0.0040625,91.9,128,102,58.8,50,532.0849,1064.17,129,4.5,36.5761,65110.31,30,3006,0
0.004155093,92.6,129,102,58.8,50,532.0849,1064.17,129,4.8,36.5761,65110.31,30,3006,0
0.004247685,93.1,129,102,58.8,50,532.0849,1064.17,129,4.2,36.5761,65110.31,30,3006,0
0.004351852,94,129,102,58.8,50,532.0849,1064.17,129,4,36.5761,65110.31,30,3006,0
0.004444444,94.6,130,106,58.8,50,532.0849,1064.17,129,3.9,36.5761,65110.31,30,3006,0
0.004537037,95.3,130,102,58.8,50,532.0849,1064.17,128,2.1,36.5761,65110.31,30,3006,0
0.004641204,95.8,130,102,58.8,50,532.0849,1064.17,128,2.7,36.5761,65110.31,30,3006,0
0.004733796,96.4,130,102,58.8,50,532.0849,1064.17,128,3,36.5761,65110.31,30,3006,0
0.004826389,97.1,129,102,58.8,50,532.0849,1064.17,128,2.8,36.5761,65110.31,30,3006,0
0.004918981,97.6,129,102,58.8,50,531.5278,1063.056,128,2.7,36.5401,65042.14,30,3005,0
0.005011574,98.4,129,102,58.8,50,531.5278,1063.056,128,2.6,36.5401,65042.14,30,3005,0
0.005104167,99.1,129,102,58.8,50,531.5278,1063.056,128,2.3,36.5401,65042.14,30,3005,0
0.005208333,99.6,129,102,58.8,50,530.9708,1061.942,128,2.4,36.5041,64973.98,30,3004,0
0.005300926,100.2,129,102,58.8,50,530.9708,1061.942,128,3,36.5041,64973.98,30,3004,0
0.005393519,100.9,129,102,58.8,50,529.8569,1059.714,128,2.6,36.4321,64837.67,30,3002,0
0.005486111,101.2,129,102,58.8,50,529.2999,1058.6,128,2.7,36.3961,64769.51,30,3001,0
0.005578704,102,129,102,58.8,50,528.7429,1057.486,127,1.2,36.3601,64701.36,30,3000,0
0.005671296,102.5,129,102,58.8,50,527.6289,1055.258,127,1.4,36.2881,64565.04,30,2998,0
0.005775463,103,128,102,58.8,50,527.0719,1054.144,127,2.3,36.2521,64496.88,30,2997,0
0.005868056,103.6,128,102,58.8,50,526.5149,1053.03,127,1.8,36.2161,64428.71,30,2996,0
0.005960648,104.1,128,102,58.8,50,525.4009,1050.802,127,2,36.1441,64292.39,30,2994,0
0.006053241,104.7,128,102,58.8,50,524.8439,1049.688,127,1.9,36.1081,64224.23,30,2993,0
0.006157407,105.2,128,106,58.8,50,523.1729,1046.346,127,2,36.0001,64019.76,30,2990,0
0.00625,105.6,128,106,58.8,50,522.616,1045.232,127,2.1,35.9641,63951.61,30,2989,0
0.006342593,106.1,128,102,58.8,50,520.9449,1041.89,127,2,35.8561,63747.13,30,2986,0
0.006435185,106.5,128,102,58.8,50,519.2739,1038.548,127,2,35.7481,63542.65,30,2983,0
0.006527778,107,128,106,58.8,50,518.7169,1037.434,127,1.9,35.7121,63474.49,30,2982,0
0.006631944,107.4,128,102,58.8,50,515.4129,1030.826,126,0.1,35.4961,63070.18,30,2976,0
0.006724537,107.7,127,106,58.8,50,513.2626,1026.525,126,1.1,35.3521,62807.05,30,2972,0
0.00681713,108.3,127,106,58.8,50,511.6499,1023.3,126,2,35.2441,62609.71,30,2969,0
0.006909722,108.4,127,102,58.8,50,508.4245,1016.849,126,1.9,35.0281,62215.02,30,2963,0
0.007002315,109,127,102,58.8,50,503.0487,1006.097,126,1.4,34.6681,61557.2,30,2953,0
0.007106481,109.3,127,102,58.8,50,497.673,995.346,126,1.3,34.3081,60899.38,30,2943,0
0.007199074,109.9,127,106,58.8,50,494.4476,988.8952,126,1.6,34.0921,60504.7,30,2937,0
0.007291667,110,126,102,58.8,50,492.2973,984.5946,126,1.4,33.9481,60241.57,30,2933,0
0.007384259,110.4,126,102,58.8,50,491.2222,982.4443,126,1.8,33.8761,60110,30,2931,0
0.007476852,110.8,126,106,58.8,50,489.6094,979.2189,126,1.8,33.7681,59912.66,30,2928,0
0.007569444,111.1,126,102,58.8,50,487.9967,975.9935,126,1.6,33.6601,59715.32,30,2925,0
0.007673611,111.5,126,102,58.8,50,486.9216,973.8431,125,0.3,33.5881,59583.75,30,2923,0
0.007766204,111.8,126,106,58.8,50,485.8464,971.6929,125,1.3,33.5161,59452.19,30,2921,0
0.007858796,112,126,106,58.8,50,485.3089,970.6177,125,1.5,33.4801,59386.41,30,2920,0
0.007951389,112.4,125,106,58.8,50,484.7713,969.5427,125,1.3,33.4441,59320.63,30,2919,0
0.008043981,112.7,125,102,58.8,50,484.2342,968.4684,125,1.3,33.4081,59254.9,30,2918,0
0.008148148,112.9,125,102,58.8,50,482.6515,965.303,125,1.1,33.3001,59061.23,30,2915,0
0.008240741,113.1,125,102,58.8,50,482.6515,965.303,125,1,33.3001,59061.23,30,2915,0
0.008333333,113.5,125,102,58.8,50,482.124,964.2479,125,1.2,33.2641,58996.67,30,2914,0
0.008425926,113.6,125,102,58.8,50,481.0688,962.1375,125,1.7,33.1921,58867.55,30,2912,0
0.008518519,114,125,102,58.8,50,481.0688,962.1375,125,1.2,33.1921,58867.55,30,2912,0
0.008622685,114.2,125,102,58.8,50,479.4861,958.9722,124,0,33.0841,58673.88,30,2909,0
0.008715278,114.5,125,102,58.8,50,478.4309,956.8618,124,0,33.0121,58544.76,30,2907,0
0.00880787,114.7,125,102,58.8,50,476.8482,953.6964,124,0.8,32.9041,58351.09,30,2904,0
0.008900463,114.9,125,102,58.8,50,474.7379,949.4757,124,1,32.7601,58092.85,30,2900,0
0.00900463,115.1,125,102,58.8,50,473.6827,947.3655,124,0.8,32.6881,57963.73,30,2898,0
0.009097222,115.3,124,102,58.8,50,469.9897,939.9794,124,1.2,32.4361,57511.83,30,2891,0
0.009189815,115.6,124,106,58.8,50,465.7691,931.5382,124,1.1,32.1481,56995.36,30,2883,0
0.009282407,115.6,124,102,58.8,50,461.0209,922.0418,124,1,31.8241,56414.33,30,2874,0
0.009386574,116,124,106,58.8,50,457.3279,914.6558,124,0.8,31.5721,55962.42,30,2867,0
0.009479167,116.2,124,102,58.8,50,455.2176,910.4352,124,1.1,31.4281,55704.19,30,2863,0
0.009571759,116.3,124,106,58.8,50,453.6349,907.2697,124,1.2,31.3201,55510.51,30,2860,0
0.009664352,116.5,124,106,58.8,50,452.052,904.1039,124,1.1,31.2121,55316.82,30,2857,0
0.009756944,116.5,124,102,58.8,50,450.9915,901.9829,123,0,31.1401,55187.04,30,2855,0
0.009861111,116.9,124,102,58.8,50,450.4612,900.9223,123,0.3,31.1041,55122.15,30,2854,0
0.009953704,117.1,124,106,58.8,50,448.8703,897.7407,123,1.4,30.9961,54927.48,30,2851,0
0.010046296,117.1,123,102,58.8,50,448.8703,897.7407,123,0.5,30.9961,54927.48,30,2851,0
0.010138889,117.2,124,102,58.8,50,447.8098,895.6196,123,0.1,30.9241,54797.71,30,2849,0
0.010231481,117.4,123,106,58.8,50,447.2795,894.559,123,0.6,30.8881,54732.82,30,2848,0
0.010335648,117.4,123,102,58.8,50,447.2795,894.559,123,1,30.8881,54732.82,30,2848,0
0.010428241,117.8,123,106,58.8,50,446.7492,893.4985,123,1.3,30.8521,54667.93,30,2847,0
0.010520833,117.8,123,106,58.8,50,446.2189,892.4379,123,1,30.8161,54603.04,30,2846,0
0.010613426,118,123,106,58.8,50,446.2189,892.4379,123,1.1,30.8161,54603.04,30,2846,0
0.010706019,118.1,123,106,58.8,50,445.6887,891.3773,122,0,30.7801,54538.15,30,2845,0
0.010810185,118.1,123,106,58.8,50,445.1584,890.3168,122,0,30.7441,54473.26,30,2844,0
0.010902778,118.3,123,106,58.8,50,444.6281,889.2562,122,0,30.7081,54408.37,30,2843,0
0.01099537,118.3,123,102,58.8,50,444.6281,889.2562,122,0.7,30.7081,54408.37,30,2843,0
0.011087963,118.5,122,106,58.8,50,444.0978,888.1957,122,0.9,30.6721,54343.48,30,2842,0
0.011180556,118.7,122,106,58.8,50,443.5676,887.1351,122,0.8,30.6361,54278.59,30,2841,0
0.011284722,118.7,122,102,58.8,50,444.0978,888.1957,122,0.5,30.6721,54343.48,30,2842,0
0.011377315,118.7,122,102,58.8,50,444.0978,888.1957,122,0.6,30.6721,54343.48,30,2842,0
0.011469907,118.7,122,106,58.8,50,443.0373,886.0745,122,0.7,30.6001,54213.7,30,2840,0
0.011574074,119,122,106,58.8,50,443.0373,886.0745,122,0.8,30.6001,54213.7,30,2840,0
0.011666667,119,122,102,58.8,50,443.0373,886.0745,122,0.7,30.6001,54213.7,30,2840,0
0.011759259,119,122,106,58.8,50,442.507,885.014,121,0,30.5641,54148.81,30,2839,0
0.011851852,119.2,122,102,58.8,50,441.9767,883.9535,121,0,30.5281,54083.93,30,2838,0
0.011944444,119.2,122,106,58.8,50,442.507,885.014,121,0,30.5641,54148.81,30,2839,0
0.012037037,119.2,121,102,58.8,50,441.9767,883.9535,121,0.9,30.5281,54083.93,30,2838,0
0.01212963,119.2,121,102,58.8,50,441.9767,883.9535,121,0.3,30.5281,54083.93,30,2838,0
0.012233796,119.4,121,106,58.8,50,441.9767,883.9535,121,0.4,30.5281,54083.93,30,2838,0
0.012326389,119.4,121,106,58.8,50,441.4464,882.8929,121,0.1,30.4921,54019.04,30,2837,0
0.012418981,119.4,121,102,58.8,50,441.4464,882.8929,121,0.1,30.4921,54019.04,30,2837,0
0.012511574,119.4,121,106,58.8,50,441.4464,882.8929,121,0.2,30.4921,54019.04,30,2837,0
0.012604167,119.6,121,102,58.8,50,440.9162,881.8323,121,0.2,30.4561,53954.15,30,2836,0
0.012708333,119.6,121,106,58.8,50,440.9162,881.8323,121,0,30.4561,53954.15,30,2836,0
0.012800926,119.6,121,102,58.8,50,440.9162,881.8323,121,0.2,30.4561,53954.15,30,2836,0
0.012893519,119.8,121,102,58.8,50,440.9162,881.8323,120,0,30.4561,53954.15,30,2836,0
0.012986111,119.8,121,106,58.8,50,440.9162,881.8323,120,0,30.4561,53954.15,30,2836,0
0.013090278,119.8,121,102,58.8,50,440.3859,880.7717,120,0,30.4201,53889.25,30,2835,0
0.01318287,119.8,121,102,58.8,50,440.3859,880.7717,120,0,30.4201,53889.25,30,2835,0
0.013275463,119.8,121,102,58.8,50,440.3859,880.7717,120,0.1,30.4201,53889.25,30,2835,0
0.013368056,119.9,121,102,117.61,100,530.4139,530.4139,120,0.1,36.4681,64905.83,30,3003,0
0.013460648,119.9,120,102,58.8,50,436.674,873.3479,120,0,30.1681,53435.04,30,2828,0
0.013564815,119.9,120,106,29.4,25,304.3619,1217.448,120,0.1,21.1681,37244.23,30,2578,0
0.013657407,119.9,120,106,58.8,50,312.6963,625.3926,120,0.3,21.7441,38264.1,30,2594,0
0.013761574,119.9,120,106,88.2,75,464.1863,618.9151,120,0.8,32.0401,56801.68,30,2880,0
0.013854167,119.9,120,102,88.2,75,479.4861,639.3148,120,0.5,33.0841,58673.88,30,2909,0
0.013946759,120.1,120,102,117.61,100,530.4139,530.4139,226,70,36.4681,64905.83,30,3003,0
0.014039352,120.1,128,102,58.8,50,354.0114,708.0227,250,70,24.5521,43319.75,30,2672,0
0.014131944,119.9,142,106,58.8,50,339.0962,678.1924,250,70,23.5441,41494.61,30,2644,0
0.014224537,119.9,161,106,58.8,50,315.8217,631.6434,249,70,21.9601,38646.55,30,2600,0
0.014328704,120.1,176,106,58.8,50,295.5065,591.0131,249,70,20.5561,36160.62,30,2561,0
0.014421296,120.1,191,106,58.8,50,40.5962,81.1925,249,55.3,2.8441,4967.691,30,2069,0
0.014513889,120.5,206,112,58.8,50,37.4674,74.9349,248,44.9,2.6281,4584.825,30,2063,0
0.014606481,120.8,215,112,58.8,50,32.2536,64.5071,248,40.9,2.2681,3946.812,30,2053,0
0.014710648,121.4,224,112,58.8,50,27.6462,55.2923,248,30.5,1.9441,3383.011,30,2044,0
0.014803241,122.3,233,112,58.8,50,22.5268,45.0536,248,27.2,1.5841,2756.565,30,2034,0
0.014895833,123.4,237,112,58.8,50,19.4552,38.9104,247,29.4,1.3681,2380.698,30,2028,0
0.014988426,124.6,240,112,58.8,50,18.4313,36.8626,247,27.2,1.2961,2255.409,30,2026,0
0.015081019,125.7,244,112,58.8,50,17.4075,34.8149,247,22.3,1.2241,2130.119,30,2024,0
0.015173611,127.1,247,115,58.8,50,16.3836,32.7672,247,20.7,1.1521,2004.83,30,2022,0
0.015277778,128.6,249,112,58.8,50,15.3597,30.7194,246,18.1,1.0801,1879.541,30,2020,0
0.01537037,130.4,251,112,58.8,50,14.8478,29.6956,246,17.4,1.0441,1816.897,30,2019,0
0.015462963,132.2,252,115,58.8,50,14.8478,29.6956,246,16.3,1.0441,1816.897,30,2019,0
0.015555556,133.8,252,115,58.8,50,14.3358,28.6717,245,13.4,1.0081,1754.252,30,2018,0
0.015648148,135.4,253,115,58.8,50,14.3358,28.6717,245,13.1,1.0081,1754.252,30,2018,0
0.015752315,137.2,253,112,58.8,50,13.8239,27.6478,245,12.2,0.9721,1691.608,30,2017,0
0.015844907,139.4,253,115,58.8,50,13.8239,27.6478,245,12.1,0.9721,1691.608,30,2017,0
0.0159375,141.2,253,115,58.8,50,13.8239,27.6478,244,10,0.9721,1691.608,30,2017,0
0.016030093,143.3,253,115,58.8,50,13.312,26.6239,244,9.6,0.9361,1628.963,30,2016,0
0.016122685,145.1,252,115,58.8,50,13.312,26.6239,244,10.1,0.9361,1628.963,30,2016,0
0.016226852,146.5,252,115,58.8,50,13.312,26.6239,244,9.9,0.9361,1628.963,30,2016,0
0.016319444,148.5,252,115,58.8,50,13.312,26.6239,243,7.3,0.9361,1628.963,30,2016,0
0.016412037,150.1,251,115,58.8,50,13.312,26.6239,243,8.2,0.9361,1628.963,30,2016,0
0.01650463,151.9,250,115,58.8,50,12.8,25.6001,243,8.9,0.9001,1566.318,30,2015,0
0.016597222,153.9,250,115,58.8,50,12.8,25.6001,243,8.6,0.9001,1566.318,30,2015,0
0.016689815,155.4,249,118,58.8,50,12.8,25.6001,242,6.4,0.9001,1566.318,30,2015,0
0.016793981,156.8,248,115,58.8,50,12.8,25.6001,242,7.5,0.9001,1566.318,30,2015,0
0.016886574,158.8,248,118,58.8,50,12.8,25.6001,242,8,0.9001,1566.318,30,2015,0
0.016979167,160.4,247,115,58.8,50,12.8,25.6001,241,6.3,0.9001,1566.318,30,2015,0
0.017071759,162.2,247,118,58.8,50,12.2881,24.5762,241,6.8,0.8641,1503.674,30,2014,0
0.017164352,164,246,115,58.8,50,12.2881,24.5762,241,7.7,0.8641,1503.674,30,2014,0
0.017256944,165.4,245,118,58.8,50,12.2881,24.5762,241,7.3,0.8641,1503.674,30,2014,0
0.017349537,166.7,245,118,58.8,50,12.2881,24.5762,240,5.6,0.8641,1503.674,30,2014,0
0.01744213,168.1,244,115,58.8,50,12.2881,24.5762,240,6.7,0.8641,1503.674,30,2014,0
0.017534722,169.4,244,115,58.8,50,12.2881,24.5762,240,7.1,0.8641,1503.674,30,2014,0
0.017638889,170.5,243,115,58.8,50,12.2881,24.5762,239,5.3,0.8641,1503.674,30,2014,0
0.017731481,172.1,243,118,58.8,50,11.7762,23.5523,239,5.3,0.8281,1441.029,30,2013,0
0.017824074,173.2,242,115,58.8,50,11.7762,23.5523,239,6.4,0.8281,1441.029,30,2013,0
0.017916667,174.2,242,118,58.8,50,11.7762,23.5523,239,6.9,0.8281,1441.029,30,2013,0
0.018009259,175.3,241,115,58.8,50,11.7762,23.5523,238,4.6,0.8281,1441.029,30,2013,0
0.018101852,176.4,241,118,58.8,50,11.7762,23.5523,238,4.8,0.8281,1441.029,30,2013,0
0.018194444,177.5,241,118,58.8,50,11.7762,23.5523,238,6.2,0.8281,1441.029,30,2013,0
0.018298611,178.7,240,115,58.8,50,11.7762,23.5523,238,6.7,0.8281,1441.029,30,2013,0
0.018391204,179.6,240,115,58.8,50,11.7762,23.5523,237,4.3,0.8281,1441.029,30,2013,0
0.018483796,180.7,240,118,58.8,50,11.2642,22.5285,237,5.1,0.7921,1378.385,30,2012,0
0.018576389,181.8,239,118,58.8,50,11.2642,22.5285,237,6.3,0.7921,1378.385,30,2012,0
0.018668981,182.5,239,118,58.8,50,11.2642,22.5285,236,5.9,0.7921,1378.385,30,2012,0
0.018761574,183.6,238,118,58.8,50,11.2642,22.5285,236,4.4,0.7921,1378.385,30,2012,0
0.018854167,184.7,238,118,58.8,50,11.2642,22.5285,236,4.9,0.7921,1378.385,30,2012,0
0.018958333,185.6,238,118,58.8,50,11.2642,22.5285,236,5.6,0.7921,1378.385,30,2012,0
0.019050926,186.5,237,118,58.8,50,11.2642,22.5285,235,3.6,0.7921,1378.385,30,2012,0
0.019143519,187.5,237,118,58.8,50,11.2642,22.5285,235,4.1,0.7921,1378.385,30,2012,0
0.019236111,188.4,237,118,58.8,50,11.2642,22.5285,235,5.6,0.7921,1378.385,30,2012,0
0.019340278,189.3,236,118,58.8,50,11.2642,22.5285,235,5.7,0.7921,1378.385,30,2012,0
0.01943287,190.2,236,118,58.8,50,11.2642,22.5285,234,3.4,0.7921,1378.385,30,2012,0
0.019525463,191.1,236,118,58.8,50,11.2642,22.5285,234,4.1,0.7921,1378.385,30,2012,0
0.019618056,191.8,235,118,58.8,50,10.7523,21.5046,234,5.3,0.7561,1315.74,30,2011,0
0.019710648,192.9,235,118,58.8,50,10.7523,21.5046,234,5.3,0.7561,1315.74,30,2011,0
0.019803241,193.6,235,118,58.8,50,10.7523,21.5046,233,3.1,0.7561,1315.74,30,2011,0
0.019907407,194.2,234,118,58.8,50,10.7523,21.5046,233,4.3,0.7561,1315.74,30,2011,0
0.02,195.1,234,118,58.8,50,10.7523,21.5046,233,5.3,0.7561,1315.74,30,2011,0
0.020092593,195.6,234,118,58.8,50,10.7523,21.5046,232,3.3,0.7561,1315.74,30,2011,0
0.020185185,196.3,234,118,58.8,50,10.7523,21.5046,232,3.7,0.7561,1315.74,30,2011,0
0.020277778,197.1,233,118,58.8,50,10.7523,21.5046,232,4.1,0.7561,1315.74,30,2011,0
0.020381944,198.1,233,118,58.8,50,10.7523,21.5046,232,5.1,0.7561,1315.74,30,2011,0
0.020474537,199.4,233,118,58.8,50,10.7523,21.5046,231,2.5,0.7561,1315.74,30,2011,0
0.02056713,200.8,233,118,58.8,50,10.7523,21.5046,231,3.2,0.7561,1315.74,30,2011,0
0.020659722,201.9,232,118,58.8,50,10.7523,21.5046,231,4.4,0.7561,1315.74,30,2011,0
0.020752315,203,232,118,58.8,50,10.2404,20.4807,230,2.8,0.7201,1253.095,30,2010,0
0.020844907,203.7,232,118,58.8,50,10.2404,20.4807,230,2.6,0.7201,1253.095,30,2010,0
0.020949074,204.6,231,118,58.8,50,10.2404,20.4807,230,4,0.7201,1253.095,30,2010,0
0.021041667,205.3,231,118,58.8,50,10.2404,20.4807,230,4.2,0.7201,1253.095,30,2010,0
0.021134259,205.9,231,118,58.8,50,10.2404,20.4807,229,2.4,0.7201,1253.095,30,2010,0
0.021226852,206.6,230,118,58.8,50,10.2404,20.4807,229,2.9,0.7201,1253.095,30,2010,0
0.021331019,207.1,230,118,58.8,50,10.2404,20.4807,229,3.7,0.7201,1253.095,30,2010,0
0.021423611,207.7,230,118,58.8,50,10.2404,20.4807,229,3.8,0.7201,1253.095,30,2010,0
0.021516204,208.2,230,118,58.8,50,10.2404,20.4807,228,2.1,0.7201,1253.095,30,2010,0
0.021608796,208.6,229,118,58.8,50,10.2404,20.4807,228,2.8,0.7201,1253.095,30,2010,0
0.021701389,209.1,229,118,58.8,50,10.2404,20.4807,228,4,0.7201,1253.095,30,2010,0
0.021793981,209.6,229,118,58.8,50,10.2404,20.4807,228,3.6,0.7201,1253.095,30,2010,0
0.021886574,210,229,118,58.8,50,10.2404,20.4807,227,1.6,0.7201,1253.095,30,2010,0
0.021990741,210.4,228,118,58.8,50,10.2404,20.4807,227,3.4,0.7201,1253.095,30,2010,0
0.022083333,210.9,228,118,58.8,50,10.2404,20.4807,227,3.3,0.7201,1253.095,30,2010,0
0.022175926,211.3,228,118,58.8,50,10.2404,20.4807,226,1.5,0.7201,1253.095,30,2010,0
0.022268519,211.6,227,118,58.8,50,9.7284,19.4569,226,1.8,0.6841,1190.451,30,2009,0
0.022361111,212,227,118,58.8,50,9.7284,19.4569,226,2.9,0.6841,1190.451,30,2009,0
0.022465278,212.3,227,118,58.8,50,9.7284,19.4569,226,3.3,0.6841,1190.451,30,2009,0
0.02255787,212.7,227,118,58.8,50,9.7284,19.4569,225,1.1,0.6841,1190.451,30,2009,0
0.022650463,213.1,226,118,58.8,50,9.7284,19.4569,225,2.4,0.6841,1190.451,30,2009,0
0.022743056,213.4,226,118,58.8,50,9.7284,19.4569,225,2.9,0.6841,1190.451,30,2009,0
0.022835648,213.6,226,118,58.8,50,9.7284,19.4569,224,3.1,0.6841,1190.451,30,2009,0
0.022928241,214,225,118,58.8,50,9.7284,19.4569,224,1.5,0.6841,1190.451,30,2009,0
0.023020833,214.1,225,118,58.8,50,9.7284,19.4569,224,2.2,0.6841,1190.451,30,2009,0
0.023125,214.3,225,118,58.8,50,9.7284,19.4569,224,3,0.6841,1190.451,30,2009,0
0.023217593,214.5,224,118,58.8,50,9.7284,19.4569,223,1.2,0.6841,1190.451,30,2009,0
0.023310185,214.9,224,118,58.8,50,9.7284,19.4569,223,1.9,0.6841,1190.451,30,2009,0
0.023402778,215,224,118,58.8,50,9.7284,19.4569,223,2.3,0.6841,1190.451,30,2009,0
0.02349537,215.2,224,118,58.8,50,9.7284,19.4569,223,3.3,0.6841,1190.451,30,2009,0
0.023587963,215.4,223,118,58.8,50,9.7284,19.4569,222,0.9,0.6841,1190.451,30,2009,0
0.02369213,215.6,223,118,58.8,50,9.7284,19.4569,222,1.4,0.6841,1190.451,30,2009,0
0.023784722,215.8,223,118,58.8,50,9.7284,19.4569,222,2.8,0.6841,1190.451,30,2009,0
0.023877315,215.9,222,118,58.8,50,9.2165,18.433,222,3.1,0.6481,1127.806,30,2008,0
0.023969907,216.1,222,118,58.8,50,9.2165,18.433,221,0.5,0.6481,1127.806,30,2008,0
0.0240625,216.3,222,118,58.8,50,9.2165,18.433,221,1.7,0.6481,1127.806,30,2008,0
0.024155093,216.3,222,118,58.8,50,9.2165,18.433,221,2.7,0.6481,1127.806,30,2008,0
0.024259259,216.7,221,118,58.8,50,9.2165,18.433,220,0.8,0.6481,1127.806,30,2008,0
0.024351852,216.7,221,118,58.8,50,9.2165,18.433,220,1.5,0.6481,1127.806,30,2008,0
0.024444444,216.7,221,118,117.61,100,9.2165,9.2165,220,2.3,0.6481,1127.806,30,2008,0
0.024548611,216.7,221,118,88.2,75,9.2165,12.2887,220,2.3,0.6481,1127.806,30,2008,0
0.024641204,217,220,118,58.8,50,9.2165,18.433,220,2.4,0.6481,1127.806,30,2008,0
0.024733796,217,220,118,29.4,25,9.2165,36.866,220,2.3,0.6481,1127.806,30,2008,0
0.024826389,217,220,118,58.8,50,9.2165,36.866,220,2.2,0.6481,1127.806,30,2008,0
0.024918981,217,220,118,88.2,75,9.2165,18.433,220,2.3,0.6481,1127.806,30,2008,0
0.025023148,217.2,220,118,88.2,75,9.2165,12.2887,220,2.5,0.6481,1127.806,30,2008,0
0.025115741,217.2,220,118,117.61,100,9.2165,9.2165,270,70,0.6481,1127.806,30,2008,0
0.025208333,217.2,225,118,58.8,50,8.7046,17.4091,340,70,0.6121,1065.162,30,2007,0
0.025300926,217.2,238,118,58.8,50,8.7046,17.4091,340,70,0.6121,1065.162,30,2007,0
0.025393519,217.4,253,118,58.8,50,8.7046,17.4091,339,70,0.6121,1065.162,30,2007,0
0.025486111,217.4,271,118,58.8,50,8.7046,17.4091,339,67.9,0.6121,1065.162,30,2007,0
0.025578704,217.6,284,118,58.8,50,8.7046,17.4091,339,53.3,0.6121,1065.162,30,2007,0
0.025671296,217.9,296,118,58.8,50,8.7046,17.4091,339,44.7,0.6121,1065.162,30,2007,0
0.025787037,218.5,308,118,58.8,50,8.7046,17.4091,338,40.5,0.6121,1065.162,30,2007,0
0.025891204,219.5,315,121,58.8,50,8.7046,17.4091,338,41.2,0.6121,1065.162,30,2007,0
0.025983796,220.6,320,121,58.8,50,8.7046,17.4091,338,37.5,0.6121,1065.162,30,2007,0
0.026087963,221.7,326,121,58.8,50,8.7046,17.4091,337,30,0.6121,1065.162,30,2007,0
0.026180556,223.3,330,121,58.8,50,8.7046,17.4091,337,27.9,0.6121,1065.162,30,2007,0
0.026273148,224.8,333,121,58.8,50,8.7046,17.4091,337,26.5,0.6121,1065.162,30,2007,0
0.026365741,226.2,336,121,58.8,50,8.7046,17.4091,337,24.1,0.6121,1065.162,30,2007,0
0.026458333,228.3,338,121,58.8,50,8.1926,16.3853,336,20.1,0.5761,1002.517,30,2006,0
0.026550926,229.8,340,127,58.8,50,8.1926,16.3853,336,19.6,0.5761,1002.517,30,2006,0
0.026643519,231.6,341,127,58.8,50,8.1926,16.3853,336,18.8,0.5761,1002.517,30,2006,0
0.026747685,233.7,342,127,58.8,50,8.1926,16.3853,336,17.6,0.5761,1002.517,30,2006,0
0.026840278,235.4,342,127,58.8,50,8.1926,16.3853,335,15,0.5761,1002.517,30,2006,0
0.02693287,237.2,343,127,58.8,50,8.1926,16.3853,335,15.1,0.5761,1002.517,30,2006,0
0.027025463,239.3,343,127,58.8,50,8.1926,16.3853,335,14.8,0.5761,1002.517,30,2006,0
0.027118056,240.9,343,127,58.8,50,8.1926,16.3853,334,12.2,0.5761,1002.517,30,2006,0
0.027210648,242.7,343,127,58.8,50,8.1926,16.3853,334,11.9,0.5761,1002.517,30,2006,0
0.027303241,244.7,342,127,58.8,50,8.1926,16.3853,334,12.5,0.5761,1002.517,30,2006,0
0.027407407,246.5,342,127,58.8,50,8.1926,16.3853,334,12.5,0.5761,1002.517,30,2006,0
0.0275,248.1,341,127,58.8,50,8.1926,16.3853,333,9.8,0.5761,1002.517,30,2006,0
0.027592593,249.9,341,127,58.8,50,8.1926,16.3853,333,10.7,0.5761,1002.517,30,2006,0
0.027685185,251.4,340,130,58.8,50,8.1926,16.3853,333,10.9,0.5761,1002.517,30,2006,0
0.027777778,253,340,127,58.8,50,8.1926,16.3853,332,8.7,0.5761,1002.517,30,2006,0
0.02787037,255,339,130,58.8,50,8.1926,16.3853,332,9.1,0.5761,1002.517,30,2006,0
0.027962963,256.4,339,127,58.8,50,8.1926,16.3853,332,9.8,0.5761,1002.517,30,2006,0
0.028055556,257.8,338,130,58.8,50,8.1926,16.3853,332,10,0.5761,1002.517,30,2006,0
0.028148148,259.4,337,130,58.8,50,8.1926,16.3853,331,8.1,0.5761,1002.517,30,2006,0
0.028252315,261.1,337,130,58.8,50,8.1926,16.3853,331,8.4,0.5761,1002.517,30,2006,0
0.028344907,262.3,336,130,58.8,50,8.1926,16.3853,331,9.2,0.5761,1002.517,30,2006,0
0.0284375,263.9,336,130,58.8,50,8.1926,16.3853,331,9.1,0.5761,1002.517,30,2006,0
0.028530093,265.4,335,130,58.8,50,7.6807,15.3614,330,7.3,0.5401,939.8726,30,2005,0
0.028622685,266.6,335,130,58.8,50,7.6807,15.3614,330,8,0.5401,939.8726,30,2005,0
0.028715278,268.3,334,127,58.8,50,7.6807,15.3614,330,8.8,0.5401,939.8726,30,2005,0
0.02880787,269.5,334,130,58.8,50,7.6807,15.3614,330,9,0.5401,939.8726,30,2005,0
0.028912037,270.8,333,130,58.8,50,7.6807,15.3614,329,6.9,0.5401,939.8726,30,2005,0
0.02900463,272,333,130,58.8,50,7.6807,15.3614,329,7.8,0.5401,939.8726,30,2005,0
0.029097222,273.3,332,130,58.8,50,7.6807,15.3614,329,8.5,0.5401,939.8726,30,2005,0
0.029189815,274.6,332,130,58.8,50,7.6807,15.3614,328,6.4,0.5401,939.8726,30,2005,0
0.029282407,276,331,130,58.8,50,7.6807,15.3614,328,6.7,0.5401,939.8726,30,2005,0
0.029386574,277.1,331,130,58.8,50,7.6807,15.3614,328,7.8,0.5401,939.8726,30,2005,0
0.029479167,278.1,330,130,58.8,50,7.6807,15.3614,328,7.8,0.5401,939.8726,30,2005,0
0.029571759,279.2,330,130,58.8,50,7.6807,15.3614,327,6.1,0.5401,939.8726,30,2005,0
0.029664352,280.3,330,130,58.8,50,7.6807,15.3614,327,7,0.5401,939.8726,30,2005,0
0.029756944,281.2,329,130,58.8,50,7.6807,15.3614,327,7.9,0.5401,939.8726,30,2005,0
0.029849537,282.5,329,130,58.8,50,7.6807,15.3614,327,7.6,0.5401,939.8726,30,2005,0
0.029953704,283.5,329,130,58.8,50,7.6807,15.3614,326,5.7,0.5401,939.8726,30,2005,0
0.030046296,284.4,328,130,58.8,50,7.6807,15.3614,326,6.8,0.5401,939.8726,30,2005,0
0.030138889,285.3,328,130,58.8,50,7.6807,15.3614,326,7.4,0.5401,939.8726,30,2005,0
0.030231481,286.2,327,130,58.8,50,7.6807,15.3614,325,5.7,0.5401,939.8726,30,2005,0
0.030324074,287,327,130,58.8,50,7.6807,15.3614,325,5.9,0.5401,939.8726,30,2005,0
0.030416667,288,327,130,58.8,50,7.1688,14.3375,325,6.6,0.5041,877.228,30,2004,0
0.030509259,288.8,326,130,58.8,50,7.1688,14.3375,325,7,0.5041,877.228,30,2004,0
0.030613426,289.5,326,130,58.8,50,7.1688,14.3375,324,5.1,0.5041,877.228,30,2004,0
0.030706019,290.4,326,130,58.8,50,7.1688,14.3375,324,5.2,0.5041,877.228,30,2004,0
0.030798611,291.1,325,130,58.8,50,7.1688,14.3375,324,6.8,0.5041,877.228,30,2004,0
0.030891204,291.8,325,134,58.8,50,7.1688,14.3375,324,6.8,0.5041,877.228,30,2004,0
0.030983796,292.7,325,130,58.8,50,7.1688,14.3375,323,4.8,0.5041,877.228,30,2004,0
0.031076389,293.4,325,130,58.8,50,7.1688,14.3375,323,5.7,0.5041,877.228,30,2004,0
0.031168981,294,324,130,58.8,50,7.1688,14.3375,323,6.4,0.5041,877.228,30,2004,0
0.031261574,294.5,324,130,58.8,50,7.1688,14.3375,322,4.7,0.5041,877.228,30,2004,0
0.031365741,295.2,324,130,58.8,50,7.1688,14.3375,322,4.8,0.5041,877.228,30,2004,0
0.031458333,295.8,323,134,58.8,50,7.1688,14.3375,322,6,0.5041,877.228,30,2004,0
0.031550926,296.5,323,134,58.8,50,7.1688,14.3375,322,6.4,0.5041,877.228,30,2004,0
0.031643519,297,323,130,58.8,50,7.1688,14.3375,321,4.6,0.5041,877.228,30,2004,0
0.031736111,297.6,323,130,58.8,50,7.1688,14.3375,321,5.1,0.5041,877.228,30,2004,0
0.031828704,298.1,322,134,58.8,50,7.1688,14.3375,321,6.2,0.5041,877.228,30,2004,0
0.031921296,298.6,322,130,58.8,50,7.1688,14.3375,321,5.9,0.5041,877.228,30,2004,0
0.032025463,299,322,130,58.8,50,7.1688,14.3375,320,4.3,0.5041,877.228,30,2004,0
0.032118056,299.7,321,130,58.8,50,6.6568,13.3136,320,5.3,0.4681,814.5834,30,2003,0
0.032210648,300.1,321,130,58.8,50,6.6568,13.3136,320,5.6,0.4681,814.5834,30,2003,0
0.032303241,300.6,321,134,58.8,50,6.6568,13.3136,319,3.7,0.4681,814.5834,30,2003,0
0.032395833,301,321,130,58.8,50,6.6568,13.3136,319,3.6,0.4681,814.5834,30,2003,0
0.0325,301.3,320,130,58.8,50,6.6568,13.3136,319,5.8,0.4681,814.5834,30,2003,0
0.032592593,301.7,320,134,58.8,50,6.6568,13.3136,319,5.3,0.4681,814.5834,30,2003,0
0.032685185,302.1,320,134,58.8,50,6.6568,13.3136,318,4.1,0.4681,814.5834,30,2003,0
0.032777778,302.4,319,134,58.8,50,6.6568,13.3136,318,4.2,0.4681,814.5834,30,2003,0
0.03287037,302.8,319,130,58.8,50,6.6568,13.3136,318,5.2,0.4681,814.5834,30,2003,0
0.032974537,303.1,319,130,58.8,50,6.6568,13.3136,318,5.5,0.4681,814.5834,30,2003,0
0.03306713,303.5,319,130,58.8,50,6.6568,13.3136,317,3.7,0.4681,814.5834,30,2003,0
0.033159722,303.9,318,134,58.8,50,6.6568,13.3136,317,4.3,0.4681,814.5834,30,2003,0
0.033252315,304,318,134,58.8,50,6.6568,13.3136,317,4.8,0.4681,814.5834,30,2003,0
0.033344907,304.4,318,130,58.8,50,6.6568,13.3136,316,3.6,0.4681,814.5834,30,2003,0
0.0334375,304.8,317,134,58.8,50,6.6568,13.3136,316,3.5,0.4681,814.5834,30,2003,0
0.033541667,304.9,317,130,58.8,50,6.6568,13.3136,316,4.6,0.4681,814.5834,30,2003,0
0.033634259,305.1,317,130,58.8,50,6.6568,13.3136,316,4.7,0.4681,814.5834,30,2003,0
0.033726852,305.3,317,130,58.8,50,6.1449,12.2898,315,3.1,0.4321,751.9389,30,2002,0
0.033819444,305.5,316,130,58.8,50,6.1449,12.2898,315,3.8,0.4321,751.9389,30,2002,0
0.033912037,305.8,316,130,58.8,50,6.1449,12.2898,315,4.2,0.4321,751.9389,30,2002,0
0.034016204,306,316,130,58.8,50,6.1449,12.2898,315,5.3,0.4321,751.9389,30,2002,0
0.034108796,306,315,130,58.8,50,6.1449,12.2898,314,2.8,0.4321,751.9389,30,2002,0
0.034201389,306.2,315,130,58.8,50,6.1449,12.2898,314,3.7,0.4321,751.9389,30,2002,0
0.034293981,306.6,315,130,58.8,50,6.1449,12.2898,314,4.9,0.4321,751.9389,30,2002,0
0.034386574,306.6,314,130,58.8,50,6.1449,12.2898,313,3.2,0.4321,751.9389,30,2002,0
0.034490741,306.9,314,134,58.8,50,6.1449,12.2898,313,3.1,0.4321,751.9389,30,2002,0
0.034583333,306.9,314,134,58.8,50,6.1449,12.2898,313,4.3,0.4321,751.9389,30,2002,0
0.034675926,307.1,314,130,58.8,50,6.1449,12.2898,313,4.5,0.4321,751.9389,30,2002,0
0.034768519,307.1,313,130,58.8,50,6.1449,12.2898,312,2.5,0.4321,751.9389,30,2002,0
0.034872685,307.1,313,134,58.8,50,6.1449,12.2898,312,3.3,0.4321,751.9389,30,2002,0
0.034965278,307.3,313,134,58.8,50,6.1449,12.2898,312,3.9,0.4321,751.9389,30,2002,0
0.03505787,307.5,312,130,58.8,50,6.1449,12.2898,312,4.3,0.4321,751.9389,30,2002,0
0.035150463,307.5,312,130,58.8,50,6.1449,12.2898,311,2.5,0.4321,751.9389,30,2002,0
0.035243056,307.5,312,130,58.8,50,6.1449,12.2898,311,3.4,0.4321,751.9389,30,2002,0
0.035347222,307.6,312,130,58.8,50,6.1449,12.2898,311,4.4,0.4321,751.9389,30,2002,0
0.035439815,307.6,311,130,58.8,50,6.1449,12.2898,310,2.4,0.4321,751.9389,30,2002,0
0.035532407,307.8,311,134,58.8,50,5.6329,11.2659,310,3,0.3961,689.2943,30,2001,0
0.035625,307.8,311,130,117.61,100,5.6329,5.6329,310,3.9,0.3961,689.2943,30,2001,0
0.035717593,307.8,310,130,88.2,75,5.6329,7.5106,310,4.2,0.3961,689.2943,30,2001,0
0.035810185,307.8,310,130,58.8,50,5.6329,11.2659,310,4,0.3961,689.2943,30,2001,0
0.035914352,307.8,310,130,58.8,50,5.6329,11.2659,310,3.7,0.3961,689.2943,30,2001,0
0.036006944,307.8,310,134,29.4,25,5.6329,22.5318,310,4,0.3961,689.2943,30,2001,0
0.036099537,307.8,310,130,58.8,50,5.6329,11.2659,310,4,0.3961,689.2943,30,2001,0
0.03619213,307.8,310,134,88.2,75,5.6329,7.5106,310,4.1,0.3961,689.2943,30,2001,0
0.036284722,307.8,310,130,117.61,100,5.6329,5.6329,344,60.3,0.3961,689.2943,30,2001,0
0.036388889,307.8,313,130,58.8,50,5.6329,11.2659,445,70,0.3961,689.2943,30,2001,0
0.036481481,307.6,326,134,58.8,50,5.6329,11.2659,445,70,0.3961,689.2943,30,2001,0
0.036574074,307.6,340,134,58.8,50,5.6329,11.2659,444,70,0.3961,689.2943,30,2001,0
0.036666667,307.6,352,130,58.8,50,5.6329,11.2659,444,70,0.3961,689.2943,30,2001,0
0.036759259,307.8,369,130,58.8,50,5.121,10.242,444,70,0.3601,626.6497,30,2000,0
0.036863426,308,381,134,58.8,50,5.121,10.242,443,70,0.3601,626.6497,30,2000,0
0.036956019,308.4,393,134,58.8,50,5.121,10.242,443,61.4,0.3601,626.6497,30,2000,0
0.037048611,308.9,405,134,58.8,50,5.121,10.242,443,51.2,0.3601,626.6497,30,2000,0
0.037141204,309.8,414,134,58.8,50,5.121,10.242,442,45.9,0.3601,626.6497,30,2000,0
0.03724537,311,422,134,58.8,50,5.121,10.242,442,43.1,0.3601,626.6497,30,2000,0
0.037337963,312.3,427,134,58.8,50,5.121,10.242,442,41.6,0.3601,626.6497,30,2000,0
0.037430556,313.7,432,134,58.8,50,5.121,10.242,441,37,0.3601,626.6497,30,2000,0
0.037523148,315.2,436,134,58.8,50,5.121,10.242,441,33.4,0.3601,626.6497,30,2000,0
0.037627315,317.2,439,149,58.8,50,5.121,10.242,441,31,0.3601,626.6497,30,2000,0
0.037719907,318.8,442,149,58.8,50,5.121,10.242,440,27.9,0.3601,626.6497,30,2000,0
0.0378125,320.8,444,149,58.8,50,5.121,10.242,440,26.3,0.3601,626.6497,30,2000,0
0.037905093,322.4,445,152,58.8,50,5.121,10.242,440,25.3,0.3601,626.6497,30,2000,0
0.037997685,324,446,152,58.8,50,5.121,10.242,440,23.5,0.3601,626.6497,30,2000,0
0.038101852,326,447,152,58.8,50,5.121,10.242,439,20.9,0.3601,626.6497,30,2000,0
0.038194444,327.6,447,149,58.8,50,5.121,10.242,439,21.2,0.3601,626.6497,30,2000,0
0.038287037,329.4,448,152,58.8,50,5.121,10.242,439,20.1,0.3601,626.6497,30,2000,0
0.03837963,331,448,152,58.8,50,5.121,10.242,438,17.8,0.3601,626.6497,30,2000,0
0.038472222,333,448,152,58.8,50,5.121,10.242,438,17.4,0.3601,626.6497,30,2000,0
0.038564815,334.8,447,152,58.8,50,4.6091,9.2182,438,17.5,0.3241,564.0051,30,1999,0
0.038668981,336.4,447,152,58.8,50,4.6091,9.2182,437,15.5,0.3241,564.0051,30,1999,0
0.038761574,338.4,446,152,58.8,50,4.6091,9.2182,437,16.1,0.3241,564.0051,30,1999,0
0.038854167,340.2,446,155,58.8,50,4.6091,9.2182,437,15.4,0.3241,564.0051,30,1999,0
0.038946759,342.1,445,152,58.8,50,4.6091,9.2182,436,13.6,0.3241,564.0051,30,1999,0
0.039039352,343.9,445,155,58.8,50,4.6091,9.2182,436,14,0.3241,564.0051,30,1999,0
0.039143519,345.7,444,155,58.8,50,4.6091,9.2182,436,14.2,0.3241,564.0051,30,1999,0
0.039236111,347.5,443,155,58.8,50,4.6091,9.2182,435,12.4,0.3241,564.0051,30,1999,0
0.039328704,349.2,443,155,58.8,50,4.6091,9.2182,435,12.9,0.3241,564.0051,30,1999,0
0.039421296,350.8,442,155,58.8,50,4.6091,9.2182,435,13.5,0.3241,564.0051,30,1999,0
0.039513889,352.8,441,155,58.8,50,4.6091,9.2182,434,11.5,0.3241,564.0051,30,1999,0
0.039606481,354.4,441,155,58.8,50,4.6091,9.2182,434,12,0.3241,564.0051,30,1999,0
0.039710648,356,440,155,58.8,50,4.6091,9.2182,434,12.6,0.3241,564.0051,30,1999,0
0.039803241,357.8,439,155,58.8,50,4.6091,9.2182,433,10.8,0.3241,564.0051,30,1999,0
0.039895833,359.4,439,155,58.8,50,4.6091,9.2182,433,11.5,0.3241,564.0051,30,1999,0
0.039988426,361.4,438,155,58.8,50,4.6091,9.2182,433,11.6,0.3241,564.0051,30,1999,0
0.040081019,362.8,438,155,58.8,50,4.6091,9.2182,433,11.6,0.3241,564.0051,30,1999,0
0.040173611,364.3,437,155,58.8,50,4.6091,9.2182,432,10.2,0.3241,564.0051,30,1999,0
0.040266204,367.1,436,155,58.8,50,4.0971,8.1943,432,11.3,0.2881,501.3605,30,1998,0
0.04037037,368.4,436,161,58.8,50,4.0971,8.1943,432,11.7,0.2881,501.3605,30,1998,0
0.040462963,369.8,435,155,58.8,50,4.0971,8.1943,431,9.6,0.2881,501.3605,30,1998,0
0.040555556,371.5,435,155,58.8,50,4.0971,8.1943,431,10.4,0.2881,501.3605,30,1998,0
0.040648148,372.7,434,161,58.8,50,4.0971,8.1943,431,11.2,0.2881,501.3605,30,1998,0
0.040740741,374,434,161,58.8,50,4.0971,8.1943,430,9.5,0.2881,501.3605,30,1998,0
0.040844907,375.6,433,161,58.8,50,4.0971,8.1943,430,9.9,0.2881,501.3605,30,1998,0
0.0409375,376.8,433,161,58.8,50,4.0971,8.1943,430,10.7,0.2881,501.3605,30,1998,0
0.041041667,378.1,432,161,58.8,50,4.0971,8.1943,429,9,0.2881,501.3605,30,1998,0
0.041134259,379.4,432,161,58.8,50,4.0971,8.1943,429,9.4,0.2881,501.3605,30,1998,0
0.041238426,380.6,431,161,58.8,50,4.0971,8.1943,429,10.3,0.2881,501.3605,30,1998,0
0.041331019,381.7,431,161,58.8,50,4.0971,8.1943,428,8.8,0.2881,501.3605,30,1998,0
0.041423611,383,431,161,58.8,50,3.5852,7.1704,428,9.4,0.2521,438.716,30,1997,0
0.041516204,383.9,430,161,58.8,50,3.5852,7.1704,428,10,0.2521,438.716,30,1997,0
0.041608796,385.1,430,161,58.8,50,3.5852,7.1704,427,8.1,0.2521,438.716,30,1997,0
0.041701389,386,429,161,58.8,50,3.5852,7.1704,427,8.3,0.2521,438.716,30,1997,0
0.041793981,386.7,429,161,58.8,50,3.5852,7.1704,427,9.4,0.2521,438.716,30,1997,0
0.041886574,387.6,429,161,58.8,50,3.5852,7.1704,426,7.9,0.2521,438.716,30,1997,0
0.041979167,388.5,428,161,58.8,50,3.5852,7.1704,426,8.4,0.2521,438.716,30,1997,0
0.042083333,389.3,428,161,58.8,50,3.5852,7.1704,426,9.1,0.2521,438.716,30,1997,0
0.042175926,390.2,428,155,58.8,50,3.5852,7.1704,425,7.2,0.2521,438.716,30,1997,0
0.042268519,390.9,427,155,58.8,50,3.5852,7.1704,425,8.2,0.2521,438.716,30,1997,0
0.042361111,391.6,427,149,58.8,50,3.5852,7.1704,425,8.7,0.2521,438.716,30,1997,0
0.042453704,392.3,426,134,58.8,50,3.0733,6.1466,424,7.4,0.2161,376.0714,30,1996,0
0.04255787,393,426,130,58.8,50,3.0733,6.1466,424,7.5,0.2161,376.0714,30,1996,0
0.042650463,393.7,426,127,58.8,50,3.0733,6.1466,424,8,0.2161,376.0714,30,1996,0
0.042743056,394.3,425,121,58.8,50,3.0733,6.1466,424,9,0.2161,376.0714,30,1996,0
0.042847222,395,425,115,58.8,50,3.0733,6.1466,423,7.1,0.2161,376.0714,30,1996,0
0.042939815,395.5,425,112,58.8,50,3.0733,6.1466,423,7.6,0.2161,376.0714,30,1996,0
0.043032407,396.1,424,106,58.8,50,3.0733,6.1466,423,8.5,0.2161,376.0714,30,1996,0
0.043125,396.8,424,102,58.8,50,3.0733,6.1466,422,7.3,0.2161,376.0714,30,1996,0
0.043217593,397.2,423,99,58.8,50,3.0733,6.1466,422,8,0.2161,376.0714,30,1996,0
0.043321759,397.7,423,96,58.8,50,2.0494,4.0988,422,8,0.1441,250.7822,30,1994,0
0.043414352,398.2,423,93,58.8,50,2.0494,4.0988,421,6.8,0.1441,250.7822,30,1994,0
0.043506944,398.8,423,93,58.8,50,2.0494,4.0988,421,7.3,0.1441,250.7822,30,1994,0
0.043611111,399.3,422,93,58.8,50,2.0494,4.0988,421,8,0.1441,250.7822,30,1994,0
0.043703704,399.7,422,93,58.8,50,2.0494,4.0988,420,6.2,0.1441,250.7822,30,1994,0
0.043796296,400.4,421,93,58.8,50,2.0494,4.0988,420,7.2,0.1441,250.7822,30,1994,0
0.043888889,400.8,421,93,58.8,50,2.0494,4.0988,420,8,0.1441,250.7822,30,1994,0
0.043993056,401.3,421,93,58.8,50,2.0494,4.0988,419,6.1,0.1441,250.7822,30,1994,0
0.044085648,401.7,420,93,58.8,50,2.0494,4.0988,419,7.1,0.1441,250.7822,30,1994,0
0.044178241,402.2,420,93,58.8,50,2.0494,4.0988,419,7.4,0.1441,250.7822,30,1994,0
0.044282407,402.4,420,93,58.8,50,2.0494,4.0988,418,6.1,0.1441,250.7822,30,1994,0
0.044375,402.7,420,96,58.8,50,2.0494,4.0988,418,6.3,0.1441,250.7822,30,1994,0
0.044467593,403.1,419,96,58.8,50,2.0494,4.0988,418,7.2,0.1441,250.7822,30,1994,0
0.044560185,403.5,419,93,58.8,50,2.0494,4.0988,417,5.6,0.1441,250.7822,30,1994,0
0.044664352,403.6,418,96,58.8,50,2.0494,4.0988,417,6.1,0.1441,250.7822,30,1994,0
0.044756944,404,418,96,58.8,50,2.0494,4.0988,417,6.8,0.1441,250.7822,30,1994,0
0.044849537,404.2,418,96,58.8,50,1.5375,3.0749,417,7.4,0.1081,188.1376,30,1993,0
0.044953704,404.5,418,96,58.8,50,1.5375,3.0749,416,5.3,0.1081,188.1376,30,1993,0
0.045046296,404.7,417,96,58.8,50,1.5375,3.0749,416,6.1,0.1081,188.1376,30,1993,0
0.045138889,404.9,417,93,58.8,50,1.5375,3.0749,415,5.6,0.1081,188.1376,30,1993,0
0.045231481,405.1,417,96,58.8,50,1.5375,3.0749,415,5.3,0.1081,188.1376,30,1993,0
0.045335648,405.1,416,96,58.8,50,1.5375,3.0749,415,6.7,0.1081,188.1376,30,1993,0
0.045428241,405.3,416,96,58.8,50,1.5375,3.0749,414,4.7,0.1081,188.1376,30,1993,0
0.045520833,405.4,416,96,58.8,50,1.5375,3.0749,414,5.1,0.1081,188.1376,30,1993,0
0.045613426,405.4,415,96,58.8,50,1.0255,2.0511,414,6.1,0.0721,125.4931,30,1992,0
0.045706019,405.4,415,96,58.8,50,1.0255,2.0511,414,6.6,0.0721,125.4931,30,1992,0
0.045810185,405.8,415,96,58.8,50,1.0255,2.0511,413,4.8,0.0721,125.4931,30,1992,0
0.045902778,405.8,414,96,58.8,50,1.0255,2.0511,413,5.7,0.0721,125.4931,30,1992,0
0.04599537,405.8,414,96,58.8,50,1.0255,2.0511,413,6.2,0.0721,125.4931,30,1992,0
0.046087963,405.8,414,96,58.8,50,0.5136,1.0272,412,4.8,0.0361,62.8485,30,1991,0
0.04619213,405.8,413,96,58.8,50,0.5136,1.0272,412,5.5,0.0361,62.8485,30,1991,0
0.046284722,405.8,413,96,58.8,50,0.5136,1.0272,412,6.5,0.0361,62.8485,30,1991,0
0.046377315,405.8,413,96,58.8,50,0.5136,1.0272,411,4.3,0.0361,62.8485,30,1991,0
0.046469907,405.8,412,96,58.8,50,0.0017,0.0033,411,4.8,0.0001,0.2039,30,1990,0
0.046574074,405.8,412,96,58.8,50,0.0017,0.0033,411,5.8,0.0001,0.2039,30,1990,0
0.046666667,405.8,412,96,58.8,50,0.0017,0.0033,410,4.6,0.0001,0.2039,30,1990,0
0.046759259,405.8,411,96,58.8,50,0.0017,0.0033,410,5.3,0.0001,0.2039,30,1990,0
0.046851852,405.6,411,96,117.61,100,0.0017,0.0017,410,5.7,0.0001,0.2039,30,1990,0
0.046944444,405.4,411,96,88.2,75,0.0017,0.0022,410,6.2,0.0001,0.2039,30,1990,0
0.047048611,405.4,410,96,58.8,50,0.0017,0.0033,410,5.7,0.0001,0.2039,30,1990,0
0.047141204,405.4,410,96,29.4,25,0.0017,0.0067,410,6.4,0.0001,0.2039,30,1990,0
0.047233796,405.3,410,96,58.8,50,0.0017,0.0033,410,6,0.0001,0.2039,30,1990,0
0.047326389,405.3,410,96,88.2,75,0.0017,0.0022,410,6.4,0.0001,0.2039,30,1990,0
0.047418981,405.1,410,96,117.61,100,0.0017,0.0017,410,6.1,0.0001,0.2039,30,1990,0
0.047511574,405.1,410,93,117.61,100,0.0017,0.0017,491,70,0.0001,0.2039,30,1990,0
0.047615741,404.9,416,96,58.8,50,0.0017,0.0033,500,70,0.0001,0.2039,30,1990,0
0.047708333,404.9,427,96,58.8,50,0,0,500,70,-0.0359,0,30,1989,0
0.047800926,404.7,442,96,58.8,50,0,0,499,60.7,-0.0359,0,30,1989,0
0.047893519,404.9,453,96,58.8,50,0,0,499,47.5,-0.0359,0,30,1989,0
0.047986111,404.9,464,96,58.8,50,0,0,499,44.3,-0.0359,0,30,1989,0
0.048090278,405.1,471,96,58.8,50,0,0,499,44.5,-0.0359,0,30,1989,0
0.04818287,405.6,476,99,58.8,50,0,0,499,41.5,-0.0359,0,30,1989,0
0.048275463,406,482,102,58.8,50,0,0,499,36.6,-0.0359,0,30,1989,0
0.048368056,406.7,486,106,58.8,50,0,0,498,32.2,-0.0359,0,30,1989,0
0.048460648,407.4,490,106,58.8,50,0,0,498,30.7,-0.0359,0,30,1989,0
0.048553241,408.5,492,106,58.8,50,0,0,498,29.8,-0.0359,0,30,1989,0
0.048657407,409.7,495,112,58.8,50,0,0,498,27.6,-0.0359,0,30,1989,0
0.04875,411,497,112,58.8,50,0,0,498,26.2,-0.0359,0,30,1989,0
0.048842593,412.4,498,112,58.8,50,0,0,498,25.4,-0.0359,0,30,1989,0
0.048935185,414.1,500,115,58.8,50,0,0,497,23,-0.0719,0,30,1988,0
0.049027778,416.2,500,115,58.8,50,0,0,497,23.3,-0.0719,0,30,1988,0
0.04912037,418,501,118,58.8,50,0,0,497,23,-0.0719,0,30,1988,0
0.049212963,420.7,501,118,58.8,50,0,0,497,22.4,-0.0719,0,30,1988,0
0.04931713,422.9,501,121,58.8,50,0,0,497,21.3,-0.0719,0,30,1988,0
0.049409722,425.4,501,121,58.8,50,0,0,496,20,-0.0719,0,30,1988,0
0.049513889,427.5,501,121,58.8,50,0,0,496,19.6,-0.0719,0,30,1988,0
0.049606481,429.9,501,127,58.8,50,0,0,496,19.9,-0.0719,0,30,1988,0
0.049710648,432.6,501,127,58.8,50,0,0,496,19.6,-0.0719,0,30,1988,0
0.049803241,434.7,501,127,58.8,50,0,0,496,19.3,-0.0719,0,30,1988,0
0.049895833,437.3,501,127,58.8,50,0,0,495,18.8,-0.0719,0,30,1988,0
0.05,439.1,500,130,58.8,50,0,0,495,17.3,-0.0719,0,30,1988,0
0.050092593,441,500,130,58.8,50,0,0,495,18.1,-0.0719,0,30,1988,0
0.050185185,443.2,499,130,58.8,50,0,0,495,17.9,-0.0719,0,30,1988,0
0.050277778,445,499,130,58.8,50,0,0,495,17.7,-0.0719,0,30,1988,0
0.05037037,446.4,499,134,58.8,50,0,0,495,17.3,-0.0719,0,30,1988,0
0.050474537,448.2,499,130,58.8,50,0,0,494,15.6,-0.0719,0,30,1988,0
0.05056713,449.8,498,134,58.8,50,0,0,494,15.9,-0.0719,0,30,1988,0
0.050659722,451.3,498,134,58.8,50,0,0,494,16.6,-0.0719,0,30,1988,0
0.050752315,452.7,498,134,58.8,50,0,0,494,16.3,-0.0719,0,30,1988,0
0.050844907,454,497,134,58.8,50,0,0,494,15.8,-0.0719,0,30,1988,0
0.0509375,455.2,497,134,58.8,50,0,0,493,13.8,-0.1079,0,30,1987,0
0.051041667,456.3,497,134,58.8,50,0,0,493,14.9,-0.1079,0,30,1987,0
0.051134259,457.4,496,149,58.8,50,0,0,493,15,-0.1079,0,30,1987,0
0.051226852,458.3,496,149,58.8,50,0,0,493,15.2,-0.1079,0,30,1987,0
0.051319444,459.4,496,149,58.8,50,0,0,493,15.2,-0.1439,0,30,1986,0
0.051412037,460.3,496,149,58.8,50,0,0,493,14.8,-0.1439,0,30,1986,0
0.05150463,461,495,149,58.8,50,0,0,492,13.6,-0.1799,0,30,1985,0
0.051597222,461.9,495,149,58.8,50,0,0,492,13.9,-0.1799,0,30,1985,0
0.051701389,462.6,495,149,58.8,50,0,0,492,14.3,-0.1799,0,30,1985,0
0.051793981,463.3,494,149,58.8,50,0,0,492,14.1,-0.2159,0,30,1984,0
0.051886574,464,494,149,58.8,50,0,0,492,13.8,-0.2159,0,30,1984,0
0.051979167,464.6,494,152,58.8,50,0,0,492,14.3,-0.2519,0,30,1983,0
0.052071759,465.1,494,152,58.8,50,0,0,491,12.5,-0.2879,0,30,1982,0
0.052175926,465.7,493,152,58.8,50,0,0,491,13.1,-0.2879,0,30,1982,0
0.052268519,466,493,149,58.8,50,0,0,491,13.8,-0.3239,0,30,1981,0
0.052361111,466.6,493,152,58.8,50,0,0,491,13.7,-0.3239,0,30,1981,0
0.052453704,467.1,493,152,58.8,50,0,0,491,13,-0.3599,0,30,1980,0
0.052546296,467.5,492,152,58.8,50,0,0,490,12.2,-0.3599,0,30,1980,0
0.052638889,468,492,152,58.8,50,0,0,490,11.9,-0.3959,0,30,1979,0
0.052743056,468.4,492,155,58.8,50,0,0,490,13.2,-0.4319,0,30,1978,0
0.052835648,468.7,492,155,58.8,50,0,0,490,13,-0.4319,0,30,1978,0
0.052928241,468.9,492,152,58.8,50,0,0,490,12.2,-0.4679,0,30,1977,0
0.053020833,469.3,491,152,58.8,50,0,0,489,10.8,-0.4679,0,30,1977,0
0.053113426,469.6,491,152,58.8,50,0,0,489,12,-0.5039,0,30,1976,0
0.053217593,469.8,491,155,58.8,50,0,0,489,12.1,-0.5399,0,30,1975,0
0.053310185,470.2,491,152,58.8,50,0,0,489,12.2,-0.5399,0,30,1975,0
0.053402778,470.5,490,155,58.8,50,0,0,489,12.1,-0.5759,0,30,1974,0
0.05349537,470.9,490,152,58.8,50,0,0,489,12.1,-0.5759,0,30,1974,0
0.053599537,471.1,490,155,58.8,50,0,0,488,10.1,-0.6119,0,30,1973,0
0.05369213,471.2,490,155,58.8,50,0,0,488,11,-0.6119,0,30,1973,0
0.053784722,471.4,489,155,58.8,50,0,0,488,12.2,-0.6479,0,30,1972,0
0.053877315,471.4,489,155,58.8,50,0,0,488,12,-0.6839,0,30,1971,0
0.053969907,471.6,489,155,58.8,50,0,0,488,11.7,-0.6839,0,30,1971,0
0.0540625,472,489,155,58.8,50,0,0,488,11.3,-0.7199,0,30,1970,0
0.054155093,472,489,155,58.8,50,0,0,487,10,-0.7199,0,30,1970,0
0.054247685,472.1,489,155,58.8,50,0,0,487,10.7,-0.7559,0,30,1969,0
0.054351852,472.3,488,155,58.8,50,0,0,487,11.3,-0.7919,0,30,1968,0
0.054444444,472.5,488,155,58.8,50,0,0,487,10.9,-0.7919,0,30,1968,0
0.054537037,472.5,488,155,58.8,50,0,0,487,11,-0.8279,0,30,1967,0
0.05462963,472.5,488,155,58.8,50,0,0,486,9.5,-0.8279,0,30,1967,0
0.054722222,472.9,487,155,58.8,50,0,0,486,11,-0.8639,0,30,1966,0
0.054814815,472.9,487,161,58.8,50,0,0,486,10.1,-0.8639,0,30,1966,0
0.054918981,472.9,487,155,58.8,50,0,0,486,10.7,-0.8999,0,30,1965,0
0.055011574,472.9,487,155,58.8,50,0,0,486,10.7,-0.8999,0,30,1965,0
0.055104167,473,487,155,58.8,50,0,0,485,9,-0.9359,0,30,1964,0
0.055196759,473,487,155,58.8,50,0,0,485,8.9,-0.9359,0,30,1964,0
0.055289352,473,486,155,58.8,50,0,0,485,10.2,-0.9719,0,30,1963,0
0.055381944,473,486,155,58.8,50,0,0,485,10.6,-1.0079,0,30,1962,0
0.055474537,473,486,161,58.8,50,0,0,485,10.7,-1.0079,0,30,1962,0
0.055578704,473.2,486,155,58.8,50,0,0,485,9.9,-1.0439,0,30,1961,0
0.055671296,473.2,486,155,58.8,50,0,0,484,8.9,-1.0439,0,30,1961,0
0.055763889,473,485,155,58.8,50,0,0,484,10,-1.0799,0,30,1960,0
0.055856481,473.2,485,155,58.8,50,0,0,484,10.1,-1.1159,0,30,1959,0
0.055949074,473.2,485,155,58.8,50,0,0,484,10.2,-1.1159,0,30,1959,0
0.056053241,473,485,155,58.8,50,0,0,484,10,-1.1519,0,30,1958,0
0.056145833,473,484,161,58.8,50,0,0,483,8.6,-1.1519,0,30,1958,0
0.05625,473,484,155,58.8,50,0,0,483,9,-1.1879,0,30,1957,0
0.056342593,473,484,155,58.8,50,0,0,483,9.7,-1.2239,0,30,1956,0
0.056435185,472.9,484,161,58.8,50,0,0,483,10,-1.2599,0,30,1955,0
0.056527778,472.9,484,161,58.8,50,0,0,483,9.8,-1.2599,0,30,1955,0
0.05662037,472.9,484,155,58.8,50,0,0,483,9.5,-1.2959,0,30,1954,0
0.056712963,472.9,483,161,58.8,50,0,0,482,8.4,-1.2959,0,30,1954,0
0.05681713,472.9,483,155,58.8,50,0,0,482,8.9,-1.3319,0,30,1953,0
0.056909722,472.7,483,155,58.8,50,0,0,482,9.8,-1.3319,0,30,1953,0
0.057002315,472.7,483,161,58.8,50,0,0,482,9.5,-1.3679,0,30,1952,0
0.057094907,472.5,483,161,58.8,50,0,0,482,9.4,-1.4039,0,30,1951,0
0.0571875,472.5,482,161,58.8,50,0,0,482,10,-1.4039,0,30,1951,0
0.057280093,472.5,482,155,58.8,50,0,0,481,7.9,-1.4399,0,30,1950,0
0.057372685,472.3,482,155,58.8,50,0,0,481,9,-1.4399,0,30,1950,0
0.057476852,472.3,482,161,58.8,50,0,0,481,9.5,-1.4759,0,30,1949,0
0.057569444,472.1,482,155,58.8,50,0,0,481,9.1,-1.4759,0,30,1949,0
0.057662037,472,481,161,58.8,50,0,0,481,9.2,-1.5119,0,30,1948,0
0.05775463,472,481,155,58.8,50,0,0,480,7.5,-1.5479,0,30,1947,0
0.057847222,472,481,155,58.8,50,0,0,480,8.7,-1.5479,0,30,1947,0
0.057939815,471.8,481,161,58.8,50,0,0,480,9.3,-1.5839,0,30,1946,0
0.058032407,471.6,481,155,117.61,100,0,0,480,9.3,-1.6199,0,30,1945,0
0.058136574,471.4,480,161,88.2,75,0,0,480,8.6,-1.6199,0,30,1945,0
0.058229167,471.4,480,161,58.8,50,0,0,480,9.4,-1.6559,0,30,1944,0
0.058321759,471.4,480,161,29.4,25,0,0,480,9.4,-1.6559,0,30,1944,0
0.058414352,471.2,480,161,58.8,50,0,0,480,9.3,-1.6919,0,30,1943,0
0.058506944,471.2,480,161,88.2,75,0,0,480,9.1,-1.7279,0,30,1942,0
0.058599537,471.1,480,161,88.2,75,0,0,480,9.7,-1.7279,0,30,1942,0
0.05869213,470.9,480,161,117.61,100,0,0,480,9.8,-1.7639,0,30,1941,0