File: data/opybr-AA-cons-T.csv
Elapsed Time,Sample Temp,Heater Temp,Pressure,Rotor Speed,Shear Rate,Shear Stress,Viscosity,Temperature Setpoint,T Output,Bob Deflection,Torque,Motor Temp,Raw Encoder Value,Aux1
(hh:mm:ss),(°F),(°F),(PSIg),(RPM),(1/s),(dyne/cm²),(cP),(°F),(%),(deg.),(dyne-cm),(°C),(cts),
1.16E-05,85.1,84,115,0,0,75.4215,0,32,0,5.2559,9229.197,30,345,0
6.94E-05,84.9,83,115,58.8,50,756.6309,1513.262,410,70,51.048,92587.61,30,1617,0
0.000127315,84.9,87,115,58.8,50,760.5215,1521.043,410,70,51.3,93063.7,30,1624,0
0.000196759,84.9,94,115,58.8,50,761.6332,1523.266,409,70,51.372,93199.74,30,1626,0
0.00025463,84.9,104,118,58.8,50,761.6332,1523.266,409,70,51.372,93199.74,30,1626,0
0.0003125,84.9,119,118,58.8,50,761.0774,1522.155,409,70,51.336,93131.72,30,1625,0
0.000393519,84.7,129,118,58.8,50,759.4099,1518.82,408,70,51.228,92927.67,30,1622,0
0.000451389,84.7,145,118,58.8,50,756.6309,1513.262,408,70,51.048,92587.61,30,1617,0
0.000509259,84.5,160,118,58.8,50,752.7402,1505.48,408,70,50.796,92111.51,30,1610,0
0.000578704,84.5,171,121,58.8,50,748.2936,1496.587,407,70,50.508,91567.39,30,1602,0
0.000636574,84.5,185,121,58.8,50,743.2913,1486.583,407,70,50.184,90955.27,30,1593,0
0.000694444,84.9,194,121,58.8,50,721.0587,1442.117,407,70,48.744,88234.7,30,1553,0
0.000752315,84.9,202,121,58.8,50,696.0469,1392.094,406,70,47.124,85174.05,30,1508,0
0.000810185,84.9,214,127,58.8,50,439.3228,878.6457,406,70,30.348,53759.18,30,1042,0
0.00087963,85.1,222,127,58.8,50,362.5107,725.0214,406,70,25.128,44359.8,30,897,0
0.0009375,85.4,233,127,58.8,50,315.8192,631.6385,405,70,21.96,38646.25,30,809,0
0.00099537,85.8,241,127,58.8,50,269.3133,538.6266,405,70,18.756,32955.41,30,720,0
0.001053241,86.5,249,127,58.8,50,222.8846,445.7692,405,70,15.552,27274,30,631,0
0.001111111,86.9,256,130,58.8,50,208.3582,416.7165,404,70,14.544,25496.44,30,603,0
0.001168981,87.6,265,130,58.8,50,197.9822,395.9645,404,70,13.824,24226.74,30,583,0
0.001226852,88.5,272,130,58.8,50,188.7361,377.4721,404,70,13.176,23095.3,30,565,0
0.001296296,89.4,281,130,58.8,50,181.6044,363.2088,404,70,12.672,22222.61,30,551,0
0.001354167,90.5,287,130,58.8,50,174.9821,349.9642,403,70,12.204,21412.26,30,538,0
0.001412037,91.5,294,134,58.8,50,172.4351,344.8701,403,70,12.024,21100.58,30,533,0
0.001469907,93,302,134,58.8,50,169.888,339.7761,403,70,11.844,20788.91,30,528,0
0.001527778,94.6,308,134,58.8,50,167.341,334.682,402,70,11.664,20477.23,30,523,0
0.001585648,96,314,134,58.8,50,164.794,329.588,402,70,11.484,20165.55,30,518,0
0.001643519,97.5,321,134,58.8,50,162.247,324.4939,402,69,11.304,19853.88,30,513,0
0.001712963,99.6,327,134,58.8,50,160.2091,320.4182,401,62.6,11.16,19604.51,30,509,0
0.001770833,101.2,334,134,58.8,50,158.6805,317.3611,401,58.6,11.052,19417.46,30,506,0
0.001828704,103.9,339,134,58.8,50,157.152,314.304,401,57.9,10.944,19230.42,30,503,0
0.001886574,105.7,343,134,58.8,50,155.6234,311.2469,400,55.9,10.836,19043.37,30,500,0
0.001944444,107.5,349,130,58.8,50,154.6044,309.2089,400,55,10.764,18918.68,30,498,0
0.002013889,110.6,352,115,58.8,50,152.0569,304.1137,400,54.3,10.584,18606.93,30,493,0
0.002071759,112.7,356,112,58.8,50,149.5093,299.0186,399,51.7,10.404,18295.19,30,488,0
0.00212963,115.1,359,99,58.8,50,146.9617,293.9234,399,50.5,10.224,17983.45,30,483,0
0.0021875,117.2,363,96,58.8,50,144.9237,289.8473,399,49.2,10.08,17734.06,30,479,0
0.00224537,120.5,366,84,58.8,50,138.8095,277.619,399,49.1,9.6479,16985.88,30,467,0
0.002303241,122.8,370,71,58.8,50,133.2048,266.4097,398,46.3,9.2519,16300.04,30,456,0
0.002361111,125.9,372,71,58.8,50,116.5293,233.0585,398,45.9,8.0999,14259.48,30,424,0
0.002430556,128.2,374,71,58.8,50,115.4793,230.9586,398,45.9,8.0279,14131,30,422,0
0.002488426,130.9,377,71,58.8,50,114.9543,229.9087,397,43.1,7.9919,14066.76,30,421,0
0.002546296,134.3,378,71,58.8,50,114.4294,228.8588,397,42.5,7.9559,14002.53,30,420,0
0.002604167,136.7,380,87,58.8,50,114.4294,228.8588,397,42.5,7.9559,14002.53,30,420,0
0.002662037,139.4,382,118,58.8,50,113.9044,227.8088,396,41.6,7.9199,13938.29,30,419,0
0.002719907,142.6,383,121,58.8,50,113.9044,227.8088,396,38.4,7.9199,13938.29,30,419,0
0.002789352,144.9,385,127,58.8,50,113.3794,226.7589,396,38.1,7.8839,13874.05,30,418,0
0.002847222,147.3,386,127,58.8,50,113.3794,226.7589,395,36.3,7.8839,13874.05,30,418,0
0.002905093,150.7,387,130,58.8,50,112.8545,225.7089,395,35.7,7.8479,13809.81,30,417,0
0.002962963,152.8,389,130,58.8,50,112.8545,225.7089,395,34.9,7.8479,13809.81,30,417,0
0.003032407,156.1,390,130,58.8,50,112.8545,225.7089,394,34.1,7.8479,13809.81,30,417,0
0.003090278,158.6,390,134,58.8,50,112.3295,224.659,394,32.2,7.8119,13745.57,30,416,0
0.003148148,160.7,391,134,58.8,50,112.3295,224.659,394,31.9,7.8119,13745.57,30,416,0
0.003206019,164,392,134,58.8,50,112.3295,224.659,394,31.9,7.8119,13745.57,30,416,0
0.003263889,166,392,134,58.8,50,111.8045,223.6091,393,29.8,7.7759,13681.33,30,415,0
0.003321759,168.3,393,134,58.8,50,111.8045,223.6091,393,29.4,7.7759,13681.33,30,415,0
0.00337963,171.4,394,134,58.8,50,111.2796,222.5591,393,28.5,7.7399,13617.09,30,414,0
0.0034375,173.5,394,134,58.8,50,111.2796,222.5591,392,27.1,7.7399,13617.09,30,414,0
0.003506944,175.8,394,134,58.8,50,111.2796,222.5591,392,27.3,7.7399,13617.09,30,414,0
0.003564815,178.9,394,149,58.8,50,111.2796,222.5591,392,27.3,7.7399,13617.09,30,414,0
0.003622685,180.9,395,134,58.8,50,110.7546,221.5092,392,26.4,7.7039,13552.85,30,413,0
0.003680556,182.9,395,134,58.8,50,110.7546,221.5092,392,26.2,7.7039,13552.85,30,413,0
0.003738426,185.7,395,149,58.8,50,110.7546,221.5092,392,25.6,7.7039,13552.85,30,413,0
0.003796296,187.7,395,149,58.8,50,110.7546,221.5092,392,25.4,7.7039,13552.85,30,413,0
0.003865741,190.1,395,149,58.8,50,110.2296,220.4593,392,24.9,7.6679,13488.61,30,412,0
0.003923611,192.6,395,149,58.8,50,110.2296,220.4593,392,24.7,7.6679,13488.61,30,412,0
0.003981481,194.7,395,149,58.8,50,110.2296,220.4593,392,24.5,7.6679,13488.61,30,412,0
0.004039352,196.5,396,149,58.8,50,110.2296,220.4593,392,24.4,7.6679,13488.61,30,412,0
0.004097222,199,396,149,58.8,50,110.2296,220.4593,392,24.1,7.6679,13488.61,30,412,0
0.004155093,201,396,149,58.8,50,109.7047,219.4093,392,23.6,7.6319,13424.37,30,411,0
0.004212963,203.5,396,149,58.8,50,109.7047,219.4093,392,22.8,7.6319,13424.37,30,411,0
0.004282407,205.3,396,149,58.8,50,109.7047,219.4093,392,22.8,7.6319,13424.37,30,411,0
0.004340278,207.1,396,149,58.8,50,109.7047,219.4093,392,22.9,7.6319,13424.37,30,411,0
0.004398148,209.8,396,149,58.8,50,109.1797,218.3594,392,22.3,7.5959,13360.13,30,410,0
0.004456019,211.4,396,149,58.8,50,109.1797,218.3594,392,22.2,7.5959,13360.13,30,410,0
0.004513889,213.2,396,149,58.8,50,109.1797,218.3594,392,21.9,7.5959,13360.13,30,410,0
0.004571759,215.6,396,149,58.8,50,109.1797,218.3594,392,21.5,7.5959,13360.13,30,410,0
0.004641204,217.6,396,149,58.8,50,109.1797,218.3594,392,21.4,7.5959,13360.13,30,410,0
0.004699074,219.4,396,149,58.8,50,109.1797,218.3594,392,21.2,7.5959,13360.13,30,410,0
0.004837963,224,396,149,58.8,50,108.6547,217.3095,392,20.4,7.5599,13295.89,30,409,0
0.004895833,225.6,396,149,58.8,50,108.6547,217.3095,392,20.6,7.5599,13295.89,30,409,0
0.004953704,227.4,395,149,58.8,50,108.6547,217.3095,392,20.3,7.5599,13295.89,30,409,0
0.005011574,229.6,395,152,58.8,50,108.1298,216.2595,392,20.4,7.5239,13231.65,30,408,0
0.005069444,231.2,395,149,58.8,50,108.1298,216.2595,392,19.8,7.5239,13231.65,30,408,0
0.005127315,232.8,395,149,58.8,50,108.1298,216.2595,392,19.6,7.5239,13231.65,30,408,0
0.005185185,235,395,152,58.8,50,108.1298,216.2595,392,19.3,7.5239,13231.65,30,408,0
0.00525463,236.6,395,149,58.8,50,108.1298,216.2595,392,18.7,7.5239,13231.65,30,408,0
0.0053125,238.2,395,149,58.8,50,107.6048,215.2096,392,19,7.4879,13167.41,30,407,0
0.00537037,240.4,395,149,58.8,50,107.6048,215.2096,392,18.9,7.4879,13167.41,30,407,0
0.005428241,242,395,149,58.8,50,107.6048,215.2096,392,18.4,7.4879,13167.41,30,407,0
0.005486111,243.6,395,149,58.8,50,107.6048,215.2096,392,18.6,7.4879,13167.41,30,407,0
0.005543981,245.6,395,149,58.8,50,107.6048,215.2096,392,18.3,7.4879,13167.41,30,407,0
0.005601852,247,395,149,58.8,50,107.6048,215.2096,392,17.9,7.4879,13167.41,30,407,0
0.005671296,249.4,395,149,58.8,50,107.6048,215.2096,392,18,7.4879,13167.41,30,407,0
0.005729167,250.8,395,149,58.8,50,107.6048,215.2096,392,17.4,7.4879,13167.41,30,407,0
0.005787037,252.1,395,149,58.8,50,107.6048,215.2096,392,16.7,7.4879,13167.41,30,407,0
0.005844907,254.1,395,149,58.8,50,107.0798,214.1597,392,17.4,7.4519,13103.17,30,406,0
0.005902778,255.7,395,149,58.8,50,107.0798,214.1597,392,17.6,7.4519,13103.17,30,406,0
0.005960648,257.1,395,149,58.8,50,107.0798,214.1597,392,17.2,7.4519,13103.17,30,406,0
0.006030093,259.3,395,149,58.8,50,107.0798,214.1597,392,17.3,7.4519,13103.17,30,406,0
0.006087963,260.5,395,149,58.8,50,107.0798,214.1597,392,16.3,7.4519,13103.17,30,406,0
0.006145833,262.5,395,149,58.8,50,107.0798,214.1597,392,17.1,7.4519,13103.17,30,406,0
0.006203704,263.9,395,149,58.8,50,107.0798,214.1597,392,16.1,7.4519,13103.17,30,406,0
0.006261574,265.2,395,152,58.8,50,107.0798,214.1597,392,16.6,7.4519,13103.17,30,406,0
0.006319444,267.4,394,149,58.8,50,107.0798,214.1597,392,16.3,7.4519,13103.17,30,406,0
0.006400463,269.2,394,152,58.8,50,107.0798,214.1597,392,16.3,7.4519,13103.17,30,406,0
0.00650463,271.5,394,149,58.8,50,106.5549,213.1097,392,16.2,7.4159,13038.93,30,405,0
0.006574074,272.9,394,149,58.8,50,106.5549,213.1097,392,15.3,7.4159,13038.93,30,405,0
0.006643519,275.3,394,149,58.8,50,106.5549,213.1097,392,15.8,7.4159,13038.93,30,405,0
0.006712963,276.9,394,152,58.8,50,106.5549,213.1097,392,15.3,7.4159,13038.93,30,405,0
0.006770833,278.7,394,149,58.8,50,106.5549,213.1097,392,15.2,7.4159,13038.93,30,405,0
0.006840278,280.1,394,149,58.8,50,106.0299,212.0598,392,15.3,7.3799,12974.69,30,404,0
0.006898148,281.4,394,149,58.8,50,106.0299,212.0598,392,15.4,7.3799,12974.69,30,404,0
0.006956019,283,394,149,58.8,50,106.0299,212.0598,392,15.2,7.3799,12974.69,30,404,0
0.007013889,284.3,394,149,58.8,50,106.0299,212.0598,392,14.5,7.3799,12974.69,30,404,0
0.007071759,285.5,394,149,58.8,50,106.0299,212.0598,392,14.7,7.3799,12974.69,30,404,0
0.00712963,287,394,149,58.8,50,106.0299,212.0598,392,14.4,7.3799,12974.69,30,404,0
0.0071875,288.6,394,149,58.8,50,106.0299,212.0598,392,14.9,7.3799,12974.69,30,404,0
0.00724537,289.7,394,149,58.8,50,106.0299,212.0598,392,14.3,7.3799,12974.69,30,404,0
0.007303241,290.9,394,149,58.8,50,106.0299,212.0598,392,15,7.3799,12974.69,30,404,0
0.007361111,292.5,394,149,58.8,50,106.0299,212.0598,392,14.3,7.3799,12974.69,30,404,0
0.007430556,293.6,394,149,58.8,50,105.5049,211.0098,392,14.3,7.3439,12910.45,30,403,0
0.007488426,295,394,149,58.8,50,105.5049,211.0098,392,13.6,7.3439,12910.45,30,403,0
0.007546296,296.3,394,149,58.8,50,105.5049,211.0098,392,14,7.3439,12910.45,30,403,0
0.007604167,297.6,394,149,58.8,50,105.5049,211.0098,392,13.9,7.3439,12910.45,30,403,0
0.007662037,298.6,394,149,58.8,50,105.5049,211.0098,392,14,7.3439,12910.45,30,403,0
0.007719907,300.1,394,149,58.8,50,105.5049,211.0098,392,13.6,7.3439,12910.45,30,403,0
0.007777778,301.2,394,149,58.8,50,105.5049,211.0098,392,13.1,7.3439,12910.45,30,403,0
0.007847222,302.2,394,149,58.8,50,105.5049,211.0098,392,13.4,7.3439,12910.45,30,403,0
0.007905093,303.7,394,149,58.8,50,105.5049,211.0098,392,13.2,7.3439,12910.45,30,403,0
0.007962963,304.9,394,149,58.8,50,105.5049,211.0098,392,13.2,7.3439,12910.45,30,403,0
0.008020833,305.8,393,149,58.8,50,105.5049,211.0098,392,13.3,7.3439,12910.45,30,403,0
0.008078704,307.1,393,149,58.8,50,105.5049,211.0098,392,13.2,7.3439,12910.45,30,403,0
0.008136574,308.2,393,149,58.8,50,105.5049,211.0098,392,13,7.3439,12910.45,30,403,0
0.008194444,309.2,394,134,58.8,50,104.9799,209.9599,392,12.5,7.3079,12846.21,30,402,0
0.008252315,310.5,393,149,58.8,50,104.9799,209.9599,392,12.8,7.3079,12846.21,30,402,0
0.008310185,311.6,393,149,58.8,50,104.9799,209.9599,392,13,7.3079,12846.21,30,402,0
0.00837963,312.5,393,149,58.8,50,104.9799,209.9599,392,12.4,7.3079,12846.21,30,402,0
0.0084375,313.6,393,149,58.8,50,104.9799,209.9599,392,12.5,7.3079,12846.21,30,402,0
0.00849537,314.6,393,149,58.8,50,104.9799,209.9599,392,12.4,7.3079,12846.21,30,402,0
0.008553241,315.5,393,149,58.8,50,104.9799,209.9599,392,12.4,7.3079,12846.21,30,402,0
0.008611111,316.8,393,134,58.8,50,104.9799,209.9599,392,12.1,7.3079,12846.21,30,402,0
0.008680556,317.7,393,134,58.8,50,104.455,208.91,392,12.2,7.2719,12781.98,30,401,0
0.008738426,318.8,393,149,58.8,50,104.455,208.91,392,12.3,7.2719,12781.98,30,401,0
0.008796296,319.7,393,149,58.8,50,104.455,208.91,392,12,7.2719,12781.98,30,401,0
0.008854167,320.6,393,149,58.8,50,104.455,208.91,392,11.9,7.2719,12781.98,30,401,0
0.008912037,321.7,393,134,58.8,50,104.455,208.91,392,12.1,7.2719,12781.98,30,401,0
0.008969907,322.6,393,149,58.8,50,104.455,208.91,392,11.9,7.2719,12781.98,30,401,0
0.009027778,323.3,393,149,58.8,50,104.455,208.91,392,12.1,7.2719,12781.98,30,401,0
0.009085648,324.5,393,149,58.8,50,104.455,208.91,392,11.7,7.2719,12781.98,30,401,0
0.009143519,325.2,393,149,58.8,50,104.455,208.91,392,11.3,7.2719,12781.98,30,401,0
0.009212963,326.1,393,149,58.8,50,104.455,208.91,392,11.7,7.2719,12781.98,30,401,0
0.009270833,327,393,149,58.8,50,104.455,208.91,392,11.7,7.2719,12781.98,30,401,0
0.009328704,327.9,393,149,58.8,50,103.93,207.86,392,11.4,7.2359,12717.74,30,400,0
0.009386574,328.7,393,134,58.8,50,103.93,207.86,392,11.3,7.2359,12717.74,30,400,0
0.009444444,329.6,393,149,58.8,50,103.93,207.86,392,11.2,7.2359,12717.74,30,400,0
0.009502315,330.3,393,149,58.8,50,103.93,207.86,392,11.6,7.2359,12717.74,30,400,0
0.009560185,331.2,393,149,58.8,50,103.93,207.86,392,11.3,7.2359,12717.74,30,400,0
0.009618056,332.1,393,134,58.8,50,103.93,207.86,392,10.9,7.2359,12717.74,30,400,0
0.0096875,332.8,393,134,58.8,50,103.93,207.86,392,11.1,7.2359,12717.74,30,400,0
0.00974537,333.5,393,134,58.8,50,103.93,207.86,392,10.9,7.2359,12717.74,30,400,0
0.009803241,334.4,393,134,58.8,50,103.93,207.86,392,10.9,7.2359,12717.74,30,400,0
0.009861111,335,393,149,58.8,50,103.93,207.86,392,11.3,7.2359,12717.74,30,400,0
0.009918981,335.7,393,149,58.8,50,103.93,207.86,392,10.9,7.2359,12717.74,30,400,0
0.009976852,336.6,393,134,58.8,50,103.93,207.86,392,11,7.2359,12717.74,30,400,0
0.010034722,337.1,393,134,58.8,50,103.4051,206.8101,392,10.4,7.1999,12653.5,30,399,0
0.010092593,338,393,149,58.8,50,103.4051,206.8101,392,10.9,7.1999,12653.5,30,399,0
0.010150463,338.6,393,149,58.8,50,103.4051,206.8101,392,10.2,7.1999,12653.5,30,399,0
0.010208333,339.3,393,134,58.8,50,103.4051,206.8101,392,10.8,7.1999,12653.5,30,399,0
0.010266204,339.8,393,149,58.8,50,102.8801,205.7602,392,10.4,7.1639,12589.26,30,398,0
0.010335648,340.5,393,134,58.8,50,102.8801,205.7602,392,10.3,7.1639,12589.26,30,398,0
0.010393519,341.3,393,149,58.8,50,102.8801,205.7602,392,10.7,7.1639,12589.26,30,398,0
0.010451389,341.8,393,149,58.8,50,102.8801,205.7602,392,10.2,7.1639,12589.26,30,398,0
0.010509259,342.5,393,134,58.8,50,102.8801,205.7602,392,10.9,7.1639,12589.26,30,398,0
0.01056713,343,393,134,58.8,50,102.8801,205.7602,392,10,7.1639,12589.26,30,398,0
0.010625,343.8,393,134,58.8,50,102.8801,205.7602,392,9.9,7.1639,12589.26,30,398,0
0.01068287,344.3,393,134,58.8,50,102.8801,205.7602,392,10.1,7.1639,12589.26,30,398,0
0.010740741,344.8,393,134,58.8,50,102.8801,205.7602,392,10.2,7.1639,12589.26,30,398,0
0.010798611,345.6,393,134,58.8,50,102.8801,205.7602,392,10.1,7.1639,12589.26,30,398,0
0.010868056,346.1,393,134,58.8,50,102.3551,204.7102,392,10.3,7.1279,12525.02,30,397,0
0.010925926,346.6,393,134,58.8,50,102.3551,204.7102,392,10.5,7.1279,12525.02,30,397,0
0.010983796,347,393,134,58.8,50,102.3551,204.7102,392,9.8,7.1279,12525.02,30,397,0
0.011041667,347.9,393,134,58.8,50,102.3551,204.7102,392,9.6,7.1279,12525.02,30,397,0
0.011099537,348.3,393,149,58.8,50,102.3551,204.7102,392,9.9,7.1279,12525.02,30,397,0
0.011157407,348.8,393,149,58.8,50,102.3551,204.7102,392,10.3,7.1279,12525.02,30,397,0
0.011215278,349.3,393,134,58.8,50,102.3551,204.7102,392,10.1,7.1279,12525.02,30,397,0
0.011273148,349.9,393,134,58.8,50,102.3551,204.7102,392,9.4,7.1279,12525.02,30,397,0
0.011331019,350.4,393,149,58.8,50,102.3551,204.7102,392,9.7,7.1279,12525.02,30,397,0
0.011388889,351,393,134,58.8,50,102.3551,204.7102,392,9.7,7.1279,12525.02,30,397,0
0.011458333,351.5,393,134,58.8,50,102.3551,204.7102,392,9.6,7.1279,12525.02,30,397,0
0.011516204,352,393,134,58.8,50,102.3551,204.7102,392,9.7,7.1279,12525.02,30,397,0
0.011574074,352.4,393,134,58.8,50,102.3551,204.7102,392,9.8,7.1279,12525.02,30,397,0
0.011631944,352.8,393,134,58.8,50,102.3551,204.7102,392,9.4,7.1279,12525.02,30,397,0
0.011689815,353.3,393,134,58.8,50,102.3551,204.7102,392,9.4,7.1279,12525.02,30,397,0
0.011747685,353.8,393,134,58.8,50,102.3551,204.7102,392,9.5,7.1279,12525.02,30,397,0
0.011805556,354.2,393,134,58.8,50,102.3551,204.7102,392,9.3,7.1279,12525.02,30,397,0
0.011863426,354.7,393,134,58.8,50,101.8301,203.6603,392,9.5,7.0919,12460.78,30,396,0
0.011921296,355.1,393,134,58.8,50,101.8301,203.6603,392,9.5,7.0919,12460.78,30,396,0
0.011990741,355.6,393,134,58.8,50,101.8301,203.6603,392,9.3,7.0919,12460.78,30,396,0
0.012048611,356,393,134,58.8,50,101.8301,203.6603,392,9.4,7.0919,12460.78,30,396,0
0.012106481,356.4,393,134,58.8,50,101.8301,203.6603,392,9,7.0919,12460.78,30,396,0
0.012164352,356.7,393,134,58.8,50,101.8301,203.6603,392,9,7.0919,12460.78,30,396,0
0.012222222,357.3,393,149,58.8,50,101.8301,203.6603,392,9.4,7.0919,12460.78,30,396,0
0.012280093,357.8,393,134,58.8,50,101.8301,203.6603,392,9.3,7.0919,12460.78,30,396,0
0.012337963,358.2,392,134,58.8,50,101.3052,202.6104,392,9.4,7.0559,12396.54,30,395,0
0.012395833,358.5,393,134,58.8,50,101.3052,202.6104,392,9.1,7.0559,12396.54,30,395,0
0.012465278,358.7,393,134,58.8,50,101.3052,202.6104,392,9,7.0559,12396.54,30,395,0
0.012523148,359.2,393,134,58.8,50,101.3052,202.6104,392,8.9,7.0559,12396.54,30,395,0
0.012581019,359.6,393,134,58.8,50,101.3052,202.6104,392,9,7.0559,12396.54,30,395,0
0.012638889,359.9,393,134,58.8,50,101.3052,202.6104,392,8.6,7.0559,12396.54,30,395,0
0.012696759,360.3,392,134,58.8,50,101.3052,202.6104,392,9.2,7.0559,12396.54,30,395,0
0.01275463,360.7,392,134,58.8,50,100.7802,201.5604,392,8.9,7.0199,12332.3,30,394,0
0.0128125,361,392,134,58.8,50,100.7802,201.5604,392,8.9,7.0199,12332.3,30,394,0
0.01287037,361.2,392,134,58.8,50,100.7802,201.5604,392,8.9,7.0199,12332.3,30,394,0
0.012939815,361.7,392,134,58.8,50,100.7802,201.5604,392,8.9,7.0199,12332.3,30,394,0
0.012997685,361.9,393,134,58.8,50,100.7802,201.5604,392,8.3,7.0199,12332.3,30,394,0
0.013055556,362.3,392,134,58.8,50,100.7802,201.5604,392,8.9,7.0199,12332.3,30,394,0
0.013113426,362.6,392,134,58.8,50,100.7802,201.5604,392,8.9,7.0199,12332.3,30,394,0
0.013171296,362.8,392,134,58.8,50,100.7802,201.5604,392,9,7.0199,12332.3,30,394,0
0.013229167,363.4,392,134,58.8,50,100.2552,200.5105,392,8.4,6.9839,12268.06,30,393,0
0.013287037,363.5,392,134,58.8,50,100.2552,200.5105,392,8.4,6.9839,12268.06,30,393,0
0.013356481,363.9,393,134,58.8,50,100.2552,200.5105,392,8.1,6.9839,12268.06,30,393,0
0.013414352,364.1,392,134,58.8,50,100.2552,200.5105,392,8.7,6.9839,12268.06,30,393,0
0.013472222,364.4,392,134,58.8,50,100.2552,200.5105,392,8.5,6.9839,12268.06,30,393,0
0.013530093,364.6,392,134,58.8,50,100.2552,200.5105,392,8.7,6.9839,12268.06,30,393,0
0.013587963,365,392,134,58.8,50,100.2552,200.5105,392,8.6,6.9839,12268.06,30,393,0
0.013645833,365.3,392,134,58.8,50,100.2552,200.5105,392,8.2,6.9839,12268.06,30,393,0
0.013703704,365.5,392,134,58.8,50,100.2552,200.5105,392,8.4,6.9839,12268.06,30,393,0
0.013761574,366.8,392,134,58.8,50,100.2552,200.5105,392,8.4,6.9839,12268.06,30,393,0
0.013819444,367.1,392,134,58.8,50,99.7303,199.4606,392,8.6,6.9479,12203.82,30,392,0
0.013877315,367.3,392,134,58.8,50,99.7303,199.4606,392,8.2,6.9479,12203.82,30,392,0
0.013935185,367.7,392,134,58.8,50,99.7303,199.4606,392,8,6.9479,12203.82,30,392,0
0.013993056,367.9,392,134,58.8,50,99.7303,199.4606,392,8.4,6.9479,12203.82,30,392,0
0.0140625,368.2,392,134,58.8,50,99.7303,199.4606,392,8.4,6.9479,12203.82,30,392,0
0.01412037,368.4,392,134,58.8,50,99.7303,199.4606,392,8.1,6.9479,12203.82,30,392,0
0.014178241,368.6,392,134,58.8,50,99.7303,199.4606,392,8.4,6.9479,12203.82,30,392,0
0.014247685,368.9,392,134,58.8,50,99.7303,199.4606,392,8.1,6.9479,12203.82,30,392,0
0.014305556,369.1,392,134,58.8,50,99.7303,199.4606,392,8.1,6.9479,12203.82,30,392,0
0.014363426,369.5,392,134,58.8,50,99.2053,198.4106,392,8.6,6.9119,12139.58,30,391,0
0.014421296,369.7,392,134,58.8,50,99.2053,198.4106,392,7.7,6.9119,12139.58,30,391,0
0.014479167,369.8,392,130,58.8,50,99.2053,198.4106,392,7.8,6.9119,12139.58,30,391,0
0.014537037,370,392,130,58.8,50,99.2053,198.4106,392,8.1,6.9119,12139.58,30,391,0
0.014606481,370.2,392,134,58.8,50,99.2053,198.4106,392,8.2,6.9119,12139.58,30,391,0
0.014664352,370.4,392,134,58.8,50,99.2053,198.4106,392,8.1,6.9119,12139.58,30,391,0
0.014722222,370.7,392,134,58.8,50,99.2053,198.4106,392,8,6.9119,12139.58,30,391,0
0.014780093,370.9,392,134,58.8,50,99.2053,198.4106,392,7.8,6.9119,12139.58,30,391,0
0.014837963,370.9,392,134,58.8,50,99.2053,198.4106,392,8.2,6.9119,12139.58,30,391,0
0.014895833,371.3,392,134,58.8,50,99.2053,198.4106,392,8,6.9119,12139.58,30,391,0
0.014953704,371.5,392,130,58.8,50,99.2053,198.4106,392,8.4,6.9119,12139.58,30,391,0
0.015011574,371.6,392,134,58.8,50,99.2053,198.4106,392,8.1,6.9119,12139.58,30,391,0
0.015069444,371.8,392,130,58.8,50,99.2053,198.4106,392,7.6,6.9119,12139.58,30,391,0
0.015127315,372.2,392,134,58.8,50,99.2053,198.4106,392,7.8,6.9119,12139.58,30,391,0
0.015185185,372.2,392,134,58.8,50,98.6803,197.3607,392,7.7,6.8759,12075.34,30,390,0
0.015243056,372.5,392,134,58.8,50,98.6803,197.3607,392,7.9,6.8759,12075.34,30,390,0
0.0153125,372.5,392,134,58.8,50,98.6803,197.3607,392,8.2,6.8759,12075.34,30,390,0
0.01537037,372.7,392,134,58.8,50,98.6803,197.3607,392,8,6.8759,12075.34,30,390,0
0.015428241,372.9,392,130,58.8,50,98.6803,197.3607,392,7.7,6.8759,12075.34,30,390,0
0.015486111,373.1,392,134,58.8,50,98.6803,197.3607,392,7.5,6.8759,12075.34,30,390,0
0.015543981,373.4,392,134,58.8,50,98.6803,197.3607,392,7.7,6.8759,12075.34,30,390,0
0.015613426,373.6,392,134,58.8,50,98.6803,197.3607,392,7.9,6.8759,12075.34,30,390,0
0.015671296,373.6,392,134,58.8,50,98.6803,197.3607,392,7.8,6.8759,12075.34,30,390,0
0.015729167,373.8,392,130,58.8,50,98.6803,197.3607,392,7.7,6.8759,12075.34,30,390,0
0.015787037,374,392,134,58.8,50,98.1554,196.3107,392,7.8,6.8399,12011.1,30,389,0
0.015844907,374,392,134,58.8,50,98.1554,196.3107,392,7.7,6.8399,12011.1,30,389,0
0.015902778,374.3,392,134,58.8,50,98.1554,196.3107,393,9.8,6.8399,12011.1,30,389,0
0.015960648,374.3,392,130,58.8,50,98.1554,196.3107,405,29.1,6.8399,12011.1,30,389,0
0.016018519,374.5,393,134,58.8,50,98.1554,196.3107,410,33.8,6.8399,12011.1,30,389,0
0.016087963,374.7,395,134,58.8,50,98.1554,196.3107,410,25.6,6.8399,12011.1,30,389,0
0.016145833,374.9,398,130,58.8,50,98.1554,196.3107,410,14.9,6.8399,12011.1,30,389,0
0.016203704,375,401,130,58.8,50,98.1554,196.3107,410,12,6.8399,12011.1,30,389,0
0.016261574,375.2,402,134,58.8,50,98.1554,196.3107,410,12.6,6.8399,12011.1,30,389,0
0.016331019,375.2,403,130,58.8,50,98.1554,196.3107,410,14.8,6.8399,12011.1,30,389,0
0.016388889,375.4,404,130,58.8,50,98.1554,196.3107,410,16.9,6.8399,12011.1,30,389,0
0.01650463,375.6,404,130,58.8,50,98.1554,196.3107,410,16.2,6.8399,12011.1,30,389,0
0.0165625,376.1,406,134,58.8,50,97.6304,195.2608,396,0,6.8039,11946.86,30,388,0
0.01662037,376.1,407,130,58.8,50,97.6304,195.2608,396,0,6.8039,11946.86,30,388,0
0.016678241,376.3,407,130,58.8,50,97.6304,195.2608,396,0,6.8039,11946.86,30,388,0
0.016736111,376.7,405,134,58.8,50,97.6304,195.2608,396,0.2,6.8039,11946.86,30,388,0
0.016793981,376.8,404,134,58.8,50,97.6304,195.2608,396,4.1,6.8039,11946.86,30,388,0
0.016863426,377,403,130,58.8,50,97.6304,195.2608,396,6.2,6.8039,11946.86,30,388,0
0.016921296,377.2,402,134,58.8,50,97.6304,195.2608,396,6.8,6.8039,11946.86,30,388,0
0.016979167,377.6,401,134,58.8,50,97.6304,195.2608,396,5.8,6.8039,11946.86,30,388,0
0.017037037,377.7,401,130,58.8,50,97.1054,194.2109,396,4.9,6.7679,11882.62,30,387,0
0.017094907,377.9,401,130,58.8,50,97.1054,194.2109,396,4.9,6.7679,11882.62,30,387,0
0.017152778,378.3,400,130,58.8,50,97.1054,194.2109,396,4.9,6.7679,11882.62,30,387,0
0.017210648,378.5,400,130,58.8,50,97.1054,194.2109,396,5.4,6.7679,11882.62,30,387,0
0.017719907,379.9,397,130,58.8,50,96.5855,193.1711,395,5.2,6.7319,11819,30,386,0
0.017789352,380.3,397,130,58.8,50,96.5855,193.1711,395,5.3,6.7319,11819,30,386,0
0.017847222,380.4,397,130,58.8,50,96.5855,193.1711,395,5.9,6.7319,11819,30,386,0
0.017905093,380.6,397,130,58.8,50,96.5855,193.1711,395,6.7,6.7319,11819,30,386,0
0.017962963,380.6,396,130,58.8,50,96.5855,193.1711,395,6.5,6.7319,11819,30,386,0
0.018020833,380.8,396,130,58.8,50,96.5855,193.1711,395,6.6,6.7319,11819,30,386,0
0.018090278,381,396,130,58.8,50,96.5855,193.1711,395,6.8,6.7319,11819,30,386,0
0.018148148,381.2,396,130,58.8,50,96.0693,192.1387,395,6.6,6.6959,11755.84,30,385,0
0.018206019,381.2,396,130,58.8,50,96.0693,192.1387,395,6.6,6.6959,11755.84,30,385,0
0.018263889,381.2,396,130,58.8,50,96.0693,192.1387,395,6.5,6.6959,11755.84,30,385,0
0.018321759,381.5,396,130,58.8,50,96.0693,192.1387,395,6.9,6.6959,11755.84,30,385,0
0.01837963,381.5,395,130,58.8,50,96.0693,192.1387,395,7.1,6.6959,11755.84,30,385,0
0.0184375,381.5,395,130,58.8,50,96.0693,192.1387,395,6.7,6.6959,11755.84,30,385,0
0.018506944,381.7,395,130,58.8,50,96.0693,192.1387,394,5.5,6.6959,11755.84,30,385,0
0.018564815,381.9,395,130,58.8,50,96.0693,192.1387,394,5.8,6.6959,11755.84,30,385,0
0.018622685,382.1,395,130,58.8,50,96.0693,192.1387,394,6.2,6.6959,11755.84,30,385,0
0.018680556,382.1,395,130,58.8,50,95.5531,191.1063,394,6.6,6.6599,11692.67,30,384,0
0.018738426,382.1,395,130,58.8,50,95.5531,191.1063,394,7.2,6.6599,11692.67,30,384,0
0.01880787,382.2,394,130,58.8,50,95.5531,191.1063,394,6.6,6.6599,11692.67,30,384,0
0.018865741,382.2,394,130,58.8,50,95.5531,191.1063,394,6.5,6.6599,11692.67,30,384,0
0.018923611,382.4,394,130,58.8,50,95.5531,191.1063,394,6.2,6.6599,11692.67,30,384,0
0.018981481,382.4,394,130,58.8,50,95.5531,191.1063,394,6.6,6.6599,11692.67,30,384,0
0.019039352,382.4,394,130,58.8,50,95.5531,191.1063,394,7.1,6.6599,11692.67,30,384,0
0.019097222,382.6,394,130,58.8,50,95.5531,191.1063,394,7,6.6599,11692.67,30,384,0
0.019166667,382.6,394,130,58.8,50,95.0369,190.0739,394,7.1,6.6239,11629.51,30,383,0
0.019224537,382.6,394,130,58.8,50,95.0369,190.0739,394,6.9,6.6239,11629.51,30,383,0
0.019282407,382.8,394,130,58.8,50,95.0369,190.0739,394,6.9,6.6239,11629.51,30,383,0
0.019340278,382.8,394,134,58.8,50,95.0369,190.0739,394,6.7,6.6239,11629.51,30,383,0
0.019398148,382.8,394,130,58.8,50,95.0369,190.0739,394,7.1,6.6239,11629.51,30,383,0
0.019456019,383,394,130,58.8,50,95.0369,190.0739,393,5.5,6.6239,11629.51,30,383,0
0.019513889,383,394,130,58.8,50,95.0369,190.0739,393,5.7,6.6239,11629.51,30,383,0
0.019571759,383,394,130,58.8,50,95.0369,190.0739,393,6.3,6.6239,11629.51,30,383,0
0.019641204,383,394,130,58.8,50,95.0369,190.0739,393,6.4,6.6239,11629.51,30,383,0
0.019699074,383.1,394,130,58.8,50,95.0369,190.0739,393,6.2,6.6239,11629.51,30,383,0
0.019756944,383.1,393,130,58.8,50,95.0369,190.0739,393,6.8,6.6239,11629.51,30,383,0
0.019814815,383.3,393,130,58.8,50,95.0369,190.0739,393,6.8,6.6239,11629.51,30,383,0
0.019872685,383.3,393,130,58.8,50,95.0369,190.0739,393,6,6.6239,11629.51,30,383,0
0.019930556,383.3,393,130,58.8,50,94.5207,189.0415,393,6.5,6.5879,11566.34,30,382,0
0.02,383.3,393,130,58.8,50,94.5207,189.0415,393,6.8,6.5879,11566.34,30,382,0
0.02005787,383.3,393,130,58.8,50,94.5207,189.0415,393,6.6,6.5879,11566.34,30,382,0
0.020115741,383.5,393,130,58.8,50,94.5207,189.0415,393,6.6,6.5879,11566.34,30,382,0
0.020173611,383.5,393,130,58.8,50,94.5207,189.0415,393,6.6,6.5879,11566.34,30,382,0
0.020243056,383.5,393,130,58.8,50,94.5207,189.0415,393,6.5,6.5879,11566.34,30,382,0
0.020300926,383.5,393,130,58.8,50,94.5207,189.0415,393,6.6,6.5879,11566.34,30,382,0
0.020358796,383.5,393,130,58.8,50,94.5207,189.0415,393,6.9,6.5879,11566.34,30,382,0
0.020416667,383.7,393,130,58.8,50,94.0046,188.0091,392,5.7,6.5519,11503.17,30,381,0
0.020474537,383.7,393,130,58.8,50,94.5207,189.0415,392,5.4,6.5879,11566.34,30,382,0
0.020532407,383.7,393,130,58.8,50,94.0046,188.0091,392,6,6.5519,11503.17,30,381,0
0.020590278,383.9,393,130,58.8,50,94.0046,188.0091,392,6.6,6.5519,11503.17,30,381,0
0.020648148,383.9,392,130,58.8,50,94.0046,188.0091,392,7.1,6.5519,11503.17,30,381,0
0.020706019,383.9,392,130,58.8,50,94.0046,188.0091,392,6.2,6.5519,11503.17,30,381,0
0.020763889,383.9,392,130,58.8,50,94.0046,188.0091,392,6.3,6.5519,11503.17,30,381,0
0.020821759,383.9,392,127,58.8,50,94.0046,188.0091,392,6.4,6.5519,11503.17,30,381,0
0.020891204,383.9,392,127,117.61,100,94.0046,94.0046,392,6.5,6.5519,11503.17,30,381,0
0.020949074,383.9,392,130,117.61,100,94.0046,94.0046,392,6.6,6.5519,11503.17,30,381,0
0.021006944,384,392,130,88.2,75,94.0046,125.3394,392,6.3,6.5519,11503.17,30,381,0
0.021064815,384,392,130,88.2,75,94.0046,125.3394,392,6.4,6.5519,11503.17,30,381,0
0.021134259,384,392,130,58.8,50,94.0046,188.0091,392,6.4,6.5519,11503.17,30,381,0
0.02119213,384,392,130,58.8,50,94.0046,188.0091,392,6.7,6.5519,11503.17,30,381,0
0.02125,384,392,130,29.4,25,94.0046,376.0182,392,6.7,6.5519,11503.17,30,381,0
0.02130787,384,392,130,58.8,50,93.4884,186.9767,392,6.6,6.5159,11440.01,30,380,0
0.021365741,384,392,130,58.8,50,93.4884,186.9767,392,6.7,6.5159,11440.01,30,380,0
0.021423611,384.2,392,130,88.2,75,93.4884,124.6511,392,6.7,6.5159,11440.01,30,380,0
0.021481481,384.2,392,127,88.2,75,93.4884,124.6511,392,6.7,6.5159,11440.01,30,380,0
0.021539352,384.2,392,130,117.61,100,93.4884,93.4884,392,6.5,6.5159,11440.01,30,380,0
0.021597222,384.2,392,130,117.61,100,93.4884,93.4884,392,6.8,6.5159,11440.01,30,380,0
0.021655093,384.2,392,130,58.8,50,93.4884,186.9767,392,6.6,6.5159,11440.01,30,380,0
0.021712963,384.2,392,127,58.8,50,93.4884,186.9767,392,6.8,6.5159,11440.01,30,380,0
0.021782407,384.2,392,130,58.8,50,93.4884,186.9767,392,6.8,6.5159,11440.01,30,380,0
0.021840278,384.2,392,155,58.8,50,93.4884,186.9767,392,6.4,6.5159,11440.01,30,380,0
0.021898148,384.4,392,202,58.8,50,93.4884,186.9767,392,6.6,6.5159,11440.01,30,380,0
0.021956019,384.4,392,214,58.8,50,92.9722,185.9443,392,6.7,6.4799,11376.84,30,379,0
0.022013889,384.4,392,239,58.8,50,92.9722,185.9443,392,6.6,6.4799,11376.84,30,379,0
0.022071759,384.6,392,283,58.8,50,92.9722,185.9443,392,6.5,6.4799,11376.84,30,379,0
0.022141204,384.4,392,289,58.8,50,92.9722,185.9443,392,6.6,6.4799,11376.84,30,379,0
0.022199074,384.8,392,339,58.8,50,92.9722,185.9443,392,6.5,6.4799,11376.84,30,379,0
0.022256944,384.8,392,357,58.8,50,92.9722,185.9443,392,6.6,6.4799,11376.84,30,379,0
0.022314815,384.8,392,391,58.8,50,92.9722,185.9443,392,6.6,6.4799,11376.84,30,379,0
0.022372685,384.8,392,401,58.8,50,92.9722,185.9443,392,6.8,6.4799,11376.84,30,379,0
0.02244213,384.8,392,413,58.8,50,92.9722,185.9443,392,6.9,6.4799,11376.84,30,379,0
0.0225,384.8,392,425,58.8,50,92.9722,185.9443,392,7.1,6.4799,11376.84,30,379,0
0.02255787,384.8,392,438,58.8,50,92.9722,185.9443,392,6.6,6.4799,11376.84,30,379,0
0.022615741,384.8,392,447,58.8,50,92.9722,185.9443,392,6.7,6.4799,11376.84,30,379,0
0.022673611,384.6,392,453,58.8,50,92.9722,185.9443,392,6.6,6.4799,11376.84,30,379,0
0.022743056,384.6,392,460,58.8,50,92.9722,185.9443,392,6.6,6.4799,11376.84,30,379,0
0.022800926,384.6,392,469,58.8,50,92.9722,185.9443,392,6.8,6.4799,11376.84,30,379,0
0.022858796,384.8,392,472,58.8,50,92.9722,185.9443,392,6.9,6.4799,11376.84,30,379,0
0.022916667,384.8,392,481,58.8,50,92.9722,185.9443,392,6.8,6.4799,11376.84,30,379,0
0.022974537,384.8,392,491,58.8,50,92.9722,185.9443,392,6.9,6.4799,11376.84,30,379,0
0.023032407,384.8,392,497,58.8,50,92.9722,185.9443,392,6.8,6.4799,11376.84,30,379,0
0.023101852,384.8,392,506,58.8,50,92.9722,185.9443,392,6.6,6.4799,11376.84,30,379,0
0.023159722,384.8,392,509,58.8,50,92.9722,185.9443,392,6.9,6.4799,11376.84,30,379,0
0.023217593,384.8,392,512,58.8,50,92.9722,185.9443,392,6.8,6.4799,11376.84,30,379,0
0.023275463,384.8,392,512,58.8,50,92.9722,185.9443,392,7.2,6.4799,11376.84,30,379,0
0.023333333,384.8,392,512,58.8,50,92.456,184.9119,392,6.5,6.4439,11313.68,30,378,0
0.023391204,384.8,392,512,58.8,50,92.456,184.9119,392,6.8,6.4439,11313.68,30,378,0
0.023449074,384.8,392,512,58.8,50,92.456,184.9119,392,6.3,6.4439,11313.68,30,378,0
0.023506944,384.8,392,512,58.8,50,92.456,184.9119,392,6.5,6.4439,11313.68,30,378,0
0.023564815,384.8,392,512,58.8,50,92.456,184.9119,392,6.7,6.4439,11313.68,30,378,0
0.023622685,384.8,392,512,58.8,50,92.456,184.9119,392,6.9,6.4439,11313.68,30,378,0
0.023680556,384.8,392,512,58.8,50,92.456,184.9119,392,7,6.4439,11313.68,30,378,0
0.023738426,384.8,392,512,117.61,100,92.456,92.456,392,6.4,6.4439,11313.68,30,378,0
0.02380787,384.8,392,512,117.61,100,92.456,92.456,392,6.7,6.4439,11313.68,30,378,0
0.023865741,384.8,392,512,88.2,75,92.456,123.2746,392,6.9,6.4439,11313.68,30,378,0
0.023923611,384.8,392,512,88.2,75,92.456,123.2746,392,7,6.4439,11313.68,30,378,0
0.023981481,384.8,392,512,58.8,50,92.456,184.9119,392,6.8,6.4439,11313.68,30,378,0
0.024039352,384.8,392,512,29.4,25,92.456,369.8239,392,6.9,6.4439,11313.68,30,378,0
0.024097222,384.8,392,512,29.4,25,92.456,369.8239,392,6.7,6.4439,11313.68,30,378,0
0.024155093,384.8,392,512,58.8,50,92.456,369.8239,392,7,6.4439,11313.68,30,378,0
0.024212963,384.8,392,512,58.8,50,92.456,184.9119,392,6.9,6.4439,11313.68,30,378,0
0.024270833,384.8,392,512,88.2,75,91.9398,183.8795,392,6.6,6.4079,11250.51,30,377,0
0.024328704,384.9,392,509,88.2,75,91.9398,122.5863,392,6.8,6.4079,11250.51,30,377,0
0.024398148,384.8,392,509,117.61,100,91.9398,91.9398,392,6.6,6.4079,11250.51,30,377,0
0.024456019,384.8,392,512,117.61,100,91.9398,91.9398,392,7,6.4079,11250.51,30,377,0
0.024513889,384.8,392,512,58.8,50,91.9398,183.8795,392,6.7,6.4079,11250.51,30,377,0
0.024571759,384.8,392,512,58.8,50,91.9398,183.8795,392,6.9,6.4079,11250.51,30,377,0
0.024641204,384.8,392,512,58.8,50,91.9398,183.8795,392,6.7,6.4079,11250.51,30,377,0
0.024699074,384.8,392,525,58.8,50,91.9398,183.8795,392,7,6.4079,11250.51,30,377,0
0.024756944,385.1,392,590,58.8,50,91.9398,183.8795,392,6.9,6.4079,11250.51,30,377,0
0.024814815,385.1,392,606,58.8,50,91.9398,183.8795,392,6.6,6.4079,11250.51,30,377,0
0.024872685,385.3,392,649,58.8,50,91.9398,183.8795,392,6.7,6.4079,11250.51,30,377,0
0.024930556,385.1,392,665,58.8,50,91.4236,182.8471,392,6.8,6.3719,11187.34,30,376,0
0.024988426,385.1,392,674,58.8,50,91.4236,182.8471,392,6.7,6.3719,11187.34,30,376,0
0.025046296,385.1,392,689,58.8,50,91.4236,182.8471,392,6.8,6.3719,11187.34,30,376,0
0.025104167,385.1,392,702,58.8,50,91.4236,182.8471,392,6.7,6.3719,11187.34,30,376,0
0.025162037,385.1,392,711,58.8,50,91.4236,182.8471,392,6.9,6.3719,11187.34,30,376,0
0.025219907,385.1,392,714,58.8,50,91.4236,182.8471,392,6.6,6.3719,11187.34,30,376,0
0.025289352,385.1,392,727,58.8,50,91.4236,182.8471,392,6.9,6.3719,11187.34,30,376,0
0.025347222,385.3,392,742,58.8,50,91.4236,182.8471,392,6.9,6.3719,11187.34,30,376,0
0.025405093,385.1,392,761,58.8,50,90.9074,181.8147,392,6.6,6.3359,11124.18,30,375,0
0.025462963,385.1,392,764,58.8,50,90.9074,181.8147,392,7,6.3359,11124.18,30,375,0
0.025520833,385.1,392,764,58.8,50,90.9074,181.8147,392,6.7,6.3359,11124.18,30,375,0
0.025578704,385.1,392,764,58.8,50,90.9074,181.8147,392,6.6,6.3359,11124.18,30,375,0
0.025636574,385.1,392,764,58.8,50,90.9074,181.8147,392,7.2,6.3359,11124.18,30,375,0
0.025694444,385.1,392,767,58.8,50,90.9074,181.8147,392,6.8,6.3359,11124.18,30,375,0
0.025752315,385.1,392,767,58.8,50,90.9074,181.8147,392,6.9,6.3359,11124.18,30,375,0
0.025810185,385.1,392,770,58.8,50,90.3912,180.7823,392,6.6,6.2999,11061.01,30,374,0
0.025868056,385.1,392,770,58.8,50,90.3912,180.7823,392,7,6.2999,11061.01,30,374,0
0.025925926,385.1,392,776,58.8,50,90.3912,180.7823,392,6.6,6.2999,11061.01,30,374,0
0.025983796,385.1,392,780,58.8,50,90.3912,180.7823,392,6.8,6.2999,11061.01,30,374,0
0.026053241,385.1,392,780,58.8,50,90.3912,180.7823,392,7,6.2999,11061.01,30,374,0
0.026111111,385.1,392,783,58.8,50,90.3912,180.7823,392,7.1,6.2999,11061.01,30,374,0
0.026168981,385.1,392,786,58.8,50,90.3912,180.7823,392,6.9,6.2999,11061.01,30,374,0
0.026226852,385.1,392,792,58.8,50,90.3912,180.7823,392,6.8,6.2999,11061.01,30,374,0
0.026284722,385.1,392,795,58.8,50,90.3912,180.7823,392,6.5,6.2999,11061.01,30,374,0
0.026342593,385.1,392,798,58.8,50,90.3912,180.7823,392,6.5,6.2999,11061.01,30,374,0
0.026400463,385.1,392,801,58.8,50,89.875,179.75,392,6.8,6.2639,10997.85,30,373,0
0.026458333,385.1,392,801,58.8,50,89.875,179.75,392,6.9,6.2639,10997.85,30,373,0
0.026539352,385.1,392,811,58.8,50,89.875,179.75,392,7,6.2639,10997.85,30,373,0
0.026597222,385.1,392,811,117.61,100,89.875,89.875,392,6.4,6.2639,10997.85,30,373,0
0.026655093,385.1,392,814,117.61,100,89.875,89.875,392,6.8,6.2639,10997.85,30,373,0
0.026736111,385.1,392,814,88.2,75,89.875,119.8333,392,6.8,6.2639,10997.85,30,373,0
0.026805556,385.1,392,814,88.2,75,89.875,119.8333,392,6.9,6.2639,10997.85,30,373,0
0.026863426,385.1,392,814,58.8,50,89.875,179.75,392,7,6.2639,10997.85,30,373,0
0.026921296,384.9,392,814,58.8,50,89.875,179.75,392,6.9,6.2639,10997.85,30,373,0
0.026979167,385.1,392,817,29.4,25,89.3588,357.4352,392,6.6,6.2279,10934.68,30,372,0
0.027037037,385.1,392,814,58.8,50,89.3588,178.7176,392,6.3,6.2279,10934.68,30,372,0
0.027094907,385.1,392,814,58.8,50,89.3588,178.7176,392,6.6,6.2279,10934.68,30,372,0
0.027152778,385.1,392,814,88.2,75,89.3588,119.1451,392,7.2,6.2279,10934.68,30,372,0
0.027222222,385.1,392,814,88.2,75,89.3588,119.1451,392,7,6.2279,10934.68,30,372,0
0.027280093,385.1,392,811,117.61,100,89.3588,119.1451,392,6.5,6.2279,10934.68,30,372,0
0.027337963,385.1,392,811,117.61,100,89.3588,89.3588,392,6.9,6.2279,10934.68,30,372,0
0.027395833,385.1,392,814,58.8,50,89.3588,178.7176,392,6.9,6.2279,10934.68,30,372,0
0.027453704,385.1,392,811,58.8,50,89.3588,178.7176,392,6.9,6.2279,10934.68,30,372,0
0.027511574,385.1,392,873,58.8,50,88.8426,177.6852,392,7,6.1919,10871.51,30,371,0
0.027569444,385.7,392,919,58.8,50,88.8426,177.6852,392,6.9,6.1919,10871.51,30,371,0
0.027627315,386,392,1034,58.8,50,88.8426,177.6852,392,6.8,6.1919,10871.51,30,371,0
0.027685185,385.7,392,1065,58.8,50,88.8426,177.6852,392,6.7,6.1919,10871.51,30,371,0
0.027743056,385.7,392,1099,58.8,50,88.8426,177.6852,392,6.8,6.1919,10871.51,30,371,0
0.027800926,385.5,392,1127,58.8,50,88.8426,177.6852,392,6.9,6.1919,10871.51,30,371,0
0.02787037,385.3,392,1134,58.8,50,88.8426,177.6852,392,6.6,6.1919,10871.51,30,371,0
0.027928241,385.3,392,1134,58.8,50,88.8426,177.6852,392,6.8,6.1919,10871.51,30,371,0
0.027986111,385.3,392,1174,58.8,50,88.8426,177.6852,392,6.7,6.1919,10871.51,30,371,0
0.028043981,385.3,392,1196,58.8,50,88.8426,177.6852,392,6.9,6.1919,10871.51,30,371,0
0.028101852,385.3,392,1205,58.8,50,88.8426,177.6852,392,6.8,6.1919,10871.51,30,371,0
0.028159722,385.3,392,1208,58.8,50,88.3264,176.6528,392,6.7,6.1559,10808.35,30,370,0
0.028217593,385.3,392,1205,58.8,50,88.3264,176.6528,392,6.7,6.1559,10808.35,30,370,0
0.028275463,385.3,392,1208,58.8,50,88.3264,176.6528,392,6.9,6.1559,10808.35,30,370,0
0.028333333,385.1,392,1208,58.8,50,88.3264,176.6528,392,7.2,6.1559,10808.35,30,370,0
0.028391204,385.1,392,1208,58.8,50,88.3264,176.6528,392,6.9,6.1559,10808.35,30,370,0
0.028449074,385.1,392,1211,58.8,50,88.3264,176.6528,392,6.4,6.1559,10808.35,30,370,0
0.028518519,385.3,392,1211,58.8,50,88.3264,176.6528,392,6.6,6.1559,10808.35,30,370,0
0.028576389,385.3,392,1211,58.8,50,87.8102,175.6204,392,6.9,6.1199,10745.18,30,369,0
0.028634259,385.3,392,1217,58.8,50,87.8102,175.6204,392,7.1,6.1199,10745.18,30,369,0
0.02869213,385.3,392,1211,58.8,50,87.8102,175.6204,392,6.9,6.1199,10745.18,30,369,0
0.02875,385.3,392,1211,58.8,50,87.8102,175.6204,392,6.6,6.1199,10745.18,30,369,0
0.02880787,385.1,392,1211,58.8,50,87.8102,175.6204,392,6.7,6.1199,10745.18,30,369,0
0.028865741,385.1,392,1211,58.8,50,87.8102,175.6204,392,7,6.1199,10745.18,30,369,0
0.028923611,385.1,392,1208,58.8,50,87.8102,175.6204,392,7,6.1199,10745.18,30,369,0
0.028981481,385.3,392,1342,58.8,50,87.8102,175.6204,392,7.1,6.1199,10745.18,30,369,0
0.029039352,386,392,1425,58.8,50,87.294,174.588,392,7,6.0839,10682.02,30,368,0
0.029097222,385.5,392,1407,58.8,50,87.294,174.588,392,6.9,6.0839,10682.02,30,368,0
0.029155093,385.3,392,1401,58.8,50,87.294,174.588,392,7,6.0839,10682.02,30,368,0
0.029224537,385.3,392,1394,58.8,50,87.294,174.588,392,6.7,6.0839,10682.02,30,368,0
0.029282407,385.3,392,1391,58.8,50,87.294,174.588,392,6.7,6.0839,10682.02,30,368,0
0.029340278,385.3,392,1382,58.8,50,86.7778,173.5556,392,7.2,6.0479,10618.85,30,367,0
0.029398148,385.3,392,1376,58.8,50,86.7778,173.5556,392,7,6.0479,10618.85,30,367,0
0.029467593,385.3,392,1366,117.61,100,86.7778,173.5556,392,7,6.0479,10618.85,30,367,0
0.029525463,385.1,392,1363,117.61,100,86.7778,86.7778,392,6.8,6.0479,10618.85,30,367,0
0.029583333,385.1,392,1348,88.2,75,86.7778,115.7037,392,7.1,6.0479,10618.85,30,367,0
0.029641204,385.1,392,1342,88.2,75,86.7778,115.7037,392,7,6.0479,10618.85,30,367,0
0.029699074,385.1,392,1339,58.8,50,86.7778,173.5556,392,6.9,6.0479,10618.85,30,367,0
0.029756944,385.1,392,1329,58.8,50,86.7778,173.5556,392,6.8,6.0479,10618.85,30,367,0
0.029814815,385.1,392,1320,29.4,25,86.7778,347.1112,392,6.7,6.0479,10618.85,30,367,0
0.029872685,385.1,392,1320,29.4,25,86.7778,347.1112,392,6.8,6.0479,10618.85,30,367,0
0.029930556,385.1,392,1311,58.8,50,86.7778,173.5556,392,6.9,6.0479,10618.85,30,367,0
0.03,385.1,392,1304,58.8,50,86.2616,172.5232,392,7.2,6.0119,10555.68,30,366,0
0.03005787,385.1,392,1298,88.2,75,86.2616,115.0155,392,6.8,6.0119,10555.68,30,366,0
0.030115741,385.1,392,1286,88.2,75,86.2616,115.0155,392,7,6.0119,10555.68,30,366,0
0.030173611,385.1,392,1280,117.61,100,86.2616,86.2616,392,6.9,6.0119,10555.68,30,366,0
0.030231481,385.1,392,1276,117.61,100,86.2616,86.2616,392,7.1,6.0119,10555.68,30,366,0
0.030289352,385.1,392,1270,58.8,50,86.2616,172.5232,392,6.8,6.0119,10555.68,30,366,0
0.030347222,385.1,392,1264,58.8,50,86.2616,172.5232,392,6.8,6.0119,10555.68,30,366,0
0.030405093,385.1,392,1261,58.8,50,86.2616,172.5232,392,6.9,6.0119,10555.68,30,366,0
0.030462963,384.9,392,1258,58.8,50,82.6482,165.2965,392,6.9,5.7599,10113.52,30,359,0
0.030532407,385.1,392,1245,58.8,50,82.6482,165.2965,392,7,5.7599,10113.52,30,359,0
0.030590278,385.1,392,1242,58.8,50,82.6482,165.2965,392,7.2,5.7599,10113.52,30,359,0
0.030648148,385.1,392,1298,58.8,50,82.6482,165.2965,392,6.4,5.7599,10113.52,30,359,0
0.030706019,385.5,392,1394,58.8,50,82.6482,165.2965,392,6.9,5.7599,10113.52,30,359,0
0.030763889,386,392,1553,58.8,50,82.6482,165.2965,392,7.3,5.7599,10113.52,30,359,0
0.030821759,385.8,392,1621,58.8,50,82.6482,165.2965,392,6.9,5.7599,10113.52,30,359,0
0.030891204,386,392,1758,58.8,50,82.6482,165.2965,392,7.2,5.7599,10113.52,30,359,0
0.030949074,386,392,1814,58.8,50,82.6482,165.2965,392,6.9,5.7599,10113.52,30,359,0
0.031006944,385.7,392,1817,58.8,50,82.6482,165.2965,392,6.9,5.7599,10113.52,30,359,0
0.031064815,385.3,392,1823,58.8,50,82.132,164.2641,392,7,5.7239,10050.36,30,358,0
0.031122685,385.3,392,1823,58.8,50,82.132,164.2641,392,6.9,5.7239,10050.36,30,358,0
0.031180556,385.3,392,1823,58.8,50,82.132,164.2641,392,6.9,5.7239,10050.36,30,358,0
0.031238426,385.3,392,1823,58.8,50,82.132,164.2641,392,6.6,5.7239,10050.36,30,358,0
0.031296296,385.3,392,1823,58.8,50,82.132,164.2641,392,7,5.7239,10050.36,30,358,0
0.031354167,385.3,392,1823,58.8,50,82.132,164.2641,392,6.9,5.7239,10050.36,30,358,0
0.031412037,385.3,392,1820,58.8,50,82.132,164.2641,392,6.7,5.7239,10050.36,30,358,0
0.031481481,385.3,392,1820,58.8,50,82.132,164.2641,392,6.8,5.7239,10050.36,30,358,0
0.031539352,385.3,392,1823,58.8,50,82.132,164.2641,392,7.2,5.7239,10050.36,30,358,0
0.031597222,385.3,392,1820,58.8,50,82.132,164.2641,392,6.8,5.7239,10050.36,30,358,0
0.031655093,385.3,392,1820,58.8,50,81.6159,163.2317,392,7,5.6879,9987.19,30,357,0
0.031712963,385.3,392,1823,58.8,50,81.6159,163.2317,392,6.8,5.6879,9987.19,30,357,0
0.031770833,385.3,392,1820,58.8,50,81.6159,163.2317,392,6.9,5.6879,9987.19,30,357,0
0.031828704,385.3,392,1823,58.8,50,81.6159,163.2317,392,7,5.6879,9987.19,30,357,0
0.031886574,385.3,392,1823,58.8,50,81.6159,163.2317,392,6.7,5.6879,9987.19,30,357,0
0.031956019,385.3,392,1823,58.8,50,81.6159,163.2317,392,6.8,5.6879,9987.19,30,357,0
0.032013889,385.3,392,1820,58.8,50,81.6159,163.2317,392,7.3,5.6879,9987.19,30,357,0
0.032071759,385.1,392,1820,58.8,50,81.6159,163.2317,392,7.1,5.6879,9987.19,30,357,0
0.032141204,385.3,392,1820,58.8,50,81.6159,163.2317,392,6.9,5.6879,9987.19,30,357,0
0.032199074,385.1,392,1817,58.8,50,81.6159,163.2317,392,6.8,5.6879,9987.19,30,357,0
0.032256944,385.3,392,1817,58.8,50,81.6159,163.2317,392,6.7,5.6879,9987.19,30,357,0
0.032314815,385.3,392,1820,117.61,100,81.6159,163.2317,392,7,5.6879,9987.19,30,357,0
0.032372685,385.3,392,1820,117.61,100,81.6159,81.6159,392,7.1,5.6879,9987.19,30,357,0
0.032430556,385.3,392,1820,88.2,75,81.6159,81.6159,392,6.9,5.6879,9987.19,30,357,0
0.032488426,385.3,392,1820,88.2,75,81.6159,108.8211,392,6.8,5.6879,9987.19,30,357,0
0.032546296,385.1,392,1820,58.8,50,81.0997,108.1329,392,6.9,5.6519,9924.024,30,356,0
0.032604167,385.1,392,1820,58.8,50,81.0997,162.1993,392,6.9,5.6519,9924.024,30,356,0
0.032662037,385.1,392,1817,29.4,25,81.0997,324.3986,392,6.7,5.6519,9924.024,30,356,0
0.032719907,385.1,392,1820,29.4,25,81.0997,324.3986,392,7,5.6519,9924.024,30,356,0
0.032777778,385.1,392,1820,58.8,50,81.0997,162.1993,392,7.4,5.6519,9924.024,30,356,0
0.032835648,385.1,392,1820,58.8,50,81.0997,162.1993,392,7,5.6519,9924.024,30,356,0
0.032905093,385.1,392,1820,88.2,75,81.0997,108.1329,392,6.9,5.6519,9924.024,30,356,0
0.032962963,385.1,392,1820,88.2,75,81.0997,108.1329,392,6.8,5.6519,9924.024,30,356,0
0.033020833,385.1,392,1820,117.61,100,81.0997,81.0997,392,7,5.6519,9924.024,30,356,0
0.033078704,385.1,392,1823,117.61,100,81.0997,81.0997,392,7.3,5.6519,9924.024,30,356,0
0.033136574,385.1,392,1820,58.8,50,81.0997,162.1993,392,6.9,5.6519,9924.024,30,356,0
0.033194444,385.1,392,1820,58.8,50,81.0997,162.1993,392,6.9,5.6519,9924.024,30,356,0
0.033252315,385.1,392,1820,58.8,50,81.0997,162.1993,392,6.8,5.6519,9924.024,30,356,0
0.033310185,385.1,392,1820,58.8,50,81.0997,162.1993,392,7,5.6519,9924.024,30,356,0
0.03337963,385.1,392,1820,58.8,50,81.0997,162.1993,392,7.2,5.6519,9924.024,30,356,0
0.0334375,385.1,392,1820,58.8,50,81.0997,162.1993,392,6.9,5.6519,9924.024,30,356,0
0.03349537,385.1,392,1820,58.8,50,81.0997,162.1993,392,6.6,5.6519,9924.024,30,356,0
0.033553241,385.1,392,1820,58.8,50,81.0997,162.1993,392,7.1,5.6519,9924.024,30,356,0
0.033611111,385.1,392,1820,58.8,50,81.0997,162.1993,392,7.4,5.6519,9924.024,30,356,0
0.033668981,385.1,392,1820,58.8,50,81.0997,162.1993,392,6.9,5.6519,9924.024,30,356,0
0.033726852,385.1,392,1820,58.8,50,81.0997,162.1993,392,6.8,5.6519,9924.024,30,356,0
0.033784722,385.1,392,1820,58.8,50,81.0997,162.1993,392,7.4,5.6519,9924.024,30,356,0
0.033842593,385.1,392,1820,58.8,50,80.5835,161.1669,392,6.8,5.6159,9860.858,30,355,0
0.033900463,385.1,392,1820,58.8,50,80.5835,161.1669,392,6.7,5.6159,9860.858,30,355,0
0.033958333,385.1,392,1820,58.8,50,80.5835,161.1669,392,7.2,5.6159,9860.858,30,355,0
0.034016204,385.1,392,1820,58.8,50,80.5835,161.1669,392,7,5.6159,9860.858,30,355,0
0.034074074,385.1,392,1820,58.8,50,80.5835,161.1669,392,7,5.6159,9860.858,30,355,0
0.034131944,385.1,392,1820,58.8,50,80.5835,161.1669,392,6.8,5.6159,9860.858,30,355,0
0.034201389,385.1,392,1820,58.8,50,80.5835,161.1669,392,7.1,5.6159,9860.858,30,355,0
0.034259259,385.1,392,1820,58.8,50,80.5835,161.1669,392,6.9,5.6159,9860.858,30,355,0
0.03431713,385.1,392,1820,58.8,50,80.5835,161.1669,392,6.7,5.6159,9860.858,30,355,0
0.034375,385.1,392,1820,58.8,50,80.5835,161.1669,392,7.3,5.6159,9860.858,30,355,0
0.03443287,385.1,392,1820,58.8,50,80.5835,161.1669,392,7.1,5.6159,9860.858,30,355,0
0.034490741,385.1,392,1823,58.8,50,80.5835,161.1669,392,7.3,5.6159,9860.858,30,355,0
0.034548611,385.1,392,1820,58.8,50,80.0673,160.1345,392,7,5.5799,9797.692,30,354,0
0.034606481,385.1,392,1820,58.8,50,80.0673,160.1345,392,7,5.5799,9797.692,30,354,0
0.034664352,385.1,392,1820,58.8,50,80.0673,160.1345,392,6.8,5.5799,9797.692,30,354,0
0.034722222,385.1,392,1820,58.8,50,80.0673,160.1345,392,6.6,5.5799,9797.692,30,354,0
0.034780093,385.1,392,1820,58.8,50,80.0673,160.1345,392,7.1,5.5799,9797.692,30,354,0
0.034837963,385.1,392,1820,58.8,50,80.0673,160.1345,392,7.1,5.5799,9797.692,30,354,0
0.034907407,385.1,392,1820,58.8,50,80.0673,160.1345,392,6.8,5.5799,9797.692,30,354,0
0.034965278,385.1,392,1820,58.8,50,80.0673,160.1345,392,6.8,5.5799,9797.692,30,354,0
0.035023148,385.1,392,1820,58.8,50,80.0673,160.1345,392,6.7,5.5799,9797.692,30,354,0
0.035081019,385.1,392,1820,58.8,50,80.0673,160.1345,392,7.4,5.5799,9797.692,30,354,0
0.035138889,385.1,392,1820,58.8,50,80.0673,160.1345,392,7.1,5.5799,9797.692,30,354,0
0.035162037,385.1,392,1817,58.8,50,80.0673,160.1345,392,6.9,5.5799,9797.692,30,354,0